Workbook

Sheet Creature
A1: ID | B1: Name | C1: Camp | D1: Type | E1: Cost | F1: Career | G1: SoldierLv | H1: Quality | I1: Star | J1: Icon | K1: Icon1 | L1: Audio | M1: HP | N1: UpHP | O1: Atk | P1: UpAtk | Q1: Def | R1: UpDef | S1: Ap | T1: UpAp | U1: Mdef | V1: UpMdef | W1: Dex | X1: UpDex | Y1: Range | Z1: Warn | AA1: Move | AB1: AtkCd | AC1: AtkGoal | AD1: Talent | AE1: InitCareer | AF1: Synthesis | AG1: Show | AH1: SoldierShow | AI1: SplashTalk | AJ1: Amplify1 | AK1: Amplify2 | AL1: Add | AM1: Camp | AN1: FlyOrLand | AO1: LockLv | AP1: Shop | AQ1: Persent | AR1: Leader | AS1: UpLeader | AT1: Skill | AU1: Mp | AV1: UpMp
A2: int | B2: string | C2: int | D2: int | E2: string | F2: int | G2: int | H2: int | I2: int | J2: string | K2: string | L2: string | M2: int | N2: float | O2: int | P2: float | Q2: int | R2: float | S2: int | T2: float | U2: int | V2: float | W2: int | X2: float | Y2: int | Z2: int | AA2: int | AB2: int | AC2: int | AD2: string | AE2: string | AF2: string | AG2: int | AH2: string | AI2: string | AJ2: float | AK2: float | AL2: int | AM2: int | AN2: int | AO2: int | AP2: int | AQ2: int | AR2: int | AS2: float | AT2: string | AU2: int | AV2: float
A3: id | B3: 名字 | C3: 种族 | D3: 类型1 | E3: 花费 | F3: 初始职业 | G3: 士兵等级 | H3: 品质（D-SSS） | I3: 初始星级 | J3: 模型 | K3: 图标 | L3: 配音资源 | M3: 生命值 | N3: 生命值成长 | O3: 攻击 | P3: 攻击每级成长值 | Q3: 防御 | R3: 防御每级成长值 | S3: 魔力 | T3: 魔力每级成长值 | U3: 魔防 | V3: 魔防值每级成长值 | W3: 技巧 | X3: 技巧加成 | Y3: 攻击距离 | Z3: 警戒范围 | AA3: 移速 | AB3: 攻击间隔/8 | AC3: 攻击目标 | AD3: 携带天赋 | AE3: 初始职业 | AF3: 重复获得和合成 | AG3: 分解道具碎片展示 | AH3: 兵种展示 | AI3: boss闪屏的话 | AJ3: 查看界面放大 | AK3: 地图模型放大 | AL3: 战斗战力 | AM3: 种族 | AN3: 类型0地面1飞兵 | AO3: 解锁章节 | AP3: 购买价格 | AQ3: 抽卡概率权重值 | AR3: 英雄领导力 | AS3: 领导力成长 | AT3: 技能 | AU3: 魔法值 | AV3: 魔法值每级成长值
A4: 11001 | B4: 玛伦 | C4: 1 | D4: 1 | E4: 1:300 | F4: 1 | G4: 0 | H4: 1 | I4: 1 | J4: Mahlon.1 | K4: Mahlon.1 | L4: 0 | M4: 600 | N4: 10 | O4: =英雄数据!N4 -> 74 | P4: =英雄数据!O4 -> 2.09 | Q4: =英雄数据!R4 -> 34 | R4: =英雄数据!S4 -> 1.43 | S4: =英雄数据!V4 -> 45 | T4: =英雄数据!W4 -> 1.21 | U4: =英雄数据!Z4 -> 28 | V4: =英雄数据!AA4 -> 1.32 | W4: 14 | X4: 1 | Y4: 250 | Z4: =MIN(Y4+400,1300) -> 650 | AA4: 400 | AB4: 8 | AC4: =_xlfn.IFS(OR(F4="1",F4="2",F4="7",F4="8"),2,OR(F4="3",F4="4",F4="5",F4="6"),1) -> 2 | AD4: 110011|110012|110013|110014|110010|110016|110017 | AE4: 110002 | AF4: 101001:5 | AG4: 101001 | AH4: 111002:121001:131001:141001:151001:161002 | AI4: 0 | AJ4: 1 | AK4: 1.7 | AL4: 0 | AM4: 3 | AN4: 0 | AO4: 0 | AP4: 2500 | AQ4: 8 | AR4: 60 | AS4: 12 | AT4: 514+1|0+0|516+0|-1+0|701+0|-1+0|174+0|-1+0|801+0 | AU4: 0 | AV4: 0
A5: 12001 | B5: 克莱斯 | C5: 1 | D5: 1 | E5: 1:300 | F5: 2 | G5: 0 | H5: 1 | I5: 1 | J5: Kress.1 | K5: Kress.1 | L5: 0 | M5: 590 | N5: 14 | O5: =英雄数据!N5 -> 78 | P5: =英雄数据!O5 -> 2.2 | Q5: =英雄数据!R5 -> 30 | R5: =英雄数据!S5 -> 1.32 | S5: =英雄数据!V5 -> 41 | T5: =英雄数据!W5 -> 1.21 | U5: =英雄数据!Z5 -> 27 | V5: =英雄数据!AA5 -> 1.32 | W5: 16 | X5: 1 | Y5: 250 | Z5: =MIN(Y5+400,1300) -> 650 | AA5: 550 | AB5: 8 | AC5: =_xlfn.IFS(OR(F5="1",F5="2",F5="7",F5="8"),2,OR(F5="3",F5="4",F5="5",F5="6"),1) -> 2 | AD5: 110021|110015|110023|110024|110025|110026|110027 | AE5: 110003 | AF5: 102001:5 | AG5: 102001 | AH5: 811001:821001:731001:241001:251001:161001 | AI5: 0 | AJ5: 1 | AK5: 1.7 | AL5: 0 | AM5: 1 | AN5: 1 | AO5: 0 | AP5: 3000 | AQ5: 3 | AR5: 45 | AS5: 8 | AT5: 560+1|0+0|903+0|-1+0|704+0|-1+0|179+0|-1+0|804+0 | AU5: 0 | AV5: 0
A6: 13001 | B6: 艾丝琳 | C6: 1 | D6: 1 | E6: 1:300 | F6: 3 | G6: 0 | H6: 1 | I6: 1 | J6: Eileen.1 | K6: Eileen.1 | L6: 0 | M6: 500 | N6: 12 | O6: =英雄数据!N6 -> 68 | P6: =英雄数据!O6 -> 1.87 | Q6: =英雄数据!R6 -> 23 | R6: =英雄数据!S6 -> 1.1 | S6: =英雄数据!V6 -> 37 | T6: =英雄数据!W6 -> 1.32 | U6: =英雄数据!Z6 -> 25 | V6: =英雄数据!AA6 -> 1.43 | W6: 15 | X6: 1 | Y6: 1200 | Z6: =MIN(Y6+400,1300) -> 1300 | AA6: 400 | AB6: 10 | AC6: =_xlfn.IFS(OR(F6="1",F6="2",F6="7",F6="8"),2,OR(F6="3",F6="4",F6="5",F6="6"),1) -> 1 | AD6: 110031|110032|110033|110034|110035|110036|110037 | AE6: 110004 | AF6: 103001:5 | AG6: 103001 | AH6: 111002:321001:331001:341001:351001:361001 | AI6: 0 | AJ6: 1 | AK6: 1.7 | AL6: 0 | AM6: 2 | AN6: 0 | AO6: 2 | AP6: 2500 | AQ6: 14 | AR6: 30 | AS6: 9 | AT6: 510+1|0+0|503+0|-1+0|703+0|-1+0|174+0|-1+0|803+0 | AU6: 0 | AV6: 0
A7: 14001 | B7: 克莱亚 | C7: 1 | D7: 1 | E7: 1:300 | F7: 4 | G7: 0 | H7: 1 | I7: 1 | J7: Lela.1 | K7: Lela.1 | L7: 0 | M7: 570 | N7: 13.5 | O7: =英雄数据!N7 -> 72 | P7: =英雄数据!O7 -> 2.2 | Q7: =英雄数据!R7 -> 28 | R7: =英雄数据!S7 -> 1.32 | S7: =英雄数据!V7 -> 47 | T7: =英雄数据!W7 -> 1.32 | U7: =英雄数据!Z7 -> 30 | V7: =英雄数据!AA7 -> 1.54 | W7: 18 | X7: 1 | Y7: 250 | Z7: =MIN(Y7+400,1300) -> 650 | AA7: 550 | AB7: 8 | AC7: =_xlfn.IFS(OR(F7="1",F7="2",F7="7",F7="8"),2,OR(F7="3",F7="4",F7="5",F7="6"),1) -> 1 | AD7: 110041|110042|110043|110044|110045|110046|110047 | AE7: 110005 | AF7: 104001:5 | AG7: 104001 | AH7: 411001:121001:431001:441001:451001:461001 | AI7: 0 | AJ7: 1 | AK7: 1.7 | AL7: 0 | AM7: 3 | AN7: 0 | AO7: 2 | AP7: 2500 | AQ7: 4 | AR7: 60 | AS7: 10 | AT7: 505+1|0+0|511+0|-1+0|702+0|-1+0|175+0|-1+0|802+0 | AU7: 0 | AV7: 0
A8: 15001 | B8: 法拉 | C8: 2 | D8: 1 | E8: 1:300 | F8: 5 | G8: 0 | H8: 1 | I8: 1 | J8: Farad.1 | K8: Farad.1 | L8: 0 | M8: 500 | N8: 11 | O8: =英雄数据!N8 -> 49 | P8: =英雄数据!O8 -> 2.2 | Q8: =英雄数据!R8 -> 16 | R8: =英雄数据!S8 -> 1.1 | S8: =英雄数据!V8 -> 69 | T8: =英雄数据!W8 -> 2.2 | U8: =英雄数据!Z8 -> 33 | V8: =英雄数据!AA8 -> 1.76 | W8: 12 | X8: 1 | Y8: 1200 | Z8: =MIN(Y8+400,1300) -> 1300 | AA8: 400 | AB8: 10 | AC8: =_xlfn.IFS(OR(F8="1",F8="2",F8="7",F8="8"),2,OR(F8="3",F8="4",F8="5",F8="6"),1) -> 1 | AD8: 110051|110052|110053|110054|110055|110056|110057 | AE8: 110006 | AF8: 105001:5 | AG8: 105001 | AH8: 111001:521001:531001:541001:351001:561001 | AI8: 0 | AJ8: 1 | AK8: 1.7 | AL8: 0 | AM8: 2 | AN8: 1 | AO8: 2 | AP8: 3000 | AQ8: 3 | AR8: 40 | AS8: 11 | AT8: 529+1|0+0|530+0|-1+0|705+0|-1+0|179+0|-1+0|805+0 | AU8: 0 | AV8: 0
A9: 16001 | B9: 米娜 | C9: 2 | D9: 1 | E9: 1:300 | F9: 6 | G9: 0 | H9: 1 | I9: 1 | J9: Mina.1 | K9: Mina.1 | L9: 0 | M9: 530 | N9: 12 | O9: =英雄数据!N9 -> 55 | P9: =英雄数据!O9 -> 2.09 | Q9: =英雄数据!R9 -> 23 | R9: =英雄数据!S9 -> 1.21 | S9: =英雄数据!V9 -> 60 | T9: =英雄数据!W9 -> 2.09 | U9: =英雄数据!Z9 -> 44 | V9: =英雄数据!AA9 -> 1.98 | W9: 10 | X9: 1 | Y9: 1200 | Z9: =MIN(Y9+400,1300) -> 1300 | AA9: 400 | AB9: 10 | AC9: =_xlfn.IFS(OR(F9="1",F9="2",F9="7",F9="8"),2,OR(F9="3",F9="4",F9="5",F9="6"),1) -> 1 | AD9: 110061|110062|110063|110064|110065|110066|110067 | AE9: 110007 | AF9: 106001:5 | AG9: 106001 | AH9: 111001:621001:631001:641001:651001:661001 | AI9: 0 | AJ9: 1 | AK9: 1.7 | AL9: 0 | AM9: 1 | AN9: 0 | AO9: 2 | AP9: 3000 | AQ9: 8 | AR9: 45 | AS9: 12 | AT9: 523+1|0+0|572+0|-1+0|706+0|-1+0|176+0|-1+0|806+0 | AU9: 0 | AV9: 0
A10: 21001 | B10: 迈森 | C10: 1 | D10: 1 | E10: 1:400 | F10: 1 | G10: 0 | H10: 2 | I10: 2 | J10: Meissen.1 | K10: Meissen.1 | L10: 0 | M10: 645 | N10: 16.5 | O10: =英雄数据!N10 -> 93 | P10: =英雄数据!O10 -> 2.73 | Q10: =英雄数据!R10 -> 50 | R10: =英雄数据!S10 -> 1.82 | S10: =英雄数据!V10 -> 57 | T10: =英雄数据!W10 -> 1.56 | U10: =英雄数据!Z10 -> 37 | V10: =英雄数据!AA10 -> 1.69 | W10: 10 | X10: 1 | Y10: 250 | Z10: =MIN(Y10+400,1300) -> 650 | AA10: 400 | AB10: 8 | AC10: =_xlfn.IFS(OR(F10="1",F10="2",F10="7",F10="8"),2,OR(F10="3",F10="4",F10="5",F10="6"),1) -> 2 | AD10: 120011|120012|120013|120014|120015|120016|120017 | AE10: 120001 | AF10: 201001:20 | AG10: 201001 | AH10: 111002:121001:131001:341002:151001:161002 | AI10: 0 | AJ10: 1 | AK10: 1.7 | AL10: 0 | AM10: 2 | AN10: 1 | AO10: 3 | AP10: 4000 | AQ10: 3 | AR10: 30 | AS10: 10 | AT10: 509+1|0+0|901+0|-1+0|709+0|-1+0|177+0|-1+0|809+0 | AU10: 0 | AV10: 0
A11: 22001 | B11: 格莱 | C11: 1 | D11: 1 | E11: 1:400 | F11: 2 | G11: 0 | H11: 2 | I11: 2 | J11: Glay.1 | K11: Glay.1 | L11: 0 | M11: 634 | N11: 10.4 | O11: =英雄数据!N11 -> 97 | P11: =英雄数据!O11 -> 2.86 | Q11: =英雄数据!R11 -> 46 | R11: =英雄数据!S11 -> 1.69 | S11: =英雄数据!V11 -> 53 | T11: =英雄数据!W11 -> 1.56 | U11: =英雄数据!Z11 -> 36 | V11: =英雄数据!AA11 -> 1.69 | W11: 17 | X11: 1 | Y11: 250 | Z11: =MIN(Y11+400,1300) -> 650 | AA11: 550 | AB11: 8 | AC11: =_xlfn.IFS(OR(F11="1",F11="2",F11="7",F11="8"),2,OR(F11="3",F11="4",F11="5",F11="6"),1) -> 2 | AD11: 120021|120022|120023|120024|120025|120026|120027 | AE11: 120002 | AF11: 202001:20 | AG11: 202001 | AH11: 111002:221001:231001:341002:151001:261001 | AI11: 0 | AJ11: 1 | AK11: 1.7 | AL11: 0 | AM11: 3 | AN11: 1 | AO11: 3 | AP11: 3500 | AQ11: 3 | AR11: 70 | AS11: 16 | AT11: 507+1|0+0|549+0|-1+0|710+0|-1+0|174+0|-1+0|810+0 | AU11: 0 | AV11: 0
A12: 23001 | B12: 蒂亚 | C12: 1 | D12: 1 | E12: 1:400 | F12: 3 | G12: 0 | H12: 2 | I12: 2 | J12: Tia.1 | K12: Tia.1 | L12: 0 | M12: 535 | N12: 13.2 | O12: =英雄数据!N12 -> 88 | P12: =英雄数据!O12 -> 2.73 | Q12: =英雄数据!R12 -> 37 | R12: =英雄数据!S12 -> 1.43 | S12: =英雄数据!V12 -> 48 | T12: =英雄数据!W12 -> 1.69 | U12: =英雄数据!Z12 -> 32 | V12: =英雄数据!AA12 -> 1.82 | W12: 24 | X12: 1 | Y12: 1200 | Z12: =MIN(Y12+400,1300) -> 1300 | AA12: 400 | AB12: 10 | AC12: =_xlfn.IFS(OR(F12="1",F12="2",F12="7",F12="8"),2,OR(F12="3",F12="4",F12="5",F12="6"),1) -> 1 | AD12: 120031|120032|120033|120034|120035|120036|120037 | AE12: 120003 | AF12: 201001:20 | AG12: 203001 | AH12: 111002:321001:331001:341002:351001:361001 | AI12: 0 | AJ12: 1 | AK12: 1.7 | AL12: 0 | AM12: 2 | AN12: 1 | AO12: 4 | AP12: 3500 | AQ12: 3 | AR12: 30 | AS12: 17 | AT12: 569+1|0+0|162+0|-1+0|711+0|-1+0|175+0|-1+0|811+0 | AU12: 0 | AV12: 0
A13: 24001 | B13: 卡秋雅 | C13: 1 | D13: 1 | E13: 1:400 | F13: 4 | G13: 0 | H13: 2 | I13: 2 | J13: Kachuya.1 | K13: Kachuya.1 | L13: 0 | M13: 612 | N13: 14.9 | O13: =英雄数据!N13 -> 93 | P13: =英雄数据!O13 -> 2.86 | Q13: =英雄数据!R13 -> 44 | R13: =英雄数据!S13 -> 1.69 | S13: =英雄数据!V13 -> 61 | T13: =英雄数据!W13 -> 1.69 | U13: =英雄数据!Z13 -> 41 | V13: =英雄数据!AA13 -> 1.95 | W13: 20 | X13: 1 | Y13: 250 | Z13: =MIN(Y13+400,1300) -> 650 | AA13: 550 | AB13: 8 | AC13: =_xlfn.IFS(OR(F13="1",F13="2",F13="7",F13="8"),2,OR(F13="3",F13="4",F13="5",F13="6"),1) -> 1 | AD13: 120041|120042|120043|120044|120045|120046|120047 | AE13: 120004 | AF13: 204001:20 | AG13: 204001 | AH13: 411001:221001:431001:441001:451001:461002 | AI13: 0 | AJ13: 1 | AK13: 1.7 | AL13: 0 | AM13: 3 | AN13: 1 | AO13: 4 | AP13: 3500 | AQ13: 8 | AR13: 60 | AS13: 18 | AT13: 570+1|0+0|517+0|-1+0|712+0|-1+0|179+0|-1+0|812+0 | AU13: 0 | AV13: 0
A14: 25001 | B14: 索尼娅 | C14: 2 | D14: 1 | E14: 1:400 | F14: 5 | G14: 0 | H14: 2 | I14: 2 | J14: Sonia.1 | K14: Sonia.1 | L14: 0 | M14: 535 | N14: 12.1 | O14: =英雄数据!N14 -> 74 | P14: =英雄数据!O14 -> 3.25 | Q14: =英雄数据!R14 -> 32 | R14: =英雄数据!S14 -> 1.43 | S14: =英雄数据!V14 -> 92 | T14: =英雄数据!W14 -> 3.25 | U14: =英雄数据!Z14 -> 42 | V14: =英雄数据!AA14 -> 2.34 | W14: 13 | X14: 1 | Y14: 1200 | Z14: =MIN(Y14+400,1300) -> 1300 | AA14: 400 | AB14: 10 | AC14: =_xlfn.IFS(OR(F14="1",F14="2",F14="7",F14="8"),2,OR(F14="3",F14="4",F14="5",F14="6"),1) -> 1 | AD14: 120051|120052|120053|120054|120055|120056|120057 | AE14: 120005 | AF14: 205001:20 | AG14: 205001 | AH14: 111002:521001:531002:541001:151001:561001 | AI14: 0 | AJ14: 1 | AK14: 1.7 | AL14: 0 | AM14: 1 | AN14: 1 | AO14: 4 | AP14: 3500 | AQ14: 4 | AR14: 45 | AS14: 19 | AT14: 567+1|0+0|568+0|-1+0|713+0|-1+0|178+0|-1+0|813+0 | AU14: 0 | AV14: 0
A15: 26001 | B15: 莱恩 | C15: 2 | D15: 1 | E15: 1:400 | F15: 6 | G15: 0 | H15: 2 | I15: 2 | J15: Ryan.1 | K15: Ryan.1 | L15: 0 | M15: 568 | N15: 13.2 | O15: =英雄数据!N15 -> 71 | P15: =英雄数据!O15 -> 2.99 | Q15: =英雄数据!R15 -> 39 | R15: =英雄数据!S15 -> 1.56 | S15: =英雄数据!V15 -> 83 | T15: =英雄数据!W15 -> 2.99 | U15: =英雄数据!Z15 -> 58 | V15: =英雄数据!AA15 -> 2.6 | W15: 11 | X15: 1 | Y15: 1200 | Z15: =MIN(Y15+400,1300) -> 1300 | AA15: 400 | AB15: 10 | AC15: =_xlfn.IFS(OR(F15="1",F15="2",F15="7",F15="8"),2,OR(F15="3",F15="4",F15="5",F15="6"),1) -> 1 | AD15: 120061|120062|120063|120064|120065|120066|120067 | AE15: 120006 | AF15: 206001:20 | AG15: 206001 | AH15: 111002:621001:631001:641002:651001:661001 | AI15: 0 | AJ15: 1 | AK15: 1.7 | AL15: 0 | AM15: 1 | AN15: 1 | AO15: 4 | AP15: 3500 | AQ15: 14 | AR15: 45 | AS15: 20 | AT15: 565+1|0+0|566+0|-1+0|714+0|-1+0|178+0|-1+0|814+0 | AU15: 0 | AV15: 0
A16: 28001 | B16: 姆多 | C16: 1 | D16: 1 | E16: 1:400 | F16: 8 | G16: 0 | H16: 2 | I16: 2 | J16: Mudo.1 | K16: Mudo.1 | L16: 0 | M16: 623 | N16: 19.8 | O16: =英雄数据!N16 -> 98 | P16: =英雄数据!O16 -> 2.73 | Q16: =英雄数据!R16 -> 42 | R16: =英雄数据!S16 -> 1.69 | S16: =英雄数据!V16 -> 49 | T16: =英雄数据!W16 -> 1.43 | U16: =英雄数据!Z16 -> 23 | V16: =英雄数据!AA16 -> 1.43 | W16: 26 | X16: 1 | Y16: 250 | Z16: =MIN(Y16+400,1300) -> 650 | AA16: 400 | AB16: 8 | AC16: =_xlfn.IFS(OR(F16="1",F16="2",F16="7",F16="8"),2,OR(F16="3",F16="4",F16="5",F16="6"),1) -> 2 | AD16: 120071|120072|120073|120074|120075|120076|120077 | AE16: 120007 | AF16: 208001:20 | AG16: 208001 | AH16: 711001:721001:831001:741002:751001:161001 | AI16: 0 | AJ16: 1 | AK16: 1.7 | AL16: 0 | AM16: 1 | AN16: 1 | AO16: 4 | AP16: 3500 | AQ16: 14 | AR16: 45 | AS16: 20 | AT16: 565+1|0+0|566+0|-1+0|714+0|-1+0|178+0|-1+0|814+0 | AU16: 0 | AV16: 0
A17: 31001 | B17: 亚瑟 | C17: 1 | D17: 1 | E17: 1:500 | F17: 1 | G17: 0 | H17: 3 | I17: 3 | J17: Arthur.1 | K17: Arthur.1 | L17: 0 | M17: 690 | N17: 19.8 | O17: =英雄数据!N17 -> 120 | P17: =英雄数据!O17 -> 3.75 | Q17: =英雄数据!R17 -> 69 | R17: =英雄数据!S17 -> 2.55 | S17: =英雄数据!V17 -> 70 | T17: =英雄数据!W17 -> 2.1 | U17: =英雄数据!Z17 -> 48 | V17: =英雄数据!AA17 -> 2.4 | W17: 17 | X17: 1 | Y17: 250 | Z17: =MIN(Y17+400,1300) -> 650 | AA17: 400 | AB17: 8 | AC17: =_xlfn.IFS(OR(F17="1",F17="2",F17="7",F17="8"),2,OR(F17="3",F17="4",F17="5",F17="6"),1) -> 2 | AD17: 1300011|1300012|1300013|1300014|1300015|1300016|1300017 | AE17: 130001 | AF17: 301001:60 | AG17: 301001 | AH17: 111002:221001:231001:141002:351001:261001:161002 | AI17: 0 | AJ17: 1 | AK17: 1.7 | AL17: 0 | AM17: 1 | AN17: 0 | AO17: 5 | AP17: 3500 | AQ17: 3 | AR17: 45 | AS17: 21 | AT17: 506+1|0+0|564+0|-1+0|710+0|-1+0|176+0|-1+0|810+0 | AU17: 0 | AV17: 0
A18: 32001 | B18: 罗宾 | C18: 1 | D18: 1 | E18: 1:500 | F18: 3 | G18: 0 | H18: 3 | I18: 3 | J18: Robin.1 | K18: Robin.1 | L18: 0 | M18: 606 | N18: 10.8 | O18: =英雄数据!N18 -> 96 | P18: =英雄数据!O18 -> 3.75 | Q18: =英雄数据!R18 -> 42 | R18: =英雄数据!S18 -> 1.95 | S18: =英雄数据!V18 -> 61 | T18: =英雄数据!W18 -> 2.4 | U18: =英雄数据!Z18 -> 46 | V18: =英雄数据!AA18 -> 2.55 | W18: 26 | X18: 1 | Y18: 1200 | Z18: =MIN(Y18+400,1300) -> 1300 | AA18: 400 | AB18: 10 | AC18: =_xlfn.IFS(OR(F18="1",F18="2",F18="7",F18="8"),2,OR(F18="3",F18="4",F18="5",F18="6"),1) -> 1 | AD18: 1300031|1300032|1300033|1300034|1300035|1300036|1300037 | AE18: 130003 | AF18: 302001:60 | AG18: 302001 | AH18: 111002:321001:331001:341002:751002:361001:361002 | AI18: 0 | AJ18: 1 | AK18: 1.7 | AL18: 0 | AM18: 3 | AN18: 0 | AO18: 5 | AP18: 3500 | AQ18: 3 | AR18: 60 | AS18: 15 | AT18: 562+1|0+0|563+0|-1+0|716+0|-1+0|175+0|-1+0|816+0 | AU18: 0 | AV18: 0
A19: 34001 | B19: 贝尔 | C19: 1 | D19: 1 | E19: 1:500 | F19: 4 | G19: 0 | H19: 3 | I19: 3 | J19: Bel.1 | K19: Bel.1 | L19: 0 | M19: 654 | N19: 17.9 | O19: =英雄数据!N19 -> 117 | P19: =英雄数据!O19 -> 3.9 | Q19: =英雄数据!R19 -> 60 | R19: =英雄数据!S19 -> 2.4 | S19: =英雄数据!V19 -> 75 | T19: =英雄数据!W19 -> 2.4 | U19: =英雄数据!Z19 -> 52 | V19: =英雄数据!AA19 -> 2.7 | W19: 21 | X19: 1 | Y19: 250 | Z19: =MIN(Y19+400,1300) -> 650 | AA19: 550 | AB19: 8 | AC19: =_xlfn.IFS(OR(F19="1",F19="2",F19="7",F19="8"),2,OR(F19="3",F19="4",F19="5",F19="6"),1) -> 1 | AD19: 1300051|1300052|1300053|1300054|1300055|1300056|1300057 | AE19: 130005 | AF19: 304001:60 | AG19: 304001 | AH19: 411001:221001:431001:741003:451001:761002:861001 | AI19: 0 | AJ19: 1 | AK19: 1.7 | AL19: 0 | AM19: 2 | AN19: 0 | AO19: 5 | AP19: 3500 | AQ19: 14 | AR19: 30 | AS19: 24 | AT19: 908+1|0+0|573+0|-1+0|707+0|-1+0|177+0|-1+0|818+0 | AU19: 0 | AV19: 0
A20: 35001 | B20: 卢修斯 | C20: 2 | D20: 1 | E20: 1:500 | F20: 5 | G20: 0 | H20: 3 | I20: 3 | J20: Lucius.1 | K20: Lucius.1 | L20: 0 | M20: 570 | N20: 14.5 | O20: =英雄数据!N20 -> 76 | P20: =英雄数据!O20 -> 4.2 | Q20: =英雄数据!R20 -> 49 | R20: =英雄数据!S20 -> 1.95 | S20: =英雄数据!V20 -> 115 | T20: =英雄数据!W20 -> 4.2 | U20: =英雄数据!Z20 -> 55 | V20: =英雄数据!AA20 -> 3.3 | W20: 14 | X20: 1 | Y20: 1200 | Z20: =MIN(Y20+400,1300) -> 1300 | AA20: 400 | AB20: 10 | AC20: =_xlfn.IFS(OR(F20="1",F20="2",F20="7",F20="8"),2,OR(F20="3",F20="4",F20="5",F20="6"),1) -> 1 | AD20: 1300061|1300062|1300063|1300064|1300065|1300066|1300067 | AE20: 130006 | AF20: 305001:60 | AG20: 305001 | AH20: 711001:721002:731002:741001:651002:761001:861002 | AI20: 0 | AJ20: 1 | AK20: 1.7 | AL20: 0 | AM20: 3 | AN20: 1 | AO20: 6 | AP20: 3500 | AQ20: 3 | AR20: 30 | AS20: 25 | AT20: 512+1|0+0|574+0|-1+0|702+0|-1+0|175+0|-1+0|819+0 | AU20: 0 | AV20: 0
A21: 36001 | B21: 莉斯 | C21: 2 | D21: 1 | E21: 1:500 | F21: 6 | G21: 0 | H21: 3 | I21: 3 | J21: Liz.1 | K21: Liz.1 | L21: 0 | M21: 630 | N21: 10.8 | O21: =英雄数据!N21 -> 81 | P21: =英雄数据!O21 -> 3.9 | Q21: =英雄数据!R21 -> 42 | R21: =英雄数据!S21 -> 2.1 | S21: =英雄数据!V21 -> 108 | T21: =英雄数据!W21 -> 3.9 | U21: =英雄数据!Z21 -> 72 | V21: =英雄数据!AA21 -> 3.6 | W21: 12 | X21: 1 | Y21: 1200 | Z21: =MIN(Y21+400,1300) -> 1300 | AA21: 400 | AB21: 10 | AC21: =_xlfn.IFS(OR(F21="1",F21="2",F21="7",F21="8"),2,OR(F21="3",F21="4",F21="5",F21="6"),1) -> 1 | AD21: 1300071|1300072|1300073|1300074|1300075|1300076|1300077 | AE21: 130007 | AF21: 306001:60 | AG21: 306001 | AH21: 111002:621001:631001:641002:651001:661001:561001 | AI21: 0 | AJ21: 1 | AK21: 1.7 | AL21: 0 | AM21: 1 | AN21: 0 | AO21: 6 | AP21: 4000 | AQ21: 3 | AR21: 30 | AS21: 26 | AT21: 501+1|0+0|107+0|-1+0|706+0|-1+0|176+0|-1+0|817+0 | AU21: 0 | AV21: 0
A22: 111001 | B22: 步兵 | C22: 11 | D22: 2 | E22: 1:70 | F22: 1 | G22: 1 | H22: 0 | I22: 0 | J22: bubing01_Lv1 | K22: bubing01_Lv1 | L22: 0 | M22: =士兵数据!L2 -> 296 | N22: 0 | O22: =士兵数据!N2 -> 81 | P22: 0 | Q22: =士兵数据!P2 -> 37 | R22: 0 | S22: =士兵数据!Q2 -> 50 | T22: 0 | U22: =士兵数据!T2 -> 31 | V22: 0 | W22: 10 | X22: 0 | Y22: 200 | Z22: 1300 | AA22: 400 | AB22: 8 | AC22: 2 | AD22: 70011|71011 | AE22: 0 | AF22: 0 | AG22: 0 | AH22: 0 | AI22: 看我手中的长矛可会放过你。 | AJ22: 1.5 | AK22: 1.7 | AL22: 100 | AM22: 11 | AN22: 0 | AO22: 2 | AP22: 0 | AQ22: 0 | AR22: 20 | AS22: 0 | AT22: 553+1|105+1 | AU22: 0 | AV22: 0
A23: 111002 | B23: 枪兵 | C23: 11 | D23: 2 | E23: 1:80 | F23: 1 | G23: 1 | H23: 0 | I23: 0 | J23: bubing02_Lv2 | K23: bubing02_Lv2 | L23: 0 | M23: =士兵数据!L3 -> 348 | N23: 0 | O23: =士兵数据!N3 -> 77 | P23: 0 | Q23: =士兵数据!P3 -> 63 | R23: 0 | S23: =士兵数据!Q3 -> 50 | T23: 0 | U23: =士兵数据!T3 -> 54 | V23: 0 | W23: 10 | X23: 0 | Y23: 200 | Z23: 1300 | AA23: 400 | AB23: 8 | AC23: 2 | AD23: 70021|71021|90321 | AE23: 0 | AF23: 0 | AG23: 0 | AH23: 0 | AI23: 看我手中的长矛可会放过你。 | AJ23: 1.5 | AK23: 1.7 | AL23: 100 | AM23: 11 | AN23: 0 | AO23: 4 | AP23: 0 | AQ23: 0 | AR23: 90 | AS23: 0 | AT23: 553+1|172+1 | AU23: 0 | AV23: 0
A24: 121001 | B24: 重装步兵 | C24: 11 | D24: 2 | E24: 1:120 | F24: 1 | G24: 2 | H24: 0 | I24: 0 | J24: bubing01_Lv2 | K24: bubing01_Lv2 | L24: 0 | M24: =士兵数据!L4 -> 676 | N24: 0 | O24: =士兵数据!N4 -> 101 | P24: 0 | Q24: =士兵数据!P4 -> 73 | R24: 0 | S24: =士兵数据!Q4 -> 60 | T24: 0 | U24: =士兵数据!T4 -> 63 | V24: 0 | W24: 11 | X24: 0 | Y24: 200 | Z24: 1300 | AA24: 400 | AB24: 8 | AC24: 2 | AD24: 70031|71031 | AE24: 0 | AF24: 0 | AG24: 0 | AH24: 0 | AI24: 箭雨射击快。 | AJ24: 1.5 | AK24: 1.7 | AL24: 100 | AM24: 11 | AN24: 0 | AO24: 4 | AP24: 0 | AQ24: 0 | AR24: 90 | AS24: 0 | AT24: 553+1|172+1 | AU24: 0 | AV24: 0
A25: 131001 | B25: 重装枪兵 | C25: 11 | D25: 2 | E25: 1:130,2:80 | F25: 1 | G25: 3 | H25: 0 | I25: 0 | J25: bubing02_Lv1 | K25: bubing02_Lv1 | L25: 0 | M25: =士兵数据!L5 -> 827 | N25: 0 | O25: =士兵数据!N5 -> 126 | P25: 0 | Q25: =士兵数据!P5 -> 91 | R25: 0 | S25: =士兵数据!Q5 -> 65 | T25: 0 | U25: =士兵数据!T5 -> 79 | V25: 0 | W25: 11 | X25: 0 | Y25: 200 | Z25: 1300 | AA25: 400 | AB25: 8 | AC25: 2 | AD25: 70041|71041|90321 | AE25: 0 | AF25: 0 | AG25: 0 | AH25: 0 | AI25: 看我手中的长矛可会放过你。 | AJ25: 1.5 | AK25: 2 | AL25: 100 | AM25: 11 | AN25: 0 | AO25: 4 | AP25: 0 | AQ25: 0 | AR25: 90 | AS25: 0 | AT25: 553+1|172+1 | AU25: 0 | AV25: 0
A26: 141001 | B26: 皇室近卫 | C26: 11 | D26: 2 | E26: 1:160,2:120 | F26: 1 | G26: 4 | H26: 0 | I26: 0 | J26: bubing01_Lv3 | K26: bubing01_Lv3 | L26: 0 | M26: =士兵数据!L6 -> 1170 | N26: 0 | O26: =士兵数据!N6 -> 176 | P26: 0 | Q26: =士兵数据!P6 -> 111 | R26: 0 | S26: =士兵数据!Q6 -> 70 | T26: 0 | U26: =士兵数据!T6 -> 98 | V26: 0 | W26: 11 | X26: 0 | Y26: 200 | Z26: 1300 | AA26: 400 | AB26: 8 | AC26: 2 | AD26: 70051|71051|72051 | AE26: 0 | AF26: 0 | AG26: 0 | AH26: 0 | AI26: 我的火球可不是吃素的。 | AJ26: 1.5 | AK26: 2 | AL26: 100 | AM26: 11 | AN26: 0 | AO26: 4 | AP26: 0 | AQ26: 0 | AR26: 90 | AS26: 0 | AT26: 553+1|172+1 | AU26: 0 | AV26: 0
A27: 141002 | B27: 禁卫 | C27: 11 | D27: 2 | E27: 1:150,2:110 | F27: 1 | G27: 4 | H27: 0 | I27: 0 | J27: bubing04_Lv3 | K27: bubing04_Lv3 | L27: 0 | M27: =士兵数据!L7 -> 1155 | N27: 0 | O27: =士兵数据!N7 -> 166 | P27: 0 | Q27: =士兵数据!P7 -> 118 | R27: 0 | S27: =士兵数据!Q7 -> 72 | T27: 0 | U27: =士兵数据!T7 -> 103 | V27: 0 | W27: 11 | X27: 0 | Y27: 200 | Z27: 1300 | AA27: 400 | AB27: 8 | AC27: 2 | AD27: 70061|71061|72061 | AE27: 0 | AF27: 0 | AG27: 0 | AH27: 0 | AI27: 哇哇哇哇！ | AJ27: 1.5 | AK27: 2 | AL27: 100 | AM27: 11 | AN27: 0 | AO27: 4 | AP27: 0 | AQ27: 0 | AR27: 90 | AS27: 0 | AT27: 553+1|172+1 | AU27: 0 | AV27: 0
A28: 151001 | B28: 将军 | C28: 11 | D28: 2 | E28: 1:180,2:150 | F28: 1 | G28: 5 | H28: 0 | I28: 0 | J28: bubing02_Lv3 | K28: bubing02_Lv3 | L28: 0 | M28: =士兵数据!L8 -> 1423 | N28: 0 | O28: =士兵数据!N8 -> 247 | P28: 0 | Q28: =士兵数据!P8 -> 131 | R28: 0 | S28: =士兵数据!Q8 -> 75 | T28: 0 | U28: =士兵数据!T8 -> 142 | V28: 0 | W28: 11 | X28: 0 | Y28: 200 | Z28: 1300 | AA28: 400 | AB28: 8 | AC28: 2 | AD28: 70071|71071|72071 | AE28: 0 | AF28: 0 | AG28: 0 | AH28: 0 | AI28: 尝尝我手中的剑。 | AJ28: 1.5 | AK28: 2.5 | AL28: 100 | AM28: 11 | AN28: 0 | AO28: 4 | AP28: 0 | AQ28: 0 | AR28: 90 | AS28: 0 | AT28: 553+1|172+1 | AU28: 0 | AV28: 0
A29: 161001 | B29: 比蒙巨兽 | C29: 11 | D29: 2 | E29: 1:250,2:230 | F29: 1 | G29: 6 | H29: 0 | I29: 0 | J29: bubing03_Lv3 | K29: bubing03_Lv3 | L29: 0 | M29: =士兵数据!L9 -> 1946 | N29: 0 | O29: =士兵数据!N9 -> 296 | P29: 0 | Q29: =士兵数据!P9 -> 151 | R29: 0 | S29: =士兵数据!Q9 -> 80 | T29: 0 | U29: =士兵数据!T9 -> 133 | V29: 0 | W29: 12 | X29: 0 | Y29: 200 | Z29: 1300 | AA29: 400 | AB29: 8 | AC29: 2 | AD29: 70081|71081|72081 | AE29: 0 | AF29: 0 | AG29: 0 | AH29: 0 | AI29: 炮火覆盖，真理只在我的大炮射程内。 | AJ29: 1.5 | AK29: 3 | AL29: 100 | AM29: 11 | AN29: 0 | AO29: 4 | AP29: 0 | AQ29: 0 | AR29: 90 | AS29: 0 | AT29: 553+1|172+1 | AU29: 0 | AV29: 0
A30: 161002 | B30: 天使 | C30: 11 | D30: 2 | E30: 1:400,2:380 | F30: 1 | G30: 6 | H30: 0 | I30: 0 | J30: bubing05_Lv3 | K30: bubing05_Lv3 | L30: 0 | M30: =士兵数据!L10 -> 3100 | N30: 0 | O30: =士兵数据!N10 -> 333 | P30: 0 | Q30: =士兵数据!P10 -> 160 | R30: 0 | S30: =士兵数据!Q10 -> 80 | T30: 0 | U30: =士兵数据!T10 -> 175 | V30: 0 | W30: 11 | X30: 0 | Y30: 200 | Z30: 1300 | AA30: 400 | AB30: 8 | AC30: 2 | AD30: 70081|71081|72081 | AE30: 0 | AF30: 0 | AG30: 0 | AH30: 0 | AI30: 炮火覆盖，真理只在我的大炮射程内。 | AJ30: 1.5 | AK30: 3 | AL30: 100 | AM30: 11 | AN30: 0 | AO30: 4 | AP30: 0 | AQ30: 0 | AR30: 90 | AS30: 0 | AT30: 553+1|172+1 | AU30: 0 | AV30: 0
A31: 221001 | B31: 骑兵 | C31: 11 | D31: 2 | E31: 1:180 | F31: 2 | G31: 2 | H31: 0 | I31: 0 | J31: qibing01_Lv1 | K31: qibing01_Lv1 | L31: 0 | M31: =士兵数据!L11 -> 619 | N31: 0 | O31: =士兵数据!N11 -> 103 | P31: 0 | Q31: =士兵数据!P11 -> 49 | R31: 0 | S31: =士兵数据!Q11 -> 62 | T31: 0 | U31: =士兵数据!T11 -> 42 | V31: 0 | W31: 11 | X31: 0 | Y31: 200 | Z31: 1300 | AA31: 500 | AB31: 8 | AC31: 2 | AD31: 70091|71091 | AE31: 0 | AF31: 0 | AG31: 0 | AH31: 0 | AI31: 随我冲锋，粉碎敌军的攻击。 | AJ31: 1.5 | AK31: 1.7 | AL31: 100 | AM31: 11 | AN31: 0 | AO31: 4 | AP31: 0 | AQ31: 0 | AR31: 90 | AS31: 0 | AT31: 553+1|172+1 | AU31: 0 | AV31: 0
A32: 231001 | B32: 精锐骑士 | C32: 11 | D32: 2 | E32: 1:200,2:150 | F32: 2 | G32: 3 | H32: 0 | I32: 0 | J32: qibing01_Lv2 | K32: qibing01_Lv2 | L32: 0 | M32: =士兵数据!L12 -> 967 | N32: 0 | O32: =士兵数据!N12 -> 132 | P32: 0 | Q32: =士兵数据!P12 -> 68 | R32: 0 | S32: =士兵数据!Q12 -> 67 | T32: 0 | U32: =士兵数据!T12 -> 60 | V32: 0 | W32: 12 | X32: 0 | Y32: 200 | Z32: 1300 | AA32: 500 | AB32: 8 | AC32: 2 | AD32: 70101|71101 | AE32: 0 | AF32: 0 | AG32: 0 | AH32: 0 | AI32: 让你尝尝我法术的味道。 | AJ32: 1.5 | AK32: 2 | AL32: 100 | AM32: 11 | AN32: 0 | AO32: 4 | AP32: 0 | AQ32: 0 | AR32: 90 | AS32: 0 | AT32: 553+1|172+1 | AU32: 0 | AV32: 0
A33: 241001 | B33: 野蛮骑士 | C33: 11 | D33: 2 | E33: 1:220,2:180 | F33: 2 | G33: 4 | H33: 0 | I33: 0 | J33: qibing02_Lv3 | K33: qibing02_Lv3 | L33: 0 | M33: =士兵数据!L13 -> 1391 | N33: 0 | O33: =士兵数据!N13 -> 188 | P33: 0 | Q33: =士兵数据!P13 -> 89 | R33: 0 | S33: =士兵数据!Q13 -> 72 | T33: 0 | U33: =士兵数据!T13 -> 77 | V33: 0 | W33: 12 | X33: 0 | Y33: 200 | Z33: 1300 | AA33: 500 | AB33: 8 | AC33: 2 | AD33: 70111|71111|72111 | AE33: 0 | AF33: 0 | AG33: 0 | AH33: 0 | AI33: 让你尝尝我法术的味道。 | AJ33: 1.5 | AK33: 2 | AL33: 100 | AM33: 11 | AN33: 0 | AO33: 4 | AP33: 0 | AQ33: 0 | AR33: 90 | AS33: 0 | AT33: 553+1|172+1 | AU33: 0 | AV33: 0
... A83: 861002 | B83: 翡翠龙 | C83: 11 | D83: 2 | E83: 1:380,2:360 | F83: 8 | G83: 6 | H83: 0 | I83: 0 | J83: yeshou05_lv3 | K83: yeshou05_lv3 | L83: 0 | M83: =士兵数据!L63 -> 2665 | N83: 0 | O83: =士兵数据!N63 -> 314 | P83: 0 | Q83: =士兵数据!P63 -> 148 | R83: 0 | S83: =士兵数据!Q63 -> 85 | T83: 0 | U83: =士兵数据!T63 -> 178 | V83: 0 | W83: 14 | X83: 0 | Y83: 200 | Z83: 1300 | AA83: 400 | AB83: 8 | AC83: 2 | AD83: 70431|71431|72431 | AE83: 0 | AF83: 0 | AG83: 0 | AH83: 0 | AI83: 让你尝尝我法术的味道。 | AJ83: 1.5 | AK83: 3 | AL83: 100 | AM83: 11 | AN83: 0 | AO83: 4 | AP83: 0 | AQ83: 0 | AR83: 90 | AS83: 0 | AT83: 553+1|172+1 | AU83: 0 | AV83: 0
A84: 10000001 | B84: 骷髅射手-召唤 | C84: 11 | D84: 2 | E84: 0 | F84: 7 | G84: 1 | H84: 0 | I84: 0 | J84: monster013 | K84: =J84 -> monster013 | L84: 0 | M84: =士兵数据!L64 -> 0 | N84: 0 | O84: =士兵数据!N64 -> 0 | P84: 0 | Q84: =士兵数据!P64 -> 0 | R84: 0 | S84: =士兵数据!Q64 -> 0 | T84: 0 | U84: =士兵数据!T64 -> 0 | V84: 0 | W84: 12 | X84: 0 | Y84: 1200 | Z84: 1300 | AA84: 400 | AB84: 10 | AC84: =_xlfn.IFS(OR(F84="1",F84="2",F84="7",F84="8"),2,OR(F84="3",F84="4",F84="5",F84="6"),1) -> 2 | AD84: 0 | AE84: 0 | AF84: 0 | AG84: 0 | AH84: 0 | AI84: 让你尝尝我法术的味道。 | AJ84: =AJ82 -> 1.5 | AK84: 1.7 | AL84: 100 | AM84: 11 | AN84: 0 | AO84: 4 | AP84: 0 | AQ84: 0 | AR84: 90 | AS84: 0 | AT84: 553+1|172+1 | AU84: 0 | AV84: 0
A85: 10000002 | B85: 大熊-召唤 | C85: 11 | D85: 2 | E85: 0 | F85: 7 | G85: 1 | H85: 0 | I85: 0 | J85: daxiong_1 | K85: =J85 -> daxiong_1 | L85: 0 | M85: =士兵数据!L65 -> 0 | N85: 0 | O85: =士兵数据!N65 -> 0 | P85: 0 | Q85: =士兵数据!P65 -> 0 | R85: 0 | S85: =士兵数据!Q65 -> 0 | T85: 0 | U85: =士兵数据!T65 -> 0 | V85: 0 | W85: 12 | X85: 0 | Y85: 200 | Z85: 1300 | AA85: 400 | AB85: 8 | AC85: =_xlfn.IFS(OR(F85="1",F85="2",F85="7",F85="8"),2,OR(F85="3",F85="4",F85="5",F85="6"),1) -> 2 | AD85: 23004911 | AE85: 0 | AF85: 0 | AG85: 0 | AH85: 0 | AI85: 让你尝尝我法术的味道。 | AJ85: =AJ84 -> 1.5 | AK85: 1.7 | AL85: 100 | AM85: 11 | AN85: 0 | AO85: 4 | AP85: 0 | AQ85: 0 | AR85: 90 | AS85: 0 | AT85: 553+1|172+1 | AU85: 0 | AV85: 0
A86: 10000003 | B86: 小熊-召唤 | C86: 11 | D86: 2 | E86: 0 | F86: 7 | G86: 1 | H86: 0 | I86: 0 | J86: xiaoxiong_1 | K86: =J86 -> xiaoxiong_1 | L86: 0 | M86: =士兵数据!L66 -> 0 | N86: 0 | O86: =士兵数据!N66 -> 0 | P86: 0 | Q86: =士兵数据!P66 -> 0 | R86: 0 | S86: =士兵数据!Q66 -> 0 | T86: 0 | U86: =士兵数据!T66 -> 0 | V86: 0 | W86: 12 | X86: 0 | Y86: 200 | Z86: 1300 | AA86: 400 | AB86: 8 | AC86: =_xlfn.IFS(OR(F86="1",F86="2",F86="7",F86="8"),2,OR(F86="3",F86="4",F86="5",F86="6"),1) -> 2 | AD86: 0 | AE86: 0 | AF86: 0 | AG86: 0 | AH86: 0 | AI86: 让你尝尝我法术的味道。 | AJ86: =AJ85 -> 1.5 | AK86: 1.7 | AL86: 100 | AM86: 11 | AN86: 0 | AO86: 4 | AP86: 0 | AQ86: 0 | AR86: 90 | AS86: 0 | AT86: 553+1|172+1 | AU86: 0 | AV86: 0

Sheet Sheet2
B1: 人族 | F1: 森林 | J1: 兽族
A2: 1 | B2: 长矛战士 | C2: 金色长矛 | D2: 冠军长矛 | E2: Footman_Blue | F2: 森林狼 | G2: 精英狼 | H2: 远古狼 | I2: Forest Wolf | J2: 兽族斧兵 | K2: 精英斧兵 | L2: 狂战斧兵 | M2: Berserker_Red
A3: 2 | B3: 弓箭手 | C3: 金色射手 | D3: 冠军射手 | E3: Archer_Blue | F3: 胖刺蘑菇 | G3: 剧毒蘑菇 | H3: 蘑菇王 | I3: Evil Mushroom | J3: 兽族火枪 | K3: 精英火枪 | L3: 毁灭火枪 | M3: HeadHunter_Red | O3: 人族女王
A4: 3 | B4: 火球法师 | C4: 红袍法师 | D4: 炎法师 | E4: Mage_Blue | F4: 花精灵 | G4: 高级精灵 | H4: 仙女精灵 | I4: Nymph Fairy | J4: 兽族雷法 | K4: 火红雷法 | L4: 先知雷法 | M4: Warlock_Red | O4: 兽人英雄
A5: 4 | B5: 狮鹫 | C5: 精英狮鹫 | D5: 王国狮鹫 | E5: Griffin_Blue | F5: 石头人 | G5: 铁壁石头 | H5: 守护者 | I5: Forest Golem | J5: 兽族猎手 | K5: 兽族屠夫 | L5: 兽族魔将 | M5: Grunt_Red | O5: 幻境女王
A6: 5 | B6: 重战士 | C6: 钢铁重战 | D6: 王国重战 | E6: Knight_Blue | F6: 森林巨人 | G6: 森林主 | H6: 大地之神 | I6: Treant Guard | J6: 猪骑兵 | K6: 猛猪骑兵 | L6: 兽族战骑 | M6: HogRider_Red | O6: 冰雪女王
A7: 6 | B7: 人族坦克 | C7: 精英坦克 | D7: 皇家坦克 | E7: SiegeEngine_Blue | F7: 五头龙 | G7: 五头巨龙 | H7: 终极巨龙 | I7: FiveHeadDragon | J7: 绿龙 | K7: 金龙 | L7: 雷龙 | M7: Drake_Red | O7: 英灵
A8: 7 | B8: 重骑士 | C8: 精英骑士 | D8: 冠军骑士 | E8: Horseman_Blue | F8: 凤凰 | G8: 凤凰 | H8: 凤凰 | I8: phoenix | J8: 独眼 | K8: 独眼巨人 | L8: 独眼王 | M8: Cyclops | O8: 审判天使
A9: 8 | B9: 贤法师 | C9: 黑袍法师 | D9: 白袍法师 | E9: Archmage | F9: 黑龙 | G9: 暗黑龙 | H9: 灭世龙 | I9: TigerDragoBlack | J9: 巨兽 | K9: 千年巨兽 | L9: 万年巨兽 | M9: YuanGuJuRen | O9: 死亡之主
A10: 9 | B10: 天使 | C10: 大天使 | D10: 圣天使 | E10: KaiEr | F10: 圣龙 | G10: 圣龙 | H10: 圣龙 | I10: highDragon | J10: 远古巨龙 | K10: 远古巨龙 | L10: 远古巨龙 | M10: kingDragon | O10: 骷髅法师
O11: 诱惑魔女
O12: 古之龙
O13: 末日火
B14: 冰雪 | F14: 地狱 | J14: 亡灵 | O14: 吸血伯爵
B15: 雪巫师 | C15: 冰巫师 | D15: 极寒巫师 | E15: Goblin Mage | F15: 恶魔之子 | G15: 恶魔之火 | H15: 恶魔之雷 | I15: Cute Devil | J15: 稻草人 | K15: 精英稻草 | L15: 无畏稻草 | M15: Scarecrow Purple | O15: 秩序古法
B16: 霜灵 | C16: 冰灵 | D16: 护冰灵 | E16: Treant | F16: 远古恶魔2 | G16: 远古恶魔2 | H16: 远古恶魔2 | I16: demon_grunt | J16: 鬼树 | K16: 魂灵树 | L16: 暗灵树 | M16: Dark Treant | O16: 地狱魔王
B17: 三尾狼 | C17: 三尾座狼 | D17: 冻魔狼 | E17: Snow Wolf | F17: 远古恶魔3 | G17: 远古恶魔3 | H17: 远古恶魔3 | I17: demon_bomb | J17: 王蛇 | K17: 幽冥蛇 | L17: 绝蛇 | M17: King Cobra
B18: 雪女 | C18: 雪语 | D18: 雪女神 | E18: Elemental Sorceress | F18: 光线巫师 | G18: 魔术巫师 | H18: 炎巫 | I18: One Eyed | J18: 鬼长矛 | K18: 幽魂长矛 | L18: 虚空长矛 | M18: Wraith Spearman
B19: 蛮熊 | C19: 蛮熊将军 | D19: 冰域霸主 | E19: Big Bear | F19: 夜魔 | G19: 魅魔 | H19: 梦境魔女 | I19: Succubus | J19: 鬼重战 | K19: 幽魂重战 | L19: 虚空重战 | M19: Wraith Swordsman
B20: 蛇女 | C20: 蛇女战士 | D20: 剑蛇姬 | E20: SnakeMonster | F20: 牛头人 | G20: 牛魔将 | H20: 牛魔王 | I20: niutouren | J20: 巫妖 | K20: 巫妖王 | L20: 不死者之王 | M20: Lich
B21: 寒冰人 | C21: 寒冰巨人 | D21: 寒冰泰坦 | E21: Snow Titan | F21: 地狱兽 | G21: 地狱巨兽 | H21: 深渊巨兽 | I21: Hell Creeper | J21: 黑骑士 | K21: 亡灵骑士 | L21: 毁灭骑士 | M21: undeadKnight
B22: 泰坦 | C22: 泰坦巨人 | D22: 泰坦神 | E22: Titan | F22: 恶魔 | G22: 大恶魔 | H22: 末日魔王 | I22: Fire Demon | J22: 骨龙 | K22: 骨龙 | L22: 骨龙 | M22: boneDragon
B23: 魔法龙 | C23: 魔法龙 | D23: 魔法龙 | E23: magicDragon | F23: 熔岩龙 | G23: 熔岩龙 | H23: 熔岩龙 | I23: lavaDragon | J23: 蜘蛛女王 | K23: 恐怖蜘蛛 | L23: 绝望蜘蛛 | M23: Spider Venom

Sheet 备份
A1: ID | B1: Name | C1: Camp | D1: Type | E1: Cost | F1: Career | G1: SoldierLv | H1: Quality | I1: Star | J1: Icon | K1: Icon1 | L1: Audio | M1: HP | N1: UpHP | O1: Atk | P1: UpAtk | Q1: Def | R1: UpDef | S1: Ap | T1: UpAp | U1: Mdef | V1: UpMdef | W1: Dex | X1: UpDex | Y1: Range | Z1: Warn | AA1: Move | AB1: AtkCd | AC1: AtkGoal | AD1: Talent | AE1: InitCareer | AF1: Synthesis | AG1: Show | AH1: SoldierShow | AI1: SplashTalk | AJ1: Amplify1 | AK1: Amplify2 | AL1: Camp | AM1: FlyOrLand | AN1: LockLv | AO1: Shop | AP1: Persent | AQ1: Leader | AR1: UpLeader | AS1: Skill | AT1: Mp | AU1: UpMp
A2: int | B2: string | C2: int | D2: int | E2: int | F2: int | G2: int | H2: int | I2: int | J2: string | K2: string | L2: string | M2: int | N2: float | O2: int | P2: float | Q2: int | R2: float | S2: int | T2: float | U2: int | V2: float | W2: int | X2: float | Y2: int | Z2: int | AA2: int | AB2: int | AC2: int | AD2: string | AE2: string | AF2: string | AG2: int | AH2: string | AI2: string | AJ2: float | AK2: float | AL2: int | AM2: int | AN2: int | AO2: int | AP2: int | AQ2: int | AR2: float | AS2: string | AT2: int | AU2: float
A3: id | B3: 名字 | C3: 种族 | D3: 类型1 | E3: 花费 | F3: 初始职业 | G3: 士兵等级 | H3: 品质（D-SSS） | I3: 初始星级 | J3: 模型 | K3: 图标 | L3: 配音资源 | M3: 生命值 | N3: 生命值成长 | O3: 攻击 | P3: 攻击每级成长值 | Q3: 防御 | R3: 防御每级成长值 | S3: 魔力 | T3: 魔力每级成长值 | U3: 魔防 | V3: 魔防值每级成长值 | W3: 技巧 | X3: 技巧加成 | Y3: 攻击距离 | Z3: 警戒范围 | AA3: 移速 | AB3: 攻击间隔/8 | AC3: 攻击目标 | AD3: 携带天赋 | AE3: 初始职业 | AF3: 重复获得和合成 | AG3: 分解道具碎片展示 | AH3: 兵种展示 | AI3: boss闪屏的话 | AJ3: 查看界面放大 | AK3: 地图模型放大 | AL3: 种族 | AM3: 类型0地面1飞兵 | AN3: 解锁章节 | AO3: 购买价格 | AP3: 抽卡概率权重值 | AQ3: 英雄领导力 | AR3: 领导力成长 | AS3: 技能 | AT3: 魔法值 | AU3: 魔法值每级成长值
A4: 11001 | B4: 玛伦 | C4: 1 | D4: 1 | E4: 0 | F4: 1 | G4: 0 | H4: 1 | I4: 1 | J4: Mahlon.1 | K4: Mahlon.1 | L4: Mahlon_01,Mahlon_02,Mahlon_03 | M4: 600 | N4: 10 | O4: 68 | P4: 1.9 | Q4: 31 | R4: 1.3 | S4: 41 | T4: 1.1 | U4: 26 | V4: 1.2 | W4: 14 | X4: 1 | Y4: 200 | Z4: =MIN(Y4+400,1100) -> 600 | AA4: 300 | AB4: 8 | AC4: =_xlfn.IFS(OR(F4="1",F4="2",F4="7",F4="8"),2,OR(F4="3",F4="4",F4="5",F4="6"),1) -> 2 | AD4: 110011|110012|110013|110014|110010|110016|110017 | AE4: 110002 | AF4: 101001:5 | AG4: 101001 | AH4: 111002:121001:131001:141001:151001:161002 | AI4: 0 | AJ4: 1 | AK4: 1 | AL4: 3 | AM4: 0 | AN4: 0 | AO4: 2500 | AP4: 8 | AQ4: 60 | AR4: 12 | AS4: 514+1|0+0|516+0|-1+0|701+0|-1+0|174+0|-1+0|801+0 | AT4: 0 | AU4: 0
A5: 12001 | B5: 克莱斯 | C5: 1 | D5: 1 | E5: 0 | F5: 2 | G5: 0 | H5: 1 | I5: 1 | J5: Kress.1 | K5: Kress.1 | L5: Kress_01,Kress_02,Kress_03 | M5: 590 | N5: 14 | O5: 71 | P5: 2 | Q5: 28 | R5: 1.2 | S5: 38 | T5: 1.1 | U5: 25 | V5: 1.2 | W5: 16 | X5: 1 | Y5: 200 | Z5: =MIN(Y5+400,1100) -> 600 | AA5: 450 | AB5: 8 | AC5: =_xlfn.IFS(OR(F5="1",F5="2",F5="7",F5="8"),2,OR(F5="3",F5="4",F5="5",F5="6"),1) -> 2 | AD5: 110021|110015|110023|110024|110025|110026|110027 | AE5: 110003 | AF5: 102001:5 | AG5: 102001 | AH5: 811001:821001:731001:241001:251001:161001 | AI5: 0 | AJ5: 1 | AK5: 1 | AL5: 1 | AM5: 1 | AN5: 0 | AO5: 3000 | AP5: 3 | AQ5: 45 | AR5: 8 | AS5: 560+1|0+0|903+0|-1+0|704+0|-1+0|179+0|-1+0|804+0 | AT5: 0 | AU5: 0
A6: 13001 | B6: 艾丝琳 | C6: 1 | D6: 1 | E6: 0 | F6: 3 | G6: 0 | H6: 1 | I6: 1 | J6: Eileen.1 | K6: Eileen.1 | L6: Eileen_01,Eileen_02,Eileen_03 | M6: 500 | N6: 12 | O6: 62 | P6: 1.7 | Q6: 21 | R6: 1 | S6: 34 | T6: 1.2 | U6: 23 | V6: 1.3 | W6: 15 | X6: 1 | Y6: 1200 | Z6: =MIN(Y6+400,1100) -> 1100 | AA6: 300 | AB6: 10 | AC6: =_xlfn.IFS(OR(F6="1",F6="2",F6="7",F6="8"),2,OR(F6="3",F6="4",F6="5",F6="6"),1) -> 1 | AD6: 110031|110032|110033|110034|110035|110036|110037 | AE6: 110004 | AF6: 103001:5 | AG6: 103001 | AH6: 111002:321001:331001:341001:351001:361001 | AI6: 0 | AJ6: 1 | AK6: 1 | AL6: 2 | AM6: 0 | AN6: 2 | AO6: 2500 | AP6: 14 | AQ6: 30 | AR6: 9 | AS6: 510+1|0+0|503+0|-1+0|703+0|-1+0|174+0|-1+0|803+0 | AT6: 0 | AU6: 0
A7: 14001 | B7: 克莱亚 | C7: 1 | D7: 1 | E7: 0 | F7: 4 | G7: 0 | H7: 1 | I7: 1 | J7: Lela.1 | K7: Lela.1 | L7: Lela_01,Lela_02,Lela_03 | M7: 570 | N7: 13.5 | O7: 66 | P7: 2 | Q7: 26 | R7: 1.2 | S7: 43 | T7: 1.2 | U7: 28 | V7: 1.4 | W7: 18 | X7: 1 | Y7: 200 | Z7: =MIN(Y7+400,1100) -> 600 | AA7: 450 | AB7: 8 | AC7: =_xlfn.IFS(OR(F7="1",F7="2",F7="7",F7="8"),2,OR(F7="3",F7="4",F7="5",F7="6"),1) -> 1 | AD7: 110041|110042|110043|110044|110045|110046|110047 | AE7: 110005 | AF7: 104001:5 | AG7: 104001 | AH7: 411001:121001:431001:441001:451001:461001 | AI7: 0 | AJ7: 1 | AK7: 1 | AL7: 3 | AM7: 0 | AN7: 2 | AO7: 2500 | AP7: 4 | AQ7: 60 | AR7: 10 | AS7: 505+1|0+0|511+0|-1+0|702+0|-1+0|175+0|-1+0|802+0 | AT7: 0 | AU7: 0
A8: 15001 | B8: 法拉 | C8: 2 | D8: 1 | E8: 0 | F8: 5 | G8: 0 | H8: 1 | I8: 1 | J8: Farad.1 | K8: Farad.1 | L8: Farad_01,Farad_02,Farad_03 | M8: 500 | N8: 11 | O8: 45 | P8: 2 | Q8: 15 | R8: 1 | S8: 63 | T8: 2 | U8: 30 | V8: 1.6 | W8: 12 | X8: 1 | Y8: 1200 | Z8: =MIN(Y8+400,1100) -> 1100 | AA8: 300 | AB8: 10 | AC8: =_xlfn.IFS(OR(F8="1",F8="2",F8="7",F8="8"),2,OR(F8="3",F8="4",F8="5",F8="6"),1) -> 1 | AD8: 110051|110052|110053|110054|110055|110056|110057 | AE8: 110006 | AF8: 105001:5 | AG8: 105001 | AH8: 111001:521001:531001:541001:351001:561001 | AI8: 0 | AJ8: 1 | AK8: 1 | AL8: 2 | AM8: 1 | AN8: 2 | AO8: 3000 | AP8: 3 | AQ8: 40 | AR8: 11 | AS8: 529+1|0+0|530+0|-1+0|705+0|-1+0|179+0|-1+0|805+0 | AT8: 0 | AU8: 0
A9: 16001 | B9: 米娜 | C9: 2 | D9: 1 | E9: 0 | F9: 6 | G9: 0 | H9: 1 | I9: 1 | J9: Mina.1 | K9: Mina.1 | L9: Mina_01,Mina_02,Mina_03 | M9: 530 | N9: 12 | O9: 50 | P9: 1.9 | Q9: 21 | R9: 1.1 | S9: 55 | T9: 1.9 | U9: 40 | V9: 1.8 | W9: 10 | X9: 1 | Y9: 1200 | Z9: =MIN(Y9+400,1100) -> 1100 | AA9: 300 | AB9: 10 | AC9: =_xlfn.IFS(OR(F9="1",F9="2",F9="7",F9="8"),2,OR(F9="3",F9="4",F9="5",F9="6"),1) -> 1 | AD9: 110061|110062|110063|110064|110065|110066|110067 | AE9: 110007 | AF9: 106001:5 | AG9: 106001 | AH9: 111001:621001:631001:641001:651001:661001 | AI9: 0 | AJ9: 1 | AK9: 1 | AL9: 1 | AM9: 0 | AN9: 2 | AO9: 3000 | AP9: 8 | AQ9: 45 | AR9: 12 | AS9: 523+1|0+0|572+0|-1+0|706+0|-1+0|176+0|-1+0|806+0 | AT9: 0 | AU9: 0
A10: 21001 | B10: 迈森 | C10: 1 | D10: 1 | E10: 0 | F10: 1 | G10: 0 | H10: 2 | I10: 2 | J10: Meissen.1 | K10: Meissen.1 | L10: Meissen_01,Meissen_02,Meissen_03 | M10: 645 | N10: 16.5 | O10: 72 | P10: 2.1 | Q10: 39 | R10: 1.4 | S10: 44 | T10: 1.2 | U10: 29 | V10: 1.3 | W10: 10 | X10: 1 | Y10: 200 | Z10: =MIN(Y10+400,1100) -> 600 | AA10: 300 | AB10: 8 | AC10: =_xlfn.IFS(OR(F10="1",F10="2",F10="7",F10="8"),2,OR(F10="3",F10="4",F10="5",F10="6"),1) -> 2 | AD10: 120011|120012|120013|120014|120010|120016|120017 | AE10: 120001 | AF10: 201001:20 | AG10: 201001 | AH10: 111002:121001:131001:341002:151001:161002 | AI10: 0 | AJ10: 1 | AK10: 1 | AL10: 2 | AM10: 1 | AN10: 3 | AO10: 4000 | AP10: 3 | AQ10: 30 | AR10: 10 | AS10: 509+1|0+0|901+0|-1+0|709+0|-1+0|177+0|-1+0|809+0 | AT10: 0 | AU10: 0
A11: 22001 | B11: 格莱 | C11: 1 | D11: 1 | E11: 0 | F11: 2 | G11: 0 | H11: 2 | I11: 2 | J11: Glay.1 | K11: Glay.1 | L11: Glay_01,Glay_02,Glay_03 | M11: 634 | N11: 10.4 | O11: 75 | P11: 2.2 | Q11: 36 | R11: 1.3 | S11: 41 | T11: 1.2 | U11: 28 | V11: 1.3 | W11: 17 | X11: 1 | Y11: 200 | Z11: =MIN(Y11+400,1100) -> 600 | AA11: 450 | AB11: 8 | AC11: =_xlfn.IFS(OR(F11="1",F11="2",F11="7",F11="8"),2,OR(F11="3",F11="4",F11="5",F11="6"),1) -> 2 | AD11: 120021|120022|120023|120024|120025|120026|120027 | AE11: 120002 | AF11: 202001:20 | AG11: 202001 | AH11: 111002:221001:231001:341002:151001:261001 | AI11: 0 | AJ11: 1 | AK11: 1 | AL11: 3 | AM11: 1 | AN11: 3 | AO11: 3500 | AP11: 3 | AQ11: 70 | AR11: 16 | AS11: 507+1|0+0|549+0|-1+0|710+0|-1+0|174+0|-1+0|810+0 | AT11: 0 | AU11: 0
A12: 23001 | B12: 蒂亚 | C12: 1 | D12: 1 | E12: 0 | F12: 3 | G12: 0 | H12: 2 | I12: 2 | J12: Tia.1 | K12: Tia.1 | L12: Tia_01,Tia_02,Tia_03 | M12: 535 | N12: 13.2 | O12: 68 | P12: 2.1 | Q12: 29 | R12: 1.1 | S12: 37 | T12: 1.3 | U12: 25 | V12: 1.4 | W12: 24 | X12: 1 | Y12: 1200 | Z12: =MIN(Y12+400,1100) -> 1100 | AA12: 300 | AB12: 10 | AC12: =_xlfn.IFS(OR(F12="1",F12="2",F12="7",F12="8"),2,OR(F12="3",F12="4",F12="5",F12="6"),1) -> 1 | AD12: 120031|120032|120033|120034|120035|120036|120037 | AE12: 120003 | AF12: 201001:20 | AG12: 203001 | AH12: 111002:321001:331001:341002:351001:361001 | AI12: 0 | AJ12: 1 | AK12: 1 | AL12: 2 | AM12: 1 | AN12: 4 | AO12: 3500 | AP12: 3 | AQ12: 30 | AR12: 17 | AS12: 569+1|0+0|162+0|-1+0|711+0|-1+0|175+0|-1+0|811+0 | AT12: 0 | AU12: 0
A13: 24001 | B13: 卡秋雅 | C13: 1 | D13: 1 | E13: 0 | F13: 4 | G13: 0 | H13: 2 | I13: 2 | J13: Kachuya.1 | K13: Kachuya.1 | L13: Kachuya_01,Kachuya_02,Kachuya_03 | M13: 612 | N13: 14.9 | O13: 72 | P13: 2.2 | Q13: 34 | R13: 1.3 | S13: 47 | T13: 1.3 | U13: 32 | V13: 1.5 | W13: 20 | X13: 1 | Y13: 200 | Z13: =MIN(Y13+400,1100) -> 600 | AA13: 450 | AB13: 8 | AC13: =_xlfn.IFS(OR(F13="1",F13="2",F13="7",F13="8"),2,OR(F13="3",F13="4",F13="5",F13="6"),1) -> 1 | AD13: 120041|120042|120043|120044|120045|120046|120047 | AE13: 120004 | AF13: 204001:20 | AG13: 204001 | AH13: 411001:221001:431001:441001:451001:461002 | AI13: 0 | AJ13: 1 | AK13: 1 | AL13: 3 | AM13: 1 | AN13: 4 | AO13: 3500 | AP13: 8 | AQ13: 60 | AR13: 18 | AS13: 570+1|0+0|517+0|-1+0|712+0|-1+0|179+0|-1+0|812+0 | AT13: 0 | AU13: 0
A14: 25001 | B14: 索尼娅 | C14: 2 | D14: 1 | E14: 0 | F14: 5 | G14: 0 | H14: 2 | I14: 2 | J14: Sonia.1 | K14: Sonia.1 | L14: Sonia_01,Sonia_02,Sonia_03 | M14: 535 | N14: 12.1 | O14: 57 | P14: 2.5 | Q14: 25 | R14: 1.1 | S14: 71 | T14: 2.5 | U14: 33 | V14: 1.8 | W14: 13 | X14: 1 | Y14: 1200 | Z14: =MIN(Y14+400,1100) -> 1100 | AA14: 300 | AB14: 10 | AC14: =_xlfn.IFS(OR(F14="1",F14="2",F14="7",F14="8"),2,OR(F14="3",F14="4",F14="5",F14="6"),1) -> 1 | AD14: 120051|120052|120053|120054|120055|120056|120057 | AE14: 120005 | AF14: 205001:20 | AG14: 205001 | AH14: 111002:521001:531002:541001:151001:561001 | AI14: 0 | AJ14: 1 | AK14: 1 | AL14: 1 | AM14: 1 | AN14: 4 | AO14: 3500 | AP14: 4 | AQ14: 45 | AR14: 19 | AS14: 567+1|0+0|568+0|-1+0|713+0|-1+0|178+0|-1+0|813+0 | AT14: 0 | AU14: 0
A15: 26001 | B15: 莱恩 | C15: 2 | D15: 1 | E15: 0 | F15: 6 | G15: 0 | H15: 2 | I15: 2 | J15: Ryan.1 | K15: Ryan.1 | L15: Ryan_01,Ryan_02,Ryan_03 | M15: 568 | N15: 13.2 | O15: 55 | P15: 2.3 | Q15: 30 | R15: 1.2 | S15: 64 | T15: 2.3 | U15: 45 | V15: 2 | W15: 11 | X15: 1 | Y15: 1200 | Z15: =MIN(Y15+400,1100) -> 1100 | AA15: 300 | AB15: 10 | AC15: =_xlfn.IFS(OR(F15="1",F15="2",F15="7",F15="8"),2,OR(F15="3",F15="4",F15="5",F15="6"),1) -> 1 | AD15: 120061|120062|120063|120064|120065|120066|120067 | AE15: 120006 | AF15: 206001:20 | AG15: 206001 | AH15: 111002:621001:631001:641002:651001:661001 | AI15: 0 | AJ15: 1 | AK15: 1 | AL15: 1 | AM15: 1 | AN15: 4 | AO15: 3500 | AP15: 14 | AQ15: 45 | AR15: 20 | AS15: 565+1|0+0|566+0|-1+0|714+0|-1+0|178+0|-1+0|814+0 | AT15: 0 | AU15: 0
A16: 28001 | B16: 姆多 | C16: 1 | D16: 1 | E16: 0 | F16: 8 | G16: 0 | H16: 2 | I16: 2 | J16: Mudo.1 | K16: Mudo.1 | L16: Mudo_01,Mudo_02,Mudo_03 | M16: 623 | N16: 19.8 | O16: 76 | P16: 2.1 | Q16: 33 | R16: 1.3 | S16: 38 | T16: 1.1 | U16: 18 | V16: 1.1 | W16: 26 | X16: 1 | Y16: 200 | Z16: =MIN(Y16+400,1100) -> 600 | AA16: 300 | AB16: 8 | AC16: =_xlfn.IFS(OR(F16="1",F16="2",F16="7",F16="8"),2,OR(F16="3",F16="4",F16="5",F16="6"),1) -> 2 | AD16: 120071|120072|120073|120074|120075|120076|120077 | AE16: 120007 | AF16: 208001:20 | AG16: 208001 | AH16: 711001:721001:831001:741002:751001:161001 | AI16: 0 | AJ16: 1 | AK16: 1 | AL16: 1 | AM16: 1 | AN16: 4 | AO16: 3500 | AP16: 14 | AQ16: 45 | AR16: 20 | AS16: 565+1|0+0|566+0|-1+0|714+0|-1+0|178+0|-1+0|814+0 | AT16: 0 | AU16: 0
A17: 31001 | B17: 亚瑟 | C17: 1 | D17: 1 | E17: 0 | F17: 1 | G17: 0 | H17: 3 | I17: 3 | J17: Arthur.1 | K17: Arthur.1 | L17: Arthur_01,Arthur_02,Arthur_03 | M17: 690 | N17: 19.8 | O17: 80 | P17: 2.5 | Q17: 46 | R17: 1.7 | S17: 47 | T17: 1.4 | U17: 32 | V17: 1.6 | W17: 17 | X17: 1 | Y17: 200 | Z17: =MIN(Y17+400,1100) -> 600 | AA17: 300 | AB17: 8 | AC17: =_xlfn.IFS(OR(F17="1",F17="2",F17="7",F17="8"),2,OR(F17="3",F17="4",F17="5",F17="6"),1) -> 2 | AD17: 1300011|1300012|1300013|1300014|1300015|1300016|1300017 | AE17: 130001 | AF17: 301001:60 | AG17: 301001 | AH17: 111002:221001:231001:141002:351001:261001:161002 | AI17: 0 | AJ17: 1 | AK17: 1 | AL17: 1 | AM17: 0 | AN17: 5 | AO17: 3500 | AP17: 3 | AQ17: 45 | AR17: 21 | AS17: 506+1|0+0|564+0|-1+0|710+0|-1+0|176+0|-1+0|810+0 | AT17: 0 | AU17: 0
A18: 31002 | B18: 蕾贝卡 | C18: 1 | D18: 1 | E18: 0 | F18: 2 | G18: 0 | H18: 3 | I18: 3 | J18: Rebecca.1 | K18: Rebecca.1 | L18: Rebecca_01,Rebecca_02,Rebecca_03 | M18: 678 | N18: 18.5 | O18: 83 | P18: 2.6 | Q18: 42 | R18: 1.6 | S18: 44 | T18: 1.4 | U18: 32 | V18: 1.6 | W18: 19 | X18: 1 | Y18: 200 | Z18: =MIN(Y18+400,1100) -> 600 | AA18: 450 | AB18: 8 | AC18: =_xlfn.IFS(OR(F18="1",F18="2",F18="7",F18="8"),2,OR(F18="3",F18="4",F18="5",F18="6"),1) -> 2 | AD18: 1300021|1300022|1300023|1300024|1300025|1300026|1300027 | AE18: 130002 | AF18: 301002:60 | AG18: 301002 | AH18: 111002:221001:231001:341002:151001:261001:161002 | AI18: 0 | AJ18: 1 | AK18: 1 | AL18: 1 | AM18: 0 | AN18: 5 | AO18: 3500 | AP18: 3 | AQ18: 45 | AR18: 21 | AS18: 506+1|0+0|564+0|-1+0|710+0|-1+0|176+0|-1+0|810+0 | AT18: 0 | AU18: 0
A19: 32001 | B19: 罗宾 | C19: 1 | D19: 1 | E19: 0 | F19: 3 | G19: 0 | H19: 3 | I19: 3 | J19: Robin.1 | K19: Robin.1 | L19: Robin_01,Robin_02,Robin_03 | M19: 606 | N19: 10.8 | O19: 64 | P19: 2.5 | Q19: 28 | R19: 1.3 | S19: 41 | T19: 1.6 | U19: 31 | V19: 1.7 | W19: 26 | X19: 1 | Y19: 1200 | Z19: =MIN(Y19+400,1100) -> 1100 | AA19: 300 | AB19: 10 | AC19: =_xlfn.IFS(OR(F19="1",F19="2",F19="7",F19="8"),2,OR(F19="3",F19="4",F19="5",F19="6"),1) -> 1 | AD19: 1300031|1300032|1300033|1300034|1300035|1300036|1300037 | AE19: 130003 | AF19: 302001:60 | AG19: 302001 | AH19: 111002:321001:331001:341002:751002:361001:361002 | AI19: 0 | AJ19: 1 | AK19: 1 | AL19: 3 | AM19: 0 | AN19: 5 | AO19: 3500 | AP19: 3 | AQ19: 60 | AR19: 15 | AS19: 562+1|0+0|563+0|-1+0|716+0|-1+0|175+0|-1+0|816+0 | AT19: 0 | AU19: 0
A20: 33001 | B20: 兰斯 | C20: 1 | D20: 1 | E20: 0 | F20: 1 | G20: 0 | H20: 3 | I20: 3 | J20: Lance.1 | K20: Lance.1 | L20: Lance_01,Lance_02,Lance_03 | M20: 750 | N20: 25.1 | O20: 61 | P20: 1.6 | Q20: 55 | R20: 2 | S20: 46 | T20: 1.3 | U20: 37 | V20: 1.3 | W20: 13 | X20: 1 | Y20: 200 | Z20: =MIN(Y20+400,1100) -> 600 | AA20: 300 | AB20: 8 | AC20: =_xlfn.IFS(OR(F20="1",F20="2",F20="7",F20="8"),2,OR(F20="3",F20="4",F20="5",F20="6"),1) -> 2 | AD20: 1300041|1300042|1300043|1300044|1300045|1300046|1300047 | AE20: 130004 | AF20: 303001:60 | AG20: 303001 | AH20: 111002:221001:231001:141002:351001:261001:361001 | AI20: 0 | AJ20: 1 | AK20: 1 | AL20: 1 | AM20: 0 | AN20: 5 | AO20: 4000 | AP20: 4 | AQ20: 45 | AR20: 23 | AS20: 212+1|0+0|101+0|-1+0|708+0|-1+0|176+0|-1+0|820+0 | AT20: 0 | AU20: 0
A21: 34001 | B21: 贝尔 | C21: 1 | D21: 1 | E21: 0 | F21: 4 | G21: 0 | H21: 3 | I21: 3 | J21: Bel.1 | K21: Bel.1 | L21: Bel_01,Bel_02,Bel_03 | M21: 654 | N21: 17.9 | O21: 78 | P21: 2.6 | Q21: 40 | R21: 1.6 | S21: 50 | T21: 1.6 | U21: 35 | V21: 1.8 | W21: 21 | X21: 1 | Y21: 200 | Z21: =MIN(Y21+400,1100) -> 600 | AA21: 450 | AB21: 8 | AC21: =_xlfn.IFS(OR(F21="1",F21="2",F21="7",F21="8"),2,OR(F21="3",F21="4",F21="5",F21="6"),1) -> 1 | AD21: 1300051|1300052|1300053|1300054|1300055|1300056|1300057 | AE21: 130005 | AF21: 304001:60 | AG21: 304001 | AH21: 411001:221001:431001:741003:451001:761002:861001 | AI21: 0 | AJ21: 1 | AK21: 1 | AL21: 2 | AM21: 0 | AN21: 5 | AO21: 3500 | AP21: 14 | AQ21: 30 | AR21: 24 | AS21: 908+1|0+0|573+0|-1+0|707+0|-1+0|177+0|-1+0|818+0 | AT21: 0 | AU21: 0
... A25: 37002 | B25: 卢比 | C25: 1 | D25: 1 | E25: 0 | F25: 7 | G25: 0 | H25: 3 | I25: 3 | J25: Ruby.1 | K25: Ruby.1 | L25: Ruby_01,Ruby_02,Ruby_03 | M25: 666 | N25: 23.8 | O25: 71 | P25: 2.5 | Q25: 39 | R25: 1.6 | S25: 41 | T25: 1.3 | U25: 20 | V25: 1.3 | W25: 29 | X25: 1 | Y25: 200 | Z25: =MIN(Y25+400,1100) -> 600 | AA25: 300 | AB25: 8 | AC25: =_xlfn.IFS(OR(F25="1",F25="2",F25="7",F25="8"),2,OR(F25="3",F25="4",F25="5",F25="6"),1) -> 2 | AD25: 1300091|1300092|1300093|1300094|1300095|1300096|1300097 | AE25: 130009 | AF25: 307002:60 | AG25: 307002 | AH25: 711001:821001:831001:741002:851001:161001:761001 | AI25: 0 | AJ25: 1 | AK25: 1 | AL25: 3 | AM25: 1 | AN25: 6 | AO25: 3500 | AP25: 3 | AQ25: 30 | AR25: 25 | AS25: 512+1|0+0|574+0|-1+0|702+0|-1+0|175+0|-1+0|819+0 | AT25: 0 | AU25: 0
A26: 38001 | B26: 莫妮卡 | C26: 2 | D26: 1 | E26: 0 | F26: 8 | G26: 0 | H26: 3 | I26: 3 | J26: Monica.1 | K26: Monica.1 | L26: Monica_01,Monica_02,Monica_03 | M26: 682 | N26: 14.5 | O26: 68 | P26: 2.7 | Q26: 28 | R26: 1.3 | S26: 82 | T26: 2.7 | U26: 37 | V26: 2.2 | W26: 14 | X26: 1 | Y26: 1200 | Z26: =MIN(Y26+400,1100) -> 1100 | AA26: 300 | AB26: 10 | AC26: 1 | AD26: 1300101|1300102|1300103|1300104|1300105|1300106|1300107 | AE26: 130010 | AF26: 308001:60 | AG26: 308001 | AH26: 811001:821001:831001:841001:551001:761001:361003 | AI26: 0 | AJ26: 1 | AK26: 1 | AL26: 1 | AM26: 0 | AN26: 6 | AO26: 4000 | AP26: 3 | AQ26: 30 | AR26: 26 | AS26: 501+1|0+0|107+0|-1+0|706+0|-1+0|176+0|-1+0|817+0 | AT26: 0 | AU26: 0
A27: 38002 | B27: 迪蒙 | C27: 1 | D27: 1 | E27: 0 | F27: 8 | G27: 0 | H27: 3 | I27: 3 | J27: Dimon.1 | K27: Dimon.1 | L27: dimon_01,dimon_02,dimon_03 | M27: 690 | N27: 20 | O27: 62 | P27: 1.3 | Q27: 53 | R27: 1.2 | S27: 34 | T27: 1 | U27: 45 | V27: 1.9 | W27: 14 | X27: 1 | Y27: 200 | Z27: =MIN(Y27+400,1100) -> 600 | AA27: 300 | AB27: 8 | AC27: =_xlfn.IFS(OR(F27="1",F27="2",F27="7",F27="8"),2,OR(F27="3",F27="4",F27="5",F27="6"),1) -> 2 | AD27: 1300111|1300112|1300113|1300114|1300115|1300116|1300117 | AE27: 130011 | AF27: 308002:60 | AG27: 308002 | AH27: 711001:821001:831001:741002:251002:161001:761001 | AI27: 0 | AJ27: 1 | AK27: 1 | AL27: 1 | AM27: 0 | AN27: 6 | AO27: 4000 | AP27: 3 | AQ27: 30 | AR27: 26 | AS27: 501+1|0+0|107+0|-1+0|706+0|-1+0|176+0|-1+0|817+0 | AT27: 0 | AU27: 0
A28: 111001 | B28: 步兵 | C28: 11 | D28: 2 | E28: 1:80 | F28: 1 | G28: 1 | H28: 0 | I28: 0 | J28: bubing01_Lv1 | K28: bubing01_Lv1 | M28: =士兵数据!L2 -> 296 | N28: 0 | O28: =士兵数据!N2 -> 81 | P28: 0 | Q28: =士兵数据!P2 -> 37 | R28: 0 | S28: =士兵数据!R2 -> 60 | T28: 0 | U28: =士兵数据!T2 -> 31 | V28: 0 | W28: =士兵数据!V2 -> 10 | X28: 0 | Y28: 200 | Z28: =MIN(Y28+400,1100) -> 600 | AA28: 300 | AB28: 8 | AC28: =_xlfn.IFS(OR(F28="1",F28="2",F28="7",F28="8"),2,OR(F28="3",F28="4",F28="5",F28="6"),1) -> 2 | AD28: 70011|71011 | AE28: 0 | AF28: 0 | AG28: 0 | AH28: 0 | AI28: 看我手中的长矛可会放过你。 | AJ28: 1 | AK28: 1 | AL28: 11 | AM28: 0 | AN28: 2 | AO28: 0 | AP28: 0 | AQ28: 20 | AR28: 0 | AS28: 553+1|105+1 | AT28: 0 | AU28: 0
A29: 111002 | B29: 枪兵 | C29: 11 | D29: 2 | E29: 1:80 | F29: 1 | G29: 1 | H29: 0 | I29: 0 | J29: bubing02_Lv1 | K29: bubing02_Lv1 | M29: =士兵数据!L3 -> 348 | N29: 0 | O29: =士兵数据!N3 -> 77 | P29: 0 | Q29: =士兵数据!P3 -> 63 | R29: 0 | S29: =士兵数据!R3 -> 61 | T29: 0 | U29: =士兵数据!T3 -> 54 | V29: 0 | W29: =士兵数据!V3 -> 10 | X29: 0 | Y29: 200 | Z29: =MIN(Y29+400,1100) -> 600 | AA29: 300 | AB29: 8 | AC29: =_xlfn.IFS(OR(F29="1",F29="2",F29="7",F29="8"),2,OR(F29="3",F29="4",F29="5",F29="6"),1) -> 2 | AD29: 70021|71021 | AE29: 0 | AF29: 0 | AG29: 0 | AH29: 0 | AI29: 看我手中的长矛可会放过你。 | AJ29: =AJ28 -> 1 | AK29: 1 | AL29: 11 | AM29: 0 | AN29: 4 | AO29: 0 | AP29: 0 | AQ29: 90 | AR29: 0 | AS29: 553+1|172+1 | AT29: 0 | AU29: 0
A30: 121001 | B30: 重装步兵 | C30: 11 | D30: 2 | E30: 1:110 | F30: 1 | G30: 2 | H30: 0 | I30: 0 | J30: bubing01_Lv2 | K30: bubing01_Lv2 | M30: =士兵数据!L4 -> 676 | N30: 0 | O30: =士兵数据!N4 -> 101 | P30: 0 | Q30: =士兵数据!P4 -> 73 | R30: 0 | S30: =士兵数据!R4 -> 85 | T30: 0 | U30: =士兵数据!T4 -> 63 | V30: 0 | W30: =士兵数据!V4 -> 11 | X30: 0 | Y30: 200 | Z30: =MIN(Y30+400,1100) -> 600 | AA30: 300 | AB30: 8 | AC30: =_xlfn.IFS(OR(F30="1",F30="2",F30="7",F30="8"),2,OR(F30="3",F30="4",F30="5",F30="6"),1) -> 2 | AD30: 70031|71031 | AE30: 0 | AF30: 0 | AG30: 0 | AH30: 0 | AI30: 箭雨射击快。 | AJ30: =AJ29 -> 1 | AK30: 1 | AL30: 11 | AM30: 0 | AN30: 4 | AO30: 0 | AP30: 0 | AQ30: 90 | AR30: 0 | AS30: 553+1|172+1 | AT30: 0 | AU30: 0
A31: 121002 | B31: 重装枪兵 | C31: 11 | D31: 2 | E31: 1:110 | F31: 1 | G31: 2 | H31: 0 | I31: 0 | J31: bubing02_Lv2 | K31: bubing02_Lv2 | M31: =士兵数据!L5 -> 827 | N31: 0 | O31: =士兵数据!N5 -> 126 | P31: 0 | Q31: =士兵数据!P5 -> 91 | R31: 0 | S31: =士兵数据!R5 -> 102 | T31: 0 | U31: =士兵数据!T5 -> 79 | V31: 0 | W31: =士兵数据!V5 -> 11 | X31: 0 | Y31: 200 | Z31: =MIN(Y31+400,1100) -> 600 | AA31: 300 | AB31: 8 | AC31: =_xlfn.IFS(OR(F31="1",F31="2",F31="7",F31="8"),2,OR(F31="3",F31="4",F31="5",F31="6"),1) -> 2 | AD31: 70041|71041 | AE31: 0 | AF31: 0 | AG31: 0 | AH31: 0 | AI31: 看我手中的长矛可会放过你。 | AJ31: =AJ30 -> 1 | AK31: 1 | AL31: 11 | AM31: 0 | AN31: 4 | AO31: 0 | AP31: 0 | AQ31: 90 | AR31: 0 | AS31: 553+1|172+1 | AT31: 0 | AU31: 0
A32: 131001 | B32: 皇室近卫 | C32: 11 | D32: 2 | E32: 1:140,2:120 | F32: 1 | G32: 3 | H32: 0 | I32: 0 | J32: bubing01_Lv3 | K32: bubing01_Lv3 | M32: =士兵数据!L6 -> 1170 | N32: 0 | O32: =士兵数据!N6 -> 176 | P32: 0 | Q32: =士兵数据!P6 -> 111 | R32: 0 | S32: =士兵数据!R6 -> 123 | T32: 0 | U32: =士兵数据!T6 -> 98 | V32: 0 | W32: =士兵数据!V6 -> 11 | X32: 0 | Y32: 200 | Z32: =MIN(Y32+400,1100) -> 600 | AA32: 300 | AB32: 8 | AC32: =_xlfn.IFS(OR(F32="1",F32="2",F32="7",F32="8"),2,OR(F32="3",F32="4",F32="5",F32="6"),1) -> 2 | AD32: 70051|71051|72051 | AE32: 0 | AF32: 0 | AG32: 0 | AH32: 0 | AI32: 我的火球可不是吃素的。 | AJ32: =AJ31 -> 1 | AK32: 1 | AL32: 11 | AM32: 0 | AN32: 4 | AO32: 0 | AP32: 0 | AQ32: 90 | AR32: 0 | AS32: 553+1|172+1 | AT32: 0 | AU32: 0
A33: 131002 | B33: 刀锋战士 | C33: 11 | D33: 2 | E33: 1:140,2:120 | F33: 1 | G33: 3 | H33: 0 | I33: 0 | J33: bubing02_Lv3 | K33: bubing02_Lv3 | M33: =士兵数据!L7 -> 1155 | N33: 0 | O33: =士兵数据!N7 -> 166 | P33: 0 | Q33: =士兵数据!P7 -> 118 | R33: 0 | S33: =士兵数据!R7 -> 125 | T33: 0 | U33: =士兵数据!T7 -> 103 | V33: 0 | W33: =士兵数据!V7 -> 11 | X33: 0 | Y33: 200 | Z33: =MIN(Y33+400,1100) -> 600 | AA33: 300 | AB33: 8 | AC33: =_xlfn.IFS(OR(F33="1",F33="2",F33="7",F33="8"),2,OR(F33="3",F33="4",F33="5",F33="6"),1) -> 2 | AD33: 70061|71061|72061 | AE33: 0 | AF33: 0 | AG33: 0 | AH33: 0 | AI33: 哇哇哇哇！ | AJ33: =AJ32 -> 1 | AK33: 1 | AL33: 11 | AM33: 0 | AN33: 4 | AO33: 0 | AP33: 0 | AQ33: 90 | AR33: 0 | AS33: 553+1|172+1 | AT33: 0 | AU33: 0
A34: 131003 | B34: 格斗专家 | C34: 11 | D34: 2 | E34: 1:140,2:120 | F34: 1 | G34: 3 | H34: 0 | I34: 0 | J34: bubing03_Lv3 | K34: bubing03_Lv3 | M34: =士兵数据!L8 -> 1423 | N34: 0 | O34: =士兵数据!N8 -> 247 | P34: 0 | Q34: =士兵数据!P8 -> 131 | R34: 0 | S34: =士兵数据!R8 -> 144 | T34: 0 | U34: =士兵数据!T8 -> 142 | V34: 0 | W34: =士兵数据!V8 -> 11 | X34: 0 | Y34: 200 | Z34: =MIN(Y34+400,1100) -> 600 | AA34: 300 | AB34: 8 | AC34: =_xlfn.IFS(OR(F34="1",F34="2",F34="7",F34="8"),2,OR(F34="3",F34="4",F34="5",F34="6"),1) -> 2 | AD34: 70071|71071|72071 | AE34: 0 | AF34: 0 | AG34: 0 | AH34: 0 | AI34: 尝尝我手中的剑。 | AJ34: =AJ33 -> 1 | AK34: 1 | AL34: 11 | AM34: 0 | AN34: 4 | AO34: 0 | AP34: 0 | AQ34: 90 | AR34: 0 | AS34: 553+1|172+1 | AT34: 0 | AU34: 0
A35: 131004 | B35: 将军 | C35: 11 | D35: 2 | E35: 1:140,2:120 | F35: 1 | G35: 3 | H35: 0 | I35: 0 | J35: bubing04_Lv3 | K35: bubing04_Lv3 | M35: =士兵数据!L9 -> 1946 | N35: 0 | O35: =士兵数据!N9 -> 296 | P35: 0 | Q35: =士兵数据!P9 -> 151 | R35: 0 | S35: =士兵数据!R9 -> 172 | T35: 0 | U35: =士兵数据!T9 -> 133 | V35: 0 | W35: =士兵数据!V9 -> 12 | X35: 0 | Y35: 200 | Z35: =MIN(Y35+400,1100) -> 600 | AA35: 300 | AB35: 8 | AC35: =_xlfn.IFS(OR(F35="1",F35="2",F35="7",F35="8"),2,OR(F35="3",F35="4",F35="5",F35="6"),1) -> 2 | AD35: 70081|71081|72081 | AE35: 0 | AF35: 0 | AG35: 0 | AH35: 0 | AI35: 炮火覆盖，真理只在我的大炮射程内。 | AJ35: =AJ34 -> 1 | AK35: 1 | AL35: 11 | AM35: 0 | AN35: 4 | AO35: 0 | AP35: 0 | AQ35: 90 | AR35: 0 | AS35: 553+1|172+1 | AT35: 0 | AU35: 0
A36: 211001 | B36: 骑兵 | C36: 11 | D36: 2 | E36: 1:180 | F36: 2 | G36: 1 | H36: 0 | I36: 0 | J36: qibing01_Lv1 | K36: qibing01_Lv1 | M36: =士兵数据!L11 -> 619 | N36: 0 | O36: =士兵数据!N11 -> 103 | P36: 0 | Q36: =士兵数据!P11 -> 49 | R36: 0 | S36: =士兵数据!R11 -> 91 | T36: 0 | U36: =士兵数据!T11 -> 42 | V36: 0 | W36: =士兵数据!V11 -> 11 | X36: 0 | Y36: 200 | Z36: =MIN(Y36+400,1100) -> 600 | AA36: 400 | AB36: 8 | AC36: =_xlfn.IFS(OR(F36="1",F36="2",F36="7",F36="8"),2,OR(F36="3",F36="4",F36="5",F36="6"),1) -> 2 | AD36: 70091|71091 | AE36: 0 | AF36: 0 | AG36: 0 | AH36: 0 | AI36: 随我冲锋，粉碎敌军的攻击。 | AJ36: =AJ35 -> 1 | AK36: 1 | AL36: 11 | AM36: 0 | AN36: 4 | AO36: 0 | AP36: 0 | AQ36: 90 | AR36: 0 | AS36: 553+1|172+1 | AT36: 0 | AU36: 0
A37: 221001 | B37: 精锐骑士 | C37: 11 | D37: 2 | E37: 1:210,2:190 | F37: 2 | G37: 2 | H37: 0 | I37: 0 | J37: qibing01_Lv2 | K37: qibing01_Lv2 | M37: =士兵数据!L12 -> 967 | N37: 0 | O37: =士兵数据!N12 -> 132 | P37: 0 | Q37: =士兵数据!P12 -> 68 | R37: 0 | S37: =士兵数据!R12 -> 110 | T37: 0 | U37: =士兵数据!T12 -> 60 | V37: 0 | W37: =士兵数据!V12 -> 12 | X37: 0 | Y37: 200 | Z37: =MIN(Y37+400,1100) -> 600 | AA37: 400 | AB37: 8 | AC37: =_xlfn.IFS(OR(F37="1",F37="2",F37="7",F37="8"),2,OR(F37="3",F37="4",F37="5",F37="6"),1) -> 2 | AD37: 70101|71101 | AE37: 0 | AF37: 0 | AG37: 0 | AH37: 0 | AI37: 让你尝尝我法术的味道。 | AJ37: =AJ36 -> 1 | AK37: 1 | AL37: 11 | AM37: 0 | AN37: 4 | AO37: 0 | AP37: 0 | AQ37: 90 | AR37: 0 | AS37: 553+1|172+1 | AT37: 0 | AU37: 0
A38: 231001 | B38: 皇家骑士 | C38: 11 | D38: 2 | E38: 1:240,2:220 | F38: 2 | G38: 3 | H38: 0 | I38: 0 | J38: qibing01_Lv3 | K38: qibing01_Lv3 | M38: =士兵数据!L13 -> 1391 | N38: 0 | O38: =士兵数据!N13 -> 188 | P38: 0 | Q38: =士兵数据!P13 -> 89 | R38: 0 | S38: =士兵数据!R13 -> 130 | T38: 0 | U38: =士兵数据!T13 -> 77 | V38: 0 | W38: =士兵数据!V13 -> 12 | X38: 0 | Y38: 200 | Z38: =MIN(Y38+400,1100) -> 600 | AA38: 400 | AB38: 8 | AC38: =_xlfn.IFS(OR(F38="1",F38="2",F38="7",F38="8"),2,OR(F38="3",F38="4",F38="5",F38="6"),1) -> 2 | AD38: 70111|71111|72111 | AE38: 0 | AF38: 0 | AG38: 0 | AH38: 0 | AI38: 让你尝尝我法术的味道。 | AJ38: =AJ37 -> 1 | AK38: 1 | AL38: 11 | AM38: 0 | AN38: 4 | AO38: 0 | AP38: 0 | AQ38: 90 | AR38: 0 | AS38: 553+1|172+1 | AT38: 0 | AU38: 0
A39: 231002 | B39: 黑暗骑士 | C39: 11 | D39: 2 | E39: 1:240,2:220 | F39: 2 | G39: 3 | H39: 0 | I39: 0 | J39: qibing02_Lv3 | K39: qibing02_Lv3 | M39: =士兵数据!L14 -> 1732 | N39: 0 | O39: =士兵数据!N14 -> 229 | P39: 0 | Q39: =士兵数据!P14 -> 105 | R39: 0 | S39: =士兵数据!R14 -> 136 | T39: 0 | U39: =士兵数据!T14 -> 91 | V39: 0 | W39: =士兵数据!V14 -> 12 | X39: 0 | Y39: 200 | Z39: =MIN(Y39+400,1100) -> 600 | AA39: 400 | AB39: 8 | AC39: =_xlfn.IFS(OR(F39="1",F39="2",F39="7",F39="8"),2,OR(F39="3",F39="4",F39="5",F39="6"),1) -> 2 | AD39: 70121|71121|72121 | AE39: 0 | AF39: 0 | AG39: 0 | AH39: 0 | AI39: 让你尝尝我法术的味道。 | AJ39: =AJ38 -> 1 | AK39: 1 | AL39: 11 | AM39: 0 | AN39: 4 | AO39: 0 | AP39: 0 | AQ39: 90 | AR39: 0 | AS39: 553+1|172+1 | AT39: 0 | AU39: 0
A40: 231003 | B40: 守护骑士 | C40: 11 | D40: 2 | E40: 1:240,2:220 | F40: 2 | G40: 3 | H40: 0 | I40: 0 | J40: qibing03_Lv3 | K40: qibing03_Lv3 | M40: =士兵数据!L15 -> 1691 | N40: 0 | O40: =士兵数据!N15 -> 240 | P40: 0 | Q40: =士兵数据!P15 -> 101 | R40: 0 | S40: =士兵数据!R15 -> 139 | T40: 0 | U40: =士兵数据!T15 -> 88 | V40: 0 | W40: =士兵数据!V15 -> 12 | X40: 0 | Y40: 200 | Z40: =MIN(Y40+400,1100) -> 600 | AA40: 400 | AB40: 8 | AC40: =_xlfn.IFS(OR(F40="1",F40="2",F40="7",F40="8"),2,OR(F40="3",F40="4",F40="5",F40="6"),1) -> 2 | AD40: 70131|71131|72131 | AE40: 0 | AF40: 0 | AG40: 0 | AH40: 0 | AI40: 让你尝尝我法术的味道。 | AJ40: =AJ39 -> 1 | AK40: 1 | AL40: 11 | AM40: 0 | AN40: 4 | AO40: 0 | AP40: 0 | AQ40: 90 | AR40: 0 | AS40: 553+1|172+1 | AT40: 0 | AU40: 0
A41: 311001 | B41: 木精灵 | C41: 11 | D41: 2 | E41: 1:120 | F41: 3 | G41: 1 | H41: 0 | I41: 0 | J41: gongbing01_Lv1 | K41: gongbing01_Lv1 | M41: =士兵数据!L17 -> 399 | N41: 0 | O41: =士兵数据!N17 -> 87 | P41: 0 | Q41: =士兵数据!P17 -> 35 | R41: 0 | S41: =士兵数据!R17 -> 73 | T41: 0 | U41: =士兵数据!T17 -> 37 | V41: 0 | W41: =士兵数据!V17 -> 11 | X41: 0 | Y41: 1200 | Z41: =MIN(Y41+400,1100) -> 1100 | AA41: 300 | AB41: 10 | AC41: =_xlfn.IFS(OR(F41="1",F41="2",F41="7",F41="8"),2,OR(F41="3",F41="4",F41="5",F41="6"),1) -> 1 | AD41: 70141|71141 | AE41: 0 | AF41: 0 | AG41: 0 | AH41: 0 | AI41: 让你尝尝我法术的味道。 | AJ41: =AJ40 -> 1 | AK41: 1 | AL41: 11 | AM41: 0 | AN41: 4 | AO41: 0 | AP41: 0 | AQ41: 90 | AR41: 0 | AS41: 553+1|172+1 | AT41: 0 | AU41: 0
A42: 321001 | B42: 精灵射手 | C42: 11 | D42: 2 | E42: 1:140,2:120 | F42: 3 | G42: 2 | H42: 0 | I42: 0 | J42: gongbing01_Lv2 | K42: gongbing01_Lv2 | M42: =士兵数据!L18 -> 742 | N42: 0 | O42: =士兵数据!N18 -> 128 | P42: 0 | Q42: =士兵数据!P18 -> 45 | R42: 0 | S42: =士兵数据!R18 -> 97 | T42: 0 | U42: =士兵数据!T18 -> 50 | V42: 0 | W42: =士兵数据!V18 -> 11 | X42: 0 | Y42: 1200 | Z42: =MIN(Y42+400,1100) -> 1100 | AA42: 300 | AB42: 10 | AC42: =_xlfn.IFS(OR(F42="1",F42="2",F42="7",F42="8"),2,OR(F42="3",F42="4",F42="5",F42="6"),1) -> 1 | AD42: 70151|71151 | AE42: 0 | AF42: 0 | AG42: 0 | AH42: 0 | AI42: 让你尝尝我法术的味道。 | AJ42: =AJ41 -> 1 | AK42: 1 | AL42: 11 | AM42: 0 | AN42: 4 | AO42: 0 | AP42: 0 | AQ42: 90 | AR42: 0 | AS42: 553+1|172+1 | AT42: 0 | AU42: 0
A43: 331001 | B43: 幻影射手 | C43: 11 | D43: 2 | E43: 1:160,2:140 | F43: 3 | G43: 3 | H43: 0 | I43: 0 | J43: gongbing01_Lv3 | K43: gongbing01_Lv3 | M43: =士兵数据!L19 -> 976 | N43: 0 | O43: =士兵数据!N19 -> 178 | P43: 0 | Q43: =士兵数据!P19 -> 75 | R43: 0 | S43: =士兵数据!R19 -> 92 | T43: 0 | U43: =士兵数据!T19 -> 65 | V43: 0 | W43: =士兵数据!V19 -> 11 | X43: 0 | Y43: 1200 | Z43: =MIN(Y43+400,1100) -> 1100 | AA43: 300 | AB43: 10 | AC43: =_xlfn.IFS(OR(F43="1",F43="2",F43="7",F43="8"),2,OR(F43="3",F43="4",F43="5",F43="6"),1) -> 1 | AD43: 70161|71161|72161 | AE43: 0 | AF43: 0 | AG43: 0 | AH43: 0 | AI43: 让你尝尝我法术的味道。 | AJ43: =AJ42 -> 1 | AK43: 1 | AL43: 11 | AM43: 0 | AN43: 4 | AO43: 0 | AP43: 0 | AQ43: 90 | AR43: 0 | AS43: 553+1|172+1 | AT43: 0 | AU43: 0
...

Sheet 平衡计算
D5: 58.5 | E5: =INT(D5) -> 58
D6: 61.6 | E6: =INT(D6) -> 61
D7: 42 | E7: =INT(D7) -> 42
A8: 人口消耗 | D8: 56.7 | E8: =INT(D8) -> 56
A9: 10 | D9: 15.75 | E9: =INT(D9) -> 15
A10: 15 | D10: 19 | E10: =INT(D10) -> 19
A11: 20 | D11: 64.4 | E11: =INT(D11) -> 64
A12: 30 | D12: 67.8 | E12: =INT(D12) -> 67
A13: 50 | D13: 46.2 | E13: =INT(D13) -> 46
A14: 70 | D14: 62.4 | E14: =INT(D14) -> 62
A15: 100 | D15: 17.3 | E15: =INT(D15) -> 17
A16: 150 | D16: 20.9 | E16: =INT(D16) -> 20
