Workbook

Sheet EquipRand
A1: RandId | B1: Type | C1: Lv10 | D1: Lv20 | E1: Lv30 | F1: Lv40 | G1: Lv50 | H1: XiShu | I1: NumValue
A2: int | B2: int | C2: int | D2: int | E2: int | F2: int | G2: int | H2: int | I2: int
A3: 随机属性id | B3: 1武将生命2武将攻击3武将防御|4武将智力|5移速|6射程|7攻速|8减伤|9增伤|10技能增伤|11技能减伤|12暴击|13暴击伤害14吸血|15晕击|16韧性|17魔穿|18闪避|19命中|20反伤|21真实伤害|22部队生命|23部队攻击|24部队防御}25武将生命恢复|26部队生命恢复 | C3: 等级1-10 | D3: 等级11-20 | E3: 等级21-30 | F3: 等级31-40 | G3: 等级41-50 | H3: 要除的系数 | I3: 对应的价值
A4: 1 | B4: =INT((A4-1)/10)+1 -> 1 | C4: =INT(F4/($J$4*$J$4*$J$4)) -> 31 | D4: =INT(F4/($J$4*$J$4)) -> 62 | E4: =INT(F4/$J$4) -> 125 | F4: =原始数据!R6 -> 250 | G4: =F4*2 -> 500 | H4: =VLOOKUP(B4,原始数据!$H$6:$N$31,7,FALSE) -> 1 | I4: =VLOOKUP(B4,原始数据!$H$6:$O$31,8,FALSE) -> 1 | J4: 2
A5: 2 | B5: =INT((A5-1)/10)+1 -> 1 | C5: =INT(C$4*$J$5) -> 24 | D5: =INT(D$4*$J$5) -> 49 | E5: =INT(E$4*$J$5) -> 100 | F5: =INT(F$4*$J$5) -> 200 | G5: =INT(G$4*$J$5) -> 400 | H5: =VLOOKUP(B5,原始数据!$H$6:$N$31,7,FALSE) -> 1 | I5: =VLOOKUP(B5,原始数据!$H$6:$O$31,8,FALSE) -> 1 | J5: 0.8
A6: 3 | B6: =INT((A6-1)/10)+1 -> 1 | C6: =INT(C$4*$J$6) -> 26 | D6: =INT(D$4*$J$6) -> 52 | E6: =INT(E$4*$J$6) -> 106 | F6: =INT(F$4*$J$6) -> 212 | G6: =INT(G$4*$J$6) -> 425 | H6: =VLOOKUP(B6,原始数据!$H$6:$N$31,7,FALSE) -> 1 | I6: =VLOOKUP(B6,原始数据!$H$6:$O$31,8,FALSE) -> 1 | J6: 0.85
A7: 4 | B7: =INT((A7-1)/10)+1 -> 1 | C7: =INT(C$4*$J$7) -> 27 | D7: =INT(D$4*$J$7) -> 55 | E7: =INT(E$4*$J$7) -> 112 | F7: =INT(F$4*$J$7) -> 225 | G7: =INT(G$4*$J$7) -> 450 | H7: =VLOOKUP(B7,原始数据!$H$6:$N$31,7,FALSE) -> 1 | I7: =VLOOKUP(B7,原始数据!$H$6:$O$31,8,FALSE) -> 1 | J7: 0.9
A8: 5 | B8: =INT((A8-1)/10)+1 -> 1 | C8: =INT(C$4*$J$8) -> 29 | D8: =INT(D$4*$J$8) -> 58 | E8: =INT(E$4*$J$8) -> 118 | F8: =INT(F$4*$J$8) -> 237 | G8: =INT(G$4*$J$8) -> 475 | H8: =VLOOKUP(B8,原始数据!$H$6:$N$31,7,FALSE) -> 1 | I8: =VLOOKUP(B8,原始数据!$H$6:$O$31,8,FALSE) -> 1 | J8: 0.95
A9: 6 | B9: =INT((A9-1)/10)+1 -> 1 | C9: =INT(C$4*$J$9) -> 31 | D9: =INT(D$4*$J$9) -> 62 | E9: =INT(E$4*$J$9) -> 125 | F9: =INT(F$4*$J$9) -> 250 | G9: =INT(G$4*$J$9) -> 500 | H9: =VLOOKUP(B9,原始数据!$H$6:$N$31,7,FALSE) -> 1 | I9: =VLOOKUP(B9,原始数据!$H$6:$O$31,8,FALSE) -> 1 | J9: 1
A10: 7 | B10: =INT((A10-1)/10)+1 -> 1 | C10: =INT(C$4*$J$10) -> 32 | D10: =INT(D$4*$J$10) -> 65 | E10: =INT(E$4*$J$10) -> 131 | F10: =INT(F$4*$J$10) -> 262 | G10: =INT(G$4*$J$10) -> 525 | H10: =VLOOKUP(B10,原始数据!$H$6:$N$31,7,FALSE) -> 1 | I10: =VLOOKUP(B10,原始数据!$H$6:$O$31,8,FALSE) -> 1 | J10: 1.05
A11: 8 | B11: =INT((A11-1)/10)+1 -> 1 | C11: =INT(C$4*$J$11) -> 34 | D11: =INT(D$4*$J$11) -> 68 | E11: =INT(E$4*$J$11) -> 137 | F11: =INT(F$4*$J$11) -> 275 | G11: =INT(G$4*$J$11) -> 550 | H11: =VLOOKUP(B11,原始数据!$H$6:$N$31,7,FALSE) -> 1 | I11: =VLOOKUP(B11,原始数据!$H$6:$O$31,8,FALSE) -> 1 | J11: 1.1
A12: 9 | B12: =INT((A12-1)/10)+1 -> 1 | C12: =INT(C$4*$J$12) -> 35 | D12: =INT(D$4*$J$12) -> 71 | E12: =INT(E$4*$J$12) -> 143 | F12: =INT(F$4*$J$12) -> 287 | G12: =INT(G$4*$J$12) -> 575 | H12: =VLOOKUP(B12,原始数据!$H$6:$N$31,7,FALSE) -> 1 | I12: =VLOOKUP(B12,原始数据!$H$6:$O$31,8,FALSE) -> 1 | J12: 1.15
A13: 10 | B13: =INT((A13-1)/10)+1 -> 1 | C13: =INT(C$4*$J$13) -> 37 | D13: =INT(D$4*$J$13) -> 74 | E13: =INT(E$4*$J$13) -> 150 | F13: =INT(F$4*$J$13) -> 300 | G13: =INT(G$4*$J$13) -> 600 | H13: =VLOOKUP(B13,原始数据!$H$6:$N$31,7,FALSE) -> 1 | I13: =VLOOKUP(B13,原始数据!$H$6:$O$31,8,FALSE) -> 1 | J13: 1.2
A14: 11 | B14: =INT((A14-1)/10)+1 -> 2 | C14: =INT(F14/($J$4*$J$4*$J$4)) -> 18 | D14: =INT(F14/($J$4*$J$4)) -> 37 | E14: =INT(F14/$J$4) -> 75 | F14: =原始数据!R7 -> 150 | G14: =F14*2 -> 300 | H14: =VLOOKUP(B14,原始数据!$H$6:$N$31,7,FALSE) -> 10 | I14: =VLOOKUP(B14,原始数据!$H$6:$O$31,8,FALSE) -> 27
A15: 12 | B15: =INT((A15-1)/10)+1 -> 2 | C15: =INT(C$14*$J$5) -> 14 | D15: =INT(D$14*$J$5) -> 29 | E15: =INT(E$14*$J$5) -> 60 | F15: =INT(F$14*$J$5) -> 120 | G15: =INT(G$14*$J$5) -> 240 | H15: =VLOOKUP(B15,原始数据!$H$6:$N$31,7,FALSE) -> 10 | I15: =VLOOKUP(B15,原始数据!$H$6:$O$31,8,FALSE) -> 27
A16: 13 | B16: =INT((A16-1)/10)+1 -> 2 | C16: =INT(C$14*$J$6) -> 15 | D16: =INT(D$14*$J$6) -> 31 | E16: =INT(E$14*$J$6) -> 63 | F16: =INT(F$14*$J$6) -> 127 | G16: =INT(G$14*$J$6) -> 255 | H16: =VLOOKUP(B16,原始数据!$H$6:$N$31,7,FALSE) -> 10 | I16: =VLOOKUP(B16,原始数据!$H$6:$O$31,8,FALSE) -> 27
A17: 14 | B17: =INT((A17-1)/10)+1 -> 2 | C17: =INT(C$14*$J$7) -> 16 | D17: =INT(D$14*$J$7) -> 33 | E17: =INT(E$14*$J$7) -> 67 | F17: =INT(F$14*$J$7) -> 135 | G17: =INT(G$14*$J$7) -> 270 | H17: =VLOOKUP(B17,原始数据!$H$6:$N$31,7,FALSE) -> 10 | I17: =VLOOKUP(B17,原始数据!$H$6:$O$31,8,FALSE) -> 27
A18: 15 | B18: =INT((A18-1)/10)+1 -> 2 | C18: =INT(C$14*$J$8) -> 17 | D18: =INT(D$14*$J$8) -> 35 | E18: =INT(E$14*$J$8) -> 71 | F18: =INT(F$14*$J$8) -> 142 | G18: =INT(G$14*$J$8) -> 285 | H18: =VLOOKUP(B18,原始数据!$H$6:$N$31,7,FALSE) -> 10 | I18: =VLOOKUP(B18,原始数据!$H$6:$O$31,8,FALSE) -> 27
A19: 16 | B19: =INT((A19-1)/10)+1 -> 2 | C19: =INT(C$14*$J$9) -> 18 | D19: =INT(D$14*$J$9) -> 37 | E19: =INT(E$14*$J$9) -> 75 | F19: =INT(F$14*$J$9) -> 150 | G19: =INT(G$14*$J$9) -> 300 | H19: =VLOOKUP(B19,原始数据!$H$6:$N$31,7,FALSE) -> 10 | I19: =VLOOKUP(B19,原始数据!$H$6:$O$31,8,FALSE) -> 27
A20: 17 | B20: =INT((A20-1)/10)+1 -> 2 | C20: =INT(C$14*$J$10) -> 18 | D20: =INT(D$14*$J$10) -> 38 | E20: =INT(E$14*$J$10) -> 78 | F20: =INT(F$14*$J$10) -> 157 | G20: =INT(G$14*$J$10) -> 315 | H20: =VLOOKUP(B20,原始数据!$H$6:$N$31,7,FALSE) -> 10 | I20: =VLOOKUP(B20,原始数据!$H$6:$O$31,8,FALSE) -> 27
A21: 18 | B21: =INT((A21-1)/10)+1 -> 2 | C21: =INT(C$14*$J$11) -> 19 | D21: =INT(D$14*$J$11) -> 40 | E21: =INT(E$14*$J$11) -> 82 | F21: =INT(F$14*$J$11) -> 165 | G21: =INT(G$14*$J$11) -> 330 | H21: =VLOOKUP(B21,原始数据!$H$6:$N$31,7,FALSE) -> 10 | I21: =VLOOKUP(B21,原始数据!$H$6:$O$31,8,FALSE) -> 27
A22: 19 | B22: =INT((A22-1)/10)+1 -> 2 | C22: =INT(C$14*$J$12) -> 20 | D22: =INT(D$14*$J$12) -> 42 | E22: =INT(E$14*$J$12) -> 86 | F22: =INT(F$14*$J$12) -> 172 | G22: =INT(G$14*$J$12) -> 345 | H22: =VLOOKUP(B22,原始数据!$H$6:$N$31,7,FALSE) -> 10 | I22: =VLOOKUP(B22,原始数据!$H$6:$O$31,8,FALSE) -> 27
A23: 20 | B23: =INT((A23-1)/10)+1 -> 2 | C23: =INT(C$14*$J$13) -> 21 | D23: =INT(D$14*$J$13) -> 44 | E23: =INT(E$14*$J$13) -> 90 | F23: =INT(F$14*$J$13) -> 180 | G23: =INT(G$14*$J$13) -> 360 | H23: =VLOOKUP(B23,原始数据!$H$6:$N$31,7,FALSE) -> 10 | I23: =VLOOKUP(B23,原始数据!$H$6:$O$31,8,FALSE) -> 27
A24: 21 | B24: =INT((A24-1)/10)+1 -> 3 | C24: =INT(F24/($J$4*$J$4*$J$4)) -> 18 | D24: =INT(F24/($J$4*$J$4)) -> 37 | E24: =INT(F24/$J$4) -> 75 | F24: =原始数据!R8 -> 150 | G24: =F24*2 -> 300 | H24: =VLOOKUP(B24,原始数据!$H$6:$N$31,7,FALSE) -> 10 | I24: =VLOOKUP(B24,原始数据!$H$6:$O$31,8,FALSE) -> 27
A25: 22 | B25: =INT((A25-1)/10)+1 -> 3 | C25: =INT(C$24*$J$5) -> 14 | D25: =INT(D$24*$J$5) -> 29 | E25: =INT(E$24*$J$5) -> 60 | F25: =INT(F$24*$J$5) -> 120 | G25: =INT(G$24*$J$5) -> 240 | H25: =VLOOKUP(B25,原始数据!$H$6:$N$31,7,FALSE) -> 10 | I25: =VLOOKUP(B25,原始数据!$H$6:$O$31,8,FALSE) -> 27
A26: 23 | B26: =INT((A26-1)/10)+1 -> 3 | C26: =INT(C$24*$J$6) -> 15 | D26: =INT(D$24*$J$6) -> 31 | E26: =INT(E$24*$J$6) -> 63 | F26: =INT(F$24*$J$6) -> 127 | G26: =INT(G$24*$J$6) -> 255 | H26: =VLOOKUP(B26,原始数据!$H$6:$N$31,7,FALSE) -> 10 | I26: =VLOOKUP(B26,原始数据!$H$6:$O$31,8,FALSE) -> 27
A27: 24 | B27: =INT((A27-1)/10)+1 -> 3 | C27: =INT(C$24*$J$7) -> 16 | D27: =INT(D$24*$J$7) -> 33 | E27: =INT(E$24*$J$7) -> 67 | F27: =INT(F$24*$J$7) -> 135 | G27: =INT(G$24*$J$7) -> 270 | H27: =VLOOKUP(B27,原始数据!$H$6:$N$31,7,FALSE) -> 10 | I27: =VLOOKUP(B27,原始数据!$H$6:$O$31,8,FALSE) -> 27
A28: 25 | B28: =INT((A28-1)/10)+1 -> 3 | C28: =INT(C$24*$J$8) -> 17 | D28: =INT(D$24*$J$8) -> 35 | E28: =INT(E$24*$J$8) -> 71 | F28: =INT(F$24*$J$8) -> 142 | G28: =INT(G$24*$J$8) -> 285 | H28: =VLOOKUP(B28,原始数据!$H$6:$N$31,7,FALSE) -> 10 | I28: =VLOOKUP(B28,原始数据!$H$6:$O$31,8,FALSE) -> 27
A29: 26 | B29: =INT((A29-1)/10)+1 -> 3 | C29: =INT(C$24*$J$9) -> 18 | D29: =INT(D$24*$J$9) -> 37 | E29: =INT(E$24*$J$9) -> 75 | F29: =INT(F$24*$J$9) -> 150 | G29: =INT(G$24*$J$9) -> 300 | H29: =VLOOKUP(B29,原始数据!$H$6:$N$31,7,FALSE) -> 10 | I29: =VLOOKUP(B29,原始数据!$H$6:$O$31,8,FALSE) -> 27
A30: 27 | B30: =INT((A30-1)/10)+1 -> 3 | C30: =INT(C$24*$J$10) -> 18 | D30: =INT(D$24*$J$10) -> 38 | E30: =INT(E$24*$J$10) -> 78 | F30: =INT(F$24*$J$10) -> 157 | G30: =INT(G$24*$J$10) -> 315 | H30: =VLOOKUP(B30,原始数据!$H$6:$N$31,7,FALSE) -> 10 | I30: =VLOOKUP(B30,原始数据!$H$6:$O$31,8,FALSE) -> 27
A31: 28 | B31: =INT((A31-1)/10)+1 -> 3 | C31: =INT(C$24*$J$11) -> 19 | D31: =INT(D$24*$J$11) -> 40 | E31: =INT(E$24*$J$11) -> 82 | F31: =INT(F$24*$J$11) -> 165 | G31: =INT(G$24*$J$11) -> 330 | H31: =VLOOKUP(B31,原始数据!$H$6:$N$31,7,FALSE) -> 10 | I31: =VLOOKUP(B31,原始数据!$H$6:$O$31,8,FALSE) -> 27
A32: 29 | B32: =INT((A32-1)/10)+1 -> 3 | C32: =INT(C$24*$J$12) -> 20 | D32: =INT(D$24*$J$12) -> 42 | E32: =INT(E$24*$J$12) -> 86 | F32: =INT(F$24*$J$12) -> 172 | G32: =INT(G$24*$J$12) -> 345 | H32: =VLOOKUP(B32,原始数据!$H$6:$N$31,7,FALSE) -> 10 | I32: =VLOOKUP(B32,原始数据!$H$6:$O$31,8,FALSE) -> 27
A33: 30 | B33: =INT((A33-1)/10)+1 -> 3 | C33: =INT(C$24*$J$13) -> 21 | D33: =INT(D$24*$J$13) -> 44 | E33: =INT(E$24*$J$13) -> 90 | F33: =INT(F$24*$J$13) -> 180 | G33: =INT(G$24*$J$13) -> 360 | H33: =VLOOKUP(B33,原始数据!$H$6:$N$31,7,FALSE) -> 10 | I33: =VLOOKUP(B33,原始数据!$H$6:$O$31,8,FALSE) -> 27
A34: 31 | B34: =INT((A34-1)/10)+1 -> 4 | C34: =INT(F34/($J$4*$J$4*$J$4)) -> 17 | D34: =INT(F34/($J$4*$J$4)) -> 34 | E34: =INT(F34/$J$4) -> 68 | F34: =原始数据!R9 -> 137 | G34: =F34*2 -> 274 | H34: =VLOOKUP(B34,原始数据!$H$6:$N$31,7,FALSE) -> 10 | I34: =VLOOKUP(B34,原始数据!$H$6:$O$31,8,FALSE) -> 30
A35: 32 | B35: =INT((A35-1)/10)+1 -> 4 | C35: =INT(C$34*$J$5) -> 13 | D35: =INT(D$34*$J$5) -> 27 | E35: =INT(E$34*$J$5) -> 54 | F35: =INT(F$34*$J$5) -> 109 | G35: =INT(G$34*$J$5) -> 219 | H35: =VLOOKUP(B35,原始数据!$H$6:$N$31,7,FALSE) -> 10 | I35: =VLOOKUP(B35,原始数据!$H$6:$O$31,8,FALSE) -> 30
A36: 33 | B36: =INT((A36-1)/10)+1 -> 4 | C36: =INT(C$34*$J$6) -> 14 | D36: =INT(D$34*$J$6) -> 28 | E36: =INT(E$34*$J$6) -> 57 | F36: =INT(F$34*$J$6) -> 116 | G36: =INT(G$34*$J$6) -> 232 | H36: =VLOOKUP(B36,原始数据!$H$6:$N$31,7,FALSE) -> 10 | I36: =VLOOKUP(B36,原始数据!$H$6:$O$31,8,FALSE) -> 30
A37: 34 | B37: =INT((A37-1)/10)+1 -> 4 | C37: =INT(C$34*$J$7) -> 15 | D37: =INT(D$34*$J$7) -> 30 | E37: =INT(E$34*$J$7) -> 61 | F37: =INT(F$34*$J$7) -> 123 | G37: =INT(G$34*$J$7) -> 246 | H37: =VLOOKUP(B37,原始数据!$H$6:$N$31,7,FALSE) -> 10 | I37: =VLOOKUP(B37,原始数据!$H$6:$O$31,8,FALSE) -> 30
A38: 35 | B38: =INT((A38-1)/10)+1 -> 4 | C38: =INT(C$34*$J$8) -> 16 | D38: =INT(D$34*$J$8) -> 32 | E38: =INT(E$34*$J$8) -> 64 | F38: =INT(F$34*$J$8) -> 130 | G38: =INT(G$34*$J$8) -> 260 | H38: =VLOOKUP(B38,原始数据!$H$6:$N$31,7,FALSE) -> 10 | I38: =VLOOKUP(B38,原始数据!$H$6:$O$31,8,FALSE) -> 30
A39: 36 | B39: =INT((A39-1)/10)+1 -> 4 | C39: =INT(C$34*$J$9) -> 17 | D39: =INT(D$34*$J$9) -> 34 | E39: =INT(E$34*$J$9) -> 68 | F39: =INT(F$34*$J$9) -> 137 | G39: =INT(G$34*$J$9) -> 274 | H39: =VLOOKUP(B39,原始数据!$H$6:$N$31,7,FALSE) -> 10 | I39: =VLOOKUP(B39,原始数据!$H$6:$O$31,8,FALSE) -> 30
A40: 37 | B40: =INT((A40-1)/10)+1 -> 4 | C40: =INT(C$34*$J$10) -> 17 | D40: =INT(D$34*$J$10) -> 35 | E40: =INT(E$34*$J$10) -> 71 | F40: =INT(F$34*$J$10) -> 143 | G40: =INT(G$34*$J$10) -> 287 | H40: =VLOOKUP(B40,原始数据!$H$6:$N$31,7,FALSE) -> 10 | I40: =VLOOKUP(B40,原始数据!$H$6:$O$31,8,FALSE) -> 30
...

Sheet 原始数据
P3: 1戒指/2玉佩/3武器/4防具/5鞋子/6书
D4: lv10 | E4: lv20 | F4: lv30 | G4: lv40
D5: =INT(G5/8) -> 15 | E5: =INT(G5/4) -> 31 | F5: =INT(G5/2) -> 62 | G5: 125 | J5: 参考值(英雄70级属性) | K5: 系数 | L5: 调整数值 | M5: 最大值 | N5: 需除 | O5: 价值 | P5: 部位数 | R5: 最终结果
H6: 1 | I6: 生命值 | J6: 6000 | K6: =P6*6 -> 12 | L6: 6000 | M6: =L6*N6 -> 6000 | N6: 1 | O6: 1 | P6: 2 | Q6: 防具/鞋子 | R6: =INT(M6/K6/2) -> 250 | S6: 1 | T6: 武将生命值
H7: 2 | I7: 攻击 | J7: 360 | K7: =P7*6 -> 12 | L7: 360 | M7: =L7*N7 -> 3600 | N7: 10 | O7: =INT(10000*N7/M7) -> 27 | P7: 2 | Q7: 戒指/武器 | R7: =INT(M7/K7/2) -> 150 | S7: 2 | T7: 武将攻击
C8: lv | D8: 数值 | E8: 数值 | F8: 数值 | H8: 3 | I8: 防御 | J8: 360 | K8: =P8*6 -> 12 | L8: 360 | M8: =L8*N8 -> 3600 | N8: 10 | O8: =INT(10000*N8/M8) -> 27 | P8: 2 | Q8: 防具/鞋子 | R8: =INT(M8/K8/2) -> 150 | S8: 3 | T8: 武将防御
C9: 1.1 | D9: =D$5*$C9 -> 16.5 | E9: =E$5*$C9 -> 34.1 | F9: =F$5*$C9 -> 68.2 | G9: =G$5*$C9 -> 137.5 | H9: 4 | I9: 法强 | J9: 330 | K9: =P9*6 -> 12 | L9: 330 | M9: =L9*N9 -> 3300 | N9: 10 | O9: =INT(10000*N9/M9) -> 30 | P9: 2 | Q9: 玉佩/书 | R9: =INT(M9/K9/2) -> 137 | S9: 4 | T9: 武将智力
C10: 1.2 | D10: =D$5*$C10 -> 18 | E10: =E$5*$C10 -> 37.2 | F10: =F$5*$C10 -> 74.4 | G10: =G$5*$C10 -> 150 | H10: 5 | I10: 移速 | J10: 200 | K10: =P10*6 -> 6 | L10: 200 | M10: =L10*N10 -> 2000 | N10: 10 | O10: =INT(10000*N10/M10) -> 50 | P10: 1 | Q10: 鞋子 | R10: =INT(M10/K10/2) -> 166 | S10: 5 | T10: 移速
C11: 1.3 | D11: =D$5*$C11 -> 19.5 | E11: =E$5*$C11 -> 40.3 | F11: =F$5*$C11 -> 80.6 | G11: =G$5*$C11 -> 162.5 | H11: 6 | I11: 射程 | J11: 300 | K11: =P11*6 -> 6 | L11: 300 | M11: =L11*N11 -> 3000 | N11: 10 | O11: =INT(10000*N11/M11) -> 33 | P11: 1 | Q11: 武器 | R11: =INT(M11/K11/2) -> 250 | S11: 6 | T11: 射程
C12: 1.4 | D12: =D$5*$C12 -> 21 | E12: =E$5*$C12 -> 43.4 | F12: =F$5*$C12 -> 86.8 | G12: =G$5*$C12 -> 175 | H12: 7 | I12: 攻速 | J12: 150 | K12: =P12*6 -> 6 | L12: 150 | M12: =L12*N12 -> 1500 | N12: 10 | O12: =INT(10000*N12/M12) -> 66 | P12: 1 | Q12: 武器 | R12: =INT(M12/K12/2) -> 125 | S12: 7 | T12: 攻速
C13: 1.5 | D13: =D$5*$C13 -> 22.5 | E13: =E$5*$C13 -> 46.5 | F13: =F$5*$C13 -> 93 | G13: =G$5*$C13 -> 187.5 | H13: 8 | I13: 物抗 | J13: 80 | K13: =P13*6 -> 6 | L13: 80 | M13: =L13*N13 -> 800 | N13: 10 | O13: =INT(10000*N13/M13) -> 125 | P13: 1 | Q13: 防具 | R13: =INT(M13/K13/2) -> 66 | S13: 8 | T13: 减伤
C14: 1.6 | D14: =D$5*$C14 -> 24 | E14: =E$5*$C14 -> 49.6 | F14: =F$5*$C14 -> 99.2 | G14: =G$5*$C14 -> 200 | H14: 9 | I14: 普攻增伤 | J14: 200 | K14: =P14*6 -> 6 | L14: 200 | M14: =L14*N14 -> 2000 | N14: 10 | O14: =INT(10000*N14/M14) -> 50 | P14: 1 | Q14: 武器 | R14: =INT(M14/K14/2) -> 166 | S14: 9 | T14: 增伤
C15: 1.7 | D15: =D$5*$C15 -> 25.5 | E15: =E$5*$C15 -> 52.7 | F15: =F$5*$C15 -> 105.4 | G15: =G$5*$C15 -> 212.5 | H15: 10 | I15: 魔抗 | J15: 80 | K15: =P15*6 -> 6 | L15: 80 | M15: =L15*N15 -> 800 | N15: 10 | O15: =INT(10000*N15/M15) -> 125 | P15: 1 | Q15: 防具 | R15: =INT(M15/K15/2) -> 66 | S15: 10 | T15: 技能减伤
C16: 1.8 | D16: =D$5*$C16 -> 27 | E16: =E$5*$C16 -> 55.8 | F16: =F$5*$C16 -> 111.6 | G16: =G$5*$C16 -> 225 | H16: 11 | I16: 法术增伤 | J16: 200 | K16: =P16*6 -> 6 | L16: 200 | M16: =L16*N16 -> 2000 | N16: 10 | O16: =INT(10000*N16/M16) -> 50 | P16: 1 | Q16: 玉佩 | R16: =INT(M16/K16/2) -> 166 | S16: 11 | T16: 技能伤害
C17: 1.9 | D17: =D$5*$C17 -> 28.5 | E17: =E$5*$C17 -> 58.9 | F17: =F$5*$C17 -> 117.8 | G17: =G$5*$C17 -> 237.5 | H17: 12 | I17: 暴击 | J17: 100 | K17: =P17*6 -> 6 | L17: 100 | M17: =L17*N17 -> 1000 | N17: 10 | O17: =INT(10000*N17/M17) -> 100 | P17: 1 | Q17: 武器 | R17: =INT(M17/K17/2) -> 83 | S17: 12 | T17: 暴击
C18: 2 | D18: =D$5*$C18 -> 30 | E18: =E$5*$C18 -> 62 | F18: =F$5*$C18 -> 124 | G18: =G$5*$C18 -> 250 | H18: 13 | I18: 暴伤 | J18: 200 | K18: =P18*6 -> 6 | L18: 200 | M18: =L18*N18 -> 2000 | N18: 10 | O18: =INT(10000*N18/M18) -> 50 | P18: 1 | Q18: 武器 | R18: =INT(M18/K18/2) -> 166 | S18: 13 | T18: 暴伤
C19: 2.1 | D19: =D$5*$C19 -> 31.5 | E19: =E$5*$C19 -> 65.1 | F19: =F$5*$C19 -> 130.2 | H19: 14 | I19: 吸血 | J19: 40 | K19: =P19*6 -> 12 | L19: 40 | M19: =L19*N19 -> 4000 | N19: 100 | O19: =INT(10000*N19/M19) -> 250 | P19: 2 | Q19: 戒指/玉佩 | R19: =INT(M19/K19/2) -> 166 | S19: 14 | T19: 吸血
C20: 2.2 | D20: =D$5*$C20 -> 33 | E20: =E$5*$C20 -> 68.2 | F20: =F$5*$C20 -> 136.4 | H20: 15 | I20: 物穿 | J20: 50 | K20: =P20*6 -> 6 | L20: 50 | M20: =L20*N20 -> 5000 | N20: 100 | O20: =INT(10000*N20/M20) -> 200 | P20: 1 | Q20: 戒指 | R20: =INT(M20/K20/2) -> 416 | S20: 15 | T20: 晕击
C21: 2.3 | D21: =D$5*$C21 -> 34.5 | E21: =E$5*$C21 -> 71.3 | F21: =F$5*$C21 -> 142.6 | H21: 16 | I21: 韧性 | J21: 50 | K21: =P21*6 -> 6 | L21: 50 | M21: =L21*N21 -> 500 | N21: 10 | O21: =INT(10000*N21/M21) -> 200 | P21: 1 | Q21: 防具 | R21: =INT(M21/K21/2) -> 41 | S21: 16 | T21: 韧性
C22: 2.4 | D22: =D$5*$C22 -> 36 | E22: =E$5*$C22 -> 74.4 | F22: =F$5*$C22 -> 148.8 | H22: 17 | I22: 魔穿 | J22: 50 | K22: =P22*6 -> 6 | L22: 50 | M22: =L22*N22 -> 500 | N22: 10 | O22: =INT(10000*N22/M22) -> 200 | P22: 1 | Q22: 防具 | R22: =INT(M22/K22/2) -> 41 | S22: 17 | T22: 魔穿
C23: 2.5 | D23: =D$5*$C23 -> 37.5 | E23: =E$5*$C23 -> 77.5 | F23: =F$5*$C23 -> 155 | H23: 18 | I23: 闪避 | J23: 40 | K23: =P23*6 -> 6 | L23: 40 | M23: =L23*N23 -> 4000 | N23: 100 | O23: =INT(10000*N23/M23) -> 250 | P23: 1 | Q23: 鞋子 | R23: =INT(M23/K23/2) -> 333 | S23: 18 | T23: 闪避
C24: 2.6 | D24: =D$5*$C24 -> 39 | E24: =E$5*$C24 -> 80.6 | F24: =F$5*$C24 -> 161.2 | H24: 19 | I24: 命中 | J24: 60 | K24: =P24*6 -> 6 | L24: 60 | M24: =L24*N24 -> 600 | N24: 10 | O24: =INT(10000*N24/M24) -> 166 | P24: 1 | Q24: 鞋子 | R24: =INT(M24/K24/2) -> 50 | S24: 19 | T24: 命中
C25: 2.7 | D25: =D$5*$C25 -> 40.5 | E25: =E$5*$C25 -> 83.7 | F25: =F$5*$C25 -> 167.4 | H25: 20 | I25: 反伤 | J25: 30 | K25: =P25*6 -> 6 | L25: 30 | M25: =L25*N25 -> 300 | N25: 10 | O25: =INT(10000*N25/M25) -> 333 | P25: 1 | Q25: 戒指 | R25: =INT(M25/K25/2) -> 25 | S25: 20 | T25: 反伤
C26: 2.8 | D26: =D$5*$C26 -> 42 | E26: =E$5*$C26 -> 86.8 | F26: =F$5*$C26 -> 173.6 | H26: 21 | I26: 真实伤害 | J26: 200 | K26: =P26*6 -> 6 | L26: 200 | M26: =L26*N26 -> 2000 | N26: 10 | O26: =INT(10000*N26/M26) -> 50 | P26: 1 | Q26: 戒指 | R26: =INT(M26/K26/2) -> 166 | S26: 21 | T26: 真实伤害
C27: 2.9 | D27: =D$5*$C27 -> 43.5 | E27: =E$5*$C27 -> 89.9 | F27: =F$5*$C27 -> 179.8 | H27: 22 | I27: 部队生命 | J27: 200 | K27: =P27*6 -> 12 | L27: 200 | M27: =L27*N27 -> 2000 | N27: 10 | O27: =INT(10000*N27/M27) -> 50 | P27: 2 | Q27: 玉佩,书 | R27: =INT(M27/K27/2) -> 83 | S27: 22 | T27: 部队生命
C28: 3 | D28: =D$5*$C28 -> 45 | E28: =E$5*$C28 -> 93 | F28: =F$5*$C28 -> 186 | H28: 23 | I28: 部队攻击 | J28: 200 | K28: =P28*6 -> 12 | L28: 200 | M28: =L28*N28 -> 2000 | N28: 10 | O28: =INT(10000*N28/M28) -> 50 | P28: 2 | Q28: 玉佩,书 | R28: =INT(M28/K28/2) -> 83 | S28: 23 | T28: 部队攻击
H29: 24 | I29: 部队防御 | J29: 200 | K29: =P29*6 -> 12 | L29: 200 | M29: =L29*N29 -> 2000 | N29: 10 | O29: =INT(10000*N29/M29) -> 50 | P29: 2 | Q29: 玉佩,书 | R29: =INT(M29/K29/2) -> 83 | S29: 24 | T29: 部队防御
H30: 25 | I30: 武将生命恢复 | J30: 2 | K30: =P30*6 -> 6 | L30: 3 | M30: =L30*N30 -> 3000 | N30: 1000 | O30: =INT(10000*N30/M30) -> 3333 | P30: 1 | Q30: 鞋子 | R30: =INT(M30/K30/2) -> 250 | S30: 25 | T30: 武将生命恢复
H31: 26 | I31: 部队生命恢复 | J31: 2 | K31: =P31*6 -> 6 | L31: 3 | M31: =L31*N31 -> 3000 | N31: 1000 | O31: =INT(10000*N31/M31) -> 3333 | P31: 1 | Q31: 书 | R31: =INT(M31/K31/2) -> 250 | S31: 26 | T31: 部队生命恢复
H34: 2|5|15|16|21|22
G35: 戒指 | H35: 4|12|15|23|24|25
G36: 玉佩 | H36: 2|7|8|10|13|14
G37: 武器 | H37: 1|3|9|11|17|18
G38: 防具 | H38: 1|3|6|19|20|26
G39: 鞋子 | H39: 4|5|23|24|25|27
G40: 书

Sheet Sheet2
B4: 7魔抗%|8物抗%|9吸血%|10移动距离1|11射程1|
G6: 1攻击|2防御|3法强|4魔法值|5伤害%|6单体生命%|7魔抗%|8物抗%|9吸血%|10移动距离1|11射程1|12领导力
B11: 1配件 | D11: 9 | E11: 11
B12: 2项链 | D12: 7
B13: 3武器 | D13: 9 | E13: 11
B14: 4衣服 | D14: 8
B15: 5鞋子 | D15: 8 | E15: 10
B16: 6饰品（书） | D16: 7
