Workbook

Sheet EquipLv
A1: ID | B1: Lv | C1: LvMax | D1: Quality | E1: Star | F1: SkillLv | G1: Exp | H1: Maxexp | I1: StarCast
A2: int | B2: int | C2: int | D2: int | E2: int | F2: int | G2: int | H2: int | I2: string
A3: ID | B3: 强化等级 | C3: 最大等级 | D3: 品质 | E3: 星级 | F3: 技能等级 | G3: 所需经验 | H3: 当前等级累计经验值 | I3: 升星消耗
A4: 1001 | B4: 1 | C4: 10 | D4: =MID(A4,1,1) -> 1 | E4: 1 | F4: 0 | G4: =VLOOKUP(B4,Sheet2!A1:G21,7,1) -> 70 | H4: 0 | I4: 0
A5: 1002 | B5: 2 | C5: 10 | D5: =MID(A5,1,1) -> 1 | E5: 1 | F5: 0 | G5: =VLOOKUP(B5,Sheet2!A3:G22,7,1) -> 80 | H5: =G4+H4 -> 70 | I5: 0
A6: 1003 | B6: 3 | C6: 10 | D6: =MID(A6,1,1) -> 1 | E6: 1 | F6: 0 | G6: =VLOOKUP(B6,Sheet2!A4:G23,7,1) -> 80 | H6: =G5+H5 -> 150 | I6: 0
A7: 1004 | B7: 4 | C7: 10 | D7: =MID(A7,1,1) -> 1 | E7: 1 | F7: 0 | G7: =VLOOKUP(B7,Sheet2!A5:G24,7,1) -> 90 | H7: =G6+H6 -> 230 | I7: 0
A8: 1005 | B8: 5 | C8: 10 | D8: =MID(A8,1,1) -> 1 | E8: 1 | F8: 0 | G8: =VLOOKUP(B8,Sheet2!A6:G25,7,1) -> 100 | H8: =G7+H7 -> 320 | I8: 0
A9: 1006 | B9: 6 | C9: 10 | D9: =MID(A9,1,1) -> 1 | E9: 1 | F9: 0 | G9: =VLOOKUP(B9,Sheet2!A7:G26,7,1) -> 110 | H9: =G8+H8 -> 420 | I9: 0
A10: 1007 | B10: 7 | C10: 10 | D10: =MID(A10,1,1) -> 1 | E10: 1 | F10: 0 | G10: =VLOOKUP(B10,Sheet2!A8:G27,7,1) -> 120 | H10: =G9+H9 -> 530 | I10: 0
A11: 1008 | B11: 8 | C11: 10 | D11: =MID(A11,1,1) -> 1 | E11: 1 | F11: 0 | G11: =VLOOKUP(B11,Sheet2!A9:G28,7,1) -> 130 | H11: =G10+H10 -> 650 | I11: 0
A12: 1009 | B12: 9 | C12: 10 | D12: =MID(A12,1,1) -> 1 | E12: 1 | F12: 0 | G12: =VLOOKUP(B12,Sheet2!A10:G29,7,1) -> 140 | H12: =G11+H11 -> 780 | I12: 0
A13: 1010 | B13: 10 | C13: 10 | D13: =MID(A13,1,1) -> 1 | E13: 1 | F13: 0 | G13: 150 | H13: =G12+H12 -> 920 | I13: 0
A14: 2001 | B14: 1 | C14: =MAX(E14*10,20) -> 20 | D14: =MID(A14,1,1) -> 2 | E14: 2 | F14: 0 | G14: =VLOOKUP(B14,Sheet2!A2:F31,6,1) -> 100 | H14: 0 | I14: 0
A15: 2002 | B15: 2 | C15: =MAX(E15*10,20) -> 20 | D15: =MID(A15,1,1) -> 2 | E15: 2 | F15: 0 | G15: =VLOOKUP(B15,Sheet2!A3:F32,6,1) -> 110 | H15: =G14+H14 -> 100 | I15: 0
A16: 2003 | B16: 3 | C16: =MAX(E16*10,20) -> 20 | D16: =MID(A16,1,1) -> 2 | E16: 2 | F16: 0 | G16: =VLOOKUP(B16,Sheet2!A4:F33,6,1) -> 120 | H16: =G15+H15 -> 210 | I16: 0
A17: 2004 | B17: 4 | C17: =MAX(E17*10,20) -> 20 | D17: =MID(A17,1,1) -> 2 | E17: 2 | F17: 0 | G17: =VLOOKUP(B17,Sheet2!A5:F34,6,1) -> 130 | H17: =G16+H16 -> 330 | I17: 0
A18: 2005 | B18: 5 | C18: =MAX(E18*10,20) -> 20 | D18: =MID(A18,1,1) -> 2 | E18: 2 | F18: 0 | G18: =VLOOKUP(B18,Sheet2!A6:F35,6,1) -> 150 | H18: =G17+H17 -> 460 | I18: 0
A19: 2006 | B19: 6 | C19: =MAX(E19*10,20) -> 20 | D19: =MID(A19,1,1) -> 2 | E19: 2 | F19: 0 | G19: =VLOOKUP(B19,Sheet2!A7:F36,6,1) -> 160 | H19: =G18+H18 -> 610 | I19: 0
A20: 2007 | B20: 7 | C20: =MAX(E20*10,20) -> 20 | D20: =MID(A20,1,1) -> 2 | E20: 2 | F20: 0 | G20: =VLOOKUP(B20,Sheet2!A8:F37,6,1) -> 180 | H20: =G19+H19 -> 770 | I20: 0
A21: 2008 | B21: 8 | C21: =MAX(E21*10,20) -> 20 | D21: =MID(A21,1,1) -> 2 | E21: 2 | F21: 0 | G21: =VLOOKUP(B21,Sheet2!A9:F38,6,1) -> 190 | H21: =G20+H20 -> 950 | I21: 0
A22: 2009 | B22: 9 | C22: =MAX(E22*10,20) -> 20 | D22: =MID(A22,1,1) -> 2 | E22: 2 | F22: 0 | G22: =VLOOKUP(B22,Sheet2!A10:F39,6,1) -> 210 | H22: =G21+H21 -> 1140 | I22: 0
A23: 2010 | B23: 10 | C23: =MAX(E23*10,20) -> 20 | D23: =MID(A23,1,1) -> 2 | E23: 2 | F23: 0 | G23: =VLOOKUP(B23,Sheet2!A11:F40,6,1) -> 300 | H23: =G22+H22 -> 1350 | I23: 0
A24: 2011 | B24: 11 | C24: =MAX(E24*10,20) -> 20 | D24: =MID(A24,1,1) -> 2 | E24: 2 | F24: 0 | G24: =VLOOKUP(B24,Sheet2!A12:F41,6,1) -> 320 | H24: =G23+H23 -> 1650 | I24: 0
A25: 2012 | B25: 12 | C25: =MAX(E25*10,20) -> 20 | D25: =MID(A25,1,1) -> 2 | E25: 2 | F25: 0 | G25: =VLOOKUP(B25,Sheet2!A13:F42,6,1) -> 330 | H25: =G24+H24 -> 1970 | I25: 0
A26: 2013 | B26: 13 | C26: =MAX(E26*10,20) -> 20 | D26: =MID(A26,1,1) -> 2 | E26: 2 | F26: 0 | G26: =VLOOKUP(B26,Sheet2!A14:F43,6,1) -> 350 | H26: =G25+H25 -> 2300 | I26: 0
... A32: 2019 | B32: 19 | C32: =MAX(E32*10,20) -> 20 | D32: =MID(A32,1,1) -> 2 | E32: 2 | F32: 0 | G32: =VLOOKUP(B32,Sheet2!A20:F49,6,1) -> 460 | H32: =G31+H31 -> 4650 | I32: 0
A33: 2020 | B33: 20 | C33: =MAX(E33*10,20) -> 20 | D33: =MID(A33,1,1) -> 2 | E33: 2 | F33: 0 | G33: 480 | H33: =G32+H32 -> 5110 | I33: 0
A34: 3001 | B34: 1 | C34: 40 | D34: =MID(A34,1,1) -> 3 | E34: 2 | F34: 0 | G34: =VLOOKUP(B34,Sheet2!A2:E41,5,1) -> 140 | H34: 0 | I34: 0
A35: 3002 | B35: 2 | C35: 40 | D35: =MID(A35,1,1) -> 3 | E35: 2 | F35: 0 | G35: =VLOOKUP(B35,Sheet2!A3:E42,5,1) -> 150 | H35: =G34+H34 -> 140 | I35: 0
A36: 3003 | B36: 3 | C36: 40 | D36: =MID(A36,1,1) -> 3 | E36: 2 | F36: 0 | G36: =VLOOKUP(B36,Sheet2!A4:E43,5,1) -> 160 | H36: =G35+H35 -> 290 | I36: 0
A37: 3004 | B37: 4 | C37: 40 | D37: =MID(A37,1,1) -> 3 | E37: 2 | F37: 0 | G37: =VLOOKUP(B37,Sheet2!A5:E44,5,1) -> 180 | H37: =G36+H36 -> 450 | I37: 0
A38: 3005 | B38: 5 | C38: 40 | D38: =MID(A38,1,1) -> 3 | E38: 2 | F38: 0 | G38: =VLOOKUP(B38,Sheet2!A6:E45,5,1) -> 200 | H38: =G37+H37 -> 630 | I38: 0
A39: 3006 | B39: 6 | C39: 40 | D39: =MID(A39,1,1) -> 3 | E39: 2 | F39: 0 | G39: =VLOOKUP(B39,Sheet2!A7:E46,5,1) -> 220 | H39: =G38+H38 -> 830 | I39: 0
A40: 3007 | B40: 7 | C40: 40 | D40: =MID(A40,1,1) -> 3 | E40: 2 | F40: 0 | G40: =VLOOKUP(B40,Sheet2!A8:E47,5,1) -> 240 | H40: =G39+H39 -> 1050 | I40: 0
A41: 3008 | B41: 8 | C41: 40 | D41: =MID(A41,1,1) -> 3 | E41: 2 | F41: 0 | G41: =VLOOKUP(B41,Sheet2!A9:E48,5,1) -> 260 | H41: =G40+H40 -> 1290 | I41: 0
A42: 3009 | B42: 9 | C42: 40 | D42: =MID(A42,1,1) -> 3 | E42: 2 | F42: 0 | G42: =VLOOKUP(B42,Sheet2!A10:E49,5,1) -> 280 | H42: =G41+H41 -> 1550 | I42: 0
A43: 3010 | B43: 10 | C43: 40 | D43: =MID(A43,1,1) -> 3 | E43: 2 | F43: 1 | G43: =VLOOKUP(B43,Sheet2!A11:E50,5,1) -> 400 | H43: =G42+H42 -> 1830 | I43: 0
A44: 3011 | B44: 11 | C44: 40 | D44: =MID(A44,1,1) -> 3 | E44: 2 | F44: 1 | G44: =VLOOKUP(B44,Sheet2!A12:E51,5,1) -> 420 | H44: =G43+H43 -> 2230 | I44: 0
A45: 3012 | B45: 12 | C45: 40 | D45: =MID(A45,1,1) -> 3 | E45: 2 | F45: 1 | G45: =VLOOKUP(B45,Sheet2!A13:E52,5,1) -> 440 | H45: =G44+H44 -> 2650 | I45: 0
...

Sheet Sheet2
A1: 等级 | B1: SSR | E1: SR | F1: R | G1: N | I1: SR | J1: 1.5 | L1: 品质 | M1: 4 | N1: 常数 | O1: 20 | P1: 星级常数 | Q1: 11.97
A2: 1 | B2: 200 | E2: =ROUNDUP(B2/$J$1,-1) -> 140 | F2: =ROUNDUP(B2/$J$2,-1) -> 100 | G2: =ROUNDUP(B2/$J$3,-1) -> 70 | I2: R | J2: 2
A3: 2 | B3: =ROUNDUP(B2+C3,-1) -> 220 | C3: =ROUND($O$1+A3,-1) -> 20 | E3: =ROUNDUP(B3/$J$1,-1) -> 150 | F3: =ROUNDUP(B3/$J$2,-1) -> 110 | G3: =ROUNDUP(B3/$J$3,-1) -> 80 | I3: N | J3: 3
A4: 3 | B4: =ROUNDUP(B3+C4,-1) -> 240 | C4: =ROUND($O$1+A4,-1) -> 20 | E4: =ROUNDUP(B4/$J$1,-1) -> 160 | F4: =ROUNDUP(B4/$J$2,-1) -> 120 | G4: =ROUNDUP(B4/$J$3,-1) -> 80
A5: 4 | B5: =ROUNDUP(B4+C5,-1) -> 260 | C5: =ROUND($O$1+A5,-1) -> 20 | E5: =ROUNDUP(B5/$J$1,-1) -> 180 | F5: =ROUNDUP(B5/$J$2,-1) -> 130 | G5: =ROUNDUP(B5/$J$3,-1) -> 90
A6: 5 | B6: =ROUNDUP(B5+C6,-1) -> 290 | C6: =ROUND($O$1+A6,-1) -> 30 | E6: =ROUNDUP(B6/$J$1,-1) -> 200 | F6: =ROUNDUP(B6/$J$2,-1) -> 150 | G6: =ROUNDUP(B6/$J$3,-1) -> 100
A7: 6 | B7: =ROUNDUP(B6+C7,-1) -> 320 | C7: =ROUND($O$1+A7,-1) -> 30 | E7: =ROUNDUP(B7/$J$1,-1) -> 220 | F7: =ROUNDUP(B7/$J$2,-1) -> 160 | G7: =ROUNDUP(B7/$J$3,-1) -> 110
A8: 7 | B8: =ROUNDUP(B7+C8,-1) -> 350 | C8: =ROUND($O$1+A8,-1) -> 30 | E8: =ROUNDUP(B8/$J$1,-1) -> 240 | F8: =ROUNDUP(B8/$J$2,-1) -> 180 | G8: =ROUNDUP(B8/$J$3,-1) -> 120
A9: 8 | B9: =ROUNDUP(B8+C9,-1) -> 380 | C9: =ROUND($O$1+A9,-1) -> 30 | E9: =ROUNDUP(B9/$J$1,-1) -> 260 | F9: =ROUNDUP(B9/$J$2,-1) -> 190 | G9: =ROUNDUP(B9/$J$3,-1) -> 130
A10: 9 | B10: =ROUNDUP(B9+C10,-1) -> 410 | C10: =ROUND($O$1+A10,-1) -> 30 | E10: =ROUNDUP(B10/$J$1,-1) -> 280 | F10: =ROUNDUP(B10/$J$2,-1) -> 210 | G10: =ROUNDUP(B10/$J$3,-1) -> 140
A11: 10 | B11: =ROUNDUP(B10+C11,-1) -> 600 | C11: =ROUND($O$1+A11+D11,-1) -> 190 | D11: =$M$1*(A11-1)+$Q$1*A11 -> 155.7 | E11: =ROUNDUP(B11/$J$1,-1) -> 400 | F11: =ROUNDUP(B11/$J$2,-1) -> 300 | G11: 0
A12: 11 | B12: =ROUNDUP(B11+C12,-1) -> 630 | C12: =ROUND($O$1+A12+D12,-1) -> 30 | E12: =ROUNDUP(B12/$J$1,-1) -> 420 | F12: =ROUNDUP(B12/$J$2,-1) -> 320
A13: 12 | B13: =ROUNDUP(B12+C13,-1) -> 660 | C13: =ROUND($O$1+A13+D13,-1) -> 30 | E13: =ROUNDUP(B13/$J$1,-1) -> 440 | F13: =ROUNDUP(B13/$J$2,-1) -> 330
A14: 13 | B14: =ROUNDUP(B13+C14,-1) -> 690 | C14: =ROUND($O$1+A14+D14,-1) -> 30 | E14: =ROUNDUP(B14/$J$1,-1) -> 460 | F14: =ROUNDUP(B14/$J$2,-1) -> 350
A15: 14 | B15: =ROUNDUP(B14+C15,-1) -> 720 | C15: =ROUND($O$1+A15+D15,-1) -> 30 | E15: =ROUNDUP(B15/$J$1,-1) -> 480 | F15: =ROUNDUP(B15/$J$2,-1) -> 360
A16: 15 | B16: =ROUNDUP(B15+C16,-1) -> 760 | C16: =ROUND($O$1+A16+D16,-1) -> 40 | E16: =ROUNDUP(B16/$J$1,-1) -> 510 | F16: =ROUNDUP(B16/$J$2,-1) -> 380
A17: 16 | B17: =ROUNDUP(B16+C17,-1) -> 800 | C17: =ROUND($O$1+A17+D17,-1) -> 40 | E17: =ROUNDUP(B17/$J$1,-1) -> 540 | F17: =ROUNDUP(B17/$J$2,-1) -> 400
A18: 17 | B18: =ROUNDUP(B17+C18,-1) -> 840 | C18: =ROUND($O$1+A18+D18,-1) -> 40 | E18: =ROUNDUP(B18/$J$1,-1) -> 560 | F18: =ROUNDUP(B18/$J$2,-1) -> 420
A19: 18 | B19: =ROUNDUP(B18+C19,-1) -> 880 | C19: =ROUND($O$1+A19+D19,-1) -> 40 | E19: =ROUNDUP(B19/$J$1,-1) -> 590 | F19: =ROUNDUP(B19/$J$2,-1) -> 440
A20: 19 | B20: =ROUNDUP(B19+C20,-1) -> 920 | C20: =ROUND($O$1+A20+D20,-1) -> 40 | E20: =ROUNDUP(B20/$J$1,-1) -> 620 | F20: =ROUNDUP(B20/$J$2,-1) -> 460
A21: 20 | B21: =ROUNDUP(B20+C21,-1) -> 1280 | C21: =ROUND($O$1+A21+D21,-1) -> 360 | D21: =$M$1*(A21-1)+$Q$1*A21 -> 315.4 | E21: =ROUNDUP(B21/$J$1,-1) -> 860 | F21: 0
A22: 21 | B22: =ROUNDUP(B21+C22,-1) -> 1320 | C22: =ROUND($O$1+A22+D22,-1) -> 40 | E22: =ROUNDUP(B22/$J$1,-1) -> 880
A23: 22 | B23: =ROUNDUP(B22+C23,-1) -> 1360 | C23: =ROUND($O$1+A23+D23,-1) -> 40 | E23: =ROUNDUP(B23/$J$1,-1) -> 910
A24: 23 | B24: =ROUNDUP(B23+C24,-1) -> 1400 | C24: =ROUND($O$1+A24+D24,-1) -> 40 | E24: =ROUNDUP(B24/$J$1,-1) -> 940
A25: 24 | B25: =ROUNDUP(B24+C25,-1) -> 1440 | C25: =ROUND($O$1+A25+D25,-1) -> 40 | E25: =ROUNDUP(B25/$J$1,-1) -> 960
A26: 25 | B26: =ROUNDUP(B25+C26,-1) -> 1490 | C26: =ROUND($O$1+A26+D26,-1) -> 50 | E26: =ROUNDUP(B26/$J$1,-1) -> 1000
A27: 26 | B27: =ROUNDUP(B26+C27,-1) -> 1540 | C27: =ROUND($O$1+A27+D27,-1) -> 50 | E27: =ROUNDUP(B27/$J$1,-1) -> 1030
A28: 27 | B28: =ROUNDUP(B27+C28,-1) -> 1590 | C28: =ROUND($O$1+A28+D28,-1) -> 50 | E28: =ROUNDUP(B28/$J$1,-1) -> 1060
A29: 28 | B29: =ROUNDUP(B28+C29,-1) -> 1640 | C29: =ROUND($O$1+A29+D29,-1) -> 50 | E29: =ROUNDUP(B29/$J$1,-1) -> 1100
A30: 29 | B30: =ROUNDUP(B29+C30,-1) -> 1690 | C30: =ROUND($O$1+A30+D30,-1) -> 50 | E30: =ROUNDUP(B30/$J$1,-1) -> 1130
A31: 30 | B31: =ROUNDUP(B30+C31,-1) -> 2220 | C31: =ROUND($O$1+A31+D31,-1) -> 530 | D31: =$M$1*(A31-1)+$Q$1*A31 -> 475.1 | E31: =ROUNDUP(B31/$J$1,-1) -> 1480
A32: 31 | B32: =ROUNDUP(B31+C32,-1) -> 2270 | C32: =ROUND($O$1+A32+D32,-1) -> 50 | E32: =ROUNDUP(B32/$J$1,-1) -> 1520
A33: 32 | B33: =ROUNDUP(B32+C33,-1) -> 2320 | C33: =ROUND($O$1+A33+D33,-1) -> 50 | E33: =ROUNDUP(B33/$J$1,-1) -> 1550
A34: 33 | B34: =ROUNDUP(B33+C34,-1) -> 2370 | C34: =ROUND($O$1+A34+D34,-1) -> 50 | E34: =ROUNDUP(B34/$J$1,-1) -> 1580
A35: 34 | B35: =ROUNDUP(B34+C35,-1) -> 2420 | C35: =ROUND($O$1+A35+D35,-1) -> 50 | E35: =ROUNDUP(B35/$J$1,-1) -> 1620
A36: 35 | B36: =ROUNDUP(B35+C36,-1) -> 2480 | C36: =ROUND($O$1+A36+D36,-1) -> 60 | E36: =ROUNDUP(B36/$J$1,-1) -> 1660
A37: 36 | B37: =ROUNDUP(B36+C37,-1) -> 2540 | C37: =ROUND($O$1+A37+D37,-1) -> 60 | E37: =ROUNDUP(B37/$J$1,-1) -> 1700
A38: 37 | B38: =ROUNDUP(B37+C38,-1) -> 2600 | C38: =ROUND($O$1+A38+D38,-1) -> 60 | E38: =ROUNDUP(B38/$J$1,-1) -> 1740
A39: 38 | B39: =ROUNDUP(B38+C39,-1) -> 2660 | C39: =ROUND($O$1+A39+D39,-1) -> 60 | E39: =ROUNDUP(B39/$J$1,-1) -> 1780
A40: 39 | B40: =ROUNDUP(B39+C40,-1) -> 2720 | C40: =ROUND($O$1+A40+D40,-1) -> 60 | E40: =ROUNDUP(B40/$J$1,-1) -> 1820
...

Sheet Sheet3
