Workbook

Sheet EXP
A1: Level | B1: Exp
A2: int | B2: int
A3: 等级 | B3: 升级需要的经验值，升级后多余的经验累计到下一级，每一级都从0开始计算经验值
A4: 1 | B4: 20
A5: 2 | B5: 40
A6: 3 | B6: 70
A7: 4 | B7: 110
A8: 5 | B8: 170
A9: 6 | B9: 250
A10: 7 | B10: 350
A11: 8 | B11: 480
A12: 9 | B12: 630
A13: 10 | B13: 810
A14: 11 | B14: 1020
A15: 12 | B15: 1270
... A103: 100 | B103: 427000

Sheet 英雄消耗
A1: 基础值 | B1: 50 | D1: 每级增长 | E1: 5 | G1: 基础系数 | H1: 1.1 | J1: 等级系数 | K1: 1.1
B5: 等级
B6: 1 | C6: 20 | J6: 20
B7: 2 | C7: =C6+D7 -> 40 | D7: =ROUND(($E$1+B7)*$H$1*B7*$K$1,-1) -> 20 | J7: 40 | K7: =J7-J6 -> 20
B8: 3 | C8: =C7+D8 -> 70 | D8: =ROUND(($E$1+B8)*$H$1*B8*$K$1,-1) -> 30 | J8: 60 | K8: =J8-J7 -> 20
B9: 4 | C9: =C8+D9 -> 110 | D9: =ROUND(($E$1+B9)*$H$1*B9*$K$1,-1) -> 40 | J9: 80 | K9: =J9-J8 -> 20
B10: 5 | C10: =C9+D10 -> 170 | D10: =ROUND(($E$1+B10)*$H$1*B10*$K$1,-1) -> 60 | J10: 100 | K10: =J10-J9 -> 20
B11: 6 | C11: =C10+D11 -> 250 | D11: =ROUND(($E$1+B11)*$H$1*B11*$K$1,-1) -> 80 | J11: 120 | K11: =J11-J10 -> 20
B12: 7 | C12: =C11+D12 -> 350 | D12: =ROUND(($E$1+B12)*$H$1*B12*$K$1,-1) -> 100 | J12: 140 | K12: =J12-J11 -> 20
B13: 8 | C13: =C12+D13 -> 480 | D13: =ROUND(($E$1+B13)*$H$1*B13*$K$1,-1) -> 130 | J13: 160 | K13: =J13-J12 -> 20
B14: 9 | C14: =C13+D14 -> 630 | D14: =ROUND(($E$1+B14)*$H$1*B14*$K$1,-1) -> 150 | J14: 180 | K14: =J14-J13 -> 20
B15: 10 | C15: =C14+D15 -> 810 | D15: =ROUND(($E$1+B15)*$H$1*B15*$K$1,-1) -> 180 | J15: 200 | K15: =J15-J14 -> 20
B16: 11 | C16: =C15+D16 -> 1020 | D16: =ROUND(($E$1+B16)*$H$1*B16*$K$1,-1) -> 210 | J16: 250 | K16: =J16-J15 -> 50
B17: 12 | C17: =C16+D17 -> 1270 | D17: =ROUND(($E$1+B17)*$H$1*B17*$K$1,-1) -> 250 | J17: 300 | K17: =J17-J16 -> 50
B18: 13 | C18: =C17+D18 -> 1550 | D18: =ROUND(($E$1+B18)*$H$1*B18*$K$1,-1) -> 280 | J18: 350 | K18: =J18-J17 -> 50
... B21: 16 | C21: =C20+D21 -> 2640 | D21: =ROUND(($E$1+B21)*$H$1*B21*$K$1,-1) -> 410 | J21: 500 | K21: =J21-J20 -> 50
B22: 17 | C22: =ROUND(C21+D22,-2) -> 3100 | D22: =ROUND(($E$1+B22)*$H$1*B22*$K$1,-1) -> 450 | J22: 550 | K22: =J22-J21 -> 50
B23: 18 | C23: =ROUND(C22+D23,-2) -> 3600 | D23: =ROUND(($E$1+B23)*$H$1*B23*$K$1,-1) -> 500 | J23: 600 | K23: =J23-J22 -> 50
B24: 19 | C24: =ROUND(C23+D24,-2) -> 4200 | D24: =ROUND(($E$1+B24)*$H$1*B24*$K$1,-1) -> 550 | J24: 700 | K24: =J24-J23 -> 100
B25: 20 | C25: =ROUND(C24+D25,-2) -> 4800 | D25: =ROUND(($E$1+B25)*$H$1*B25*$K$1,-1) -> 610 | J25: 1100 | K25: =J25-J24 -> 400
B26: 21 | C26: =ROUND(C25+D26,-2) -> 5500 | D26: =ROUND(($E$1+B26)*$H$1*B26*$K$1,-1) -> 660 | J26: 1400 | K26: =J26-J25 -> 300
B27: 22 | C27: =ROUND(C26+D27,-2) -> 6200 | D27: =ROUND(($E$1+B27)*$H$1*B27*$K$1,-1) -> 720 | J27: 1900 | K27: =J27-J26 -> 500
B28: 23 | C28: =ROUND(C27+D28,-2) -> 7000 | D28: =ROUND(($E$1+B28)*$H$1*B28*$K$1,-1) -> 780 | J28: 2400 | K28: =J28-J27 -> 500
B29: 24 | C29: =ROUND(C28+D29,-2) -> 7800 | D29: =ROUND(($E$1+B29)*$H$1*B29*$K$1,-1) -> 840 | J29: 2900 | K29: =J29-J28 -> 500
B30: 25 | C30: =ROUND(C29+D30,-2) -> 8700 | D30: =ROUND(($E$1+B30)*$H$1*B30*$K$1,-1) -> 910 | J30: 3500 | K30: =J30-J29 -> 600
B31: 26 | C31: =ROUND(C30+D31,-2) -> 9700 | D31: =ROUND(($E$1+B31)*$H$1*B31*$K$1,-1) -> 980 | J31: 4200 | K31: =J31-J30 -> 700
B32: 27 | C32: =ROUND(C31+D32,-2) -> 10800 | D32: =ROUND(($E$1+B32)*$H$1*B32*$K$1,-1) -> 1050 | J32: 4900 | K32: =J32-J31 -> 700
B33: 28 | C33: =ROUND(C32+D33,-2) -> 11900 | D33: =ROUND(($E$1+B33)*$H$1*B33*$K$1,-1) -> 1120 | J33: 5700 | K33: =J33-J32 -> 800
... B73: 68 | C73: =ROUND(C72+D73,-2) -> 144100 | D73: =ROUND(($E$1+B73)*$H$1*B73*$K$1,-1) -> 6010 | J73: 125000 | K73: =J73-J72 -> 0
B74: 69 | C74: =ROUND(C73+D74,-3) -> 150000 | D74: =ROUND(($E$1+B74)*$H$1*B74*$K$1,-1) -> 6180 | J74: 125000 | K74: =J74-J73 -> 0 | M74: =SUM(J6:J74) -> 2796100
B75: 70 | C75: =ROUND(C74+D75,-3) -> 156000 | D75: =ROUND(($E$1+B75)*$H$1*B75*$K$1,-1) -> 6350
B76: 71 | C76: =ROUND(C75+D76,-3) -> 163000 | D76: =ROUND(($E$1+B76)*$H$1*B76*$K$1,-1) -> 6530
B77: 72 | C77: =ROUND(C76+D77,-3) -> 170000 | D77: =ROUND(($E$1+B77)*$H$1*B77*$K$1,-1) -> 6710
B78: 73 | C78: =ROUND(C77+D78,-3) -> 177000 | D78: =ROUND(($E$1+B78)*$H$1*B78*$K$1,-1) -> 6890
B79: 74 | C79: =ROUND(C78+D79,-3) -> 184000 | D79: =ROUND(($E$1+B79)*$H$1*B79*$K$1,-1) -> 7070
B80: 75 | C80: =ROUND(C79+D80,-3) -> 191000 | D80: =ROUND(($E$1+B80)*$H$1*B80*$K$1,-1) -> 7260
B81: 76 | C81: =ROUND(C80+D81,-3) -> 198000 | D81: =ROUND(($E$1+B81)*$H$1*B81*$K$1,-1) -> 7450
B82: 77 | C82: =ROUND(C81+D82,-3) -> 206000 | D82: =ROUND(($E$1+B82)*$H$1*B82*$K$1,-1) -> 7640
B83: 78 | C83: =ROUND(C82+D83,-3) -> 214000 | D83: =ROUND(($E$1+B83)*$H$1*B83*$K$1,-1) -> 7830
B84: 79 | C84: =ROUND(C83+D84,-3) -> 222000 | D84: =ROUND(($E$1+B84)*$H$1*B84*$K$1,-1) -> 8030
...

Sheet 消耗产出
B1: 经验道具 | C1: 50 | D1: 200 | E1: 1000 | F1: 5000 | H1: 一个月升5个英雄所需道具
H2: 思路：免费满足升6个英雄 | K2: 6
A3: 等级 | H3: 一个月一次性产出和日常产出满足6个英雄升级需求
A4: 1 | B4: =VLOOKUP(A4,英雄消耗!B5:C105,2,1) -> 20 | C4: =INT($B4/C$1) -> 0 | D4: =INT($B4/D$1) -> 0 | E4: =INT($B4/E$1) -> 0 | F4: =INT($B4/F$1) -> 0 | H4: 绿色为每日保底产出，用于培养多个英雄
A5: 2 | B5: =VLOOKUP(A5,英雄消耗!B6:C106,2,1) -> 40 | C5: =INT($B5/$C$1) -> 0 | D5: =INT($B5/D$1) -> 0 | E5: =INT($B5/E$1) -> 0 | F5: =INT($B5/F$1) -> 0
A6: 3 | B6: =VLOOKUP(A6,英雄消耗!B7:C107,2,1) -> 70 | C6: =INT($B6/$C$1) -> 1 | D6: =INT($B6/D$1) -> 0 | E6: =INT($B6/E$1) -> 0 | F6: =INT($B6/F$1) -> 0 | H6: 天数 | I6: 免费 | J6: 付费 | K6: 50 | L6: 200 | M6: 1000 | N6: 5000
A7: 4 | B7: =VLOOKUP(A7,英雄消耗!B8:C108,2,1) -> 110 | C7: =INT($B7/$C$1) -> 2 | D7: =INT($B7/D$1) -> 0 | E7: =INT($B7/E$1) -> 0 | F7: =INT($B7/F$1) -> 0 | H7: 1 | I7: 13 | J7: 15 | K7: =SUM(C4:C16)*$K$2 -> 786 | L7: / | M7: / | N7: /
A8: 5 | B8: =VLOOKUP(A8,英雄消耗!B9:C109,2,1) -> 170 | C8: =INT($B8/$C$1) -> 3 | D8: =INT($B8/D$1) -> 0 | E8: =INT($B8/E$1) -> 0 | F8: =INT($B8/F$1) -> 0 | H8: 2 | I8: 15 | J8: 18 | K8: 150 | L8: =SUM(D17:D18)*$K$2 -> 120 | M8: / | N8: /
A9: 6 | B9: =VLOOKUP(A9,英雄消耗!B10:C110,2,1) -> 250 | C9: =INT($B9/$C$1) -> 5 | D9: =INT($B9/D$1) -> 1 | E9: =INT($B9/E$1) -> 0 | F9: =INT($B9/F$1) -> 0 | H9: 3 | I9: 17 | J9: 20 | K9: 150 | L9: =SUM(D19:D20)*$K$2 -> 168 | M9: / | N9: /
A10: 7 | B10: =VLOOKUP(A10,英雄消耗!B11:C111,2,1) -> 350 | C10: =INT($B10/$C$1) -> 7 | D10: =INT($B10/D$1) -> 1 | E10: =INT($B10/E$1) -> 0 | F10: =INT($B10/F$1) -> 0 | H10: 4 | I10: 18 | J10: 22 | K10: 150 | L10: 100 | M10: =SUM(E21)*$K$2 -> 18 | N10: /
A11: 8 | B11: =VLOOKUP(A11,英雄消耗!B12:C112,2,1) -> 480 | C11: =INT($B11/$C$1) -> 9 | D11: =INT($B11/D$1) -> 2 | E11: =INT($B11/E$1) -> 0 | F11: =INT($B11/F$1) -> 0 | H11: 5 | I11: 19 | J11: 24 | K11: 150 | L11: 100 | M11: =SUM(E22)*$K$2 -> 24 | N11: /
A12: 9 | B12: =VLOOKUP(A12,英雄消耗!B13:C113,2,1) -> 630 | C12: =INT($B12/$C$1) -> 12 | D12: =INT($B12/D$1) -> 3 | E12: =INT($B12/E$1) -> 0 | F12: =INT($B12/F$1) -> 0 | H12: 6 | I12: 20 | J12: 25 | K12: 150 | L12: 100 | M12: =SUM(E23)*$K$2 -> 24 | N12: /
A13: 10 | B13: =VLOOKUP(A13,英雄消耗!B14:C114,2,1) -> 810 | C13: =INT($B13/$C$1) -> 16 | D13: =INT($B13/D$1) -> 4 | E13: =INT($B13/E$1) -> 0 | F13: =INT($B13/F$1) -> 0 | H13: 7 | I13: 21 | J13: 26 | K13: 150 | L13: 100 | M13: =SUM(E24)*$K$2 -> 30 | N13: /
A14: 11 | B14: =VLOOKUP(A14,英雄消耗!B15:C115,2,1) -> 1020 | C14: =INT($B14/$C$1) -> 20 | D14: =INT($B14/D$1) -> 5 | E14: =INT($B14/E$1) -> 1 | F14: =INT($B14/F$1) -> 0 | H14: 15 | I14: 27 | J14: 34 | K14: / | L14: 100 | M14: 50 | N14: =SUM(F25:F30)*$K$2 -> 42
A15: 12 | B15: =VLOOKUP(A15,英雄消耗!B16:C116,2,1) -> 1270 | C15: =INT($B15/$C$1) -> 25 | D15: =INT($B15/D$1) -> 6 | E15: =INT($B15/E$1) -> 1 | F15: =INT($B15/F$1) -> 0 | H15: 30 | I15: 33 | J15: 42 | K15: / | L15: / | M15: 50 | N15: 25
A16: 13 | B16: =VLOOKUP(A16,英雄消耗!B17:C117,2,1) -> 1550 | C16: =INT($B16/$C$1) -> 31 | D16: =INT($B16/D$1) -> 7 | E16: =INT($B16/E$1) -> 1 | F16: =INT($B16/F$1) -> 0
A17: 14 | B17: =VLOOKUP(A17,英雄消耗!B18:C118,2,1) -> 1870 | C17: =INT($B17/$C$1) -> 37 | D17: =INT($B17/D$1) -> 9 | E17: =INT($B17/E$1) -> 1 | F17: =INT($B17/F$1) -> 0
A18: 15 | B18: =VLOOKUP(A18,英雄消耗!B19:C119,2,1) -> 2230 | C18: =INT($B18/$C$1) -> 44 | D18: =INT($B18/D$1) -> 11 | E18: =INT($B18/E$1) -> 2 | F18: =INT($B18/F$1) -> 0
A19: 16 | B19: =VLOOKUP(A19,英雄消耗!B20:C120,2,1) -> 2640 | C19: =INT($B19/$C$1) -> 52 | D19: =INT($B19/D$1) -> 13 | E19: =INT($B19/E$1) -> 2 | F19: =INT($B19/F$1) -> 0
A20: 17 | B20: =VLOOKUP(A20,英雄消耗!B21:C121,2,1) -> 3100 | C20: =INT($B20/$C$1) -> 62 | D20: =INT($B20/D$1) -> 15 | E20: =INT($B20/E$1) -> 3 | F20: =INT($B20/F$1) -> 0
A21: 18 | B21: =VLOOKUP(A21,英雄消耗!B22:C122,2,1) -> 3600 | C21: =INT($B21/$C$1) -> 72 | D21: =INT($B21/D$1) -> 18 | E21: =INT($B21/E$1) -> 3 | F21: =INT($B21/F$1) -> 0
A22: 19 | B22: =VLOOKUP(A22,英雄消耗!B23:C123,2,1) -> 4200 | C22: =INT($B22/$C$1) -> 84 | D22: =INT($B22/D$1) -> 21 | E22: =INT($B22/E$1) -> 4 | F22: =INT($B22/F$1) -> 0
A23: 20 | B23: =VLOOKUP(A23,英雄消耗!B24:C124,2,1) -> 4800 | C23: =INT($B23/$C$1) -> 96 | D23: =INT($B23/D$1) -> 24 | E23: =INT($B23/E$1) -> 4 | F23: =INT($B23/F$1) -> 0
A24: 21 | B24: =VLOOKUP(A24,英雄消耗!B25:C125,2,1) -> 5500 | C24: =INT($B24/$C$1) -> 110 | D24: =INT($B24/D$1) -> 27 | E24: =INT($B24/E$1) -> 5 | F24: =INT($B24/F$1) -> 1
A25: 22 | B25: =VLOOKUP(A25,英雄消耗!B26:C126,2,1) -> 6200 | C25: =INT($B25/$C$1) -> 124 | D25: =INT($B25/D$1) -> 31 | E25: =INT($B25/E$1) -> 6 | F25: =INT($B25/F$1) -> 1
A26: 23 | B26: =VLOOKUP(A26,英雄消耗!B27:C127,2,1) -> 7000 | C26: =INT($B26/$C$1) -> 140 | D26: =INT($B26/D$1) -> 35 | E26: =INT($B26/E$1) -> 7 | F26: =INT($B26/F$1) -> 1
A27: 24 | B27: =VLOOKUP(A27,英雄消耗!B28:C128,2,1) -> 7800 | C27: =INT($B27/$C$1) -> 156 | D27: =INT($B27/D$1) -> 39 | E27: =INT($B27/E$1) -> 7 | F27: =INT($B27/F$1) -> 1
... A103: 100 | B103: =VLOOKUP(A103,英雄消耗!B104:C204,2,1) -> 440000 | C103: =INT($B103/$C$1) -> 8800 | D103: =INT($B103/D$1) -> 2200 | E103: =INT($B103/E$1) -> 440 | F103: =INT($B103/F$1) -> 88
C104: =SUM(C4:C103) -> 230806 | D104: =SUM(D4:D103) -> 57686 | E104: =SUM(E4:E103) -> 11511 | F104: =SUM(F4:F103) -> 2267

Sheet 玩家经验预估
B1: 预计玩家体验400小时
B2: 1个英雄到50级需要70小时
B3: 1.25级每小时 | D3: 4200分钟 | H3: 20小时2000经验 | K3: 最快速度。平均1分钟10怪
C4: 等级 | D4: 累计时间(分钟) | E4: 升级消耗时间分钟 | F4: 时间增加量 | G4: 升级需要经验 | H4: 挂机经验 | I4: 经验副本 | J4: 升级所需总经验 | K4: 单个怪物经验值 | M4: 挂机推算 | P4: 小时推算
C5: 1 | D5: 3 | E5: 2 | F5: 1 | G5: =E5*10*K5 -> 80 | J5: =G5*3 -> 240 | K5: 4 | L5: =30*(C5*C5+5*C5)-80 -> 100 | M5: 1分钟40经验 | P5: 最小值 | Q5: 最大值 | R5: 平均值
C6: 2 | D6: =D5+E6 -> 6 | E6: 3 | F6: 1 | G6: =E6*10*K6 -> 120 | J6: =G6*3 -> 360 | K6: 4 | L6: =30*(C6*C6+5*C6)-80 -> 340 | M6: 60分钟2400经验 | O6: 1 | P6: =10*60*2*O6 -> 1200 | Q6: =60*10*10*O6 -> 6000 | R6: =(P6+Q6)/2 -> 3600
C7: 3 | D7: =D6+E7 -> 10 | E7: 4 | F7: 2 | G7: =E7*10*K7 -> 160 | J7: =G7*3 -> 480 | K7: 4 | L7: =30*(C7*C7+5*C7)-80 -> 640 | M7: 3600分钟14400经验 | O7: 2 | P7: =10*60*2*O7 -> 2400 | Q7: =60*10*10*O7 -> 12000 | R7: =(P7+Q7)/2 -> 7200
C8: 4 | D8: =D7+E8 -> 14 | E8: 4 | F8: 0 | G8: =E8*10*K8 -> 160 | J8: =G8*3 -> 480 | K8: 4 | L8: =30*(C8*C8+5*C8)-80 -> 1000 | M8: 挂机经验为3倍 | O8: 3 | P8: =10*60*2*O8 -> 3600 | Q8: =60*10*10*O8 -> 18000 | R8: =(P8+Q8)/2 -> 10800
C9: 5 | D9: =D8+E9 -> 19 | E9: 5 | F9: 1 | G9: =E9*10*K9 -> 200 | J9: =G9*3 -> 600 | K9: 4 | L9: =30*(C9*C9+5*C9)-80 -> 1420 | M9: 43200经验 | O9: 4 | P9: =10*60*2*O9 -> 4800 | Q9: =60*10*10*O9 -> 24000 | R9: =(P9+Q9)/2 -> 14400
C10: 6 | D10: =D9+E10 -> 25 | E10: 6 | F10: 3 | G10: =E10*10*K10 -> 240 | J10: =G10*3 -> 720 | K10: 4 | L10: =30*(C10*C10+5*C10)-80 -> 1900 | M10: 平均1小时3600经验 | O10: 5 | P10: =10*60*2*O10 -> 6000 | Q10: =60*10*10*O10 -> 30000 | R10: =(P10+Q10)/2 -> 18000
C11: 7 | D11: =D10+E11 -> 34 | E11: 9 | F11: 3 | G11: =E11*10*K11 -> 360 | J11: =G11*3 -> 1080 | K11: 4 | L11: =30*(C11*C11+5*C11)-80 -> 2440 | O11: 6 | P11: =10*60*2*O11 -> 7200 | Q11: =60*10*10*O11 -> 36000 | R11: =(P11+Q11)/2 -> 21600
C12: 8 | D12: =D11+E12 -> 46 | E12: 12 | F12: 4 | G12: =E12*10*K12 -> 480 | J12: =G12*3 -> 1440 | K12: 4 | L12: =30*(C12*C12+5*C12)-80 -> 3040 | O12: 7 | P12: =10*60*2*O12 -> 8400 | Q12: =60*10*10*O12 -> 42000 | R12: =(P12+Q12)/2 -> 25200
C13: 9 | D13: =D12+E13 -> 62 | E13: 16 | F13: 5 | G13: =E13*10*K13 -> 640 | J13: =G13*3 -> 1920 | K13: 4 | L13: =30*(C13*C13+5*C13)-80 -> 3700 | O13: 8 | P13: =10*60*2*O13 -> 9600 | Q13: =60*10*10*O13 -> 48000 | R13: =(P13+Q13)/2 -> 28800
C14: 10 | D14: =D13+E14 -> 83 | E14: 21 | F14: 6 | G14: =E14*10*K14 -> 840 | J14: =G14*3 -> 2520 | K14: 4 | L14: =30*(C14*C14+5*C14)-80 -> 4420 | O14: 9 | P14: =10*60*2*O14 -> 10800 | Q14: =60*10*10*O14 -> 54000 | R14: =(P14+Q14)/2 -> 32400
C15: 11 | D15: =D14+E15 -> 110 | E15: 27 | F15: 7 | G15: =E15*10*K15 -> 1080 | J15: =G15*3 -> 3240 | K15: 4 | L15: =30*(C15*C15+5*C15)-80 -> 5200 | O15: 10 | P15: =10*60*2*O15 -> 12000 | Q15: =60*10*10*O15 -> 60000 | R15: =(P15+Q15)/2 -> 36000
C16: 12 | D16: =D15+E16 -> 144 | E16: 34 | F16: 9 | G16: =E16*10*K16 -> 1360 | J16: =G16*3 -> 4080 | K16: 4 | L16: =30*(C16*C16+5*C16)-80 -> 6040 | O16: 11 | P16: =10*60*2*O16 -> 13200 | Q16: =60*10*10*O16 -> 66000 | R16: =(P16+Q16)/2 -> 39600
C17: 13 | D17: =D16+E17 -> 187 | E17: 43 | F17: 9 | G17: =E17*10*K17 -> 1720 | J17: =G17*3 -> 5160 | K17: 4 | L17: =30*(C17*C17+5*C17)-80 -> 6940 | O17: 12 | P17: =10*60*2*O17 -> 14400 | Q17: =60*10*10*O17 -> 72000 | R17: =(P17+Q17)/2 -> 43200
C18: 14 | D18: =D17+E18 -> 239 | E18: 52 | F18: 11 | G18: =E18*10*K18 -> 2080 | J18: =G18*3 -> 6240 | K18: 4 | L18: =30*(C18*C18+5*C18)-80 -> 7900 | O18: 13 | P18: =10*60*2*O18 -> 15600 | Q18: =60*10*10*O18 -> 78000 | R18: =(P18+Q18)/2 -> 46800
B19: 推算5小时经验为2500-7500 | C19: 15 | D19: =D18+E19 -> 302 | E19: 63 | F19: 13 | G19: =E19*10*K19 -> 2520 | H19: =G19/(2*20) -> 63 | J19: =G19*3 -> 7560 | K19: 4 | L19: =30*(C19*C19+5*C19)-80 -> 8920 | O19: 14 | P19: =10*60*2*O19 -> 16800 | Q19: =60*10*10*O19 -> 84000 | R19: =(P19+Q19)/2 -> 50400
C20: 16 | D20: =D19+E20 -> 378 | E20: 76 | F20: 14 | G20: =E20*10*K20 -> 3040 | J20: =G20*3 -> 9120 | K20: =INT((C20-1)/7)+2 -> 4 | L20: =30*(C20*C20+5*C20)-80 -> 10000 | O20: 15 | P20: =10*60*2*O20 -> 18000 | Q20: =60*10*10*O20 -> 90000 | R20: =(P20+Q20)/2 -> 54000
C21: 17 | D21: =D20+E21 -> 468 | E21: 90 | F21: 10 | G21: =E21*10*K21 -> 3600 | J21: =G21*3 -> 10800 | K21: =INT((C21-1)/7)+2 -> 4 | O21: 16 | P21: =10*60*2*O21 -> 19200 | Q21: =60*10*10*O21 -> 96000 | R21: =(P21+Q21)/2 -> 57600
C22: 18 | D22: =D21+E22 -> 568 | E22: 100 | F22: 5 | G22: =E22*10*K22 -> 4000 | J22: =G22*3 -> 12000 | K22: =INT((C22-1)/7)+2 -> 4 | O22: 17 | P22: =10*60*2*O22 -> 20400 | Q22: =60*10*10*O22 -> 102000 | R22: =(P22+Q22)/2 -> 61200
C23: 19 | D23: =D22+E23 -> 673 | E23: =E22+F23 -> 105 | F23: 5 | G23: =E23*10*K23 -> 4200 | J23: =G23*3 -> 12600 | K23: =INT((C23-1)/7)+2 -> 4 | O23: 18 | P23: =10*60*2*O23 -> 21600 | Q23: =60*10*10*O23 -> 108000 | R23: =(P23+Q23)/2 -> 64800
C24: 20 | D24: =D23+E24 -> 783 | E24: =E23+F24 -> 110 | F24: 5 | G24: =E24*10*K24 -> 4400 | J24: =G24*3 -> 13200 | K24: =INT((C24-1)/7)+2 -> 4 | O24: 19 | P24: =10*60*2*O24 -> 22800 | Q24: =60*10*10*O24 -> 114000 | R24: =(P24+Q24)/2 -> 68400
C25: 21 | D25: =D24+E25 -> 898 | E25: =E24+F25 -> 115 | F25: 5 | G25: =E25*10*K25 -> 4600 | J25: =G25*3 -> 13800 | K25: =INT((C25-1)/7)+2 -> 4 | O25: 20 | P25: =10*60*2*O25 -> 24000 | Q25: =60*10*10*O25 -> 120000 | R25: =(P25+Q25)/2 -> 72000
C26: 22 | D26: =D25+E26 -> 1018 | E26: =E25+F26 -> 120 | F26: 5 | G26: =E26*10*K26 -> 6000 | J26: =G26*3 -> 18000 | K26: =INT((C26-1)/7)+2 -> 5 | O26: 21 | P26: =10*60*2*O26 -> 25200 | Q26: =60*10*10*O26 -> 126000 | R26: =(P26+Q26)/2 -> 75600
C27: 23 | D27: =D26+E27 -> 1143 | E27: =E26+F27 -> 125 | F27: 5 | G27: =E27*10*K27 -> 6250 | J27: =G27*3 -> 18750 | K27: =INT((C27-1)/7)+2 -> 5 | O27: 22 | P27: =10*60*2*O27 -> 26400 | Q27: =60*10*10*O27 -> 132000 | R27: =(P27+Q27)/2 -> 79200
C28: 24 | D28: =D27+E28 -> 1273 | E28: =E27+F28 -> 130 | F28: 5 | G28: =E28*10*K28 -> 6500 | J28: =G28*3 -> 19500 | K28: =INT((C28-1)/7)+2 -> 5 | O28: 23 | P28: =10*60*2*O28 -> 27600 | Q28: =60*10*10*O28 -> 138000 | R28: =(P28+Q28)/2 -> 82800
C29: 25 | D29: =D28+E29 -> 1408 | E29: =E28+F29 -> 135 | F29: 5 | G29: =E29*10*K29 -> 6750 | J29: =G29*3 -> 20250 | K29: =INT((C29-1)/7)+2 -> 5 | O29: 24 | P29: =10*60*2*O29 -> 28800 | Q29: =60*10*10*O29 -> 144000 | R29: =(P29+Q29)/2 -> 86400
C30: 26 | D30: =D29+E30 -> 1548 | E30: =E29+F30 -> 140 | F30: 5 | G30: =E30*10*K30 -> 7000 | J30: =G30*3 -> 21000 | K30: =INT((C30-1)/7)+2 -> 5 | O30: 25 | P30: =10*60*2*O30 -> 30000 | Q30: =60*10*10*O30 -> 150000 | R30: =(P30+Q30)/2 -> 90000
C31: 27 | D31: =D30+E31 -> 1693 | E31: =E30+F31 -> 145 | F31: 5 | G31: =E31*10*K31 -> 7250 | J31: =G31*3 -> 21750 | K31: =INT((C31-1)/7)+2 -> 5 | O31: 26 | P31: =10*60*2*O31 -> 31200 | Q31: =60*10*10*O31 -> 156000 | R31: =(P31+Q31)/2 -> 93600
C32: 28 | D32: =D31+E32 -> 1843 | E32: =E31+F32 -> 150 | F32: 5 | G32: =E32*10*K32 -> 7500 | J32: =G32*3 -> 22500 | K32: =INT((C32-1)/7)+2 -> 5 | O32: 27 | P32: =10*60*2*O32 -> 32400 | Q32: =60*10*10*O32 -> 162000 | R32: =(P32+Q32)/2 -> 97200
C33: 29 | D33: =D32+E33 -> 1998 | E33: =E32+F33 -> 155 | F33: 5 | G33: =E33*10*K33 -> 9300 | J33: =G33*3 -> 27900 | K33: =INT((C33-1)/7)+2 -> 6 | O33: 28 | P33: =10*60*2*O33 -> 33600 | Q33: =60*10*10*O33 -> 168000 | R33: =(P33+Q33)/2 -> 100800
C34: 30 | D34: =D33+E34 -> 2158 | E34: =E33+F34 -> 160 | F34: 5 | G34: =E34*10*K34 -> 9600 | J34: =G34*3 -> 28800 | K34: =INT((C34-1)/7)+2 -> 6 | O34: 29 | P34: =10*60*2*O34 -> 34800 | Q34: =60*10*10*O34 -> 174000 | R34: =(P34+Q34)/2 -> 104400
... C45: 41 | D45: =D44+E45 -> 4248 | E45: =E44+F45 -> 215 | F45: 5 | G45: =E45*10*K45 -> 15050 | J45: =G45*3 -> 45150 | K45: =INT((C45-1)/7)+2 -> 7 | O45: 40 | P45: =10*60*2*O45 -> 48000 | Q45: =60*10*10*O45 -> 240000 | R45: =(P45+Q45)/2 -> 144000
C46: 42 | D46: =D45+E46 -> 4468 | E46: =E45+F46 -> 220 | F46: 5 | G46: =E46*10*K46 -> 15400 | J46: =G46*3 -> 46200 | K46: =INT((C46-1)/7)+2 -> 7
C47: 43 | D47: =D46+E47 -> 4693 | E47: =E46+F47 -> 225 | F47: 5 | G47: =E47*10*K47 -> 18000 | J47: =G47*3 -> 54000 | K47: =INT((C47-1)/7)+2 -> 8
C48: 44 | D48: =D47+E48 -> 4923 | E48: =E47+F48 -> 230 | F48: 5 | G48: =E48*10*K48 -> 18400 | J48: =G48*3 -> 55200 | K48: =INT((C48-1)/7)+2 -> 8
C49: 45 | D49: =D48+E49 -> 5158 | E49: =E48+F49 -> 235 | F49: 5 | G49: =E49*10*K49 -> 18800 | J49: =G49*3 -> 56400 | K49: =INT((C49-1)/7)+2 -> 8
C50: 46 | D50: =D49+E50 -> 5398 | E50: =E49+F50 -> 240 | F50: 5 | G50: =E50*10*K50 -> 19200 | J50: =G50*3 -> 57600 | K50: =INT((C50-1)/7)+2 -> 8
...

Sheet Sheet3
A2: 每级升级所需时长(秒) = LV * LV * LV * A + LV * LV * B + LV * C + D
A3: 杀死同等级怪物可获得的经验 = LV * E + F
A4: 每级所需经验 = 每级升级所需时长 / 杀死同等级怪物所需时长 * 杀死同等级怪物可获得的经验。
A6: 这里的A值一般都不要超过2，否则在后期所需经验会非常巨大，但可以为0，比如A为0，
A7: 那么升级公式就会变成三次方，如果不为0，这条公式其实就是四次方公式，而D，通常都是30的倍数，
A8: 也就是以30秒为基数，因为回合制游戏中，有一个30秒的准备时间，这个时间，
A9: 其实还需要算上进入战斗和退出战斗的时间，以30秒的倍数来计算会比较准确，当然，用其他数值也没有问题。
A11: “杀死同等级怪物可获得的经验”，是指一对一情况下的经验，如果一对多，那么还需要乘上怪物数量，而所谓的怪物数量，其实就是
A12: 每级升级所需时长 / 杀死同等级怪物所需时长
Q14: lv | S14: 升级所需时间 | T14: 分钟
Q15: 1 | S15: =POWER(Q15,3)+POWER(Q15,2)+Q15*10+60 -> 72 | T15: =ROUND(S15/60,1) -> 1.2
Q16: 2 | S16: =POWER(Q16,3)+POWER(Q16,2)+Q16*10+60 -> 92 | T16: =ROUND(S16/60,1) -> 1.5
Q17: 3 | S17: =POWER(Q17,3)+POWER(Q17,2)+Q17*10+60 -> 126 | T17: =ROUND(S17/60,1) -> 2.1
Q18: 4 | S18: =POWER(Q18,3)+POWER(Q18,2)+Q18*10+60 -> 180 | T18: =ROUND(S18/60,1) -> 3
Q19: 5 | S19: =POWER(Q19,3)+POWER(Q19,2)+Q19*10+60 -> 260 | T19: =ROUND(S19/60,1) -> 4.3
Q20: 6 | S20: =POWER(Q20,3)+POWER(Q20,2)+Q20*10+60 -> 372 | T20: =ROUND(S20/60,1) -> 6.2
Q21: 7 | S21: =POWER(Q21,3)+POWER(Q21,2)+Q21*10+60 -> 522 | T21: =ROUND(S21/60,1) -> 8.7
Q22: 8 | S22: =POWER(Q22,3)+POWER(Q22,2)+Q22*10+60 -> 716 | T22: =ROUND(S22/60,1) -> 11.9
Q23: 9 | S23: =POWER(Q23,3)+POWER(Q23,2)+Q23*10+60 -> 960 | T23: =ROUND(S23/60,1) -> 16
Q24: 10 | S24: =POWER(Q24,3)+POWER(Q24,2)+Q24*10+60 -> 1260 | T24: =ROUND(S24/60,1) -> 21
Q25: 11 | S25: =POWER(Q25,3)+POWER(Q25,2)+Q25*10+60 -> 1622 | T25: =ROUND(S25/60,1) -> 27
Q26: 12 | S26: =POWER(Q26,3)+POWER(Q26,2)+Q26*10+60 -> 2052 | T26: =ROUND(S26/60,1) -> 34.2
... Q74: 60 | S74: =POWER(Q74,3)+POWER(Q74,2)+Q74*10+60 -> 220260 | T74: =ROUND(S74/60,1) -> 3671
