Workbook

Sheet Migong
A1: MiGongID | B1: LevelType | C1: Name | D1: Icon | E1: NextLevel | F1: ChaptersLv | G1: ChaptersLv1 | H1: TurnCount | I1: TurnCount1 | J1: TurnCount2 | K1: Difficulty | L1: Difficulty1 | M1: Difficulty2 | N1: BossReward | O1: BossReward1 | P1: BossReward2 | Q1: Pool | R1: Pool1 | S1: Pool2 | T1: Showitem | U1: Energy | V1: Idle | W1: IdleKing | X1: Idle1 | Y1: Mapaudio | Z1: ChaptersId | AA1: DiffcultId | AB1: Lv | AC1: Lv1 | AD1: StartCoin | AE1: Exp | AF1: OutMonster | AG1: RoundOut | AH1: Times | AI1: BOSS | AJ1: Export | AK1: TroopLib | AL1: BossMonster | AM1: DiffXiShu | AN1: Reward | AO1: FirstSklillLib | AP1: Challenge | AQ1: ChallengeNum | AR1: ChildLevelName | AS1: ChallengePos | AT1: Box | AU1: Pos | AV1: LevelSequence | AW1: BianShenSkillLib | AX1: JuQingType | AY1: BoxAndMonsterReward | AZ1: Story | BA1: LevelStory | BB1: Nandu | BC1: Difficult | BD1: Nandu | BE1: BossAlly | BF1: BossLib | BG1: BossSkill | BH1: BossMonsterNum | BI1: Mapmodel | BJ1: MapName
A2: int | B2: int | C2: string | D2: string | E2: int | F2: int | G2: int | H2: int | I2: int | J2: int | K2: int | L2: int | M2: int | N2: string | O2: string | P2: string | Q2: string | R2: string | S2: string | T2: string | U2: int | V2: string | W2: string | X2: string | Y2: string | Z2: int | AA2: int | AB2: int | AC2: int | AD2: int | AE2: int | AF2: int | AG2: int | AH2: int | AI2: string | AJ2: string | AK2: string | AL2: string | AM2: string | AN2: string | AO2: string | AP2: string | AQ2: int | AR2: string | AS2: string | AT2: string | AU2: string | AV2: string | AW2: string | AX2: int | AY2: string | AZ2: string | BA2: string | BB2: int | BC2: float | BD2: int | BE2: string | BF2: string | BG2: string | BH2: int | BI2: string | BJ2: string
A3: 迷宫关卡章节对应id | B3: 0常规1幻境2无尽守3攻城战4守城战5拯救友军6护送友军 | C3: 名称 | D3: 图标 | E3: 下一个关卡id | F3: 简单关卡等级(参与） | G3: 困难关卡等级(参与） | H3: 简单难度回合数 | I3: 困难难度回合数 | J3: 地狱难度回合数 | K3: 简单关卡难度系数 | L3: 困难难度难度系数 | M3: 地狱难度难度系数 | N3: 简单难度（通关奖励|1星奖励|2星奖励|3星奖励） | O3: 困难难度（通关奖励|1星奖励|2星奖励|3星奖励） | P3: 地狱难度（通关奖励|1星奖励|2星奖励|3星奖励） | Q3: 简单难度卡牌掉落 | R3: 困难难度卡牌掉落 | S3: 地狱难度卡牌掉落 | T3: 挑战怪奖励展示 | U3: 消耗体力 | V3: 挂机奖励每次产出的卡牌碎片数量（品质：数量|品质：数量|...） | W3: 挂机奖励会产出那些国王的卡牌碎片（国王id：国王id） | X3: 挂机奖励每次产出的金币数量（道具id和数量） | Y3: 背景音乐 | Z3: 当前章节 | AA3: 关卡难度 | AB3: 简单怪物等级 | AC3: 困难怪物等级 | AD3: 初始金币 | AE3: 每关怪物经验 | AF3: 初始出怪时间(毫秒) | AG3: 回合出怪间隔(毫秒) | AH3: 关卡防守总波次 | AI3: BOSS出现波次 | AJ3: 出怪 | AK3: 部队库 | AL3: 层数#部队库#层数增长系数 | AM3: 关卡波次属性增长值（生命#双攻#双防） | AN3: 挑战怪奖励 | AO3: 优先必出技能，|对应等级，2 | AP3: 挑战怪 | AQ3: 挑战怪数量 | AR3: 关卡难度描述 | AS3: 关卡挑战怪点 | AT3: 宝箱坐标点 | AU3: 关卡坐标点位 | AV3: 固定事件列表 | AW3: 变身商店要展示的技能 （1|101:102:103 2|101-103） | AX3: 0无 1开始有 2结束有 3开始结束都有 | AY3: 宝箱奖励，概率：类型：数量，概率+黑金石+数量，概率+装备+数量 | AZ3: 章节背景 | BA3: 小关卡故事 | BB3: 难度描述 | BC3: 关卡难度系数 | BD3: 难度描述 | BE3: boss关友军(友军id|友军id+数量+强度+队伍人数) | BF3: bossId+强度 | BG3: boss技能 | BH3: boss关怪物队伍数量 | BI3: 地图 | BJ3: 章节背景 | BL3: 序列 | BM3: boss | BN3: bossMons | BO3: 攻城站远程 | BP3: 救援战我方
A4: 11 | B4: 0 | C4: 贪婪之祸1 | D4: img_shenyuan1 | E4: =A5 -> 12 | F4: 1 | G4: =F4+20 -> 21 | H4: 18 | I4: 18 | J4: 18 | K4: 100 | L4: 200 | M4: 300 | N4: 1:12:100#1:12:100#1:12:400|1:13:6#1:11:100|1:10000001:72|1:10000002:28 | O4: 1:12:150#1:12:300#1:12:600|1:13:6#1:11:150|1:10000001:90|1:10000002:28|1:10000003:1 | P4: 1:12:250#1:12:400#1:12:800|1:13:6#1:11:200|1:10000001:120|1:10000002:36|1:10000003:2 | Q4: 30|1010101:1020101:1040101:2010101:2030101:2080101:3010101:3020101:3080101:4010101:4020101:4030101:5010101:5020101:5060101|1|100#7|1050101:1080101:1090101:2020101:2070101:2090101:3040101:3060101:3090101:4050101:4070101:4090101:5040101:5050101:5090101|1|100 | R4: 42|1010101:1020101:1040101:2010101:2030101:2080101:3010101:3020101:3080101:4010101:4020101:4030101:5010101:5020101:5060101|1|100#10|1050101:1080101:1090101:2020101:2070101:2090101:3040101:3060101:3090101:4050101:4070101:4090101:5040101:5050101:5090101|1|100#1|1030101:1070101:2040101:2060101:3050101:3070101:4040101:4060101:5030101:5070101|1|100 | S4: 72|1010101:1020101:1040101:2010101:2030101:2080101:3010101:3020101:3080101:4010101:4020101:4030101:5010101:5020101:5060101|1|100#18|1050101:1080101:1090101:2020101:2070101:2090101:3040101:3060101:3090101:4050101:4070101:4090101:5040101:5050101:5090101|1|100#1|1030101:1070101:2040101:2060101:3050101:3070101:4040101:4060101:5030101:5070101|1|100 | T4: 0 | U4: 3 | V4: 1:6|2:1|3:0 | W4: 1:2:3:4:5 | X4: 1:12:20 | Y4: MapBingXue | Z4: 1 | AA4: 0 | AB4: =F4+AA4+Z4 -> 2 | AC4: =AB4+15 -> 17 | AD4: 1000 | AE4: 15 | AF4: 15000 | AG4: 15000 | AH4: =出怪成长!C2 -> 3 | AI4: =出怪成长!D2 -> 3#20004#1 | AJ4: 1:2:1|1:4:1|2:8:1 | AK4: 1:10001|2:10002 | AL4: =出怪成长!F2 -> 2#1#0.4|3#2#0.8 | AM4: 5#5#1 | AN4: 0 | AO4: 0 | AP4: 0 | AQ4: 0 | AR4: 1 | AS4: 0 | AT4: 0 | AU4: -584.8:283 | AV4: 1+1+1+1+9+3|1+1+1+22+6|1+1+1+9+1+4|51 | AW4: 307:313:317 | AX4: 3 | AY4: 700:12:30|100:11:2|100:1:1|10:4:1 | AZ4: 北方之地，这里远离纷争 | BA4: 森林里出现了一个厉害的怪物，我们需要去打败它 | BB4: 0 | BC4: 0.2 | BD4: 2 | BE4: 0 | BF4: 2101+0.6 | BG4: 0 | BH4: 3 | BI4: MapBingXue1 | BJ4: MapBingXue | BL4: 1 | BM4: 2101 | BN4: 2001 | BO4: 0
A5: 12 | B5: 0 | C5: 贪婪之祸2 | D5: img_shenyuan2 | E5: =A6 -> 13 | F5: 2 | G5: =F5+20 -> 22 | H5: 18 | I5: 18 | J5: 18 | K5: 150 | L5: 300 | M5: 450 | N5: 1:12:100#1:12:100#1:12:600|1:13:6#1:11:100|1:10000001:84|1:10000002:28 | O5: 1:12:150#1:12:450#1:12:900|1:13:6#1:11:150|1:10000001:108|1:10000002:32|1:10000003:1 | P5: 1:12:250#1:12:600#1:12:1200|1:13:6#1:11:200|1:10000001:144|1:10000002:43|1:10000003:2 | Q5: 30|1010101:1020101:1040101:2010101:2030101:2080101:3010101:3020101:3080101:4010101:4020101:4030101:5010101:5020101:5060101|1|100#7|1050101:1080101:1090101:2020101:2070101:2090101:3040101:3060101:3090101:4050101:4070101:4090101:5040101:5050101:5090101|1|100 | R5: 42|1010101:1020101:1040101:2010101:2030101:2080101:3010101:3020101:3080101:4010101:4020101:4030101:5010101:5020101:5060101|1|100#10|1050101:1080101:1090101:2020101:2070101:2090101:3040101:3060101:3090101:4050101:4070101:4090101:5040101:5050101:5090101|1|100#1|1030101:1070101:2040101:2060101:3050101:3070101:4040101:4060101:5030101:5070101|1|100 | S5: 72|1010101:1020101:1040101:2010101:2030101:2080101:3010101:3020101:3080101:4010101:4020101:4030101:5010101:5020101:5060101|1|100#18|1050101:1080101:1090101:2020101:2070101:2090101:3040101:3060101:3090101:4050101:4070101:4090101:5040101:5050101:5090101|1|100#1|1030101:1070101:2040101:2060101:3050101:3070101:4040101:4060101:5030101:5070101|1|100 | T5: 0 | U5: 3 | V5: 1:6|2:1|3:0 | W5: 1:2:3:4:5 | X5: 1:12:20 | Y5: MapBingXue | Z5: 1 | AA5: -1 | AB5: =F5+AA5+Z5 -> 2 | AC5: =AB5+15 -> 17 | AD5: 250 | AE5: =AE4 -> 15 | AF5: =AF4 -> 15000 | AG5: 20000 | AH5: =出怪成长!C3 -> 7 | AI5: =出怪成长!D3 -> 2#20001#1|5#20002#1|7#30001,30002#1 | AJ5: =出怪数量!Z4 -> 1:2:1|1:4:1|2:8:1|2:12:1|1:17:1|2:22:1|1:27:1 | AK5: =出怪成长!E3 -> 1:10001,10002|2:10004,10005,10006|3:10004,10005,10006 | AL5: =出怪成长!F3 -> 2#1#0.4|5#2#0.8|7#3#1 | AM5: =每波成长!G6 -> 28#7#4 | AN5: 1:11:50#2:25:500 | AO5: 0 | AP5: 200#40001:1 | AQ5: 1 | AR5: 2 | AS5: 1:41001#1 | AT5: 1:90001#1 | AU5: -266:76 | AV5: 1+1+1+1+22+3|1+1+1+9+6|1+1+1+9+1+4|52 | AW5: 307:313:317 | AX5: 3 | AY5: 700:12:30|100:11:2|100:1:1|10:4:1 | AZ5: 北方之地，这里远离纷争 | BA5: 有一群叛军占领着一座遗弃的城堡，赶走他们，这里可以成为根据地 | BB5: 0 | BC5: 0.4 | BD5: 4 | BE5: 9001+0.6 | BF5: 1101+1.2 | BG5: 0 | BH5: 3 | BI5: MapBingXue2 | BJ5: MapBingXue | BL5: 2 | BM5: 1101 | BN5: 1001 | BO5: 1002 | BR5: |3:905:1
A6: 13 | B6: 0 | C6: 贪婪之祸3 | D6: img_shenyuan3 | E6: =A7 -> 14 | F6: 3 | G6: =F6+20 -> 23 | H6: 18 | I6: 18 | J6: 18 | K6: 180 | L6: 360 | M6: 540 | N6: 1:12:110#1:12:110#1:12:800|1:13:6#1:11:100|1:10000001:96|1:10000002:28 | O6: 1:12:165#1:12:600#1:12:1200|1:13:6#1:11:150|1:10000001:126|1:10000002:36|1:10000003:1 | P6: 1:12:275#1:12:800#1:12:1600|1:13:6#1:11:200|1:10000001:168|1:10000002:50|1:10000003:2 | Q6: 30|1010101:1020101:1040101:2010101:2030101:2080101:3010101:3020101:3080101:4010101:4020101:4030101:5010101:5020101:5060101|1|100#7|1050101:1080101:1090101:2020101:2070101:2090101:3040101:3060101:3090101:4050101:4070101:4090101:5040101:5050101:5090101|1|100 | R6: 42|1010101:1020101:1040101:2010101:2030101:2080101:3010101:3020101:3080101:4010101:4020101:4030101:5010101:5020101:5060101|1|100#10|1050101:1080101:1090101:2020101:2070101:2090101:3040101:3060101:3090101:4050101:4070101:4090101:5040101:5050101:5090101|1|100#1|1030101:1070101:2040101:2060101:3050101:3070101:4040101:4060101:5030101:5070101|1|100 | S6: 72|1010101:1020101:1040101:2010101:2030101:2080101:3010101:3020101:3080101:4010101:4020101:4030101:5010101:5020101:5060101|1|100#18|1050101:1080101:1090101:2020101:2070101:2090101:3040101:3060101:3090101:4050101:4070101:4090101:5040101:5050101:5090101|1|100#1|1030101:1070101:2040101:2060101:3050101:3070101:4040101:4060101:5030101:5070101|1|100 | T6: 0 | U6: 3 | V6: 1:6|2:1|3:0 | W6: 1:2:3:4:5 | X6: 1:12:22 | Y6: MapBingXue | Z6: 1 | AA6: 0 | AB6: =F6+AA6+Z6 -> 4 | AC6: =AB6+15 -> 19 | AD6: 250 | AE6: =AE5 -> 15 | AF6: =AF5 -> 15000 | AG6: 28000 | AH6: =出怪成长!C4 -> 8 | AI6: =出怪成长!D4 -> 3#20003#1|6#20004#1|8#30001,30002#1 | AJ6: =出怪数量!Z5 -> 1:2:1|1:4:1|2:8:1|2:12:1|1:17:1|2:22:1|1:27:1|2:32:1 | AK6: =出怪成长!E4 -> 1:10004,10005|2:10004,10005,10006|3:10004,10005,10006 | AL6: =出怪成长!F4 -> 3#1#0.4|6#2#0.8|8#3#1 | AM6: =每波成长!G7 -> 30#7#4 | AN6: 1:11:50#2:25:500 | AO6: 0 | AP6: 200#40001:2;40002:1|500#40002:3 | AQ6: 2 | AR6: 3 | AS6: 1:41002#1 | AT6: 1:90001#1 | AU6: -653:-143 | AV6: 1+1+1+1+15+3+9|1+1+1+1+9+3+7|1+1+1+1+4+9|53 | AW6: 307:313:317 | AX6: 3 | AY6: 700:12:30|100:11:2|100:1:1|10:4:1 | AZ6: 北方之地，这里远离纷争 | BA6: 占领城堡不久，我们发现了兽族部队也想占领这里。我们需要守住这里。 | BB6: 0 | BC6: 0.6 | BD6: 6 | BE6: 9001+0.8 | BF6: 3101+1.8 | BG6: 0 | BH6: 3 | BI6: MapBingXue3 | BJ6: MapBingXue | BL6: 3 | BM6: 3101 | BN6: 3001 | BO6: 0 | BR6: |3:132:1
A7: 14 | B7: 0 | C7: 贪婪之祸4 | D7: img_shenyuan4 | E7: =A8 -> 15 | F7: 4 | G7: =F7+20 -> 24 | H7: 18 | I7: 18 | J7: 18 | K7: 220 | L7: 440 | M7: 660 | N7: 1:12:110#1:12:110#1:12:1000|1:13:6#1:11:100|1:10000001:108|1:10000002:28|1:10000003:1 | O7: 1:12:165#1:12:750#1:12:1500|1:13:6#1:11:150|1:10000001:144|1:10000002:43|1:10000003:2 | P7: 1:12:275#1:12:1000#1:12:2000|1:13:6#1:11:200|1:10000001:192|1:10000002:57|1:10000003:3 | Q7: 30|1010101:1020101:1040101:2010101:2030101:2080101:3010101:3020101:3080101:4010101:4020101:4030101:5010101:5020101:5060101|1|100#7|1050101:1080101:1090101:2020101:2070101:2090101:3040101:3060101:3090101:4050101:4070101:4090101:5040101:5050101:5090101|1|100#1|1030101:1070101:2040101:2060101:3050101:3070101:4040101:4060101:5030101:5070101|1|100 | R7: 42|1010101:1020101:1040101:2010101:2030101:2080101:3010101:3020101:3080101:4010101:4020101:4030101:5010101:5020101:5060101|1|100#14|1050101:1080101:1090101:2020101:2070101:2090101:3040101:3060101:3090101:4050101:4070101:4090101:5040101:5050101:5090101|1|100#1|1030101:1070101:2040101:2060101:3050101:3070101:4040101:4060101:5030101:5070101|1|100 | S7: 72|1010101:1020101:1040101:2010101:2030101:2080101:3010101:3020101:3080101:4010101:4020101:4030101:5010101:5020101:5060101|1|100#18|1050101:1080101:1090101:2020101:2070101:2090101:3040101:3060101:3090101:4050101:4070101:4090101:5040101:5050101:5090101|1|100#2|1030101:1070101:2040101:2060101:3050101:3070101:4040101:4060101:5030101:5070101|1|100 | T7: 0 | U7: 3 | V7: 1:6|2:1|3:0 | W7: 1:2:3:4:5 | X7: 1:12:22 | Y7: MapBingXue | Z7: 1 | AA7: 1 | AB7: =F7+AA7+Z7 -> 6 | AC7: =AB7+15 -> 21 | AD7: 250 | AE7: =AE6 -> 15 | AF7: =AF6 -> 15000 | AG7: =AG6 -> 28000 | AH7: =出怪成长!C5 -> 9 | AI7: =出怪成长!D5 -> 3#30001#1|7#30002#1|9#30003,30004#1 | AJ7: =出怪数量!Z6 -> 1:2:1|1:4:1|2:8:1|2:12:1|1:17:1|2:22:1|1:27:1|2:32:1|1:37:1 | AK7: =出怪成长!E5 -> 1:10004,10005|2:10004,10005,10006|3:10006,10007,10010 | AL7: =出怪成长!F5 -> 4#1#0.5|7#2#1|9#3#1.3 | AM7: =每波成长!G8 -> 31#8#5 | AN7: 1:11:50#2:25:500#3:26:500|1:11:50#2:25:500#4:50011 | AO7: 0 | AP7: 200#40001:2;40002:1|500#40002:3 | AQ7: 2 | AR7: 4 | AS7: 1:42001#1|2:42002#1 | AT7: 1:90003#1|2:90002#1 | AU7: -307:-291 | AV7: 1+1+1+1+9+3|1+1+1+15+6|1+1+1+9+1+4|51 | AW7: 305:319:330 | AX7: 3 | AY7: 700:12:30|100:11:2|100:1:1|10:4:1 | AZ7: 北方之地，这里远离纷争 | BA7: 经过调查我们发现了城堡被遗弃的原因，月圆之夜会有大批亡灵入侵，于是我们计划讨伐。 | BB7: 0 | BC7: 0.8 | BD7: 8 | BE7: 0 | BF7: 6101+2.4 | BG7: 0 | BH7: 3 | BI7: MapBingXue6 | BJ7: MapBingXue | BL7: 4 | BM7: 6101 | BN7: 6001 | BO7: 0 | BR7: |3:134:1
A8: 15 | B8: 0 | C8: 贪婪之祸5 | D8: img_shenyuan1 | E8: =A9 -> 16 | F8: 5 | G8: =F8+20 -> 25 | H8: 19 | I8: 19 | J8: 19 | K8: 250 | L8: 500 | M8: 750 | N8: 1:12:120#1:12:120#1:12:1200|1:13:6#1:11:100|1:10000001:120|1:10000002:32|1:10000003:1 | O8: 1:12:180#1:12:900#1:12:1800|1:13:6#1:11:150|1:10000001:162|1:10000002:46|1:10000003:2 | P8: 1:12:300#1:12:1200#1:12:2400|1:13:6#1:11:200|1:10000001:216|1:10000002:64|1:10000003:3 | Q8: 36|1010101:1020101:1040101:2010101:2030101:2080101:3010101:3020101:3080101:4010101:4020101:4030101:5010101:5020101:5060101|1|100#7|1050101:1080101:1090101:2020101:2070101:2090101:3040101:3060101:3090101:4050101:4070101:4090101:5040101:5050101:5090101|1|100#1|1030101:1070101:2040101:2060101:3050101:3070101:4040101:4060101:5030101:5070101|1|100 | R8: 54|1010101:1020101:1040101:2010101:2030101:2080101:3010101:3020101:3080101:4010101:4020101:4030101:5010101:5020101:5060101|1|100#14|1050101:1080101:1090101:2020101:2070101:2090101:3040101:3060101:3090101:4050101:4070101:4090101:5040101:5050101:5090101|1|100#1|1030101:1070101:2040101:2060101:3050101:3070101:4040101:4060101:5030101:5070101|1|100 | S8: 90|1010101:1020101:1040101:2010101:2030101:2080101:3010101:3020101:3080101:4010101:4020101:4030101:5010101:5020101:5060101|1|100#18|1050101:1080101:1090101:2020101:2070101:2090101:3040101:3060101:3090101:4050101:4070101:4090101:5040101:5050101:5090101|1|100#2|1030101:1070101:2040101:2060101:3050101:3070101:4040101:4060101:5030101:5070101|1|100 | T8: 0 | U8: 3 | V8: 1:7|2:1|3:0 | W8: 1:2:3:4:5 | X8: 1:12:24 | Y8: MapBingXue | Z8: 1 | AA8: -1 | AB8: =F8+AA8+Z8 -> 5 | AC8: =AB8+15 -> 20 | AD8: 250 | AE8: =AE7 -> 15 | AF8: =AF7 -> 15000 | AG8: =AG7 -> 28000 | AH8: =出怪成长!C6 -> 8 | AI8: =出怪成长!D6 -> 3#30001#1|6#30002#1|8#30003,30004#1 | AJ8: =出怪数量!Z7 -> 1:3:1|1:5:1|2:9:1|2:13:1|1:18:1|2:23:1|1:28:1|2:33:1 | AK8: =出怪成长!E6 -> 1:10004,10005|2:10006,10007,10010|3:10006,10008,10010 | AL8: =出怪成长!F6 -> 3#1#0.5|6#2#1|8#3#1.3 | AM8: =每波成长!G9 -> 28#7#4 | AN8: 1:11:50#2:25:500|1:11:100#2:25:500#3:26:500 | AO8: 0 | AP8: 200#40001:2;40002:1|500#40002:3 | AQ8: 2 | AR8: 5 | AS8: 1:42003#1|2:41004#1 | AT8: 1:90001#1|2:90003#1 | AU8: -83:-50 | AV8: 1+1+1+1+9+3|1+1+1+5+6|1+1+1+1+9+4|54 | AW8: 305:319:330 | AX8: 3 | AY8: 700:12:30|100:11:2|100:1:1|10:4:1 | AZ8: 北方之地，这里远离纷争 | BA8: 讨伐中，我们得知也有其它部队在抵抗亡灵并面临险境。于是我们准备拯救他们。 | BB8: 0 | BC8: 1 | BD8: 10 | BE8: 1001+1.2 | BF8: 6102+2.4 | BG8: 0 | BH8: 3 | BI8: MapBingXue5 | BJ8: MapBingXue | BL8: 5 | BM8: 6102 | BN8: 6002 | BO8: 0 | BR8: |3:135:1
A9: 16 | B9: 0 | C9: 贪婪之祸6 | D9: img_shenyuan2 | E9: =A10 -> 17 | F9: 6 | G9: =F9+20 -> 26 | H9: 19 | I9: 19 | J9: 19 | K9: 290 | L9: 580 | M9: 870 | N9: 1:12:120#1:12:120#1:12:1400|1:13:6#1:11:100|1:10000001:120|1:10000002:36|1:10000003:2 | O9: 1:12:180#1:12:1050#1:12:2100|1:13:6#1:11:150|1:10000001:180|1:10000002:54|1:10000003:3 | P9: 1:12:300#1:12:1400#1:12:2800|1:13:6#1:11:200|1:10000001:240|1:10000002:72|1:10000003:4 | Q9: 36|1010101:1020101:1040101:2010101:2030101:2080101:3010101:3020101:3080101:4010101:4020101:4030101:5010101:5020101:5060101|1|100#7|1050101:1080101:1090101:2020101:2070101:2090101:3040101:3060101:3090101:4050101:4070101:4090101:5040101:5050101:5090101|1|100#1|1030101:1070101:2040101:2060101:3050101:3070101:4040101:4060101:5030101:5070101|1|100 | R9: 54|1010101:1020101:1040101:2010101:2030101:2080101:3010101:3020101:3080101:4010101:4020101:4030101:5010101:5020101:5060101|1|100#14|1050101:1080101:1090101:2020101:2070101:2090101:3040101:3060101:3090101:4050101:4070101:4090101:5040101:5050101:5090101|1|100#1|1030101:1070101:2040101:2060101:3050101:3070101:4040101:4060101:5030101:5070101|1|100 | S9: 90|1010101:1020101:1040101:2010101:2030101:2080101:3010101:3020101:3080101:4010101:4020101:4030101:5010101:5020101:5060101|1|100#18|1050101:1080101:1090101:2020101:2070101:2090101:3040101:3060101:3090101:4050101:4070101:4090101:5040101:5050101:5090101|1|100#2|1030101:1070101:2040101:2060101:3050101:3070101:4040101:4060101:5030101:5070101|1|100 | T9: 0 | U9: 3 | V9: 1:7|2:1|3:0 | W9: 1:2:3:4:5 | X9: 1:12:24 | Y9: MapBingXue | Z9: 1 | AA9: 0 | AB9: =F9+AA9+Z9 -> 7 | AC9: =AB9+15 -> 22 | AD9: 250 | AE9: =AE8 -> 15 | AF9: =AF8 -> 15000 | AG9: =AG8 -> 28000 | AH9: =出怪成长!C7 -> 9 | AI9: =出怪成长!D7 -> 3#30001#1|7#30002#1|9#30001,30004#1 | AJ9: =出怪数量!Z8 -> 1:3:1|1:5:1|2:9:1|2:13:1|1:18:1|2:23:1|1:28:1|2:33:1|1:38:1 | AK9: =出怪成长!E7 -> 1:10006,10007|2:10006,10008,10010|3:10006,10007,10010 | AL9: =出怪成长!F7 -> 4#1#0.8|7#2#1.2|9#3#1.4 | AM9: =每波成长!G10 -> 30#7#4 | AN9: 1:11:50#2:25:500#3:26:500|1:11:50#2:25:500#4:50011 | AO9: 0 | AP9: 200#40001:2;40002:1|500#40002:3 | AQ9: 2 | AR9: 6 | AS9: 1:40021#1|2:40022#1 | AT9: 1:90003#1|2:90002#1 | AU9: 70:180 | AV9: 1+1+1+1+5+3|1+1+1+1+9+3|1+1+1+1+9+4+7|51 | AW9: 301:302:306:307:311:312:313:317:321:323:328 | AX9: 3 | AY9: 700:12:30|100:11:2|100:1:1|10:4:1 | AZ9: 北方之地，这里远离纷争 | BA9: 为了解决亡灵之乱，我们计划卧薪尝胆，去增强自己的实力。 | BB9: 0 | BC9: 1.2 | BD9: 12 | BE9: 0 | BF9: 1102+2.8 | BG9: 0 | BH9: 3 | BI9: MapBingXue4 | BJ9: MapBingXue | BL9: 6 | BM9: 1102 | BN9: 1002 | BO9: 0 | BR9: |3:146:1
A10: 17 | B10: 0 | C10: 贪婪之祸7 | D10: img_shenyuan3 | E10: =A11 -> 18 | F10: 7 | G10: =F10+20 -> 27 | H10: 19 | I10: 19 | J10: 19 | K10: 340 | L10: 680 | M10: 1020 | N10: 1:12:130#1:12:130#1:12:1600|1:13:6#1:11:100|1:10000001:132|1:10000002:39|1:10000003:2 | O10: 1:12:195#1:12:1200#1:12:2400|1:13:6#1:11:150|1:10000001:198|1:10000002:57|1:10000003:3 | P10: 1:12:325#1:12:1600#1:12:3200|1:13:6#1:11:200|1:10000001:264|1:10000002:79|1:10000003:4 | Q10: 36|1010101:1020101:1040101:2010101:2030101:2080101:3010101:3020101:3080101:4010101:4020101:4030101:5010101:5020101:5060101|1|100#10|1050101:1080101:1090101:2020101:2070101:2090101:3040101:3060101:3090101:4050101:4070101:4090101:5040101:5050101:5090101|1|100#1|1030101:1070101:2040101:2060101:3050101:3070101:4040101:4060101:5030101:5070101|1|100 | R10: 54|1010101:1020101:1040101:2010101:2030101:2080101:3010101:3020101:3080101:4010101:4020101:4030101:5010101:5020101:5060101|1|100#14|1050101:1080101:1090101:2020101:2070101:2090101:3040101:3060101:3090101:4050101:4070101:4090101:5040101:5050101:5090101|1|100#1|1030101:1070101:2040101:2060101:3050101:3070101:4040101:4060101:5030101:5070101|1|100 | S10: 90|1010101:1020101:1040101:2010101:2030101:2080101:3010101:3020101:3080101:4010101:4020101:4030101:5010101:5020101:5060101|1|100#25|1050101:1080101:1090101:2020101:2070101:2090101:3040101:3060101:3090101:4050101:4070101:4090101:5040101:5050101:5090101|1|100#2|1030101:1070101:2040101:2060101:3050101:3070101:4040101:4060101:5030101:5070101|1|100 | T10: 0 | U10: 3 | V10: 1:7|2:2|3:0 | W10: 1:2:3:4:5 | X10: 1:12:26 | Y10: MapBingXue | Z10: 1 | AA10: 1 | AB10: =F10+AA10+Z10 -> 9 | AC10: =AB10+15 -> 24 | AD10: 250 | AE10: =AE9 -> 15 | AF10: =AF9 -> 15000 | AG10: =AG9 -> 28000 | AH10: =出怪成长!C8 -> 9 | AI10: =出怪成长!D8 -> 3#30001#1|7#30002#1|9#30001,30004#1 | AJ10: =出怪数量!Z9 -> 1:3:1|1:5:1|2:9:1|2:13:1|1:18:1|2:23:1|1:28:1|2:33:1|1:38:1 | AK10: =出怪成长!E8 -> 1:10006,10008|2:10006,10007,10010|3:10006,10010,10009 | AL10: =出怪成长!F8 -> 4#1#0.8|7#2#1.2|9#3#1.4 | AM10: =每波成长!G11 -> 31#8#5 | AN10: 1:11:50#2:25:500|1:11:100#2:25:500#3:26:500 | AO10: 0 | AP10: 200#40001:2;40002:1|500#40002:3 | AQ10: 2 | AR10: 7 | AS10: 1:40021#1|2:40022#1 | AT10: 1:90001#1|2:90003#1 | AU10: 375:-24 | AV10: 1+1+1+1+9+3|1+1+1+5+6|1+1+1+1+9+4|54 | AW10: 305:319:330 | AX10: 3 | AY10: 700:12:30|100:11:2|100:1:1|10:4:1 | AZ10: 北方之地，这里远离纷争 | BA10: 讨伐中，我们得知也有其它部队在抵抗亡灵并面临险境。于是我们准备拯救他们。 | BB10: 0 | BC10: 1 | BD10: 14 | BE10: 0 | BF10: 1102+2.8 | BG10: 0 | BH10: 3 | BI10: MapBingXue7 | BJ10: MapBingXue
A11: 18 | B11: 0 | C11: 贪婪之祸8 | D11: img_shenyuan4 | E11: =A12 -> 19 | F11: 8 | G11: =F11+20 -> 28 | H11: 19 | I11: 19 | J11: 19 | K11: 400 | L11: 800 | M11: 1200 | N11: 1:12:130#1:12:130#1:12:1800|1:13:6#1:11:100|1:10000001:144|1:10000002:43|1:10000003:3 | O11: 1:12:195#1:12:1350#1:12:2700|1:13:6#1:11:150|1:10000001:216|1:10000002:64|1:10000003:3 | P11: 1:12:325#1:12:1800#1:12:3600|1:13:6#1:11:200|1:10000001:288|1:10000002:86|1:10000003:4 | Q11: 36|1010101:1020101:1040101:2010101:2030101:2080101:3010101:3020101:3080101:4010101:4020101:4030101:5010101:5020101:5060101|1|100#10|1050101:1080101:1090101:2020101:2070101:2090101:3040101:3060101:3090101:4050101:4070101:4090101:5040101:5050101:5090101|1|100#1|1030101:1070101:2040101:2060101:3050101:3070101:4040101:4060101:5030101:5070101|1|100 | R11: 54|1010101:1020101:1040101:2010101:2030101:2080101:3010101:3020101:3080101:4010101:4020101:4030101:5010101:5020101:5060101|1|100#14|1050101:1080101:1090101:2020101:2070101:2090101:3040101:3060101:3090101:4050101:4070101:4090101:5040101:5050101:5090101|1|100#1|1030101:1070101:2040101:2060101:3050101:3070101:4040101:4060101:5030101:5070101|1|100 | S11: 90|1010101:1020101:1040101:2010101:2030101:2080101:3010101:3020101:3080101:4010101:4020101:4030101:5010101:5020101:5060101|1|100#25|1050101:1080101:1090101:2020101:2070101:2090101:3040101:3060101:3090101:4050101:4070101:4090101:5040101:5050101:5090101|1|100#2|1030101:1070101:2040101:2060101:3050101:3070101:4040101:4060101:5030101:5070101|1|100 | T11: 0 | U11: 3 | V11: 1:7|2:2|3:0 | W11: 1:2:3:4:5 | X11: 1:12:26 | Y11: MapBingXue | Z11: 1 | AA11: 2 | AB11: =F11+AA11+Z11 -> 11 | AC11: =AB11+15 -> 26 | AD11: 250 | AE11: =AE10 -> 15 | AF11: =AF10 -> 15000 | AG11: =AG10 -> 28000 | AH11: =出怪成长!C9 -> 10 | AI11: =出怪成长!D9 -> 4#30001#1|8#30002#1|10#30001,30004#1 | AJ11: 1:3:1|1:5:1|2:9:1|2:13:1|3:18:1|3:23:1|4:28:1|4:33:1|1:14:1#2:14:1#3:14:1#4:14:1|1:18:1#2:18:1#3:18:1#4:18:1 | AK11: =出怪成长!E9 -> 1:10006,10007|2:10006,10010,10009|3:10020,10021,10023 | AL11: =出怪成长!F9 -> 5#1#0.9|8#2#1.4|10#3#1.7 | AM11: =每波成长!G12 -> 33#9#6 | AN11: 1:11:50#2:25:500#3:26:500|1:11:50#2:25:500#4:50011 | AO11: 0 | AP11: 200#40001:2;40002:1|500#40002:3 | AQ11: 2 | AR11: 8 | AS11: 1:40021#1|2:40022#1 | AT11: 1:90003#1|2:90002#1 | AU11: 406:-323 | AV11: 1+1+1+1+5+3|1+1+1+1+9+3|1+1+1+1+9+4+7|51 | AW11: 301:302:306:307:311:312:313:317:321:323:328 | AX11: 3 | AY11: 700:12:30|100:11:2|100:1:1|10:4:1 | AZ11: 北方之地，这里远离纷争 | BA11: 为了解决亡灵之乱，我们计划卧薪尝胆，去增强自己的实力。 | BB11: 0 | BC11: 1.2 | BD11: 16 | BE11: 0 | BF11: 1102+2.8 | BG11: 0 | BH11: 3 | BI11: MapBingXue8 | BJ11: MapBingXue
A12: 19 | B12: 0 | C12: 贪婪之祸9 | D12: img_shenyuan1 | E12: =A13 -> 20 | F12: 9 | G12: =F12+20 -> 29 | H12: 20 | I12: 20 | J12: 20 | K12: 460 | L12: 920 | M12: 1380 | N12: 1:12:140#1:12:140#1:12:2000|1:13:6#1:11:100|1:10000001:156|1:10000002:46|1:10000003:3 | O12: 1:12:210#1:12:1500#1:12:3000|1:13:6#1:11:150|1:10000001:234|1:10000002:68|1:10000003:6 | P12: 1:12:350#1:12:2000#1:12:4000|1:13:6#1:11:200|1:10000001:312|1:10000002:93|1:10000003:7 | Q12: 42|1010101:1020101:1040101:2010101:2030101:2080101:3010101:3020101:3080101:4010101:4020101:4030101:5010101:5020101:5060101|1|100#10|1050101:1080101:1090101:2020101:2070101:2090101:3040101:3060101:3090101:4050101:4070101:4090101:5040101:5050101:5090101|1|100#1|1030101:1070101:2040101:2060101:3050101:3070101:4040101:4060101:5030101:5070101|1|100 | R12: 60|1010101:1020101:1040101:2010101:2030101:2080101:3010101:3020101:3080101:4010101:4020101:4030101:5010101:5020101:5060101|1|100#14|1050101:1080101:1090101:2020101:2070101:2090101:3040101:3060101:3090101:4050101:4070101:4090101:5040101:5050101:5090101|1|100#1|1030101:1070101:2040101:2060101:3050101:3070101:4040101:4060101:5030101:5070101|1|100 | S12: 102|1010101:1020101:1040101:2010101:2030101:2080101:3010101:3020101:3080101:4010101:4020101:4030101:5010101:5020101:5060101|1|100#25|1050101:1080101:1090101:2020101:2070101:2090101:3040101:3060101:3090101:4050101:4070101:4090101:5040101:5050101:5090101|1|100#2|1030101:1070101:2040101:2060101:3050101:3070101:4040101:4060101:5030101:5070101|1|100 | T12: 0 | U12: 3 | V12: 1:8|2:2|3:0 | W12: 1:2:3:4:5 | X12: 1:12:28 | Y12: MapBingXue | Z12: 2 | AA12: =AA4+2 -> 2 | AB12: =F12+AA12+Z12 -> 13 | AC12: =AB12+15 -> 28 | AD12: 250 | AE12: =AE4+1 -> 16 | AF12: =AF11 -> 15000 | AG12: =AG11 -> 28000 | AH12: =出怪成长!C10 -> 8 | AI12: =出怪成长!D10 -> 3#30001#1|6#30002#1|8#30001,30004#1 | AJ12: =出怪数量!Z11 -> 1:2:1|1:4:1|2:8:1|2:13:1|1:19:1|2:25:1|1:31:1|2:37:1 | AK12: =出怪成长!E10 -> 1:10006,10010|2:10020,10021,10023|3:10020,10021,10023 | AL12: =出怪成长!F10 -> 3#1#0.9|6#2#1.4|8#3#1.7 | AM12: =每波成长!G13 -> 33#9#6 | AN12: 1:11:50#2:25:500|1:11:100#2:25:500#3:26:500 | AO12: 0 | AP12: 200#40001:2;40002:1|500#40002:3 | AQ12: 2 | AR12: 9 | AS12: 1:40021#1|2:40022#1 | AT12: 1:90001#1|2:90003#1 | AU12: -793:-246 | AV12: 1+1+1+1+15+3|1+1+1+1+9+3|1+1+1+1+4+9|51 | AW12: 0 | AX12: 3 | AY12: 700:12:30|100:11:2|90:1:1|10:4:1 | AZ12: 与北方之地接壤，兽人的领地 | BA12: 我们需要快速突破兽人部队。避免他们集结在一起。 | BB12: 0 | BC12: 2 | BD12: 20 | BE12: 0 | BF12: 3102+4.8 | BG12: 0 | BH12: 3 | BI12: MapBingXue9 | BJ12: MapCandy | BL12: 7 | BM12: 3102 | BN12: 3002 | BO12: 0
A13: 20 | B13: 0 | C13: 贪婪之祸10 | D13: img_shenyuan2 | E13: =A14 -> 21 | F13: 10 | G13: =F13+20 -> 30 | H13: 20 | I13: 20 | J13: 20 | K13: 520 | L13: 1040 | M13: 1560 | N13: 1:12:140#1:12:140#1:12:2200|1:13:6#1:11:100|1:10000001:168|1:10000002:50|1:10000003:4 | O13: 1:12:210#1:12:1650#1:12:3300|1:13:6#1:11:150|1:10000001:252|1:10000002:75|1:10000003:6 | P13: 1:12:350#1:12:2200#1:12:4400|1:13:6#1:11:200|1:10000001:336|1:10000002:100|1:10000003:7 | Q13: 42|1010101:1020101:1040101:2010101:2030101:2080101:3010101:3020101:3080101:4010101:4020101:4030101:5010101:5020101:5060101|1|100#10|1050101:1080101:1090101:2020101:2070101:2090101:3040101:3060101:3090101:4050101:4070101:4090101:5040101:5050101:5090101|1|100#1|1030101:1070101:2040101:2060101:3050101:3070101:4040101:4060101:5030101:5070101|1|100 | R13: 60|1010101:1020101:1040101:2010101:2030101:2080101:3010101:3020101:3080101:4010101:4020101:4030101:5010101:5020101:5060101|1|100#14|1050101:1080101:1090101:2020101:2070101:2090101:3040101:3060101:3090101:4050101:4070101:4090101:5040101:5050101:5090101|1|100#1|1030101:1070101:2040101:2060101:3050101:3070101:4040101:4060101:5030101:5070101|1|100 | S13: 102|1010101:1020101:1040101:2010101:2030101:2080101:3010101:3020101:3080101:4010101:4020101:4030101:5010101:5020101:5060101|1|100#25|1050101:1080101:1090101:2020101:2070101:2090101:3040101:3060101:3090101:4050101:4070101:4090101:5040101:5050101:5090101|1|100#2|1030101:1070101:2040101:2060101:3050101:3070101:4040101:4060101:5030101:5070101|1|100 | T13: 0 | U13: 3 | V13: 1:8|2:2|3:0 | W13: 1:2:3:4:5 | X13: 1:12:28 | Y13: MapBingXue | Z13: 2 | AA13: =AA5+2 -> 1 | AB13: =F13+AA13+Z13 -> 13 | AC13: =AB13+15 -> 28 | AD13: 250 | AE13: =AE5+1 -> 16 | AF13: =AF12 -> 15000 | AG13: =AG12 -> 28000 | AH13: =出怪成长!C11 -> 8 | AI13: =出怪成长!D11 -> 3#30001#1|6#30002#1|8#30001,30004#1 | AJ13: =出怪数量!Z12 -> 1:2:1|1:4:1|2:8:1|2:13:1|3:19:1|3:25:1|1:31:1|2:37:1 | AK13: =出怪成长!E11 -> 1:10020,10021|2:10020,10021,10023|3:10020,10021,10023 | AL13: =出怪成长!F11 -> 3#1#0.9|6#2#1.4|8#3#1.7 | AM13: =每波成长!G14 -> 31#8#5 | AN13: 1:11:50#2:25:500#3:26:500|1:11:50#2:25:500#4:50011 | AO13: 0 | AP13: 200#40001:2;40002:1|500#40002:3 | AQ13: 2 | AR13: 10 | AS13: 1:40021#1|2:40022#1 | AT13: 1:90003#1|2:90002#1 | AU13: -534:-321 | AV13: 1+1+1+1+3+9|1+1+1+1+3+15|1+1+1+1+9+4|52 | AW13: 0 | AX13: 3 | AY13: 700:12:30|100:11:2|90:1:1|10:4:1 | AZ13: 与北方之地接壤，兽人的领地 | BA13: 兽人先知的地盘，他们精通电系魔法。 | BB13: 0 | BC13: 2.2 | BD13: 22 | BE13: 9002+2.5 | BF13: 3103+4.4 | BG13: 0 | BH13: 3 | BI13: MapBingXue10 | BJ13: =BJ12 -> MapCandy | BL13: 8 | BM13: 3103 | BN13: 3002 | BO13: 3003 | BR13: |3:148:1
A14: 21 | B14: 0 | C14: 贪婪之祸11 | D14: img_shenyuan3 | E14: =A15 -> 22 | F14: 11 | G14: =F14+20 -> 31 | H14: 20 | I14: 20 | J14: 20 | K14: 580 | L14: 1160 | M14: 1740 | N14: 1:12:150#1:12:150#1:12:2400|1:13:6#1:11:100|1:10000001:180|1:10000002:54|1:10000003:4 | O14: 1:12:225#1:12:1800#1:12:3600|1:13:6#1:11:150|1:10000001:270|1:10000002:79|1:10000003:6 | P14: 1:12:375#1:12:2400#1:12:4800|1:13:6#1:11:200|1:10000001:360|1:10000002:108|1:10000003:7 | Q14: 42|1010101:1020101:1040101:2010101:2030101:2080101:3010101:3020101:3080101:4010101:4020101:4030101:5010101:5020101:5060101|1|100#10|1050101:1080101:1090101:2020101:2070101:2090101:3040101:3060101:3090101:4050101:4070101:4090101:5040101:5050101:5090101|1|100#1|1030101:1070101:2040101:2060101:3050101:3070101:4040101:4060101:5030101:5070101|1|100 | R14: 60|1010101:1020101:1040101:2010101:2030101:2080101:3010101:3020101:3080101:4010101:4020101:4030101:5010101:5020101:5060101|1|100#14|1050101:1080101:1090101:2020101:2070101:2090101:3040101:3060101:3090101:4050101:4070101:4090101:5040101:5050101:5090101|1|100#1|1030101:1070101:2040101:2060101:3050101:3070101:4040101:4060101:5030101:5070101|1|100 | S14: 102|1010101:1020101:1040101:2010101:2030101:2080101:3010101:3020101:3080101:4010101:4020101:4030101:5010101:5020101:5060101|1|100#25|1050101:1080101:1090101:2020101:2070101:2090101:3040101:3060101:3090101:4050101:4070101:4090101:5040101:5050101:5090101|1|100#2|1030101:1070101:2040101:2060101:3050101:3070101:4040101:4060101:5030101:5070101|1|100 | T14: 0 | U14: 3 | V14: 1:8|2:2|3:0 | W14: 1:2:3:4:5 | X14: 1:12:30 | Y14: MapBingXue | Z14: 2 | AA14: =AA6+2 -> 2 | AB14: =F14+AA14+Z14 -> 15 | AC14: =AB14+15 -> 30 | AD14: 250 | AE14: =AE6+1 -> 16 | AF14: =AF13 -> 15000 | AG14: =AG13 -> 28000 | AH14: =出怪成长!C12 -> 9 | AI14: =出怪成长!D12 -> 3#30001#1|7#30002#1|9#30001,30004#1 | AJ14: =出怪数量!Z13 -> 1:2:1|1:4:1|2:8:1|2:13:1|3:19:1|3:25:1|1:31:1|2:37:1|3:43:1 | AK14: =出怪成长!E12 -> 1:10020,10021|2:10020,10021,10023|3:10020,10021,10023 | AL14: =出怪成长!F12 -> 4#1#0.9|7#2#1.4|9#3#1.7 | AM14: =每波成长!G15 -> 33#9#6 | AN14: 1:11:50#2:25:500|1:11:100#2:25:500#3:26:500 | AO14: 0 | AP14: 200#40001:2;40002:1|500#40002:3 | AQ14: 2 | AR14: 11 | AS14: 1:40021#1|2:40022#1 | AT14: 1:90001#1|2:90003#1 | AU14: -286:-246 | AV14: 1+1+1+1+22+3+9|1+1+1+1+4+19+9|1+1+1+1+8+4+9|55 | AW14: 0 | AX14: 3 | AY14: 700:12:30|100:11:2|90:1:1|10:4:1 | AZ14: 与北方之地接壤，兽人的领地 | BA14: 战斗中，我们营救了一个贵族，需要帮助他到达安全地点。 | BB14: 0 | BC14: 2.4 | BD14: 24 | BE14: 9002+3 | BF14: 3104+3.6 | BG14: 0 | BH14: 3 | BI14: MapBingXue11 | BJ14: =BJ13 -> MapCandy | BL14: 9 | BM14: 3104 | BN14: 3002 | BO14: 0
A15: 22 | B15: 0 | C15: 贪婪之祸12 | D15: img_shenyuan4 | E15: =A16 -> 23 | F15: 12 | G15: =F15+20 -> 32 | H15: 20 | I15: 20 | J15: 20 | K15: 640 | L15: 1280 | M15: 1920 | N15: 1:12:150#1:12:150#1:12:2600|1:13:6#1:11:100|1:10000001:192|1:10000002:57|1:10000003:6 | O15: 1:12:225#1:12:1950#1:12:3900|1:13:6#1:11:150|1:10000001:288|1:10000002:86|1:10000003:7 | P15: 1:12:375#1:12:2600#1:12:5200|1:13:6#1:11:200|1:10000001:384|1:10000002:115|1:10000003:8 | Q15: 42|1010101:1020101:1040101:2010101:2030101:2080101:3010101:3020101:3080101:4010101:4020101:4030101:5010101:5020101:5060101|1|100#10|1050101:1080101:1090101:2020101:2070101:2090101:3040101:3060101:3090101:4050101:4070101:4090101:5040101:5050101:5090101|1|100#1|1030101:1070101:2040101:2060101:3050101:3070101:4040101:4060101:5030101:5070101|1|100 | R15: 60|1010101:1020101:1040101:2010101:2030101:2080101:3010101:3020101:3080101:4010101:4020101:4030101:5010101:5020101:5060101|1|100#14|1050101:1080101:1090101:2020101:2070101:2090101:3040101:3060101:3090101:4050101:4070101:4090101:5040101:5050101:5090101|1|100#1|1030101:1070101:2040101:2060101:3050101:3070101:4040101:4060101:5030101:5070101|1|100 | S15: 102|1010101:1020101:1040101:2010101:2030101:2080101:3010101:3020101:3080101:4010101:4020101:4030101:5010101:5020101:5060101|1|100#25|1050101:1080101:1090101:2020101:2070101:2090101:3040101:3060101:3090101:4050101:4070101:4090101:5040101:5050101:5090101|1|100#2|1030101:1070101:2040101:2060101:3050101:3070101:4040101:4060101:5030101:5070101|1|100 | T15: 0 | U15: 3 | V15: 1:8|2:2|3:0 | W15: 1:2:3:4:5 | X15: 1:12:30 | Y15: MapBingXue | Z15: 2 | AA15: =AA7+2 -> 3 | AB15: =F15+AA15+Z15 -> 17 | AC15: =AB15+15 -> 32 | AD15: 250 | AE15: =AE7+1 -> 16 | AF15: =AF14 -> 15000 | AG15: =AG14 -> 28000 | AH15: =出怪成长!C13 -> 10 | AI15: =出怪成长!D13 -> 4#30001#1|8#30002#1|10#30001,30004#1 | AJ15: =出怪数量!Z14 -> 1:2:1|1:4:1|2:8:1|2:13:1|3:19:1|3:25:1|1:31:1|2:37:1|3:43:1|3:49:1 | AK15: =出怪成长!E13 -> 1:10020,10021|2:10020,10021,10023|3:10025,10026,10028 | AL15: =出怪成长!F13 -> 5#1#1|8#2#1.6|10#3#2 | AM15: =每波成长!G16 -> 34#9#6 | AN15: 1:11:50#2:25:500#3:26:500|1:11:50#2:25:500#4:50011 | AO15: 0 | AP15: 200#40001:2;40002:1|500#40002:3 | AQ15: 2 | AR15: 12 | AS15: 1:40021#1|2:40022#1 | AT15: 1:90003#1|2:90002#1 | AU15: -147:-60 | AV15: 1+1+1+1+3+9|1+1+1+1+22+3+7|1+1+1+1+4+9|53 | AW15: 0 | AX15: 3 | AY15: 700:12:30|100:11:2|90:1:1|10:4:1 | AZ15: 与北方之地接壤，兽人的领地 | BA15: 帮助贵族后，他告诉我们前方的首领是一个兽族美女，值屈服于强大的人。 | BB15: 0 | BC15: 2.6 | BD15: 26 | BE15: 9002+3.5 | BF15: 3105+3.1 | BG15: 0 | BH15: 3 | BI15: MapBingXue12 | BJ15: =BJ14 -> MapCandy | BL15: 10 | BM15: 3105 | BN15: 3003 | BO15: 0 | BR15: |3:149:1
A16: 23 | B16: 0 | C16: 贪婪之祸13 | D16: img_shenyuan1 | E16: =A17 -> 24 | F16: 13 | G16: =F16+20 -> 33 | H16: 24 | I16: 24 | J16: 24 | K16: 700 | L16: 1400 | M16: 2100 | N16: 1:12:160#1:12:160#1:12:2800|1:13:6#1:11:100|1:10000001:204|1:10000002:61|1:10000003:6 | O16: 1:12:240#1:12:2100#1:12:4200|1:13:6#1:11:150|1:10000001:306|1:10000002:90|1:10000003:7 | P16: 1:12:400#1:12:2800#1:12:5600|1:13:6#1:11:200|1:10000001:408|1:10000002:122|1:10000003:8 | Q16: 48|1010101:1020101:1040101:2010101:2030101:2080101:3010101:3020101:3080101:4010101:4020101:4030101:5010101:5020101:5060101|1|100#14|1050101:1080101:1090101:2020101:2070101:2090101:3040101:3060101:3090101:4050101:4070101:4090101:5040101:5050101:5090101|1|100#1|1030101:1070101:2040101:2060101:3050101:3070101:4040101:4060101:5030101:5070101|1|100 | R16: 72|1010101:1020101:1040101:2010101:2030101:2080101:3010101:3020101:3080101:4010101:4020101:4030101:5010101:5020101:5060101|1|100#21|1050101:1080101:1090101:2020101:2070101:2090101:3040101:3060101:3090101:4050101:4070101:4090101:5040101:5050101:5090101|1|100#1|1030101:1070101:2040101:2060101:3050101:3070101:4040101:4060101:5030101:5070101|1|100 | S16: 120|1010101:1020101:1040101:2010101:2030101:2080101:3010101:3020101:3080101:4010101:4020101:4030101:5010101:5020101:5060101|1|100#36|1050101:1080101:1090101:2020101:2070101:2090101:3040101:3060101:3090101:4050101:4070101:4090101:5040101:5050101:5090101|1|100#2|1030101:1070101:2040101:2060101:3050101:3070101:4040101:4060101:5030101:5070101|1|100 | T16: 0 | U16: 3 | V16: 1:9|2:2|3:0 | W16: 1:2:3:4:5 | X16: 1:12:32 | Y16: MapBingXue | Z16: 2 | AA16: =AA8+2 -> 1 | AB16: =F16+AA16+Z16 -> 16 | AC16: =AB16+15 -> 31 | AD16: 250 | AE16: =AE8+1 -> 16 | AF16: =AF15 -> 15000 | AG16: =AG15 -> 28000 | AH16: =出怪成长!C14 -> 9 | AI16: =出怪成长!D14 -> 3#30001#1|7#30002#1|9#30001,30004#1 | AJ16: =出怪数量!Z15 -> 1:3:1|1:5:1|2:9:1|2:14:1|3:20:1|3:26:1|1:32:1|2:38:1|3:44:1 | AK16: =出怪成长!E14 -> 1:10020,10021|2:10025,10026,10028|3:10025,10026,10028 | AL16: =出怪成长!F14 -> 4#1#1|7#2#1.6|9#3#2 | AM16: =每波成长!G17 -> 31#8#5 | AN16: 1:11:50#2:25:500|1:11:100#2:25:500#3:26:500 | AO16: 0 | AP16: 200#40001:2;40002:1|500#40002:3 | AQ16: 2 | AR16: 13 | AS16: 1:40021#1|2:40022#1 | AT16: 1:90001#1|2:90003#1 | AU16: 1:133 | AV16: 1+1+1+1+5+3+9|1+1+1+1+9+3+8|1+1+1+1+4+19|51 | AW16: 0 | AX16: 3 | AY16: 700:12:30|100:11:2|90:1:1|10:4:1 | AZ16: 与北方之地接壤，兽人的领地 | BA16: 这里兽族高机动部队。我们需要防止他们逃离。 | BB16: 0 | BC16: 2.7 | BD16: 27 | BE16: 0 | BF16: 3106+2.4 | BG16: 0 | BH16: 3 | BI16: MapBingXue13 | BJ16: =BJ15 -> MapCandy | BL16: 11 | BM16: 3106 | BN16: 3003 | BO16: 0
A17: 24 | B17: 0 | C17: 贪婪之祸14 | D17: img_shenyuan2 | E17: =A18 -> 25 | F17: 14 | G17: =F17+20 -> 34 | H17: 24 | I17: 24 | J17: 24 | K17: 760 | L17: 1520 | M17: 2280 | N17: 1:12:160#1:12:160#1:12:3000|1:13:6#1:11:100|1:10000001:216|1:10000002:64|1:10000003:7 | O17: 1:12:240#1:12:2250#1:12:4500|1:13:6#1:11:150|1:10000001:324|1:10000002:97|1:10000003:7 | P17: 1:12:400#1:12:3000#1:12:6000|1:13:6#1:11:200|1:10000001:432|1:10000002:129|1:10000003:8 | Q17: 48|1010101:1020101:1040101:2010101:2030101:2080101:3010101:3020101:3080101:4010101:4020101:4030101:5010101:5020101:5060101|1|100#14|1050101:1080101:1090101:2020101:2070101:2090101:3040101:3060101:3090101:4050101:4070101:4090101:5040101:5050101:5090101|1|100#2|1030101:1070101:2040101:2060101:3050101:3070101:4040101:4060101:5030101:5070101|1|100 | R17: 72|1010101:1020101:1040101:2010101:2030101:2080101:3010101:3020101:3080101:4010101:4020101:4030101:5010101:5020101:5060101|1|100#21|1050101:1080101:1090101:2020101:2070101:2090101:3040101:3060101:3090101:4050101:4070101:4090101:5040101:5050101:5090101|1|100#3|1030101:1070101:2040101:2060101:3050101:3070101:4040101:4060101:5030101:5070101|1|100 | S17: 120|1010101:1020101:1040101:2010101:2030101:2080101:3010101:3020101:3080101:4010101:4020101:4030101:5010101:5020101:5060101|1|100#36|1050101:1080101:1090101:2020101:2070101:2090101:3040101:3060101:3090101:4050101:4070101:4090101:5040101:5050101:5090101|1|100#6|1030101:1070101:2040101:2060101:3050101:3070101:4040101:4060101:5030101:5070101|1|100 | T17: 0 | U17: 3 | V17: 1:9|2:2|3:0 | W17: 1:2:3:4:5 | X17: 1:12:32 | Y17: MapBingXue | Z17: 2 | AA17: =AA9+2 -> 2 | AB17: =F17+AA17+Z17 -> 18 | AC17: =AB17+15 -> 33 | AD17: 250 | AE17: =AE9+1 -> 16 | AF17: =AF16 -> 15000 | AG17: =AG16 -> 28000 | AH17: =出怪成长!C15 -> 9 | AI17: =出怪成长!D15 -> 3#30001#1|7#30002#1|9#30001,30004#1 | AJ17: =出怪数量!Z16 -> 1:3:1|1:5:1|2:9:1|2:14:1|1:20:1|2:26:1|1:32:1|2:38:1|2:44:1 | AK17: =出怪成长!E15 -> 1:10025,10026|2:10025,10026,10028|3:10025,10026,10028 | AL17: =出怪成长!F15 -> 4#1#1|7#2#1.6|9#3#2 | AM17: =每波成长!G18 -> 33#9#6 | AN17: 1:11:50#2:25:500#3:26:500|1:11:50#2:25:500#4:50011 | AO17: 0 | AP17: 200#40001:2;40002:1|500#40002:3 | AQ17: 2 | AR17: 14 | AS17: 1:40021#1|2:40022#1 | AT17: 1:90003#1|2:90002#1 | AU17: 309:-74 | AV17: 1+1+1+1+3+9|1+1+1+1+19+5|1+1+1+1+4+9|52 | AW17: 0 | AX17: 3 | AY17: 700:12:30|100:11:2|90:1:1|10:4:1 | AZ17: 与北方之地接壤，兽人的领地 | BA17: 终于，我们来到了兽族大本营。兽族决战。 | BB17: 0 | BC17: 3 | BD17: 30 | BE17: 9002+4.5 | BF17: 3107+2.5 | BG17: 0 | BH17: 3 | BI17: MapBingXue14 | BJ17: =BJ16 -> MapCandy | BL17: 12 | BM17: 3107 | BN17: 3003 | BO17: 3004 | BR17: |3:158:1
A18: 25 | B18: 0 | C18: 贪婪之祸15 | D18: img_shenyuan3 | E18: =A19 -> 26 | F18: 15 | G18: =F18+20 -> 35 | H18: 24 | I18: 24 | J18: 24 | K18: 820 | L18: 1640 | M18: 2460 | N18: 1:12:170#1:12:170#1:12:3200|1:13:6#1:11:100|1:10000001:228|1:10000002:68|1:10000003:7 | O18: 1:12:255#1:12:2400#1:12:4800|1:13:6#1:11:150|1:10000001:342|1:10000002:100|1:10000003:8 | P18: 1:12:425#1:12:3200#1:12:6400|1:13:6#1:11:200|1:10000001:456|1:10000002:136|1:10000003:9 | Q18: 48|1010101:1020101:1040101:2010101:2030101:2080101:3010101:3020101:3080101:4010101:4020101:4030101:5010101:5020101:5060101|1|100#14|1050101:1080101:1090101:2020101:2070101:2090101:3040101:3060101:3090101:4050101:4070101:4090101:5040101:5050101:5090101|1|100#2|1030101:1070101:2040101:2060101:3050101:3070101:4040101:4060101:5030101:5070101|1|100 | R18: 72|1010101:1020101:1040101:2010101:2030101:2080101:3010101:3020101:3080101:4010101:4020101:4030101:5010101:5020101:5060101|1|100#21|1050101:1080101:1090101:2020101:2070101:2090101:3040101:3060101:3090101:4050101:4070101:4090101:5040101:5050101:5090101|1|100#3|1030101:1070101:2040101:2060101:3050101:3070101:4040101:4060101:5030101:5070101|1|100 | S18: 120|1010101:1020101:1040101:2010101:2030101:2080101:3010101:3020101:3080101:4010101:4020101:4030101:5010101:5020101:5060101|1|100#36|1050101:1080101:1090101:2020101:2070101:2090101:3040101:3060101:3090101:4050101:4070101:4090101:5040101:5050101:5090101|1|100#6|1030101:1070101:2040101:2060101:3050101:3070101:4040101:4060101:5030101:5070101|1|100 | T18: 0 | U18: 3 | V18: 1:9|2:2|3:0 | W18: 1:2:3:4:5 | X18: 1:12:34 | Y18: MapBingXue | Z18: 2 | AA18: =AA10+2 -> 3 | AB18: =F18+AA18+Z18 -> 20 | AC18: =AB18+15 -> 35 | AD18: 250 | AE18: =AE10+1 -> 16 | AF18: =AF17 -> 15000 | AG18: =AG17 -> 28000 | AH18: =出怪成长!C16 -> 9 | AI18: =出怪成长!D16 -> 3#30001#1|7#30002#1|9#30001,30004#1 | AJ18: =出怪数量!Z17 -> 1:3:1|1:5:1|2:9:1|2:14:1|3:20:1|3:26:1|1:32:1|2:38:1|1:44:1 | AK18: =出怪成长!E16 -> 1:10025,10026|2:10025,10026,10028|3:10030,10031,10032 | AL18: =出怪成长!F16 -> 4#1#1|7#2#1.6|9#3#2 | AM18: =每波成长!G19 -> 34#9#6 | AN18: 1:11:50#2:25:500#3:26:500|1:11:50#2:25:500#4:50011 | AO18: 0 | AP18: 200#40001:2;40002:1|500#40002:3 | AQ18: 2 | AR18: 15 | AS18: 1:40021#1|2:40022#1 | AT18: 1:90003#1|2:90002#1 | AU18: 550:0 | AV18: 1+1+1+1+5+3+9|1+1+1+1+9+3+8|1+1+1+1+4+19|51 | AW18: 0 | AX18: 3 | AY18: 700:12:30|100:11:2|90:1:1|10:4:1 | AZ18: 与北方之地接壤，兽人的领地 | BA18: 这里兽族高机动部队。我们需要防止他们逃离。 | BB18: 0 | BC18: 2.7 | BD18: 27 | BE18: 0 | BF18: 3106+2.4 | BG18: 0 | BH18: 3 | BI18: MapBingXue15 | BJ18: =BJ17 -> MapCandy | BL18: 11 | BM18: 3106 | BN18: 3003 | BO18: 0
A19: 26 | B19: 0 | C19: 贪婪之祸16 | D19: img_shenyuan4 | E19: =A20 -> 27 | F19: 16 | G19: =F19+20 -> 36 | H19: 24 | I19: 24 | J19: 24 | K19: 1100 | L19: 2200 | M19: 3300 | N19: 1:12:170#1:12:170#1:12:3400|1:13:6#1:11:100|1:10000001:240|1:10000002:72|1:10000003:8 | O19: 1:12:255#1:12:2550#1:12:5100|1:13:6#1:11:150|1:10000001:360|1:10000002:108|1:10000003:9 | P19: 1:12:425#1:12:3400#1:12:6800|1:13:6#1:11:200|1:10000001:480|1:10000002:144|1:10000003:12 | Q19: 48|1010101:1020101:1040101:2010101:2030101:2080101:3010101:3020101:3080101:4010101:4020101:4030101:5010101:5020101:5060101|1|100#14|1050101:1080101:1090101:2020101:2070101:2090101:3040101:3060101:3090101:4050101:4070101:4090101:5040101:5050101:5090101|1|100#2|1030101:1070101:2040101:2060101:3050101:3070101:4040101:4060101:5030101:5070101|1|100 | R19: 72|1010101:1020101:1040101:2010101:2030101:2080101:3010101:3020101:3080101:4010101:4020101:4030101:5010101:5020101:5060101|1|100#21|1050101:1080101:1090101:2020101:2070101:2090101:3040101:3060101:3090101:4050101:4070101:4090101:5040101:5050101:5090101|1|100#3|1030101:1070101:2040101:2060101:3050101:3070101:4040101:4060101:5030101:5070101|1|100 | S19: 120|1010101:1020101:1040101:2010101:2030101:2080101:3010101:3020101:3080101:4010101:4020101:4030101:5010101:5020101:5060101|1|100#36|1050101:1080101:1090101:2020101:2070101:2090101:3040101:3060101:3090101:4050101:4070101:4090101:5040101:5050101:5090101|1|100#6|1030101:1070101:2040101:2060101:3050101:3070101:4040101:4060101:5030101:5070101|1|100 | T19: 0 | U19: 3 | V19: 1:9|2:2|3:0 | W19: 1:2:3:4:5 | X19: 1:12:34 | Y19: MapBingXue | Z19: 2 | AA19: =AA11+2 -> 4 | AB19: =F19+AA19+Z19 -> 22 | AC19: =AB19+15 -> 37 | AD19: 250 | AE19: =AE11+1 -> 16 | AF19: =AF18 -> 15000 | AG19: =AG18 -> 28000 | AH19: =出怪成长!C17 -> 10 | AI19: =出怪成长!D17 -> 4#30001#1|8#30002#1|10#30001,30004#1 | AJ19: =出怪数量!Z18 -> 1:3:1|1:5:1|2:9:1|2:14:1|3:20:1|3:26:1|1:32:1|2:38:1|1:44:1|2:50:1 | AK19: =出怪成长!E17 -> 1:10025,10026|2:10030,10031,10032|3:10031,10028,10034 | AL19: =出怪成长!F17 -> 5#1#1.1|8#2#1.8|10#3#2.3 | AM19: =每波成长!G20 -> 36#10#7 | AN19: 1:11:50#2:25:500#3:26:500|1:11:50#2:25:500#4:50011 | AO19: 0 | AP19: 200#40001:2;40002:1|500#40002:3 | AQ19: 2 | AR19: 16 | AS19: 1:40021#1|2:40022#1 | AT19: 1:90003#1|2:90002#1 | AU19: 433:192 | AV19: 1+1+1+1+3+9|1+1+1+1+19+5|1+1+1+1+4+9|52 | AW19: 0 | AX19: 3 | AY19: 700:12:30|100:11:2|90:1:1|10:4:1 | AZ19: 与北方之地接壤，兽人的领地 | BA19: 终于，我们来到了兽族大本营。兽族决战。 | BB19: 0 | BC19: 3 | BD19: 30 | BE19: 9002+4.5 | BF19: 3107+2.5 | BG19: 0 | BH19: 3 | BI19: MapBingXue16 | BJ19: =BJ18 -> MapCandy | BL19: 12 | BM19: 3107 | BN19: 3003 | BO19: 3004 | BR19: |3:158:1
A20: 27 | B20: 0 | C20: 贪婪之祸17 | D20: img_shenyuan1 | E20: =A21 -> 28 | F20: 17 | G20: =F20+20 -> 37 | H20: 28 | I20: 28 | J20: 28 | K20: 1300 | L20: 2600 | M20: 3900 | N20: 1:12:180#1:12:180#1:12:3600|1:13:6#1:11:100|1:10000001:252|1:10000002:75|1:10000003:8 | O20: 1:12:270#1:12:2700#1:12:5400|1:13:6#1:11:150|1:10000001:378|1:10000002:111|1:10000003:9 | P20: 1:12:450#1:12:3600#1:12:7200|1:13:6#1:11:200|1:10000001:504|1:10000002:151|1:10000003:12 | Q20: 54|1010101:1020101:1040101:2010101:2030101:2080101:3010101:3020101:3080101:4010101:4020101:4030101:5010101:5020101:5060101|1|100#14|1050101:1080101:1090101:2020101:2070101:2090101:3040101:3060101:3090101:4050101:4070101:4090101:5040101:5050101:5090101|1|100#2|1030101:1070101:2040101:2060101:3050101:3070101:4040101:4060101:5030101:5070101|1|100 | R20: 78|1010101:1020101:1040101:2010101:2030101:2080101:3010101:3020101:3080101:4010101:4020101:4030101:5010101:5020101:5060101|1|100#21|1050101:1080101:1090101:2020101:2070101:2090101:3040101:3060101:3090101:4050101:4070101:4090101:5040101:5050101:5090101|1|100#3|1030101:1070101:2040101:2060101:3050101:3070101:4040101:4060101:5030101:5070101|1|100 | S20: 132|1010101:1020101:1040101:2010101:2030101:2080101:3010101:3020101:3080101:4010101:4020101:4030101:5010101:5020101:5060101|1|100#36|1050101:1080101:1090101:2020101:2070101:2090101:3040101:3060101:3090101:4050101:4070101:4090101:5040101:5050101:5090101|1|100#6|1030101:1070101:2040101:2060101:3050101:3070101:4040101:4060101:5030101:5070101|1|100 | T20: 0 | U20: 3 | V20: 1:10|2:2|3:0 | W20: 1:2:3:4:5 | X20: 1:12:36 | Y20: MapBingXue | Z20: 3 | AA20: =AA12+2 -> 4 | AB20: =F20+AA20+Z20 -> 24 | AC20: =AB20+15 -> 39 | AD20: 250 | AE20: =AE12+1 -> 17 | AF20: =AF19 -> 15000 | AG20: =AG19 -> 28000 | AH20: =出怪成长!C18 -> 8 | AI20: =出怪成长!D18 -> 3#30001#1|6#30002#1|8#30001,30004#1 | AJ20: =出怪数量!Z19 -> 1:2:1|1:5:1|2:10:1|2:5:1#2:5:1#3:5:1|3:4:1#2:4:1#3:4:1|3:5:1#2:5:1#3:5:1|1:6:1#2:6:1#3:6:1|2:7:1#2:7:1#3:7:1 | AK20: =出怪成长!E18 -> 1:10030,10031|2:10031,10028,10034|3:10031,10028,10027 | AL20: =出怪成长!F18 -> 3#1#1.1|6#2#1.8|8#3#2.3 | AM20: =每波成长!G21 -> 36#10#7 | AN20: 1:11:50#2:25:500|1:11:100#2:25:500#3:26:500 | AO20: 0 | AP20: 200#40001:2;40002:1|500#40002:3 | AQ20: 2 | AR20: 17 | AS20: 1:40021#1|2:40022#1 | AT20: 1:90001#1|2:90003#1 | AU20: -661:276 | AV20: 1+1+1+1+1+20+3+8+22|1+1+1+1+1+9|1+1+1+1+1+15+4+9|51 | AW20: 0 | AX20: 3 | AY20: 700:12:30|100:11:2|80:1:1|9:4:1 | AZ20: 守护家园，抵御精灵的阴谋 | BA20: 限时战争，规定时间内。打败西城领主 | BB20: 0 | BC20: 4 | BD20: 40 | BE20: 0 | BF20: 2102+9.6 | BG20: 0 | BH20: 3 | BI20: MapBingXue17 | BJ20: MapSenLin | BL20: 13 | BM20: 2102 | BN20: 2003 | BO20: 0
A21: 28 | B21: 0 | C21: 贪婪之祸18 | D21: img_shenyuan2 | E21: =A22 -> 29 | F21: 18 | G21: =F21+20 -> 38 | H21: 28 | I21: 28 | J21: 28 | K21: 1450 | L21: 2900 | M21: 4350 | N21: 1:12:180#1:12:180#1:12:3800|1:13:6#1:11:100|1:10000001:264|1:10000002:79|1:10000003:9 | O21: 1:12:270#1:12:2850#1:12:5700|1:13:6#1:11:150|1:10000001:396|1:10000002:118|1:10000003:10 | P21: 1:12:450#1:12:3800#1:12:7600|1:13:6#1:11:200|1:10000001:528|1:10000002:158|1:10000003:13 | Q21: 54|1010101:1020101:1040101:2010101:2030101:2080101:3010101:3020101:3080101:4010101:4020101:4030101:5010101:5020101:5060101|1|100#14|1050101:1080101:1090101:2020101:2070101:2090101:3040101:3060101:3090101:4050101:4070101:4090101:5040101:5050101:5090101|1|100#2|1030101:1070101:2040101:2060101:3050101:3070101:4040101:4060101:5030101:5070101|1|100 | R21: 78|1010101:1020101:1040101:2010101:2030101:2080101:3010101:3020101:3080101:4010101:4020101:4030101:5010101:5020101:5060101|1|100#21|1050101:1080101:1090101:2020101:2070101:2090101:3040101:3060101:3090101:4050101:4070101:4090101:5040101:5050101:5090101|1|100#3|1030101:1070101:2040101:2060101:3050101:3070101:4040101:4060101:5030101:5070101|1|100 | S21: 132|1010101:1020101:1040101:2010101:2030101:2080101:3010101:3020101:3080101:4010101:4020101:4030101:5010101:5020101:5060101|1|100#36|1050101:1080101:1090101:2020101:2070101:2090101:3040101:3060101:3090101:4050101:4070101:4090101:5040101:5050101:5090101|1|100#6|1030101:1070101:2040101:2060101:3050101:3070101:4040101:4060101:5030101:5070101|1|100 | T21: 0 | U21: 3 | V21: 1:10|2:2|3:0 | W21: 1:2:3:4:5 | X21: 1:12:36 | Y21: MapBingXue | Z21: 3 | AA21: =AA13+2 -> 3 | AB21: =F21+AA21+Z21 -> 24 | AC21: =AB21+15 -> 39 | AD21: 250 | AE21: =AE13+1 -> 17 | AF21: =AF20 -> 15000 | AG21: =AG20 -> 28000 | AH21: =出怪成长!C19 -> 8 | AI21: =出怪成长!D19 -> 3#30001#1|6#30002#1|8#30001,30004#1 | AJ21: =出怪数量!Z20 -> 1:2:1|1:5:1|2:10:1|2:5:1#2:5:1#3:5:1|3:4:1#2:4:1#3:4:1|3:5:1#2:5:1#3:5:1|1:6:1#2:6:1#3:6:1|2:7:1#2:7:1#3:7:1 | AK21: =出怪成长!E19 -> 1:10031,10028|2:10031,10028,10027|3:10031,10028,10027 | AL21: =出怪成长!F19 -> 3#1#1.1|6#2#1.8|8#3#2.3 | AM21: =每波成长!G22 -> 34#9#6 | AN21: 1:11:50#2:25:500#3:26:500|1:11:50#2:25:500#4:50011 | AO21: 0 | AP21: 200#40001:2;40002:1|500#40002:3 | AQ21: 2 | AR21: 18 | AS21: 1:40021#1|2:40022#1 | AT21: 1:90003#1|2:90002#1 | AU21: -327:151 | AV21: 1+1+1+1+1+8+9|1+1+1+1+1+20+15+4+22|1+1+1+1+1+10+9+4+8|52 | AW21: 0 | AX21: 3 | AY21: 700:12:30|100:11:2|80:1:1|9:4:1 | AZ21: 守护家园，抵御精灵的阴谋 | BA21: 限时战争，规定时间内，打败侯恩伯爵 | BB21: 0 | BC21: 5 | BD21: 50 | BE21: 9001+6 | BF21: 2103+10 | BG21: 0 | BH21: 3 | BI21: MapBingXue18 | BJ21: =BJ20 -> MapSenLin | BL21: 14 | BM21: 2103 | BN21: 2003 | BO21: 2004 | BR21: |3:170:1
A22: 29 | B22: 0 | C22: 贪婪之祸19 | D22: img_shenyuan3 | E22: =A23 -> 30 | F22: 19 | G22: =F22+20 -> 39 | H22: 28 | I22: 28 | J22: 28 | K22: 1570 | L22: 3140 | M22: 4710 | N22: 1:12:190#1:12:190#1:12:4000|1:13:6#1:11:100|1:10000001:276|1:10000002:82|1:10000003:9 | O22: 1:12:285#1:12:3000#1:12:6000|1:13:6#1:11:150|1:10000001:414|1:10000002:122|1:10000003:10 | P22: 1:12:475#1:12:4000#1:12:8000|1:13:6#1:11:200|1:10000001:552|1:10000002:165|1:10000003:13 | Q22: 54|1010101:1020101:1040101:2010101:2030101:2080101:3010101:3020101:3080101:4010101:4020101:4030101:5010101:5020101:5060101|1|100#18|1050101:1080101:1090101:2020101:2070101:2090101:3040101:3060101:3090101:4050101:4070101:4090101:5040101:5050101:5090101|1|100#2|1030101:1070101:2040101:2060101:3050101:3070101:4040101:4060101:5030101:5070101|1|100 | R22: 78|1010101:1020101:1040101:2010101:2030101:2080101:3010101:3020101:3080101:4010101:4020101:4030101:5010101:5020101:5060101|1|100#25|1050101:1080101:1090101:2020101:2070101:2090101:3040101:3060101:3090101:4050101:4070101:4090101:5040101:5050101:5090101|1|100#3|1030101:1070101:2040101:2060101:3050101:3070101:4040101:4060101:5030101:5070101|1|100 | S22: 132|1010101:1020101:1040101:2010101:2030101:2080101:3010101:3020101:3080101:4010101:4020101:4030101:5010101:5020101:5060101|1|100#43|1050101:1080101:1090101:2020101:2070101:2090101:3040101:3060101:3090101:4050101:4070101:4090101:5040101:5050101:5090101|1|100#6|1030101:1070101:2040101:2060101:3050101:3070101:4040101:4060101:5030101:5070101|1|100 | T22: 0 | U22: 3 | V22: 1:10|2:3|3:0 | W22: 1:2:3:4:5 | X22: 1:12:38 | Y22: MapBingXue | Z22: 3 | AA22: =AA14+2 -> 4 | AB22: =F22+AA22+Z22 -> 26 | AC22: =AB22+15 -> 41 | AD22: 250 | AE22: =AE14+1 -> 17 | AF22: =AF21 -> 15000 | AG22: =AG21 -> 28000 | AH22: =出怪成长!C20 -> 8 | AI22: =出怪成长!D20 -> 3#30001#1|6#30002#1|8#30001,30004#1 | AJ22: =出怪数量!Z21 -> 1:2:1|1:5:1|2:10:1|2:5:1#2:5:1#3:5:1|3:4:1#2:4:1#3:4:1|3:5:1#2:5:1#3:5:1|1:6:1#2:6:1#3:6:1|2:7:1#2:7:1#3:7:1 | AK22: =出怪成长!E20 -> 1:10031,10028|2:10031,10028,10027|3:10037,10038,10029 | AL22: =出怪成长!F20 -> 3#1#1.1|6#2#1.8|8#3#2.3 | AM22: =每波成长!G23 -> 36#10#7 | AN22: 1:11:50#2:25:500|1:11:100#2:25:500#3:26:500 | AO22: 0 | AP22: 200#40001:2;40002:1|500#40002:3 | AQ22: 2 | AR22: 19 | AS22: 1:40021#1|2:40022#1 | AT22: 1:90001#1|2:90003#1 | AU22: -344:-140 | AV22: 1+1+1+1+1+15+3+9|1+1+1+1+1+4+19+9|1+1+1+1+1+3+4+9|55 | AW22: 0 | AX22: 3 | AY22: 700:12:30|100:11:2|80:1:1|9:4:1 | AZ22: 守护家园，抵御精灵的阴谋 | BA22: 护送林德公爵 | BB22: 0 | BC22: 6 | BD22: 60 | BE22: 9002+7 | BF22: 2104+9 | BG22: 0 | BH22: 3 | BI22: MapBingXue19 | BJ22: =BJ21 -> MapSenLin | BL22: 15 | BM22: 2104 | BN22: 2003 | BO22: 0
A23: 30 | B23: 0 | C23: 贪婪之祸20 | D23: img_shenyuan4 | E23: =A24 -> 31 | F23: 20 | G23: =F23+20 -> 40 | H23: 28 | I23: 28 | J23: 28 | K23: 1780 | L23: 3560 | M23: 5340 | N23: 1:12:190#1:12:190#1:12:4200|1:13:6#1:11:100|1:10000001:288|1:10000002:86|1:10000003:10 | O23: 1:12:285#1:12:3150#1:12:6300|1:13:6#1:11:150|1:10000001:432|1:10000002:129|1:10000003:10 | P23: 1:12:475#1:12:4200#1:12:8400|1:13:6#1:11:200|1:10000001:576|1:10000002:172|1:10000003:13 | Q23: 54|1010101:1020101:1040101:2010101:2030101:2080101:3010101:3020101:3080101:4010101:4020101:4030101:5010101:5020101:5060101|1|100#18|1050101:1080101:1090101:2020101:2070101:2090101:3040101:3060101:3090101:4050101:4070101:4090101:5040101:5050101:5090101|1|100#2|1030101:1070101:2040101:2060101:3050101:3070101:4040101:4060101:5030101:5070101|1|100 | R23: 78|1010101:1020101:1040101:2010101:2030101:2080101:3010101:3020101:3080101:4010101:4020101:4030101:5010101:5020101:5060101|1|100#25|1050101:1080101:1090101:2020101:2070101:2090101:3040101:3060101:3090101:4050101:4070101:4090101:5040101:5050101:5090101|1|100#3|1030101:1070101:2040101:2060101:3050101:3070101:4040101:4060101:5030101:5070101|1|100 | S23: 132|1010101:1020101:1040101:2010101:2030101:2080101:3010101:3020101:3080101:4010101:4020101:4030101:5010101:5020101:5060101|1|100#43|1050101:1080101:1090101:2020101:2070101:2090101:3040101:3060101:3090101:4050101:4070101:4090101:5040101:5050101:5090101|1|100#6|1030101:1070101:2040101:2060101:3050101:3070101:4040101:4060101:5030101:5070101|1|100 | T23: 0 | U23: 3 | V23: 1:10|2:3|3:0 | W23: 1:2:3:4:5 | X23: 1:12:38 | Y23: MapBingXue | Z23: 3 | AA23: =AA15+2 -> 5 | AB23: =F23+AA23+Z23 -> 28 | AC23: =AB23+15 -> 43 | AD23: 250 | AE23: =AE15+1 -> 17 | AF23: =AF22 -> 15000 | AG23: =AG22 -> 28000 | AH23: =出怪成长!C21 -> 9 | AI23: =出怪成长!D21 -> 3#30001#1|7#30002#1|9#30001,30004#1 | AJ23: =出怪数量!Z22 -> 1:2:1|1:5:1|2:10:1|2:5:1#2:5:1#3:5:2|3:4:2#2:4:1#3:4:2|3:5:2#2:5:1#3:5:2|1:6:1#2:6:1#3:6:2|2:7:1#2:7:1#3:7:2|1:10:1#2:10:1#3:10:2 | AK23: =出怪成长!E21 -> 1:10031,10028|2:10037,10038,10029|3:10037,10038,10029 | AL23: =出怪成长!F21 -> 4#1#1.2|7#2#2|9#3#2.6 | AM23: =每波成长!G24 -> 37#10#7 | AN23: 1:11:50#2:25:500#3:26:500|1:11:50#2:25:500#4:50011 | AO23: 0 | AP23: 200#40001:2;40002:1|500#40002:3 | AQ23: 2 | AR23: 20 | AS23: 1:40021#1|2:40022#1 | AT23: 1:90003#1|2:90002#1 | AU23: -609:-288 | AV23: 1+1+1+1+1+8+9|1+1+1+1+1+20+15+4|1+1+1+1+1+9+4+8|53 | AW23: 0 | AX23: 3 | AY23: 700:12:30|100:11:2|80:1:1|9:4:1 | AZ23: 守护家园，抵御精灵的阴谋 | BA23: 守住城池 | BB23: 0 | BC23: 7 | BD23: 70 | BE23: 9001+8 | BF23: 2105+8.4 | BG23: 0 | BH23: 3 | BI23: MapBingXue20 | BJ23: =BJ22 -> MapSenLin | BL23: 16 | BM23: 2105 | BN23: 2003 | BO23: 0 | BR23: |3:169:1
A24: 31 | B24: 0 | C24: 贪婪之祸21 | D24: img_shenyuan1 | E24: =A25 -> 32 | F24: 21 | G24: =F24+20 -> 41 | H24: 32 | I24: 32 | J24: 32 | K24: 1980 | L24: 3960 | M24: 5940 | N24: 1:12:200#1:12:200#1:12:4400|1:13:6#1:11:100|1:10000001:300|1:10000002:90|1:10000003:10 | O24: 1:12:300#1:12:3300#1:12:6600|1:13:6#1:11:150|1:10000001:450|1:10000002:133|1:10000003:12 | P24: 1:12:500#1:12:4400#1:12:8800|1:13:6#1:11:200|1:10000001:600|1:10000002:180|1:10000003:14 | Q24: 60|1010101:1020101:1040101:2010101:2030101:2080101:3010101:3020101:3080101:4010101:4020101:4030101:5010101:5020101:5060101|1|100#18|1050101:1080101:1090101:2020101:2070101:2090101:3040101:3060101:3090101:4050101:4070101:4090101:5040101:5050101:5090101|1|100#2|1030101:1070101:2040101:2060101:3050101:3070101:4040101:4060101:5030101:5070101|1|100 | R24: 90|1010101:1020101:1040101:2010101:2030101:2080101:3010101:3020101:3080101:4010101:4020101:4030101:5010101:5020101:5060101|1|100#25|1050101:1080101:1090101:2020101:2070101:2090101:3040101:3060101:3090101:4050101:4070101:4090101:5040101:5050101:5090101|1|100#3|1030101:1070101:2040101:2060101:3050101:3070101:4040101:4060101:5030101:5070101|1|100 | S24: 150|1010101:1020101:1040101:2010101:2030101:2080101:3010101:3020101:3080101:4010101:4020101:4030101:5010101:5020101:5060101|1|100#43|1050101:1080101:1090101:2020101:2070101:2090101:3040101:3060101:3090101:4050101:4070101:4090101:5040101:5050101:5090101|1|100#6|1030101:1070101:2040101:2060101:3050101:3070101:4040101:4060101:5030101:5070101|1|100 | T24: 0 | U24: 3 | V24: 1:12|2:3|3:0 | W24: 1:2:3:4:5 | X24: 1:12:40 | Y24: MapBingXue | Z24: 3 | AA24: =AA16+2 -> 3 | AB24: =F24+AA24+Z24 -> 27 | AC24: =AB24+15 -> 42 | AD24: 250 | AE24: =AE16+1 -> 17 | AF24: =AF23 -> 15000 | AG24: =AG23 -> 28000 | AH24: =出怪成长!C22 -> 8 | AI24: =出怪成长!D22 -> 3#30001#1|6#30002#1|8#30001,30004#1 | AJ24: =出怪数量!Z23 -> 1:3:1|1:6:1|2:11:1|2:5:1#2:5:1#3:5:2|3:4:2#2:4:1#3:4:2|3:5:2#2:5:1#3:5:2|1:6:1#2:6:1#3:6:2|2:7:1#2:7:1#3:7:2 | AK24: =出怪成长!E22 -> 1:10037,10038|2:10037,10038,10029|3:10037,10038,10036 | AL24: =出怪成长!F22 -> 3#1#1.2|6#2#2|8#3#2.6 | AM24: =每波成长!G25 -> 34#9#6 | AN24: 1:11:50#2:25:500|1:11:100#2:25:500#3:26:500 | AO24: 0 | AP24: 200#40001:2;40002:1|500#40002:3 | AQ24: 2 | AR24: 21 | AS24: 1:40021#1|2:40022#1 | AT24: 1:90001#1|2:90003#1 | AU24: -66:-322 | AV24: 1+1+1+1+1+20+5+9|1+1+1+1+1+9+4+8|1+1+1+1+1+9+4+19|54 | AW24: 0 | AX24: 3 | AY24: 700:12:30|100:11:2|80:1:1|9:4:1 | AZ24: 守护家园，抵御精灵的阴谋 | BA24: 人族与兽族及精灵的大规模战争 | BB24: 0 | BC24: 8 | BD24: 80 | BE24: 1005+7 | BF24: 2106+7.3 | BG24: 0 | BH24: 3 | BI24: MapBingXue21 | BJ24: =BJ23 -> MapSenLin | BL24: 17 | BM24: 2106 | BN24: 2004 | BO24: 0
A25: 32 | B25: 0 | C25: 贪婪之祸22 | D25: img_shenyuan2 | E25: =A26 -> 33 | F25: 22 | G25: =F25+20 -> 42 | H25: 32 | I25: 32 | J25: 32 | K25: 2200 | L25: 4400 | M25: 6600 | N25: 1:12:200#1:12:200#1:12:4600|1:13:6#1:11:100|1:10000001:312|1:10000002:93|1:10000003:12 | O25: 1:12:300#1:12:3450#1:12:6900|1:13:6#1:11:150|1:10000001:468|1:10000002:140|1:10000003:12 | P25: 1:12:500#1:12:4600#1:12:9200|1:13:6#1:11:200|1:10000001:624|1:10000002:187|1:10000003:14 | Q25: 60|1010101:1020101:1040101:2010101:2030101:2080101:3010101:3020101:3080101:4010101:4020101:4030101:5010101:5020101:5060101|1|100#18|1050101:1080101:1090101:2020101:2070101:2090101:3040101:3060101:3090101:4050101:4070101:4090101:5040101:5050101:5090101|1|100#2|1030101:1070101:2040101:2060101:3050101:3070101:4040101:4060101:5030101:5070101|1|100 | R25: 90|1010101:1020101:1040101:2010101:2030101:2080101:3010101:3020101:3080101:4010101:4020101:4030101:5010101:5020101:5060101|1|100#25|1050101:1080101:1090101:2020101:2070101:2090101:3040101:3060101:3090101:4050101:4070101:4090101:5040101:5050101:5090101|1|100#3|1030101:1070101:2040101:2060101:3050101:3070101:4040101:4060101:5030101:5070101|1|100 | S25: 150|1010101:1020101:1040101:2010101:2030101:2080101:3010101:3020101:3080101:4010101:4020101:4030101:5010101:5020101:5060101|1|100#43|1050101:1080101:1090101:2020101:2070101:2090101:3040101:3060101:3090101:4050101:4070101:4090101:5040101:5050101:5090101|1|100#6|1030101:1070101:2040101:2060101:3050101:3070101:4040101:4060101:5030101:5070101|1|100 | T25: 0 | U25: 3 | V25: 1:12|2:3|3:0 | W25: 1:2:3:4:5 | X25: 1:12:40 | Y25: MapBingXue | Z25: 3 | AA25: =AA17+2 -> 4 | AB25: =F25+AA25+Z25 -> 29 | AC25: =AB25+15 -> 44 | AD25: 250 | AE25: =AE17+1 -> 17 | AF25: =AF24 -> 15000 | AG25: =AG24 -> 28000 | AH25: =出怪成长!C23 -> 8 | AI25: =出怪成长!D23 -> 3#30001#1|6#30002#1|8#30001,30004#1 | AJ25: =出怪数量!Z24 -> 1:3:1|1:6:1|2:11:1|2:5:1#2:5:1#3:5:2|3:4:2#2:4:1#3:4:2|3:5:2#2:5:1#3:5:2|1:6:1#2:6:1#3:6:2|2:7:1#2:7:1#3:7:2 | AK25: =出怪成长!E23 -> 1:10037,10038|2:10037,10038,10036|3:10040,10041,10036 | AL25: =出怪成长!F23 -> 3#1#1.2|6#2#2|8#3#2.6 | AM25: =每波成长!G26 -> 36#10#7 | AN25: 1:11:50#2:25:500#3:26:500|1:11:50#2:25:500#4:50011 | AO25: 0 | AP25: 200#40001:2;40002:1|500#40002:3 | AQ25: 2 | AR25: 22 | AS25: 1:40021#1|2:40022#1 | AT25: 1:90003#1|2:90002#1 | AU25: 332:-177 | AV25: 1+1+1+1+1+9+6+8|1+1+1+1+1+5+9|1+1+1+1+1+20+4+9|52 | AW25: 0 | AX25: 3 | AY25: 700:12:30|100:11:2|80:1:1|9:4:1 | AZ25: 守护家园，抵御精灵的阴谋 | BA25: 攻打精灵城 | BB25: 0 | BC25: 9 | BD25: 90 | BE25: 9001+10 | BF25: 2107+7.7 | BG25: 0 | BH25: 3 | BI25: MapBingXue22 | BJ25: =BJ24 -> MapSenLin | BL25: 18 | BM25: 2107 | BN25: 2004 | BO25: 2005 | BR25: |3:123:1
