Workbook

Sheet Monster
A1: id | B1: Name | C1: type | D1: Career | E1: AttackType | F1: Model | G1: Icon | H1: AtkGoal | I1: Range | J1: Warn | K1: Move | L1: AtkBuild | M1: AtkCd | N1: Hp | O1: Atk | P1: Def | Q1: Ap | R1: Mdef | S1: Dex | T1: Grow | U1: skill | V1: killexp | W1: killgold | X1: Amplify1 | Y1: Amplify2 | Z1: Add
A2: int | B2: string | C2: int | D2: int | E2: int | F2: string | G2: string | H2: int | I2: int | J2: int | K2: int | L2: float | M2: int | N2: float | O2: float | P2: float | Q2: float | R2: float | S2: int | T2: float | U2: string | V2: int | W2: int | X2: float | Y2: float | Z2: int
A3: 怪物ID | B3: 名称 | C3: 类型 | D3: 初始职业 | E3: 攻击倾向 | F3: 模型 | G3: 头像 | H3: 攻击目标 | I3: 攻击距离 | J3: 警戒范围 | K3: 移速 | L3: 对建筑伤害 | M3: 攻击间隔/15 | N3: 生命 | O3: 攻击 | P3: 防御 | Q3: 魔力 | R3: 魔防 | S3: 技巧 | T3: 成长系数 | U3: 携带技能 | V3: 击杀提供经验 | W3: 击杀提供金矿 | X3: 查看界面放大 | Y3: 地图模型放大 | Z3: 战力提升
A4: 10001 | B4: 史莱黄 | C4: =LEFT(A4,1) -> 1 | D4: 7 | E4: 1 | F4: monster001 | G4: =F4 -> monster001 | H4: =_xlfn.IFS(OR(D4="1",D4="2",D4="7",D4="8"),2,OR(D4="3",D4="4",D4="5",D4="6"),1) -> 2 | I4: =_xlfn.IFS(OR(D4="1",D4="2",D4="4",D4="7",D4="8"),150,OR(D4="3",D4="5",D4="6"),800) -> 150 | J4: =MIN(I4+350,800) -> 500 | K4: 650 | L4: 52 | M4: 15 | N4: =环形怪物属性!F5 -> 415 | O4: =环形怪物属性!H5 -> 36 | P4: =环形怪物属性!K5 -> 4 | Q4: =环形怪物属性!N5 -> 23 | R4: 9.5 | S4: 5 | T4: 0.15 | U4: 0 | V4: 30 | W4: 1 | X4: 1.7 | Y4: 1.8 | Z4: 50 | AC4: 弱小怪
A5: 10002 | B5: 史莱红 | C5: =LEFT(A5,1) -> 1 | D5: 7 | E5: 1 | F5: monster002 | G5: =F5 -> monster002 | H5: =_xlfn.IFS(OR(D5="1",D5="2",D5="7",D5="8"),2,OR(D5="3",D5="4",D5="5",D5="6"),1) -> 2 | I5: =_xlfn.IFS(OR(D5="1",D5="2",D5="4",D5="7",D5="8"),150,OR(D5="3",D5="5",D5="6"),800) -> 150 | J5: =MIN(I5+350,800) -> 500 | K5: 750 | L5: 52 | M5: 15 | N5: =环形怪物属性!F6 -> 419 | O5: =环形怪物属性!H6 -> 36 | P5: =环形怪物属性!K6 -> 4 | Q5: =环形怪物属性!N6 -> 23 | R5: 9.5 | S5: 5 | T5: =T4 -> 0.15 | U5: 0 | V5: 30 | W5: 1 | X5: 1.7 | Y5: 1.8 | Z5: 50 | AC5: 物防小怪
A6: 10003 | B6: 史莱黑 | C6: =LEFT(A6,1) -> 1 | D6: 7 | E6: 1 | F6: monster003 | G6: =F6 -> monster003 | H6: =_xlfn.IFS(OR(D6="1",D6="2",D6="7",D6="8"),2,OR(D6="3",D6="4",D6="5",D6="6"),1) -> 2 | I6: =_xlfn.IFS(OR(D6="1",D6="2",D6="4",D6="7",D6="8"),150,OR(D6="3",D6="5",D6="6"),800) -> 150 | J6: =MIN(I6+350,800) -> 500 | K6: 650 | L6: 52 | M6: 15 | N6: =环形怪物属性!F7 -> 422 | O6: =环形怪物属性!H7 -> 26 | P6: =环形怪物属性!K7 -> 4 | Q6: =环形怪物属性!N7 -> 28 | R6: 9.5 | S6: 5 | T6: =T5 -> 0.15 | U6: 0 | V6: 30 | W6: 1 | X6: 1.7 | Y6: 1.8 | Z6: 50 | AC6: 魔防小怪
A7: 10004 | B7: 小哥布林 | C7: =LEFT(A7,1) -> 1 | D7: 7 | E7: 1 | F7: monster004 | G7: =F7 -> monster004 | H7: =_xlfn.IFS(OR(D7="1",D7="2",D7="7",D7="8"),2,OR(D7="3",D7="4",D7="5",D7="6"),1) -> 2 | I7: =_xlfn.IFS(OR(D7="1",D7="2",D7="4",D7="7",D7="8"),150,OR(D7="3",D7="5",D7="6"),800) -> 150 | J7: =MIN(I7+350,800) -> 500 | K7: 800 | L7: 52 | M7: 15 | N7: =环形怪物属性!F8 -> 426 | O7: =环形怪物属性!H8 -> 38 | P7: =环形怪物属性!K8 -> 5 | Q7: =环形怪物属性!N8 -> 24 | R7: 11 | S7: 5 | T7: =T6 -> 0.15 | U7: 0 | V7: 30 | W7: 1 | X7: 1.7 | Y7: 1.8 | Z7: 50 | AC7: 中小怪
A8: 10005 | B8: 大哥布林 | C8: =LEFT(A8,1) -> 1 | D8: 7 | E8: 1 | F8: monster005 | G8: =F8 -> monster005 | H8: =_xlfn.IFS(OR(D8="1",D8="2",D8="7",D8="8"),2,OR(D8="3",D8="4",D8="5",D8="6"),1) -> 2 | I8: =_xlfn.IFS(OR(D8="1",D8="2",D8="4",D8="7",D8="8"),150,OR(D8="3",D8="5",D8="6"),800) -> 150 | J8: =MIN(I8+350,800) -> 500 | K8: 620 | L8: 52 | M8: 15 | N8: =环形怪物属性!F9 -> 430 | O8: =环形怪物属性!H9 -> 39 | P8: =环形怪物属性!K9 -> 5 | Q8: =环形怪物属性!N9 -> 24 | R8: 11 | S8: 5 | T8: =T7 -> 0.15 | U8: 80011 | V8: 30 | W8: 1 | X8: 1.7 | Y8: 1.8 | Z8: 50 | AC8: 正常小怪
A9: 10006 | B9: 哥布林战士 | C9: =LEFT(A9,1) -> 1 | D9: 7 | E9: 1 | F9: monster006 | G9: =F9 -> monster006 | H9: =_xlfn.IFS(OR(D9="1",D9="2",D9="7",D9="8"),2,OR(D9="3",D9="4",D9="5",D9="6"),1) -> 2 | I9: =_xlfn.IFS(OR(D9="1",D9="2",D9="4",D9="7",D9="8"),150,OR(D9="3",D9="5",D9="6"),800) -> 150 | J9: =MIN(I9+350,800) -> 500 | K9: 650 | L9: 52 | M9: 15 | N9: =环形怪物属性!F10 -> 434 | O9: =环形怪物属性!H10 -> 41 | P9: =环形怪物属性!K10 -> 6 | Q9: =环形怪物属性!N10 -> 26 | R9: 13 | S9: 6 | T9: =T8 -> 0.15 | U9: 80071 | V9: 30 | W9: 1 | X9: 1.7 | Y9: 1.8 | Z9: 50
A10: 10007 | B10: 哥布林牧师 | C10: =LEFT(A10,1) -> 1 | D10: 6 | E10: 1 | F10: monster007 | G10: =F10 -> monster007 | H10: =_xlfn.IFS(OR(D10="1",D10="2",D10="7",D10="8"),2,OR(D10="3",D10="4",D10="5",D10="6"),1) -> 1 | I10: =_xlfn.IFS(OR(D10="1",D10="2",D10="4",D10="7",D10="8"),150,OR(D10="3",D10="5",D10="6"),800) -> 800 | J10: =MIN(I10+350,800) -> 800 | K10: 620 | L10: 52 | M10: 20 | N10: =环形怪物属性!F11 -> 419 | O10: =环形怪物属性!H11 -> 24 | P10: =环形怪物属性!K11 -> 6 | Q10: =环形怪物属性!N11 -> 39 | R10: 13 | S10: 6 | T10: =T9 -> 0.15 | U10: 80011|80071 | V10: 30 | W10: 1 | X10: 1.7 | Y10: 1.8 | Z10: 50
A11: 10008 | B11: 哥布林法师 | C11: =LEFT(A11,1) -> 1 | D11: 5 | E11: 1 | F11: monster008 | G11: =F11 -> monster008 | H11: =_xlfn.IFS(OR(D11="1",D11="2",D11="7",D11="8"),2,OR(D11="3",D11="4",D11="5",D11="6"),1) -> 1 | I11: =_xlfn.IFS(OR(D11="1",D11="2",D11="4",D11="7",D11="8"),150,OR(D11="3",D11="5",D11="6"),800) -> 800 | J11: =MIN(I11+350,800) -> 800 | K11: 620 | L11: 52 | M11: 20 | N11: =环形怪物属性!F12 -> 422 | O11: =环形怪物属性!H12 -> 26 | P11: =环形怪物属性!K12 -> 6 | Q11: 27 | R11: 13 | S11: 6 | T11: =T10 -> 0.15 | U11: 80011|80071 | V11: 30 | W11: 1 | X11: 1.7 | Y11: 1.8 | Z11: 50
A12: 10009 | B12: 哥布林射手 | C12: =LEFT(A12,1) -> 1 | D12: 3 | E12: 1 | F12: monster009 | G12: =F12 -> monster009 | H12: =_xlfn.IFS(OR(D12="1",D12="2",D12="7",D12="8"),2,OR(D12="3",D12="4",D12="5",D12="6"),1) -> 1 | I12: =_xlfn.IFS(OR(D12="1",D12="2",D12="4",D12="7",D12="8"),150,OR(D12="3",D12="5",D12="6"),800) -> 800 | J12: =MIN(I12+350,800) -> 800 | K12: 650 | L12: 52 | M12: 20 | N12: =环形怪物属性!F13 -> 426 | O12: =环形怪物属性!H13 -> 38 | P12: =环形怪物属性!K13 -> 6 | Q12: =环形怪物属性!N13 -> 28 | R12: 14.5 | S12: 8 | T12: =T11 -> 0.15 | U12: 80011|80071 | V12: 30 | W12: 1 | X12: 1.4 | Y12: 1.8 | Z12: 50
A13: 10010 | B13: 哥布林队长 | C13: =LEFT(A13,1) -> 1 | D13: 1 | E13: 1 | F13: monster010 | G13: =F13 -> monster010 | H13: =_xlfn.IFS(OR(D13="1",D13="2",D13="7",D13="8"),2,OR(D13="3",D13="4",D13="5",D13="6"),1) -> 2 | I13: =_xlfn.IFS(OR(D13="1",D13="2",D13="4",D13="7",D13="8"),150,OR(D13="3",D13="5",D13="6"),800) -> 150 | J13: =MIN(I13+350,800) -> 500 | K13: 650 | L13: 52 | M13: 15 | N13: =环形怪物属性!F14 -> 453 | O13: =环形怪物属性!H14 -> 47 | P13: =环形怪物属性!K14 -> 7 | Q13: =环形怪物属性!N14 -> 29 | R13: 16 | S13: 8 | T13: =T12 -> 0.15 | U13: 80071 | V13: 30 | W13: 1 | X13: 1.4 | Y13: 1.8 | Z13: 50
A14: 10011 | B14: 步兵 | C14: =LEFT(A14,1) -> 1 | D14: 1 | E14: 1 | F14: bubing01_Lv1 | G14: =F14 -> bubing01_Lv1 | H14: =_xlfn.IFS(OR(D14="1",D14="2",D14="7",D14="8"),2,OR(D14="3",D14="4",D14="5",D14="6"),1) -> 2 | I14: =_xlfn.IFS(OR(D14="1",D14="2",D14="4",D14="7",D14="8"),150,OR(D14="3",D14="5",D14="6"),800) -> 150 | J14: =MIN(I14+350,800) -> 500 | K14: 650 | L14: 67 | M14: 15 | N14: =环形怪物属性!F15 -> 472 | O14: =环形怪物属性!H15 -> 51 | P14: =环形怪物属性!K15 -> 9 | Q14: =环形怪物属性!N15 -> 26 | R14: 9.5 | S14: 10 | T14: 0.18 | U14: 80071 | V14: =V4+10 -> 40 | W14: 1 | X14: 1.8 | Y14: 1.8 | Z14: 50
A15: 10012 | B15: 枪兵 | C15: =LEFT(A15,1) -> 1 | D15: 1 | E15: 1 | F15: bubing02_Lv1 | G15: =F15 -> bubing02_Lv1 | H15: =_xlfn.IFS(OR(D15="1",D15="2",D15="7",D15="8"),2,OR(D15="3",D15="4",D15="5",D15="6"),1) -> 2 | I15: =_xlfn.IFS(OR(D15="1",D15="2",D15="4",D15="7",D15="8"),150,OR(D15="3",D15="5",D15="6"),800) -> 150 | J15: =MIN(I15+350,800) -> 500 | K15: 650 | L15: 67 | M15: 15 | N15: =环形怪物属性!F16 -> 492 | O15: =环形怪物属性!H16 -> 44 | P15: =环形怪物属性!K16 -> 9 | Q15: =环形怪物属性!N16 -> 26 | R15: 11 | S15: 15 | T15: =T14 -> 0.18 | U15: 80071 | V15: =V5+10 -> 40 | W15: 1 | X15: 1.8 | Y15: 1.8 | Z15: 50
A16: 10013 | B16: 骑兵 | C16: =LEFT(A16,1) -> 1 | D16: 2 | E16: 1 | F16: qibing01_Lv1 | G16: =F16 -> qibing01_Lv1 | H16: =_xlfn.IFS(OR(D16="1",D16="2",D16="7",D16="8"),2,OR(D16="3",D16="4",D16="5",D16="6"),1) -> 2 | I16: =_xlfn.IFS(OR(D16="1",D16="2",D16="4",D16="7",D16="8"),150,OR(D16="3",D16="5",D16="6"),800) -> 150 | J16: =MIN(I16+350,800) -> 500 | K16: 800 | L16: 67 | M16: 15 | N16: =环形怪物属性!F17 -> 480 | O16: =环形怪物属性!H17 -> 51 | P16: =环形怪物属性!K17 -> 8 | Q16: =环形怪物属性!N17 -> 24 | R16: 11 | S16: 10 | T16: =T15 -> 0.18 | U16: 80071 | V16: =V6+10 -> 40 | W16: 1 | X16: 1.8 | Y16: 1.8 | Z16: 50
A17: 10014 | B17: 木精灵 | C17: =LEFT(A17,1) -> 1 | D17: 3 | E17: 1 | F17: gongbing01_Lv1 | G17: =F17 -> gongbing01_Lv1 | H17: =_xlfn.IFS(OR(D17="1",D17="2",D17="7",D17="8"),2,OR(D17="3",D17="4",D17="5",D17="6"),1) -> 1 | I17: =_xlfn.IFS(OR(D17="1",D17="2",D17="4",D17="7",D17="8"),150,OR(D17="3",D17="5",D17="6"),800) -> 800 | J17: =MIN(I17+350,800) -> 800 | K17: 650 | L17: 67 | M17: 20 | N17: =环形怪物属性!F18 -> 434 | O17: =环形怪物属性!H18 -> 41 | P17: =环形怪物属性!K18 -> 7 | Q17: =环形怪物属性!N18 -> 28 | R17: 14.5 | S17: 10 | T17: =T16 -> 0.18 | U17: 80011|80071 | V17: =V7+10 -> 40 | W17: 1 | X17: 2 | Y17: 1.8 | Z17: 50
A18: 10015 | B18: 飞鹰骑士 | C18: =LEFT(A18,1) -> 1 | D18: 4 | E18: 1 | F18: feibing01_Lv1 | G18: =F18 -> feibing01_Lv1 | H18: =_xlfn.IFS(OR(D18="1",D18="2",D18="7",D18="8"),2,OR(D18="3",D18="4",D18="5",D18="6"),1) -> 1 | I18: =_xlfn.IFS(OR(D18="1",D18="2",D18="4",D18="7",D18="8"),150,OR(D18="3",D18="5",D18="6"),800) -> 150 | J18: =MIN(I18+350,800) -> 500 | K18: 800 | L18: 67 | M18: 15 | N18: =环形怪物属性!F19 -> 480 | O18: =环形怪物属性!H19 -> 49 | P18: =环形怪物属性!K19 -> 9 | Q18: =环形怪物属性!N19 -> 31 | R18: 14.5 | S18: 10 | T18: =T17 -> 0.18 | U18: 80071 | V18: =V8+10 -> 40 | W18: 1 | X18: 1.2 | Y18: 1.8 | Z18: 50
A19: 10016 | B19: 法师学徒 | C19: =LEFT(A19,1) -> 1 | D19: 5 | E19: 1 | F19: fashi01_Lv1 | G19: =F19 -> fashi01_Lv1 | H19: =_xlfn.IFS(OR(D19="1",D19="2",D19="7",D19="8"),2,OR(D19="3",D19="4",D19="5",D19="6"),1) -> 1 | I19: =_xlfn.IFS(OR(D19="1",D19="2",D19="4",D19="7",D19="8"),150,OR(D19="3",D19="5",D19="6"),800) -> 800 | J19: =MIN(I19+350,800) -> 800 | K19: 650 | L19: 67 | M19: 20 | N19: =环形怪物属性!F20 -> 434 | O19: 20 | P19: =环形怪物属性!K20 -> 7 | Q19: 36 | R19: 13 | S19: 10 | T19: =T18 -> 0.18 | U19: 80011|80071 | V19: =V9+10 -> 40 | W19: 1 | X19: 1.2 | Y19: 1.8 | Z19: 50
A20: 10017 | B20: 僧侣 | C20: =LEFT(A20,1) -> 1 | D20: 6 | E20: 1 | F20: mushi01_Lv1 | G20: =F20 -> mushi01_Lv1 | H20: =_xlfn.IFS(OR(D20="1",D20="2",D20="7",D20="8"),2,OR(D20="3",D20="4",D20="5",D20="6"),1) -> 1 | I20: =_xlfn.IFS(OR(D20="1",D20="2",D20="4",D20="7",D20="8"),150,OR(D20="3",D20="5",D20="6"),800) -> 800 | J20: =MIN(I20+350,800) -> 800 | K20: 650 | L20: 67 | M20: 20 | N20: =环形怪物属性!F21 -> 438 | O20: =环形怪物属性!H21 -> 26 | P20: =环形怪物属性!K21 -> 10 | Q20: =环形怪物属性!N21 -> 39 | R20: 21 | S20: 10 | T20: =T19 -> 0.18 | U20: 80011|80071 | V20: =V10+10 -> 40 | W20: 1 | X20: 1.5 | Y20: 1.8 | Z20: 50
A21: 10018 | B21: 骷髅兵 | C21: =LEFT(A21,1) -> 1 | D21: 7 | E21: 1 | F21: moshou01_Lv1 | G21: =F21 -> moshou01_Lv1 | H21: =_xlfn.IFS(OR(D21="1",D21="2",D21="7",D21="8"),2,OR(D21="3",D21="4",D21="5",D21="6"),1) -> 2 | I21: =_xlfn.IFS(OR(D21="1",D21="2",D21="4",D21="7",D21="8"),150,OR(D21="3",D21="5",D21="6"),800) -> 150 | J21: =MIN(I21+350,800) -> 500 | K21: 650 | L21: 67 | M21: 15 | N21: =环形怪物属性!F22 -> 484 | O21: =环形怪物属性!H22 -> 43 | P21: =环形怪物属性!K22 -> 9 | Q21: =环形怪物属性!N22 -> 26 | R21: 13 | S21: 10 | T21: =T20 -> 0.18 | U21: 80071 | V21: =V11+10 -> 40 | W21: 1 | X21: 1.5 | Y21: 1.8 | Z21: 50
A22: 10019 | B22: 狼战士 | C22: =LEFT(A22,1) -> 1 | D22: 8 | E22: 1 | F22: yeshou01_lv1 | G22: =F22 -> yeshou01_lv1 | H22: =_xlfn.IFS(OR(D22="1",D22="2",D22="7",D22="8"),2,OR(D22="3",D22="4",D22="5",D22="6"),1) -> 2 | I22: =_xlfn.IFS(OR(D22="1",D22="2",D22="4",D22="7",D22="8"),150,OR(D22="3",D22="5",D22="6"),800) -> 150 | J22: =MIN(I22+350,800) -> 500 | K22: 650 | L22: 67 | M22: 15 | N22: =环形怪物属性!F23 -> 461 | O22: =环形怪物属性!H23 -> 52 | P22: =环形怪物属性!K23 -> 8 | Q22: =环形怪物属性!N23 -> 26 | R22: 13 | S22: 10 | T22: =T21 -> 0.18 | U22: 80071 | V22: =V12+10 -> 40 | W22: 1 | X22: 1.5 | Y22: 1.8 | Z22: 50
A23: 10020 | B23: 骷髅兵 | C23: =LEFT(A23,1) -> 1 | D23: 7 | E23: 1 | F23: monster001 | G23: =F23 -> monster001 | H23: =_xlfn.IFS(OR(D23="1",D23="2",D23="7",D23="8"),2,OR(D23="3",D23="4",D23="5",D23="6"),1) -> 2 | I23: =_xlfn.IFS(OR(D23="1",D23="2",D23="4",D23="7",D23="8"),150,OR(D23="3",D23="5",D23="6"),800) -> 150 | J23: =MIN(I23+350,800) -> 500 | K23: 650 | L23: 67 | M23: 15 | N23: =环形怪物属性!F24 -> 434 | O23: =环形怪物属性!H24 -> 43 | P23: =环形怪物属性!K24 -> 8 | Q23: =环形怪物属性!N24 -> 26 | R23: 13 | S23: 10 | T23: =T22 -> 0.18 | U23: 80071 | V23: =V13+10 -> 40 | W23: 1 | X23: 1.5 | Y23: 1.8 | Z23: 50
A24: 10021 | B24: 骷髅卫士 | C24: =LEFT(A24,1) -> 1 | D24: 7 | E24: 1 | F24: monster002 | G24: =F24 -> monster002 | H24: =_xlfn.IFS(OR(D24="1",D24="2",D24="7",D24="8"),2,OR(D24="3",D24="4",D24="5",D24="6"),1) -> 2 | I24: =_xlfn.IFS(OR(D24="1",D24="2",D24="4",D24="7",D24="8"),150,OR(D24="3",D24="5",D24="6"),800) -> 150 | J24: =MIN(I24+350,800) -> 500 | K24: 650 | L24: 67 | M24: 15 | N24: =环形怪物属性!F25 -> 438 | O24: =环形怪物属性!H25 -> 39 | P24: =环形怪物属性!K25 -> 9 | Q24: =环形怪物属性!N25 -> 26 | R24: 13 | S24: 10 | T24: =T23 -> 0.18 | U24: 80071 | V24: =V14+10 -> 50 | W24: 1 | X24: 1.5 | Y24: 1.8 | Z24: 50
A25: 10022 | B25: 骷髅射手 | C25: =LEFT(A25,1) -> 1 | D25: 7 | E25: 1 | F25: monster003 | G25: =F25 -> monster003 | H25: =_xlfn.IFS(OR(D25="1",D25="2",D25="7",D25="8"),2,OR(D25="3",D25="4",D25="5",D25="6"),1) -> 2 | I25: 800 | J25: =MIN(I25+350,800) -> 800 | K25: 650 | L25: 67 | M25: 20 | N25: =环形怪物属性!F26 -> 399 | O25: =环形怪物属性!H26 -> 44 | P25: =环形怪物属性!K26 -> 8 | Q25: =环形怪物属性!N26 -> 26 | R25: 13 | S25: 10 | T25: =T24 -> 0.18 | U25: 80071 | V25: =V15+10 -> 50 | W25: 1 | X25: 1.5 | Y25: 1.8 | Z25: 50
A26: 10023 | B26: 骷髅战士 | C26: =LEFT(A26,1) -> 1 | D26: 7 | E26: 1 | F26: monster004 | G26: =F26 -> monster004 | H26: =_xlfn.IFS(OR(D26="1",D26="2",D26="7",D26="8"),2,OR(D26="3",D26="4",D26="5",D26="6"),1) -> 2 | I26: =_xlfn.IFS(OR(D26="1",D26="2",D26="4",D26="7",D26="8"),150,OR(D26="3",D26="5",D26="6"),800) -> 150 | J26: =MIN(I26+350,800) -> 500 | K26: 650 | L26: 67 | M26: 15 | N26: =环形怪物属性!F27 -> 442 | O26: =环形怪物属性!H27 -> 52 | P26: =环形怪物属性!K27 -> 8 | Q26: =环形怪物属性!N27 -> 26 | R26: 13 | S26: 10 | T26: =T25 -> 0.18 | U26: 80071 | V26: =V16+10 -> 50 | W26: 1 | X26: 1.5 | Y26: 1.8 | Z26: 50
A27: 10024 | B27: 骷髅法师 | C27: =LEFT(A27,1) -> 1 | D27: 7 | E27: 1 | F27: monster005 | G27: =F27 -> monster005 | H27: =_xlfn.IFS(OR(D27="1",D27="2",D27="7",D27="8"),2,OR(D27="3",D27="4",D27="5",D27="6"),1) -> 2 | I27: =_xlfn.IFS(OR(D27="1",D27="2",D27="4",D27="7",D27="8"),150,OR(D27="3",D27="5",D27="6"),800) -> 150 | J27: =MIN(I27+350,800) -> 500 | K27: 650 | L27: 67 | M27: 15 | N27: =环形怪物属性!F28 -> 442 | O27: =环形怪物属性!H28 -> 26 | P27: =环形怪物属性!K28 -> 8 | Q27: =环形怪物属性!N28 -> 39 | R27: 13 | S27: 10 | T27: =T26 -> 0.18 | U27: 80071 | V27: =V17+10 -> 50 | W27: 1 | X27: 1.5 | Y27: 1.8 | Z27: 50
A28: 10025 | B28: 兽人 | C28: =LEFT(A28,1) -> 1 | D28: 8 | E28: 1 | F28: monster006 | G28: =F28 -> monster006 | H28: =_xlfn.IFS(OR(D28="1",D28="2",D28="7",D28="8"),2,OR(D28="3",D28="4",D28="5",D28="6"),1) -> 2 | I28: =_xlfn.IFS(OR(D28="1",D28="2",D28="4",D28="7",D28="8"),150,OR(D28="3",D28="5",D28="6"),800) -> 150 | J28: =MIN(I28+350,800) -> 500 | K28: 650 | L28: 67 | M28: 15 | N28: =环形怪物属性!F29 -> 445 | O28: =环形怪物属性!H29 -> 52 | P28: =环形怪物属性!K29 -> 8 | Q28: =环形怪物属性!N29 -> 39 | R28: 13 | S28: 10 | T28: =T27 -> 0.18 | U28: 80071 | V28: =V18+10 -> 50 | W28: 1 | X28: 1.5 | Y28: 1.8 | Z28: 50
A29: 10026 | B29: 兽人步兵 | C29: =LEFT(A29,1) -> 1 | D29: 8 | E29: 1 | F29: monster007 | G29: =F29 -> monster007 | H29: =_xlfn.IFS(OR(D29="1",D29="2",D29="7",D29="8"),2,OR(D29="3",D29="4",D29="5",D29="6"),1) -> 2 | I29: =_xlfn.IFS(OR(D29="1",D29="2",D29="4",D29="7",D29="8"),150,OR(D29="3",D29="5",D29="6"),800) -> 150 | J29: =MIN(I29+350,800) -> 500 | K29: 650 | L29: 67 | M29: 15 | N29: =环形怪物属性!F30 -> 445 | O29: =环形怪物属性!H30 -> 52 | P29: =环形怪物属性!K30 -> 8 | Q29: =环形怪物属性!N30 -> 39 | R29: 13 | S29: 10 | T29: =T28 -> 0.18 | U29: 80071 | V29: =V19+10 -> 50 | W29: 1 | X29: 1.5 | Y29: 1.8 | Z29: 50
A30: 10027 | B30: 夜魔（蓝） | C30: =LEFT(A30,1) -> 1 | D30: 4 | E30: 1 | F30: feibing01_Lv1 | G30: =F30 -> feibing01_Lv1 | H30: =_xlfn.IFS(OR(D30="1",D30="2",D30="7",D30="8"),2,OR(D30="3",D30="4",D30="5",D30="6"),1) -> 1 | I30: =_xlfn.IFS(OR(D30="1",D30="2",D30="4",D30="7",D30="8"),150,OR(D30="3",D30="5",D30="6"),800) -> 150 | J30: =MIN(I30+350,800) -> 500 | K30: 750 | L30: 67 | M30: 15 | N30: =环形怪物属性!F31 -> 434 | O30: =环形怪物属性!H31 -> 34 | P30: =环形怪物属性!K31 -> 8 | Q30: =环形怪物属性!N31 -> 43 | R30: 13 | S30: 10 | T30: =T29 -> 0.18 | U30: 80071 | V30: =V20+10 -> 50 | W30: 1 | X30: 1.5 | Y30: 1.8 | Z30: 50
A31: 10028 | B31: 蓝猪 | C31: =LEFT(A31,1) -> 1 | D31: 2 | E31: 1 | F31: monster002 | G31: =F31 -> monster002 | H31: =_xlfn.IFS(OR(D31="1",D31="2",D31="7",D31="8"),2,OR(D31="3",D31="4",D31="5",D31="6"),1) -> 2 | I31: =_xlfn.IFS(OR(D31="1",D31="2",D31="4",D31="7",D31="8"),150,OR(D31="3",D31="5",D31="6"),800) -> 150 | J31: =MIN(I31+350,800) -> 500 | K31: 800 | L31: 67 | M31: 15 | N31: =环形怪物属性!F32 -> 445 | O31: =环形怪物属性!H32 -> 52 | P31: =环形怪物属性!K32 -> 8 | Q31: =环形怪物属性!N32 -> 39 | R31: 13 | S31: 10 | T31: =T30 -> 0.18 | U31: 80071 | V31: =V21+10 -> 50 | W31: 1 | X31: 1.5 | Y31: 1.8 | Z31: 50
A32: 10029 | B32: 飞行独眼 | C32: =LEFT(A32,1) -> 1 | D32: 4 | E32: 1 | F32: feibing01_Lv1 | G32: =F32 -> feibing01_Lv1 | H32: =_xlfn.IFS(OR(D32="1",D32="2",D32="7",D32="8"),2,OR(D32="3",D32="4",D32="5",D32="6"),1) -> 1 | I32: =_xlfn.IFS(OR(D32="1",D32="2",D32="4",D32="7",D32="8"),150,OR(D32="3",D32="5",D32="6"),800) -> 150 | J32: =MIN(I32+350,800) -> 500 | K32: 750 | L32: 67 | M32: 15 | N32: =环形怪物属性!F33 -> 415 | O32: =环形怪物属性!H33 -> 39 | P32: =环形怪物属性!K33 -> 8 | Q32: =环形怪物属性!N33 -> 44 | R32: 13 | S32: 10 | T32: =T31 -> 0.18 | U32: 80071 | V32: =V22+10 -> 50 | W32: 1 | X32: 1.5 | Y32: 1.8 | Z32: 50
A33: 10030 | B33: 蜘蛛怪 | C33: =LEFT(A33,1) -> 1 | D33: 8 | E33: 1 | F33: monster004 | G33: =F33 -> monster004 | H33: =_xlfn.IFS(OR(D33="1",D33="2",D33="7",D33="8"),2,OR(D33="3",D33="4",D33="5",D33="6"),1) -> 2 | I33: =_xlfn.IFS(OR(D33="1",D33="2",D33="4",D33="7",D33="8"),150,OR(D33="3",D33="5",D33="6"),800) -> 150 | J33: =MIN(I33+350,800) -> 500 | K33: 650 | L33: 67 | M33: 15 | N33: =环形怪物属性!F34 -> 445 | O33: =环形怪物属性!H34 -> 52 | P33: =环形怪物属性!K34 -> 8 | Q33: =环形怪物属性!N34 -> 43 | R33: 13 | S33: 10 | T33: =T32 -> 0.18 | U33: 80071 | V33: =V23+10 -> 50 | W33: 1 | X33: 1.5 | Y33: 1.8 | Z33: 50
A34: 10031 | B34: 红蛙 | C34: =LEFT(A34,1) -> 1 | D34: 1 | E34: 1 | F34: monster005 | G34: =F34 -> monster005 | H34: =_xlfn.IFS(OR(D34="1",D34="2",D34="7",D34="8"),2,OR(D34="3",D34="4",D34="5",D34="6"),1) -> 2 | I34: =_xlfn.IFS(OR(D34="1",D34="2",D34="4",D34="7",D34="8"),150,OR(D34="3",D34="5",D34="6"),800) -> 150 | J34: =MIN(I34+350,800) -> 500 | K34: 650 | L34: 67 | M34: 15 | N34: =环形怪物属性!F35 -> 449 | O34: =环形怪物属性!H35 -> 44 | P34: =环形怪物属性!K35 -> 8 | Q34: =环形怪物属性!N35 -> 43 | R34: 14.5 | S34: 15 | T34: =T33 -> 0.18 | U34: 80071 | V34: =V24+10 -> 60 | W34: 1 | X34: 1.5 | Y34: 1.8 | Z34: 50
A35: 10032 | B35: 绿蛙 | C35: =LEFT(A35,1) -> 1 | D35: 1 | E35: 1 | F35: monster006 | G35: =F35 -> monster006 | H35: =_xlfn.IFS(OR(D35="1",D35="2",D35="7",D35="8"),2,OR(D35="3",D35="4",D35="5",D35="6"),1) -> 2 | I35: =_xlfn.IFS(OR(D35="1",D35="2",D35="4",D35="7",D35="8"),150,OR(D35="3",D35="5",D35="6"),800) -> 150 | J35: =MIN(I35+350,800) -> 500 | K35: 650 | L35: 67 | M35: 15 | N35: =环形怪物属性!F36 -> 449 | O35: =环形怪物属性!H36 -> 46 | P35: =环形怪物属性!K36 -> 8 | Q35: =环形怪物属性!N36 -> 43 | R35: 14.5 | S35: 15 | T35: =T34 -> 0.18 | U35: 80071 | V35: =V25+10 -> 60 | W35: 1 | X35: 1.5 | Y35: 1.8 | Z35: 50
A36: 10033 | B36: 食人草 | C36: =LEFT(A36,1) -> 1 | D36: 5 | E36: 1 | F36: monster003 | G36: =F36 -> monster003 | H36: =_xlfn.IFS(OR(D36="1",D36="2",D36="7",D36="8"),2,OR(D36="3",D36="4",D36="5",D36="6"),1) -> 1 | I36: =_xlfn.IFS(OR(D36="1",D36="2",D36="4",D36="7",D36="8"),150,OR(D36="3",D36="5",D36="6"),800) -> 800 | J36: =MIN(I36+350,800) -> 800 | K36: 650 | L36: 67 | M36: 20 | N36: =环形怪物属性!F37 -> 415 | O36: =环形怪物属性!H37 -> 44 | P36: =环形怪物属性!K37 -> 8 | Q36: =环形怪物属性!N37 -> 43 | R36: 13 | S36: 10 | T36: =T35 -> 0.18 | U36: 80071 | V36: =V26+10 -> 60 | W36: 1 | X36: 1.5 | Y36: 1.8 | Z36: 50
A37: 10034 | B37: 红猪 | C37: =LEFT(A37,1) -> 1 | D37: 2 | E37: 1 | F37: monster006 | G37: =F37 -> monster006 | H37: =_xlfn.IFS(OR(D37="1",D37="2",D37="7",D37="8"),2,OR(D37="3",D37="4",D37="5",D37="6"),1) -> 2 | I37: =_xlfn.IFS(OR(D37="1",D37="2",D37="4",D37="7",D37="8"),150,OR(D37="3",D37="5",D37="6"),800) -> 150 | J37: =MIN(I37+350,800) -> 500 | K37: 800 | L37: 67 | M37: 15 | N37: =环形怪物属性!F38 -> 453 | O37: =环形怪物属性!H38 -> 52 | P37: =环形怪物属性!K38 -> 8 | Q37: =环形怪物属性!N38 -> 43 | R37: 13 | S37: 10 | T37: =T36 -> 0.18 | U37: 80071 | V37: =V27+10 -> 60 | W37: 1 | X37: 1.5 | Y37: 1.8 | Z37: 50
... A48: 10045 | B48: 海蜥蜴 | C48: =LEFT(A48,1) -> 1 | D48: 1 | E48: 1 | F48: monster006 | G48: =F48 -> monster006 | H48: =_xlfn.IFS(OR(D48="1",D48="2",D48="7",D48="8"),2,OR(D48="3",D48="4",D48="5",D48="6"),1) -> 2 | I48: =_xlfn.IFS(OR(D48="1",D48="2",D48="4",D48="7",D48="8"),150,OR(D48="3",D48="5",D48="6"),800) -> 150 | J48: =MIN(I48+350,800) -> 500 | K48: 650 | L48: 67 | M48: 15 | N48: =环形怪物属性!F49 -> 445 | O48: =环形怪物属性!H49 -> 47 | P48: =环形怪物属性!K49 -> 7 | Q48: =环形怪物属性!N49 -> 43 | R48: 13 | S48: 10 | T48: =T47 -> 0.18 | U48: 80071 | V48: =V38+10 -> 70 | W48: 1 | X48: 1.5 | Y48: 1.8 | Z48: 50
A49: 20001 | B49: 野猪首领 | C49: =LEFT(A49,1) -> 2 | D49: 8 | E49: 1 | F49: jymonster001 | G49: =F49 -> jymonster001 | H49: =_xlfn.IFS(OR(D49="1",D49="2",D49="7",D49="8"),2,OR(D49="3",D49="4",D49="5",D49="6"),1) -> 2 | I49: =_xlfn.IFS(OR(D49="1",D49="2",D49="4",D49="7",D49="8"),150,OR(D49="3",D49="5",D49="6"),800) -> 150 | J49: =MIN(I49+350,800) -> 500 | K49: 700 | L49: 82 | M49: 15 | N49: =环形怪物属性!F50 -> 980 | O49: =环形怪物属性!H50 -> 52 | P49: =环形怪物属性!K50 -> 13 | Q49: =环形怪物属性!N50 -> 46 | R49: 22 | S49: 10 | T49: 0.2 | U49: 0 | V49: 60 | W49: =_xlfn.IFS(C49="1",2,C49="2",5,C49="3",10,C49="4",20,TRUE,0) -> 5 | X49: 1.2 | Y49: 1.8 | Z49: 50
A50: 20002 | B50: 树精首领 | C50: =LEFT(A50,1) -> 2 | D50: 7 | E50: 1 | F50: jymonster002 | G50: =F50 -> jymonster002 | H50: =_xlfn.IFS(OR(D50="1",D50="2",D50="7",D50="8"),2,OR(D50="3",D50="4",D50="5",D50="6"),1) -> 2 | I50: =_xlfn.IFS(OR(D50="1",D50="2",D50="4",D50="7",D50="8"),150,OR(D50="3",D50="5",D50="6"),800) -> 150 | J50: =MIN(I50+350,800) -> 500 | K50: 650 | L50: 82 | M50: 15 | N50: =环形怪物属性!F51 -> 1014 | O50: =环形怪物属性!H51 -> 44 | P50: =环形怪物属性!K51 -> 14 | Q50: =环形怪物属性!N51 -> 38 | R50: 25 | S50: 10 | T50: =T49 -> 0.2 | U50: 80021 | V50: 60 | W50: =_xlfn.IFS(C50="1",2,C50="2",5,C50="3",10,C50="4",20,TRUE,0) -> 5 | X50: 1.2 | Y50: 1.8 | Z50: 50
...

Sheet Sheet2
A1: 成长系数 | B1: 0.1-0.2 | E1: 0.2 | F1: 2 | G1: 2 | H1: 1.5 | O1: 2 | P1: 1.5 | Q1: 0.2 | R1: 2
A2: 0.3 | B2: 物理小怪 | C2: 等级 | D2: 生命 | E2: 攻击 | F2: 防御 | G2: 魔力 | H2: 魔防 | L2: 法系小怪 | M2: 等级 | N2: 生命 | O2: 攻击 | P2: 防御 | Q2: 魔力 | R2: 魔防
C3: 1 | D3: 47 | E3: 9 | F3: 5 | G3: 5 | H3: 3 | M3: 1 | N3: 47 | O3: 5 | P3: 3 | Q3: 9 | R3: 5
C4: 5 | D4: 103 | E4: 21 | F4: 10 | G4: 10 | H4: 7 | M4: 5 | N4: 103 | O4: 10 | P4: 7 | Q4: 21 | R4: 10
C5: 10 | D5: 174 | E5: 35 | F5: 17 | G5: 17 | H5: 12 | M5: 10 | N5: 174 | O5: 17 | P5: 12 | Q5: 35 | R5: 17
C6: 20 | D6: 315 | E6: 63 | F6: 31 | G6: 31 | H6: 21 | M6: 20 | N6: 315 | O6: 31 | P6: 21 | Q6: 63 | R6: 31
C7: 30 | D7: 456 | E7: 91 | F7: 46 | G7: 46 | H7: 30 | M7: 30 | N7: 456 | O7: 46 | P7: 30 | Q7: 91 | R7: 46
C8: 50 | D8: 738 | E8: 148 | F8: 74 | G8: 74 | H8: 49 | M8: 50 | N8: 738 | O8: 74 | P8: 49 | Q8: 148 | R8: 74
C9: 70 | D9: 1020 | E9: 204 | F9: 102 | G9: 102 | H9: 68 | M9: 70 | N9: 1020 | O9: 102 | P9: 68 | Q9: 204 | R9: 102
E11: 0.8 | F11: 8 | H11: 1.5 | P11: 1.5 | Q11: 0.8 | R11: 8
B12: 物理防御 | C12: 等级 | D12: 生命 | E12: 攻击 | F12: 防御 | G12: 魔力 | H12: 魔防 | L12: 魔法防御 | M12: 等级 | N12: 生命 | O12: 攻击 | P12: 防御 | Q12: 魔力 | R12: 魔防
C13: 1 | D13: 50 | E13: 5 | F13: 6 | G13: 5 | H13: 4 | M13: 1 | N13: 50 | O13: 5 | P13: 4 | Q13: 5 | R13: 6
C14: 5 | D14: 110 | E14: 11 | F14: 14 | G14: 11 | H14: 9 | M14: 5 | N14: 110 | O14: 11 | P14: 9 | Q14: 11 | R14: 14
C15: 10 | D15: 185 | E15: 19 | F15: 23 | G15: 19 | H15: 15 | M15: 10 | N15: 185 | O15: 19 | P15: 15 | Q15: 19 | R15: 23
C16: 20 | D16: 335 | E16: 34 | F16: 42 | G16: 34 | H16: 28 | M16: 20 | N16: 335 | O16: 34 | P16: 28 | Q16: 34 | R16: 42
C17: 30 | D17: 485 | E17: 49 | F17: 61 | G17: 49 | H17: 40 | M17: 30 | N17: 485 | O17: 49 | P17: 40 | Q17: 49 | R17: 61
C18: 50 | D18: 785 | E18: 79 | F18: 98 | G18: 79 | H18: 65 | M18: 50 | N18: 785 | O18: 79 | P18: 65 | Q18: 79 | R18: 98
C19: 70 | D19: 1085 | E19: 109 | F19: 136 | G19: 109 | H19: 90 | M19: 70 | N19: 1085 | O19: 109 | P19: 90 | Q19: 109 | R19: 136
A21: 成长系数 | B21: 0.3-0.4 | E21: 0.15 | F21: 1.5 | G21: 2 | H21: 1.5 | K21: 成长系数 | L21: 0.4-0.5 | O21: 0.15 | P21: 1.5 | Q21: 2 | R21: 1.5
A22: 0.4 | B22: 精英怪 | C22: 等级 | D22: 生命 | E22: 攻击 | F22: 防御 | G22: 魔力 | H22: 魔防 | K22: 0.5 | L22: BOSS | M22: 等级 | N22: 生命 | O22: 攻击 | P22: 防御 | Q22: 魔力 | R22: 魔防
C23: 1 | D23: 80 | E23: 12 | F23: 8 | G23: 6 | H23: 5 | M23: 1 | N23: 100 | O23: 15 | P23: 10 | Q23: 8 | R23: 7
C24: 5 | D24: 208 | E24: 31 | F24: 21 | G24: 16 | H24: 14 | M24: 5 | N24: 300 | O24: 45 | P24: 30 | Q24: 23 | R24: 20
C25: 10 | D25: 249 | E25: 55 | F25: 37 | G25: 28 | H25: 25 | M25: 10 | N25: 550 | O25: 83 | P25: 55 | Q25: 41 | R25: 37
C26: 20 | D26: 437 | E26: 103 | F26: 69 | G26: 52 | H26: 46 | M26: 20 | N26: 1050 | O26: 158 | P26: 105 | Q26: 79 | R26: 70
C27: 30 | D27: 625 | E27: 151 | F27: 101 | G27: 76 | H27: 67 | M27: 30 | N27: 1550 | O27: 233 | P27: 155 | Q27: 116 | R27: 103
C28: 50 | D28: 1001 | E28: 247 | F28: 165 | G28: 124 | H28: 110 | M28: 50 | N28: 2550 | O28: 383 | P28: 255 | Q28: 191 | R28: 170
C29: 70 | D29: 1377 | E29: 343 | F29: 229 | G29: 172 | H29: 153 | M29: 70 | N29: 3550 | O29: 533 | P29: 355 | Q29: 266 | R29: 237

Sheet Sheet3
A1: id | B1: Name | C1: type | D1: Career | E1: AttackType | F1: Model | G1: Icon | H1: Range | I1: Warn | J1: Move | K1: AtkCd | L1: Hp | M1: Atk | N1: Def | O1: Ap | P1: Mdef | Q1: Dex | R1: Grow | S1: skill | T1: killexp | U1: killgold | V1: Amplify1 | W1: Amplify2
A2: int | B2: string | C2: int | D2: int | E2: int | F2: string | G2: string | H2: int | I2: int | J2: int | K2: int | L2: float | M2: float | N2: float | O2: float | P2: float | Q2: int | R2: float | S2: string | T2: int | U2: int | V2: string | W2: string
A3: 怪物ID | B3: 名称 | C3: 类型 | D3: 初始职业 | E3: 攻击倾向 | F3: 模型 | G3: 头像 | H3: 攻击距离 | I3: 警戒范围 | J3: 移速 | K3: 攻击间隔/10 | L3: 生命 | M3: 攻击 | N3: 防御 | O3: 魔力 | P3: 魔防 | Q3: 技巧 | R3: 成长系数 | S3: 携带技能 | T3: 击杀提供经验 | U3: 击杀提供金矿 | V3: 查看界面放大 | W3: 地图模型放大
A4: 10001 | B4: 史莱黄 | C4: =LEFT(A4,1) -> 1 | D4: 7 | E4: 1 | F4: monster001 | G4: =F4 -> monster001 | H4: 250 | I4: =IF(E4<=2,1500,0) -> 1500 | J4: 250 | K4: 20 | L4: 35 | M4: 6 | N4: 3 | O4: 1 | P4: 2 | Q4: 5 | R4: 0.2 | S4: 0 | T4: 20 | U4: =_xlfn.IFS(C4="1",2,C4="2",5,C4="3",10,C4="4",20,TRUE,0) -> 2 | V4: 1 | W4: =V4 -> 1 | X4: 弱小怪
A5: 10002 | B5: 史莱红 | C5: =LEFT(A5,1) -> 1 | D5: 7 | E5: 1 | F5: monster002 | G5: =F5 -> monster002 | H5: 250 | I5: =IF(E5<=2,1500,0) -> 1500 | J5: 250 | K5: 20 | L5: 35 | M5: 5 | N5: 3 | O5: 4 | P5: 3 | Q5: 5 | R5: 0.2 | S5: 0 | T5: 20 | U5: =_xlfn.IFS(C5="1",2,C5="2",5,C5="3",10,C5="4",20,TRUE,0) -> 2 | V5: 1 | W5: =V5 -> 1 | X5: 物防小怪
A6: 10003 | B6: 史莱黑 | C6: =LEFT(A6,1) -> 1 | D6: 7 | E6: 1 | F6: monster003 | G6: =F6 -> monster003 | H6: 500 | I6: =IF(E6<=2,1500,0) -> 1500 | J6: 250 | K6: 20 | L6: 45 | M6: 6 | N6: 5 | O6: 1 | P6: 4 | Q6: 5 | R6: 0.2 | S6: 0 | T6: 20 | U6: =_xlfn.IFS(C6="1",2,C6="2",5,C6="3",10,C6="4",20,TRUE,0) -> 2 | V6: 1 | W6: =V6 -> 1 | X6: 魔防小怪
A7: 10004 | B7: 小哥布林 | C7: =LEFT(A7,1) -> 1 | D7: 1 | E7: 1 | F7: monster004 | G7: =F7 -> monster004 | H7: 250 | I7: =IF(E7<=2,1500,0) -> 1500 | J7: 400 | K7: 20 | L7: 41 | M7: 5 | N7: 3 | O7: 2 | P7: 2 | Q7: 5 | R7: 0.2 | S7: 0 | T7: 20 | U7: =_xlfn.IFS(C7="1",2,C7="2",5,C7="3",10,C7="4",20,TRUE,0) -> 2 | V7: 1 | W7: =V7 -> 1 | X7: 中小怪
A8: 10005 | B8: 大哥布林 | C8: =LEFT(A8,1) -> 1 | D8: 1 | E8: 1 | F8: monster005 | G8: =F8 -> monster005 | H8: 800 | I8: =IF(E8<=2,1500,0) -> 1500 | J8: 220 | K8: 25 | L8: 43 | M8: 5 | N8: 3 | O8: 2 | P8: 2 | Q8: 5 | R8: 0.2 | S8: 0 | T8: 25 | U8: =_xlfn.IFS(C8="1",2,C8="2",5,C8="3",10,C8="4",20,TRUE,0) -> 2 | V8: 1 | W8: =V8 -> 1 | X8: 正常小怪
A9: 10006 | B9: 哥布林战士 | C9: =LEFT(A9,1) -> 1 | D9: 1 | E9: 1 | F9: monster006 | G9: =F9 -> monster006 | H9: 250 | I9: =IF(E9<=2,1500,0) -> 1500 | J9: 250 | K9: 20 | L9: 45 | M9: 6 | N9: 4 | O9: 3 | P9: 2 | Q9: 6 | R9: 0.2 | S9: 0 | T9: 25 | U9: =_xlfn.IFS(C9="1",2,C9="2",5,C9="3",10,C9="4",20,TRUE,0) -> 2 | V9: 1 | W9: =V9 -> 1
A10: 10007 | B10: 哥布林牧师 | C10: =LEFT(A10,1) -> 1 | D10: 6 | E10: 1 | F10: monster007 | G10: =F10 -> monster007 | H10: 700 | I10: =IF(E10<=2,1500,0) -> 1500 | J10: 220 | K10: 25 | L10: 43 | M10: 5 | N10: 4 | O10: 4 | P10: 4 | Q10: 6 | R10: 0.2 | S10: 0 | T10: 25 | U10: =_xlfn.IFS(C10="1",2,C10="2",5,C10="3",10,C10="4",20,TRUE,0) -> 2 | V10: 1 | W10: =V10 -> 1
A11: 10008 | B11: 哥布林法师 | C11: =LEFT(A11,1) -> 1 | D11: 5 | E11: 1 | F11: monster008 | G11: =F11 -> monster008 | H11: 700 | I11: =IF(E11<=2,1500,0) -> 1500 | J11: 220 | K11: 25 | L11: 42 | M11: 5 | N11: 3 | O11: 5 | P11: 4 | Q11: 6 | R11: 0.2 | S11: 0 | T11: 25 | U11: =_xlfn.IFS(C11="1",2,C11="2",5,C11="3",10,C11="4",20,TRUE,0) -> 2 | V11: 1 | W11: =V11 -> 1
A12: 10009 | B12: 哥布林守卫 | C12: =LEFT(A12,1) -> 1 | D12: 1 | E12: 2 | F12: monster009 | G12: =F12 -> monster009 | H12: 250 | I12: =IF(E12<=2,1500,0) -> 1500 | J12: 250 | K12: 20 | L12: 45 | M12: 7 | N12: 5 | O12: 3 | P12: 5 | Q12: 8 | R12: 0.2 | S12: 0 | T12: 25 | U12: =_xlfn.IFS(C12="1",2,C12="2",5,C12="3",10,C12="4",20,TRUE,0) -> 2 | V12: 1 | W12: =V12 -> 1
A13: 10010 | B13: 哥布林队长 | C13: =LEFT(A13,1) -> 1 | D13: 1 | E13: 2 | F13: monster010 | G13: =F13 -> monster010 | H13: 250 | I13: =IF(E13<=2,1500,0) -> 1500 | J13: 250 | K13: 20 | L13: 45 | M13: 8 | N13: 6 | O13: 3 | P13: 6 | Q13: 8 | R13: 0.2 | S13: 0 | T13: 25 | U13: =_xlfn.IFS(C13="1",2,C13="2",5,C13="3",10,C13="4",20,TRUE,0) -> 2 | V13: 1 | W13: =V13 -> 1
A14: 10011 | B14: 步兵 | C14: =LEFT(A14,1) -> 1 | D14: 1 | E14: 1 | F14: bubing01_Lv1 | G14: =F14 -> bubing01_Lv1 | H14: 250 | I14: =IF(E14<=2,1500,0) -> 1500 | J14: 250 | K14: 15 | L14: 45 | M14: 9 | N14: 5 | O14: 5 | P14: 3 | Q14: 10 | R14: 0.3 | S14: 0 | T14: 30 | U14: =_xlfn.IFS(C14="1",2,C14="2",5,C14="3",10,C14="4",20,TRUE,0) -> 2 | V14: 1 | W14: =V14 -> 1
A15: 10012 | B15: 枪兵 | C15: =LEFT(A15,1) -> 1 | D15: 1 | E15: 1 | F15: bubing02_Lv1 | G15: =F15 -> bubing02_Lv1 | H15: 250 | I15: =IF(E15<=2,1500,0) -> 1500 | J15: 250 | K15: 15 | L15: 50 | M15: 5 | N15: 6 | O15: 5 | P15: 4 | Q15: 10 | R15: 0.3 | S15: 0 | T15: 30 | U15: =_xlfn.IFS(C15="1",2,C15="2",5,C15="3",10,C15="4",20,TRUE,0) -> 2 | V15: 1 | W15: =V15 -> 1
A16: 10013 | B16: 骑兵 | C16: =LEFT(A16,1) -> 1 | D16: 2 | E16: 2 | F16: qibing01_Lv1 | G16: =F16 -> qibing01_Lv1 | H16: 250 | I16: =IF(E16<=2,1500,0) -> 1500 | J16: 400 | K16: 15 | L16: 47 | M16: 9 | N16: 4 | O16: 4 | P16: 4 | Q16: 10 | R16: 0.3 | S16: 0 | T16: 30 | U16: =_xlfn.IFS(C16="1",2,C16="2",5,C16="3",10,C16="4",20,TRUE,0) -> 2 | V16: 1 | W16: =V16 -> 1
A17: 10014 | B17: 木精灵 | C17: =LEFT(A17,1) -> 1 | D17: 3 | E17: 1 | F17: gongbing01_Lv1 | G17: =F17 -> gongbing01_Lv1 | H17: 1000 | I17: =IF(E17<=2,1500,0) -> 1500 | J17: 250 | K17: 20 | L17: 45 | M17: 8 | N17: 3 | O17: 6 | P17: 6 | Q17: 10 | R17: 0.3 | S17: 0 | T17: 30 | U17: =_xlfn.IFS(C17="1",2,C17="2",5,C17="3",10,C17="4",20,TRUE,0) -> 2 | V17: 1 | W17: =V17 -> 1
A18: 10015 | B18: 飞鹰骑士 | C18: =LEFT(A18,1) -> 1 | D18: 4 | E18: 2 | F18: feibing01_Lv1 | G18: =F18 -> feibing01_Lv1 | H18: 250 | I18: =IF(E18<=2,1500,0) -> 1500 | J18: 400 | K18: 15 | L18: 47 | M18: 8 | N18: 5 | O18: 8 | P18: 6 | Q18: 10 | R18: 0.3 | S18: 0 | T18: 30 | U18: =_xlfn.IFS(C18="1",2,C18="2",5,C18="3",10,C18="4",20,TRUE,0) -> 2 | V18: 1 | W18: =V18 -> 1
A19: 10016 | B19: 法师学徒 | C19: =LEFT(A19,1) -> 1 | D19: 5 | E19: 1 | F19: fashi01_Lv1 | G19: =F19 -> fashi01_Lv1 | H19: 1000 | I19: =IF(E19<=2,1500,0) -> 1500 | J19: 250 | K19: 20 | L19: 45 | M19: 5 | N19: 3 | O19: 9 | P19: 5 | Q19: 10 | R19: 0.3 | S19: 0 | T19: 30 | U19: =_xlfn.IFS(C19="1",2,C19="2",5,C19="3",10,C19="4",20,TRUE,0) -> 2 | V19: 1 | W19: =V19 -> 1
A20: 10017 | B20: 僧侣 | C20: =LEFT(A20,1) -> 1 | D20: 6 | E20: 1 | F20: mushi01_Lv1 | G20: =F20 -> mushi01_Lv1 | H20: 1000 | I20: =IF(E20<=2,1500,0) -> 1500 | J20: 250 | K20: 20 | L20: 46 | M20: 5 | N20: 7 | O20: 5 | P20: 10 | Q20: 10 | R20: 0.3 | S20: 0 | T20: 30 | U20: =_xlfn.IFS(C20="1",2,C20="2",5,C20="3",10,C20="4",20,TRUE,0) -> 2 | V20: 1 | W20: =V20 -> 1
A21: 10018 | B21: 骷髅兵 | C21: =LEFT(A21,1) -> 1 | D21: 7 | E21: 2 | F21: moshou01_Lv1 | G21: =F21 -> moshou01_Lv1 | H21: 250 | I21: =IF(E21<=2,1500,0) -> 1500 | J21: 250 | K21: 15 | L21: 48 | M21: 9 | N21: 5 | O21: 5 | P21: 5 | Q21: 10 | R21: 0.3 | S21: 0 | T21: 30 | U21: =_xlfn.IFS(C21="1",2,C21="2",5,C21="3",10,C21="4",20,TRUE,0) -> 2 | V21: 1 | W21: =V21 -> 1
A22: 10019 | B22: 狼战士 | C22: =LEFT(A22,1) -> 1 | D22: 8 | E22: 1 | F22: yeshou01_lv1 | G22: =F22 -> yeshou01_lv1 | H22: 250 | I22: =IF(E22<=2,1500,0) -> 1500 | J22: 250 | K22: 15 | L22: 47 | M22: 10 | N22: 4 | O22: 5 | P22: 5 | Q22: 10 | R22: 0.3 | S22: 0 | T22: 30 | U22: =_xlfn.IFS(C22="1",2,C22="2",5,C22="3",10,C22="4",20,TRUE,0) -> 2 | V22: 1 | W22: =V22 -> 1
A23: 20001 | B23: 野猪首领 | C23: =LEFT(A23,1) -> 2 | D23: 8 | E23: 1 | F23: jymonster001 | G23: =F23 -> jymonster001 | H23: 250 | I23: =IF(E23<=2,1500,0) -> 1500 | J23: 300 | K23: 20 | L23: 55 | M23: 11 | N23: 5 | O23: 5 | P23: 5 | Q23: 10 | R23: 0.3 | S23: 0 | T23: 50 | U23: =_xlfn.IFS(C23="1",2,C23="2",5,C23="3",10,C23="4",20,TRUE,0) -> 5 | V23: 1 | W23: =V23 -> 1 | X23: 弱精英
A24: 20002 | B24: 树精首领 | C24: =LEFT(A24,1) -> 2 | D24: 7 | E24: 1 | F24: jymonster002 | G24: =F24 -> jymonster002 | H24: 800 | I24: =IF(E24<=2,1500,0) -> 1500 | J24: 250 | K24: 25 | L24: 60 | M24: 7 | N24: 6 | O24: 6 | P24: 7 | Q24: 10 | R24: 0.3 | S24: 0 | T24: 50 | U24: =_xlfn.IFS(C24="1",2,C24="2",5,C24="3",10,C24="4",20,TRUE,0) -> 5 | V24: 1 | W24: =V24 -> 1 | X24: 弱精英
A25: 20003 | B25: 甲虫战士 | C25: =LEFT(A25,1) -> 2 | D25: 8 | E25: 1 | F25: jymonster003 | G25: =F25 -> jymonster003 | H25: 250 | I25: =IF(E25<=2,1500,0) -> 1500 | J25: 300 | K25: 20 | L25: 60 | M25: 11 | N25: 6 | O25: 6 | P25: 6 | Q25: 10 | R25: 0.3 | S25: 0 | T25: 50 | U25: =_xlfn.IFS(C25="1",2,C25="2",5,C25="3",10,C25="4",20,TRUE,0) -> 5 | V25: 1 | W25: =V25 -> 1 | X25: 正常精英
A26: 20004 | B26: 史莱金 | C26: =LEFT(A26,1) -> 2 | D26: 7 | E26: 1 | F26: jymonster004 | G26: =F26 -> jymonster004 | H26: 250 | I26: =IF(E26<=2,1500,0) -> 1500 | J26: 250 | K26: 20 | L26: 65 | M26: 12 | N26: 6 | O26: 6 | P26: 6 | Q26: 10 | R26: 0.3 | S26: 0 | T26: 50 | U26: =_xlfn.IFS(C26="1",2,C26="2",5,C26="3",10,C26="4",20,TRUE,0) -> 5 | V26: 1 | W26: =V26 -> 1 | X26: 正常精英
A27: 20005 | B27: 重装步兵 | C27: =LEFT(A27,1) -> 2 | D27: 1 | E27: 1 | F27: bubing01_Lv2 | G27: =F27 -> bubing01_Lv2 | H27: 250 | I27: =IF(E27<=2,1500,0) -> 1500 | J27: 250 | K27: 15 | L27: 76 | M27: 10 | N27: 7 | O27: 6 | P27: 5 | Q27: 15 | R27: 0.4 | S27: 0 | T27: 80 | U27: =_xlfn.IFS(C27="1",2,C27="2",5,C27="3",10,C27="4",20,TRUE,0) -> 5 | V27: 1 | W27: =V27 -> 1
A28: 20006 | B28: 重装枪兵 | C28: =LEFT(A28,1) -> 2 | D28: 1 | E28: 1 | F28: bubing02_Lv2 | G28: =F28 -> bubing02_Lv2 | H28: 250 | I28: =IF(E28<=2,1500,0) -> 1500 | J28: 250 | K28: 15 | L28: 80 | M28: 8 | N28: 8 | O28: 6 | P28: 5 | Q28: 15 | R28: 0.4 | S28: 0 | T28: 80 | U28: =_xlfn.IFS(C28="1",2,C28="2",5,C28="3",10,C28="4",20,TRUE,0) -> 5 | V28: 1 | W28: =V28 -> 1
A29: 20007 | B29: 精锐骑士 | C29: =LEFT(A29,1) -> 2 | D29: 2 | E29: 2 | F29: qibing01_Lv2 | G29: =F29 -> qibing01_Lv2 | H29: 250 | I29: =IF(E29<=2,1500,0) -> 1500 | J29: 400 | K29: 15 | L29: 76 | M29: 11 | N29: 6 | O29: 6 | P29: 5 | Q29: 15 | R29: 0.4 | S29: 0 | T29: 80 | U29: =_xlfn.IFS(C29="1",2,C29="2",5,C29="3",10,C29="4",20,TRUE,0) -> 5 | V29: 1 | W29: =V29 -> 1
A30: 20008 | B30: 精灵射手 | C30: =LEFT(A30,1) -> 2 | D30: 3 | E30: 1 | F30: gongbing01_Lv2 | G30: =F30 -> gongbing01_Lv2 | H30: 1100 | I30: =IF(E30<=2,1500,0) -> 1500 | J30: 250 | K30: 20 | L30: 72 | M30: 9 | N30: 5 | O30: 8 | P30: 5 | Q30: 15 | R30: 0.4 | S30: 0 | T30: 80 | U30: =_xlfn.IFS(C30="1",2,C30="2",5,C30="3",10,C30="4",20,TRUE,0) -> 5 | V30: 1 | W30: =V30 -> 1
A31: 20009 | B31: 飞马骑士 | C31: =LEFT(A31,1) -> 2 | D31: 4 | E31: 2 | F31: feibing01_Lv2 | G31: =F31 -> feibing01_Lv2 | H31: 250 | I31: =IF(E31<=2,1500,0) -> 1500 | J31: 400 | K31: 15 | L31: 74 | M31: 10 | N31: 6 | O31: 9 | P31: 6 | Q31: 15 | R31: 0.4 | S31: 0 | T31: 80 | U31: =_xlfn.IFS(C31="1",2,C31="2",5,C31="3",10,C31="4",20,TRUE,0) -> 5 | V31: 1 | W31: =V31 -> 1
A32: 20010 | B32: 魔女 | C32: =LEFT(A32,1) -> 2 | D32: 5 | E32: 1 | F32: fashi01_Lv2 | G32: =F32 -> fashi01_Lv2 | H32: 1000 | I32: =IF(E32<=2,1500,0) -> 1500 | J32: 250 | K32: 20 | L32: 72 | M32: 8 | N32: 5 | O32: 12 | P32: 8 | Q32: 15 | R32: 0.4 | S32: 0 | T32: 80 | U32: =_xlfn.IFS(C32="1",2,C32="2",5,C32="3",10,C32="4",20,TRUE,0) -> 5 | V32: 1 | W32: =V32 -> 1
A33: 20011 | B33: 神官 | C33: =LEFT(A33,1) -> 2 | D33: 6 | E33: 1 | F33: mushi01_Lv2 | G33: =F33 -> mushi01_Lv2 | H33: 1000 | I33: =IF(E33<=2,1500,0) -> 1500 | J33: 250 | K33: 20 | L33: 70 | M33: 8 | N33: 5 | O33: 11 | P33: 7 | Q33: 15 | R33: 0.4 | S33: 0 | T33: 80 | U33: =_xlfn.IFS(C33="1",2,C33="2",5,C33="3",10,C33="4",20,TRUE,0) -> 5 | V33: 1 | W33: =V33 -> 1
A34: 20012 | B34: 骷髅勇士 | C34: =LEFT(A34,1) -> 2 | D34: 7 | E34: 2 | F34: moshou01_Lv2 | G34: =F34 -> moshou01_Lv2 | H34: 250 | I34: =IF(E34<=2,1500,0) -> 1500 | J34: 250 | K34: 15 | L34: 76 | M34: 10 | N34: 6 | O34: 5 | P34: 4 | Q34: 15 | R34: 0.4 | S34: 0 | T34: 80 | U34: =_xlfn.IFS(C34="1",2,C34="2",5,C34="3",10,C34="4",20,TRUE,0) -> 5 | V34: 1 | W34: =V34 -> 1
A35: 20013 | B35: 狼人统领 | C35: =LEFT(A35,1) -> 2 | D35: 8 | E35: 1 | F35: yeshou01_lv2 | G35: =F35 -> yeshou01_lv2 | H35: 250 | I35: =IF(E35<=2,1500,0) -> 1500 | J35: 250 | K35: 15 | L35: 80 | M35: 12 | N35: 5 | O35: 5 | P35: 4 | Q35: 15 | R35: 0.4 | S35: 0 | T35: 80 | U35: =_xlfn.IFS(C35="1",2,C35="2",5,C35="3",10,C35="4",20,TRUE,0) -> 5 | V35: 1 | W35: =V35 -> 1
A36: 30001 | B36: 神秘史莱紫 | C36: =LEFT(A36,1) -> 3 | D36: 7 | E36: 1 | F36: boss001 | G36: =F36 -> boss001 | H36: 800 | I36: =IF(E36<=2,1500,0) -> 1500 | J36: 250 | K36: 25 | L36: 80 | M36: 8 | N36: 5 | O36: 12 | P36: 8 | Q36: 15 | R36: 0.4 | S36: 0 | T36: 100 | U36: =_xlfn.IFS(C36="1",2,C36="2",5,C36="3",10,C36="4",20,TRUE,0) -> 10 | V36: 1 | W36: =V36 -> 1 | X36: 弱BOSS
A37: 30002 | B37: 哥布林将军 | C37: =LEFT(A37,1) -> 3 | D37: 1 | E37: 2 | F37: boss002 | G37: =F37 -> boss002 | H37: 250 | I37: =IF(E37<=2,1500,0) -> 1500 | J37: 250 | K37: 20 | L37: 80 | M37: 8 | N37: 8 | O37: 6 | P37: 5 | Q37: 15 | R37: 0.4 | S37: 0 | T37: 100 | U37: =_xlfn.IFS(C37="1",2,C37="2",5,C37="3",10,C37="4",20,TRUE,0) -> 10 | V37: 1 | W37: =V37 -> 1
A38: 30003 | B38: 牛头人战士 | C38: =LEFT(A38,1) -> 3 | D38: 1 | E38: 2 | F38: boss003 | G38: =F38 -> boss003 | H38: 250 | I38: =IF(E38<=2,1500,0) -> 1500 | J38: 250 | K38: 20 | L38: 80 | M38: 10 | N38: 7 | O38: 6 | P38: 5 | Q38: 15 | R38: 0.4 | S38: 0 | T38: 100 | U38: =_xlfn.IFS(C38="1",2,C38="2",5,C38="3",10,C38="4",20,TRUE,0) -> 10 | V38: 1 | W38: =V38 -> 1
A39: 30004 | B39: 皇室近卫 | C39: =LEFT(A39,1) -> 3 | D39: 1 | E39: 1 | F39: bubing01_Lv3 | G39: =F39 -> bubing01_Lv3 | H39: 250 | I39: =IF(E39<=2,1500,0) -> 1500 | J39: 250 | K39: 15 | L39: 98 | M39: 13 | N39: 8 | O39: 7 | P39: 7 | Q39: 15 | R39: 0.5 | S39: 0 | T39: 120 | U39: =_xlfn.IFS(C39="1",2,C39="2",5,C39="3",10,C39="4",20,TRUE,0) -> 10 | V39: 1 | W39: =V39 -> 1
A40: 30005 | B40: 刀锋战士 | C40: =LEFT(A40,1) -> 3 | D40: 1 | E40: 1 | F40: bubing02_Lv3 | G40: =F40 -> bubing02_Lv3 | H40: 250 | I40: =IF(E40<=2,1500,0) -> 1500 | J40: 250 | K40: 15 | L40: 96 | M40: 14 | N40: 7 | O40: 6 | P40: 6 | Q40: 15 | R40: 0.5 | S40: 0 | T40: 120 | U40: =_xlfn.IFS(C40="1",2,C40="2",5,C40="3",10,C40="4",20,TRUE,0) -> 10 | V40: 1 | W40: =V40 -> 1
...

Sheet 环形怪物属性
E1: 0.2 | F1: 3 | G1: 300 | H1: 0.15 | I1: 1.5 | J1: 10 | K1: 0.1 | L1: 0.5 | M1: 3 | N1: =H1 -> 0.15 | O1: =I1 -> 1.5 | P1: =J1 -> 10 | Q1: 0.1 | R1: 0.5 | S1: 3
A2: id | B2: Name | C2: type | D2: Career | E2: AttackType | F2: Hp | G2: Hp | I2: Atk | L2: Def | O2: Ap | R2: Mdef
A3: int | B3: string | C3: int | D3: int | E3: int | F3: float | G3: float | I3: float | L3: float | O3: float | R3: float
A4: 怪物ID | B4: 名称 | C4: 类型 | D4: 初始职业 | E4: 攻击倾向 | F4: 生命 | G4: 原本生命 | H4: 攻击 | I4: 原本攻击 | K4: 防御 | L4: 原本防御 | N4: 魔力 | O4: 原本魔力 | Q4: 魔防 | R4: 原本魔防
A5: 10001 | B5: 史莱黄 | C5: =LEFT(A5,1) -> 1 | D5: 7 | E5: 1 | F5: =INT(G5*$F$1+(C5*$E$1*G5)+$G$1) -> 415 | G5: 36 | H5: =INT(I5*$I$1+(C5*$H$1*I5)+$J$1) -> 36 | I5: 16 | K5: =INT(L5*$L$1+(C5*$K$1*L5)+$M$1) -> 4 | L5: 3 | N5: =INT(O5*$O$1+(C5*$N$1*O5)+$P$1) -> 23 | O5: 8 | Q5: =INT(R5*$R$1+(C5*$Q$1*R5)+$S$1) -> 4 | R5: =L5 -> 3
A6: 10002 | B6: 史莱红 | C6: =LEFT(A6,1) -> 1 | D6: 7 | E6: 1 | F6: =INT(G6*$F$1+(C6*$E$1*G6)+$G$1) -> 419 | G6: 37.2 | H6: =INT(I6*$I$1+(C6*$H$1*I6)+$J$1) -> 36 | I6: 16 | K6: =INT(L6*$L$1+(C6*$K$1*L6)+$M$1) -> 4 | L6: 3 | N6: =INT(O6*$O$1+(C6*$N$1*O6)+$P$1) -> 23 | O6: 8 | Q6: =INT(R6*$R$1+(C6*$Q$1*R6)+$S$1) -> 4 | R6: =L6 -> 3
A7: 10003 | B7: 史莱黑 | C7: =LEFT(A7,1) -> 1 | D7: 7 | E7: 1 | F7: =INT(G7*$F$1+(C7*$E$1*G7)+$G$1) -> 422 | G7: 38.4 | H7: =INT(I7*$I$1+(C7*$H$1*I7)+$J$1) -> 26 | I7: 10 | K7: =INT(L7*$L$1+(C7*$K$1*L7)+$M$1) -> 4 | L7: 3 | N7: =INT(O7*$O$1+(C7*$N$1*O7)+$P$1) -> 28 | O7: 11 | Q7: =INT(R7*$R$1+(C7*$Q$1*R7)+$S$1) -> 4 | R7: =L7 -> 3
A8: 10004 | B8: 小哥布林 | C8: =LEFT(A8,1) -> 1 | D8: 7 | E8: 1 | F8: =INT(G8*$F$1+(C8*$E$1*G8)+$G$1) -> 426 | G8: 39.6 | H8: =INT(I8*$I$1+(C8*$H$1*I8)+$J$1) -> 38 | I8: 17 | K8: =INT(L8*$L$1+(C8*$K$1*L8)+$M$1) -> 5 | L8: 4 | N8: =INT(O8*$O$1+(C8*$N$1*O8)+$P$1) -> 24 | O8: 9 | Q8: =INT(R8*$R$1+(C8*$Q$1*R8)+$S$1) -> 5 | R8: =L8 -> 4
A9: 10005 | B9: 大哥布林 | C9: =LEFT(A9,1) -> 1 | D9: 7 | E9: 1 | F9: =INT(G9*$F$1+(C9*$E$1*G9)+$G$1) -> 430 | G9: 40.8 | H9: =INT(I9*$I$1+(C9*$H$1*I9)+$J$1) -> 39 | I9: 18 | K9: =INT(L9*$L$1+(C9*$K$1*L9)+$M$1) -> 5 | L9: 4 | N9: =INT(O9*$O$1+(C9*$N$1*O9)+$P$1) -> 24 | O9: 9 | Q9: =INT(R9*$R$1+(C9*$Q$1*R9)+$S$1) -> 5 | R9: =L9 -> 4
A10: 10006 | B10: 哥布林战士 | C10: =LEFT(A10,1) -> 1 | D10: 7 | E10: 1 | F10: =INT(G10*$F$1+(C10*$E$1*G10)+$G$1) -> 434 | G10: 42 | H10: =INT(I10*$I$1+(C10*$H$1*I10)+$J$1) -> 41 | I10: 19 | K10: =INT(L10*$L$1+(C10*$K$1*L10)+$M$1) -> 6 | L10: 5 | N10: =INT(O10*$O$1+(C10*$N$1*O10)+$P$1) -> 26 | O10: 10 | Q10: =INT(R10*$R$1+(C10*$Q$1*R10)+$S$1) -> 6 | R10: =L10 -> 5
A11: 10007 | B11: 哥布林牧师 | C11: =LEFT(A11,1) -> 1 | D11: 6 | E11: 1 | F11: =INT(G11*$F$1+(C11*$E$1*G11)+$G$1) -> 419 | G11: 37.2 | H11: =INT(I11*$I$1+(C11*$H$1*I11)+$J$1) -> 24 | I11: 9 | K11: =INT(L11*$L$1+(C11*$K$1*L11)+$M$1) -> 6 | L11: 5 | N11: =INT(O11*$O$1+(C11*$N$1*O11)+$P$1) -> 39 | O11: 18 | Q11: =INT(R11*$R$1+(C11*$Q$1*R11)+$S$1) -> 6 | R11: =L11 -> 5
A12: 10008 | B12: 哥布林法师 | C12: =LEFT(A12,1) -> 1 | D12: 5 | E12: 1 | F12: =INT(G12*$F$1+(C12*$E$1*G12)+$G$1) -> 422 | G12: 38.4 | H12: =INT(I12*$I$1+(C12*$H$1*I12)+$J$1) -> 26 | I12: 10 | K12: =INT(L12*$L$1+(C12*$K$1*L12)+$M$1) -> 6 | L12: 5 | N12: =INT(O12*$O$1+(C12*$N$1*O12)+$P$1) -> 39 | O12: 18 | Q12: =INT(R12*$R$1+(C12*$Q$1*R12)+$S$1) -> 6 | R12: =L12 -> 5
A13: 10009 | B13: 哥布林射手 | C13: =LEFT(A13,1) -> 1 | D13: 3 | E13: 1 | F13: =INT(G13*$F$1+(C13*$E$1*G13)+$G$1) -> 426 | G13: 39.6 | H13: =INT(I13*$I$1+(C13*$H$1*I13)+$J$1) -> 38 | I13: 17 | K13: =INT(L13*$L$1+(C13*$K$1*L13)+$M$1) -> 6 | L13: 6 | N13: =INT(O13*$O$1+(C13*$N$1*O13)+$P$1) -> 28 | O13: 11 | Q13: =INT(R13*$R$1+(C13*$Q$1*R13)+$S$1) -> 6 | R13: =L13 -> 6
A14: 10010 | B14: 哥布林队长 | C14: =LEFT(A14,1) -> 1 | D14: 1 | E14: 1 | F14: =INT(G14*$F$1+(C14*$E$1*G14)+$G$1) -> 453 | G14: 48 | H14: =INT(I14*$I$1+(C14*$H$1*I14)+$J$1) -> 47 | I14: 23 | K14: =INT(L14*$L$1+(C14*$K$1*L14)+$M$1) -> 7 | L14: 7 | N14: =INT(O14*$O$1+(C14*$N$1*O14)+$P$1) -> 29 | O14: 12 | Q14: =INT(R14*$R$1+(C14*$Q$1*R14)+$S$1) -> 7 | R14: =L14 -> 7
A15: 10011 | B15: 步兵 | C15: =LEFT(A15,1) -> 1 | D15: 1 | E15: 1 | F15: =INT(G15*$F$1+(C15*$E$1*G15)+$G$1) -> 472 | G15: 54 | H15: =INT(I15*$I$1+(C15*$H$1*I15)+$J$1) -> 51 | I15: 25 | K15: =INT(L15*$L$1+(C15*$K$1*L15)+$M$1) -> 9 | L15: 10 | N15: =INT(O15*$O$1+(C15*$N$1*O15)+$P$1) -> 26 | O15: 10 | Q15: =INT(R15*$R$1+(C15*$Q$1*R15)+$S$1) -> 4 | R15: 3
A16: 10012 | B16: 枪兵 | C16: =LEFT(A16,1) -> 1 | D16: 1 | E16: 1 | F16: =INT(G16*$F$1+(C16*$E$1*G16)+$G$1) -> 492 | G16: 60 | H16: =INT(I16*$I$1+(C16*$H$1*I16)+$J$1) -> 44 | I16: 21 | K16: =INT(L16*$L$1+(C16*$K$1*L16)+$M$1) -> 9 | L16: 11 | N16: =INT(O16*$O$1+(C16*$N$1*O16)+$P$1) -> 26 | O16: 10 | Q16: =INT(R16*$R$1+(C16*$Q$1*R16)+$S$1) -> 5 | R16: 4
A17: 10013 | B17: 骑兵 | C17: =LEFT(A17,1) -> 1 | D17: 2 | E17: 1 | F17: =INT(G17*$F$1+(C17*$E$1*G17)+$G$1) -> 480 | G17: 56.4 | H17: =INT(I17*$I$1+(C17*$H$1*I17)+$J$1) -> 51 | I17: 25 | K17: =INT(L17*$L$1+(C17*$K$1*L17)+$M$1) -> 8 | L17: 9 | N17: =INT(O17*$O$1+(C17*$N$1*O17)+$P$1) -> 24 | O17: 9 | Q17: =INT(R17*$R$1+(C17*$Q$1*R17)+$S$1) -> 5 | R17: 4
A18: 10014 | B18: 木精灵 | C18: =LEFT(A18,1) -> 1 | D18: 3 | E18: 1 | F18: =INT(G18*$F$1+(C18*$E$1*G18)+$G$1) -> 434 | G18: 42 | H18: =INT(I18*$I$1+(C18*$H$1*I18)+$J$1) -> 41 | I18: 19 | K18: =INT(L18*$L$1+(C18*$K$1*L18)+$M$1) -> 7 | L18: 8 | N18: =INT(O18*$O$1+(C18*$N$1*O18)+$P$1) -> 28 | O18: 11 | Q18: =INT(R18*$R$1+(C18*$Q$1*R18)+$S$1) -> 6 | R18: 6
A19: 10015 | B19: 飞鹰骑士 | C19: =LEFT(A19,1) -> 1 | D19: 4 | E19: 1 | F19: =INT(G19*$F$1+(C19*$E$1*G19)+$G$1) -> 480 | G19: 56.4 | H19: =INT(I19*$I$1+(C19*$H$1*I19)+$J$1) -> 49 | I19: 24 | K19: =INT(L19*$L$1+(C19*$K$1*L19)+$M$1) -> 9 | L19: 10 | N19: =INT(O19*$O$1+(C19*$N$1*O19)+$P$1) -> 31 | O19: 13 | Q19: =INT(R19*$R$1+(C19*$Q$1*R19)+$S$1) -> 6 | R19: 6
A20: 10016 | B20: 法师学徒 | C20: =LEFT(A20,1) -> 1 | D20: 5 | E20: 1 | F20: =INT(G20*$F$1+(C20*$E$1*G20)+$G$1) -> 434 | G20: 42 | H20: =INT(I20*$I$1+(C20*$H$1*I20)+$J$1) -> 26 | I20: 10 | K20: =INT(L20*$L$1+(C20*$K$1*L20)+$M$1) -> 7 | L20: 8 | N20: =INT(O20*$O$1+(C20*$N$1*O20)+$P$1) -> 43 | O20: 20 | Q20: =INT(R20*$R$1+(C20*$Q$1*R20)+$S$1) -> 6 | R20: 5
A21: 10017 | B21: 僧侣 | C21: =LEFT(A21,1) -> 1 | D21: 6 | E21: 1 | F21: =INT(G21*$F$1+(C21*$E$1*G21)+$G$1) -> 438 | G21: 43.2 | H21: =INT(I21*$I$1+(C21*$H$1*I21)+$J$1) -> 26 | I21: 10 | K21: =INT(L21*$L$1+(C21*$K$1*L21)+$M$1) -> 10 | L21: 12 | N21: =INT(O21*$O$1+(C21*$N$1*O21)+$P$1) -> 39 | O21: 18 | Q21: =INT(R21*$R$1+(C21*$Q$1*R21)+$S$1) -> 9 | R21: 10
A22: 10018 | B22: 骷髅兵 | C22: =LEFT(A22,1) -> 1 | D22: 7 | E22: 1 | F22: =INT(G22*$F$1+(C22*$E$1*G22)+$G$1) -> 484 | G22: 57.6 | H22: =INT(I22*$I$1+(C22*$H$1*I22)+$J$1) -> 43 | I22: 20 | K22: =INT(L22*$L$1+(C22*$K$1*L22)+$M$1) -> 9 | L22: 10 | N22: =INT(O22*$O$1+(C22*$N$1*O22)+$P$1) -> 26 | O22: 10 | Q22: =INT(R22*$R$1+(C22*$Q$1*R22)+$S$1) -> 6 | R22: 5
A23: 10019 | B23: 狼战士 | C23: =LEFT(A23,1) -> 1 | D23: 8 | E23: 1 | F23: =INT(G23*$F$1+(C23*$E$1*G23)+$G$1) -> 461 | G23: 50.4 | H23: =INT(I23*$I$1+(C23*$H$1*I23)+$J$1) -> 52 | I23: 26 | K23: =INT(L23*$L$1+(C23*$K$1*L23)+$M$1) -> 8 | L23: 9 | N23: =INT(O23*$O$1+(C23*$N$1*O23)+$P$1) -> 26 | O23: 10 | Q23: =INT(R23*$R$1+(C23*$Q$1*R23)+$S$1) -> 6 | R23: 5
A24: 10020 | B24: 骷髅兵 | C24: =LEFT(A24,1) -> 1 | D24: 7 | E24: 1 | F24: =INT(G24*$F$1+(C24*$E$1*G24)+$G$1) -> 434 | G24: 42 | H24: =INT(I24*$I$1+(C24*$H$1*I24)+$J$1) -> 43 | I24: 20 | K24: =INT(L24*$L$1+(C24*$K$1*L24)+$M$1) -> 8 | L24: 9 | N24: =INT(O24*$O$1+(C24*$N$1*O24)+$P$1) -> 26 | O24: 10 | Q24: =INT(R24*$R$1+(C24*$Q$1*R24)+$S$1) -> 6 | R24: 5
A25: 10021 | B25: 骷髅卫士 | C25: =LEFT(A25,1) -> 1 | D25: 7 | E25: 1 | F25: =INT(G25*$F$1+(C25*$E$1*G25)+$G$1) -> 438 | G25: 43.2 | H25: =INT(I25*$I$1+(C25*$H$1*I25)+$J$1) -> 39 | I25: 18 | K25: =INT(L25*$L$1+(C25*$K$1*L25)+$M$1) -> 9 | L25: 11 | N25: =INT(O25*$O$1+(C25*$N$1*O25)+$P$1) -> 26 | O25: 10 | Q25: =INT(R25*$R$1+(C25*$Q$1*R25)+$S$1) -> 6 | R25: 5
A26: 10022 | B26: 骷髅射手 | C26: =LEFT(A26,1) -> 1 | D26: 7 | E26: 1 | F26: =INT(G26*$F$1+(C26*$E$1*G26)+$G$1) -> 399 | G26: 31.2 | H26: =INT(I26*$I$1+(C26*$H$1*I26)+$J$1) -> 44 | I26: 21 | K26: =INT(L26*$L$1+(C26*$K$1*L26)+$M$1) -> 8 | L26: 9 | N26: =INT(O26*$O$1+(C26*$N$1*O26)+$P$1) -> 26 | O26: 10 | Q26: =INT(R26*$R$1+(C26*$Q$1*R26)+$S$1) -> 6 | R26: 5
... A114: 30040 | B114: 炎石巨人 | C114: =LEFT(A114,1) -> 3 | D114: 1 | E114: 1 | F114: =INT(G114*$F$1+(C114*$E$1*G114)+$G$1) -> 2262 | G114: 545 | H114: =INT(I114*$I$1+(C114*$H$1*I114)+$J$1) -> 58 | I114: 24.8 | K114: =INT(L114*$L$1+(C114*$K$1*L114)+$M$1) -> 18 | L114: 19.8 | N114: =INT(O114*$O$1+(C114*$N$1*O114)+$P$1) -> 29 | O114: 10 | Q114: =INT(R114*$R$1+(C114*$Q$1*R114)+$S$1) -> 15 | R114: 15
A115: 40001 | B115: 皇室近卫 | C115: 4 | D115: 1 | E115: 1 | F115: =INT(G115*$F$1+(C115*$E$1*G115)+$G$1) -> 4062 | G115: 990 | H115: =INT(I115*$I$1+(C115*$H$1*I115)+$J$1) -> 64 | I115: 25.9 | K115: =INT(L115*$L$1+(C115*$K$1*L115)+$M$1) -> 19 | L115: 18.6 | N115: =INT(O115*$O$1+(C115*$N$1*O115)+$P$1) -> 31 | O115: 10 | Q115: =INT(R115*$R$1+(C115*$Q$1*R115)+$S$1) -> 13 | R115: 12
A116: 40002 | B116: 刀锋战士 | C116: 4 | D116: 1 | E116: 1 | F116: =INT(G116*$F$1+(C116*$E$1*G116)+$G$1) -> 3796 | G116: 920 | H116: =INT(I116*$I$1+(C116*$H$1*I116)+$J$1) -> 66 | I116: 27 | K116: =INT(L116*$L$1+(C116*$K$1*L116)+$M$1) -> 18 | L116: 17.4 | N116: =INT(O116*$O$1+(C116*$N$1*O116)+$P$1) -> 28 | O116: 9 | Q116: =INT(R116*$R$1+(C116*$Q$1*R116)+$S$1) -> 12 | R116: 11
A117: 40003 | B117: 格斗专家 | C117: 4 | D117: 1 | E117: 1 | F117: =INT(G117*$F$1+(C117*$E$1*G117)+$G$1) -> 4062 | G117: 990 | H117: =INT(I117*$I$1+(C117*$H$1*I117)+$J$1) -> 62 | I117: 24.8 | K117: =INT(L117*$L$1+(C117*$K$1*L117)+$M$1) -> 18 | L117: 17.4 | N117: =INT(O117*$O$1+(C117*$N$1*O117)+$P$1) -> 28 | O117: 9 | Q117: =INT(R117*$R$1+(C117*$Q$1*R117)+$S$1) -> 12 | R117: 11
A118: 40004 | B118: 将军 | C118: 4 | D118: 1 | E118: 1 | F118: =INT(G118*$F$1+(C118*$E$1*G118)+$G$1) -> 4328 | G118: 1060 | H118: =INT(I118*$I$1+(C118*$H$1*I118)+$J$1) -> 57 | I118: 22.6 | K118: =INT(L118*$L$1+(C118*$K$1*L118)+$M$1) -> 21 | L118: 21 | N118: =INT(O118*$O$1+(C118*$N$1*O118)+$P$1) -> 26 | O118: 8 | Q118: =INT(R118*$R$1+(C118*$Q$1*R118)+$S$1) -> 12 | R118: 10
A119: 40005 | B119: 皇家骑士 | C119: 4 | D119: 2 | E119: 1 | F119: =INT(G119*$F$1+(C119*$E$1*G119)+$G$1) -> 4328 | G119: 1060 | H119: =INT(I119*$I$1+(C119*$H$1*I119)+$J$1) -> 64 | I119: 25.9 | K119: =INT(L119*$L$1+(C119*$K$1*L119)+$M$1) -> 19 | L119: 18.6 | N119: =INT(O119*$O$1+(C119*$N$1*O119)+$P$1) -> 28 | O119: 9 | Q119: =INT(R119*$R$1+(C119*$Q$1*R119)+$S$1) -> 14 | R119: 13
A120: 40006 | B120: 黑暗骑士 | C120: 4 | D120: 2 | E120: 1 | F120: =INT(G120*$F$1+(C120*$E$1*G120)+$G$1) -> 3796 | G120: 920 | H120: =INT(I120*$I$1+(C120*$H$1*I120)+$J$1) -> 66 | I120: 27 | K120: =INT(L120*$L$1+(C120*$K$1*L120)+$M$1) -> 18 | L120: 17.4 | N120: =INT(O120*$O$1+(C120*$N$1*O120)+$P$1) -> 28 | O120: 9 | Q120: =INT(R120*$R$1+(C120*$Q$1*R120)+$S$1) -> 13 | R120: 12
A121: 40007 | B121: 守护骑士 | C121: 4 | D121: 2 | E121: 1 | F121: =INT(G121*$F$1+(C121*$E$1*G121)+$G$1) -> 4062 | G121: 990 | H121: =INT(I121*$I$1+(C121*$H$1*I121)+$J$1) -> 62 | I121: 24.8 | K121: =INT(L121*$L$1+(C121*$K$1*L121)+$M$1) -> 20 | L121: 19.8 | N121: =INT(O121*$O$1+(C121*$N$1*O121)+$P$1) -> 31 | O121: 10 | Q121: =INT(R121*$R$1+(C121*$Q$1*R121)+$S$1) -> 13 | R121: 12
A122: 40008 | B122: 幻影射手 | C122: 4 | D122: 3 | E122: 1 | F122: =INT(G122*$F$1+(C122*$E$1*G122)+$G$1) -> 3264 | G122: 780 | H122: =INT(I122*$I$1+(C122*$H$1*I122)+$J$1) -> 52 | I122: 20.4 | K122: =INT(L122*$L$1+(C122*$K$1*L122)+$M$1) -> 18 | L122: 17.4 | N122: =INT(O122*$O$1+(C122*$N$1*O122)+$P$1) -> 28 | O122: 9 | Q122: =INT(R122*$R$1+(C122*$Q$1*R122)+$S$1) -> 13 | R122: 12
A123: 40009 | B123: 巡游射手 | C123: 4 | D123: 3 | E123: 1 | F123: =INT(G123*$F$1+(C123*$E$1*G123)+$G$1) -> 3530 | G123: 850 | H123: =INT(I123*$I$1+(C123*$H$1*I123)+$J$1) -> 55 | I123: 21.5 | K123: =INT(L123*$L$1+(C123*$K$1*L123)+$M$1) -> 18 | L123: 17.4 | N123: =INT(O123*$O$1+(C123*$N$1*O123)+$P$1) -> 28 | O123: 9 | Q123: =INT(R123*$R$1+(C123*$Q$1*R123)+$S$1) -> 13 | R123: 12
A124: 40010 | B124: 影 | C124: 4 | D124: 3 | E124: 1 | F124: =INT(G124*$F$1+(C124*$E$1*G124)+$G$1) -> 2998 | G124: 710 | H124: =INT(I124*$I$1+(C124*$H$1*I124)+$J$1) -> 57 | I124: 22.6 | K124: =INT(L124*$L$1+(C124*$K$1*L124)+$M$1) -> 18 | L124: 17.4 | N124: =INT(O124*$O$1+(C124*$N$1*O124)+$P$1) -> 28 | O124: 9 | Q124: =INT(R124*$R$1+(C124*$Q$1*R124)+$S$1) -> 13 | R124: 12
A125: 40011 | B125: 圣天马骑士 | C125: 4 | D125: 4 | E125: 1 | F125: =INT(G125*$F$1+(C125*$E$1*G125)+$G$1) -> 3796 | G125: 920 | H125: =INT(I125*$I$1+(C125*$H$1*I125)+$J$1) -> 64 | I125: 25.9 | K125: =INT(L125*$L$1+(C125*$K$1*L125)+$M$1) -> 19 | L125: 18.6 | N125: =INT(O125*$O$1+(C125*$N$1*O125)+$P$1) -> 33 | O125: 11 | Q125: =INT(R125*$R$1+(C125*$Q$1*R125)+$S$1) -> 16 | R125: 15
A126: 40012 | B126: 飞龙骑士 | C126: 4 | D126: 4 | E126: 1 | F126: =INT(G126*$F$1+(C126*$E$1*G126)+$G$1) -> 4328 | G126: 1060 | H126: =INT(I126*$I$1+(C126*$H$1*I126)+$J$1) -> 66 | I126: 27 | K126: =INT(L126*$L$1+(C126*$K$1*L126)+$M$1) -> 19 | L126: 18.6 | N126: =INT(O126*$O$1+(C126*$N$1*O126)+$P$1) -> 28 | O126: 9 | Q126: =INT(R126*$R$1+(C126*$Q$1*R126)+$S$1) -> 12 | R126: 11
... A146: 42003 | B146: 牛头人战士 | C146: 4 | D146: 1 | E146: 1 | F146: =INT(G146*$F$1+(C146*$E$1*G146)+$G$1) -> 2998 | G146: 710 | H146: =INT(I146*$I$1+(C146*$H$1*I146)+$J$1) -> 57 | I146: 22.6 | K146: =INT(L146*$L$1+(C146*$K$1*L146)+$M$1) -> 18 | L146: 17.4 | N146: =INT(O146*$O$1+(C146*$N$1*O146)+$P$1) -> 28 | O146: 9 | Q146: =INT(R146*$R$1+(C146*$Q$1*R146)+$S$1) -> 12 | R146: 10
