Workbook

Sheet PveMap
A1: Id | B1: Name | C1: MapID | D1: Num | E1: Mapmodel | F1: Mapaudio | G1: SpecifyID | H1: DiffcultId | I1: NextLevel | J1: ChaptersLv | K1: Random | L1: Startfood | M1: StartCoin | N1: ChaptersLv | O1: Lv | P1: Exp | Q1: BossReward | R1: Energy | S1: Tips
A2: int | B2: string | C2: int | D2: int | E2: string | F2: string | G2: string | H2: int | I2: int | J2: int | K2: string | L2: int | M2: int | N2: int | O2: int | P2: int | Q2: string | R2: int | S2: string
A3: 主键 | B3: 名称 | C3: 随机表ID | D3: 地块数量 | E3: 地图 | F3: 背景音乐 | G3: 特定地图ID | H3: 关卡难度 | I3: 下一个关卡id | J3: 关卡等级 | K3: 地块分布数量 | L3: 初始食物 | M3: 初始金币 | N3: 关卡等级 | O3: 简单怪物等级 | P3: 每关怪物经验 | Q3: 扫荡#首通#三星 | R3: 消耗体力 | S3: 关卡提示
A4: 11 | B4: 北方边境 | C4: 98 | D4: 1 | E4: MapBingXue1 | F4: MapBingXue | G4: =VLOOKUP(C4,Sheet3!I:J,2,FALSE) -> 98301 | H4: 2 | I4: =A5 -> 12 | J4: 1 | K4: =_xlfn.IFS(D4=1,Sheet3!$C$1,D4=2,Sheet3!$C$2,D4=3,Sheet3!$C$3,D4=4,Sheet3!$C$4,D4=5,Sheet3!$C$5) -> 1:1|3:1|4:2 | L4: 1000 | M4: 0 | N4: 1 | O4: =H4+J4 -> 3 | P4: 15 | Q4: 1:12:1000|1:20001:2#1:11:200|1:24:1|1:1010102:1|1:1010103:1|1:20001:2#1:11:200|1:22:2|1:24:2 | R4: 10 | S4: 占领全部领地获取胜利
A5: 12 | B5: 北方边境 | C5: 99 | D5: 1 | E5: MapBingXue1 | F5: MapBingXue | G5: =VLOOKUP(C5,Sheet3!I:J,2,FALSE) -> 99301 | H5: 1 | I5: =A6 -> 13 | J5: 2 | K5: =_xlfn.IFS(D5=1,Sheet3!$C$1,D5=2,Sheet3!$C$2,D5=3,Sheet3!$C$3,D5=4,Sheet3!$C$4,D5=5,Sheet3!$C$5) -> 1:1|3:1|4:2 | L5: 450 | M5: 0 | N5: 2 | O5: =H5+J5 -> 3 | P5: =P4 -> 15 | Q5: 1:12:1000|1:20001:2#1:11:200|1:24:1|1:1010102:1|1:1010103:1|1:20001:2#1:11:200|1:22:2|1:24:2 | R5: 10 | S5: 枪兵对骑兵会有奇效
A6: 13 | B6: 北方边境 | C6: 100 | D6: 1 | E6: MapBingXue1 | F6: MapBingXue | G6: =VLOOKUP(C6,Sheet3!I:J,2,FALSE) -> 100301 | H6: 1 | I6: =A7 -> 14 | J6: 3 | K6: =_xlfn.IFS(D6=1,Sheet3!$C$1,D6=2,Sheet3!$C$2,D6=3,Sheet3!$C$3,D6=4,Sheet3!$C$4,D6=5,Sheet3!$C$5) -> 1:1|3:1|4:2 | L6: 450 | M6: 0 | N6: 3 | O6: =H6+J6 -> 4 | P6: =P5 -> 15 | Q6: 1:12:1000|1:20001:2#1:11:200|1:24:1|1:1010102:1|1:1010103:1|1:20001:2#1:11:200|1:22:2|1:24:2 | R6: 10 | S6: 小心飞兵进攻，用弓兵消灭他们吧
A7: 14 | B7: 北方边境 | C7: 101 | D7: 1 | E7: MapBingXue1 | F7: MapBingXue | G7: =VLOOKUP(C7,Sheet3!I:J,2,FALSE) -> 101301 | H7: 2 | I7: =A8 -> 15 | J7: 4 | K7: =_xlfn.IFS(D7=1,Sheet3!$C$1,D7=2,Sheet3!$C$2,D7=3,Sheet3!$C$3,D7=4,Sheet3!$C$4,D7=5,Sheet3!$C$5) -> 1:1|3:1|4:2 | L7: 450 | M7: 0 | N7: 4 | O7: =H7+J7 -> 6 | P7: =P6 -> 15 | Q7: 1:12:1000|1:20001:2#1:11:200|1:24:1|1:1010102:1|1:1010103:1|1:20001:2#1:11:200|1:22:2|1:24:2 | R7: 10 | S7: 0
A8: 15 | B8: 北方边境 | C8: 201 | D8: 2 | E8: MapBingXue1 | F8: MapBingXue | G8: =VLOOKUP(C8,Sheet3!I:J,2,FALSE) -> 201301 | H8: 2 | I8: =A9 -> 16 | J8: 5 | K8: =_xlfn.IFS(D8=1,Sheet3!$C$1,D8=2,Sheet3!$C$2,D8=3,Sheet3!$C$3,D8=4,Sheet3!$C$4,D8=5,Sheet3!$C$5) -> 1:1|2:2|3:3|4:2|5:1 | L8: 500 | M8: 0 | N8: 5 | O8: =H8+J8 -> 7 | P8: =P7 -> 15 | Q8: 1:12:1000|1:20001:2#1:11:200|1:24:1|1:1010102:1|1:1010103:1|1:20001:2#1:11:200|1:22:2|1:24:2 | R8: 10 | S8: 0
A9: 16 | B9: 北方边境 | C9: 101 | D9: 1 | E9: MapBingXue1 | F9: MapBingXue | G9: =VLOOKUP(C9,Sheet3!I:J,2,FALSE) -> 101301 | H9: 1 | I9: =A10 -> 17 | J9: 6 | K9: =_xlfn.IFS(D9=1,Sheet3!$C$1,D9=2,Sheet3!$C$2,D9=3,Sheet3!$C$3,D9=4,Sheet3!$C$4,D9=5,Sheet3!$C$5) -> 1:1|3:1|4:2 | L9: 450 | M9: 0 | N9: 6 | O9: =H9+J9 -> 7 | P9: =P8 -> 15 | Q9: 1:12:1000|1:20001:2#1:11:200|1:24:1|1:1010102:1|1:1010103:1|1:20001:2#1:11:200|1:22:2|1:24:2 | R9: 10 | S9: 0
A10: 17 | B10: 北方边境 | C10: 101 | D10: 1 | E10: MapBingXue1 | F10: MapBingXue | G10: =VLOOKUP(C10,Sheet3!I:J,2,FALSE) -> 101301 | H10: 2 | I10: =A11 -> 18 | J10: 7 | K10: =_xlfn.IFS(D10=1,Sheet3!$C$1,D10=2,Sheet3!$C$2,D10=3,Sheet3!$C$3,D10=4,Sheet3!$C$4,D10=5,Sheet3!$C$5) -> 1:1|3:1|4:2 | L10: 450 | M10: 0 | N10: 7 | O10: =H10+J10 -> 9 | P10: =P9 -> 15 | Q10: 1:12:1000|1:20001:2#1:11:200|1:24:1|1:1010102:1|1:1010103:1|1:20001:2#1:11:200|1:22:2|1:24:2 | R10: 10 | S10: 0
A11: 18 | B11: 北方边境 | C11: 201 | D11: 2 | E11: MapBingXue1 | F11: MapBingXue | G11: =VLOOKUP(C11,Sheet3!I:J,2,FALSE) -> 201301 | H11: 3 | I11: =A12 -> 19 | J11: 8 | K11: =_xlfn.IFS(D11=1,Sheet3!$C$1,D11=2,Sheet3!$C$2,D11=3,Sheet3!$C$3,D11=4,Sheet3!$C$4,D11=5,Sheet3!$C$5) -> 1:1|2:2|3:3|4:2|5:1 | L11: 500 | M11: 0 | N11: 8 | O11: =H11+J11 -> 11 | P11: =P10 -> 15 | Q11: 1:12:1000|1:20001:2#1:11:200|1:24:1|1:1010102:1|1:1010103:1|1:20001:2#1:11:200|1:22:2|1:24:2 | R11: 10 | S11: 0
A12: 19 | B12: 北方边境 | C12: 101 | D12: 1 | E12: MapBingXue1 | F12: MapBingXue | G12: =VLOOKUP(C12,Sheet3!I:J,2,FALSE) -> 101301 | H12: 1 | I12: =A13 -> 20 | J12: 9 | K12: =_xlfn.IFS(D12=1,Sheet3!$C$1,D12=2,Sheet3!$C$2,D12=3,Sheet3!$C$3,D12=4,Sheet3!$C$4,D12=5,Sheet3!$C$5) -> 1:1|3:1|4:2 | L12: 450 | M12: 0 | N12: 9 | O12: =H12+J12 -> 10 | P12: =P11 -> 15 | Q12: 1:12:1000|1:20001:2#1:11:200|1:24:1|1:1010102:1|1:1010103:1|1:20001:2#1:11:200|1:22:2|1:24:2 | R12: 10 | S12: 0
A13: 20 | B13: 北方边境 | C13: 301 | D13: 3 | E13: MapBingXue1 | F13: MapBingXue | G13: =VLOOKUP(C13,Sheet3!I:J,2,FALSE) -> 301301 | H13: 4 | I13: =A14 -> 21 | J13: 10 | K13: =_xlfn.IFS(D13=1,Sheet3!$C$1,D13=2,Sheet3!$C$2,D13=3,Sheet3!$C$3,D13=4,Sheet3!$C$4,D13=5,Sheet3!$C$5) -> 1:1|2:2|3:7|4:5|5:1 | L13: 550 | M13: 0 | N13: 10 | O13: =H13+J13 -> 14 | P13: =P12 -> 15 | Q13: 1:12:1000|1:20001:2#1:11:200|1:24:1|1:1010102:1|1:1010103:1|1:20001:2#1:11:200|1:22:2|1:24:2 | R13: 10 | S13: 0
A14: 21 | B14: 北方边境 | C14: 201 | D14: 2 | E14: MapBingXue1 | F14: MapBingXue | G14: =VLOOKUP(C14,Sheet3!I:J,2,FALSE) -> 201301 | H14: =H4+1 -> 3 | I14: =A15 -> 22 | J14: 11 | K14: =_xlfn.IFS(D14=1,Sheet3!$C$1,D14=2,Sheet3!$C$2,D14=3,Sheet3!$C$3,D14=4,Sheet3!$C$4,D14=5,Sheet3!$C$5) -> 1:1|2:2|3:3|4:2|5:1 | L14: 500 | M14: 0 | N14: 11 | O14: =H14+J14 -> 14 | P14: =P13 -> 15 | Q14: 1:12:1000|1:20001:2#1:11:200|1:24:1|1:1010102:1|1:1010103:1|1:20001:2#1:11:200|1:22:2|1:24:2 | R14: 10 | S14: 0
A15: 22 | B15: 北方边境 | C15: 201 | D15: 2 | E15: MapBingXue1 | F15: MapBingXue | G15: =VLOOKUP(C15,Sheet3!I:J,2,FALSE) -> 201301 | H15: =H5+1 -> 2 | I15: =A16 -> 23 | J15: 12 | K15: =_xlfn.IFS(D15=1,Sheet3!$C$1,D15=2,Sheet3!$C$2,D15=3,Sheet3!$C$3,D15=4,Sheet3!$C$4,D15=5,Sheet3!$C$5) -> 1:1|2:2|3:3|4:2|5:1 | L15: 500 | M15: 0 | N15: 12 | O15: =H15+J15 -> 14 | P15: =P14 -> 15 | Q15: 1:12:1000|1:20001:2#1:11:200|1:24:1|1:1010102:1|1:1010103:1|1:20001:2#1:11:200|1:22:2|1:24:2 | R15: 10 | S15: 0
A16: 23 | B16: 北方边境 | C16: 201 | D16: 2 | E16: MapBingXue1 | F16: MapBingXue | G16: =VLOOKUP(C16,Sheet3!I:J,2,FALSE) -> 201301 | H16: =H6+1 -> 2 | I16: =A17 -> 24 | J16: 13 | K16: =_xlfn.IFS(D16=1,Sheet3!$C$1,D16=2,Sheet3!$C$2,D16=3,Sheet3!$C$3,D16=4,Sheet3!$C$4,D16=5,Sheet3!$C$5) -> 1:1|2:2|3:3|4:2|5:1 | L16: 500 | M16: 0 | N16: 13 | O16: =H16+J16 -> 15 | P16: =P15 -> 15 | Q16: 1:12:1000|1:20001:2#1:11:200|1:24:1|1:1010102:1|1:1010103:1|1:20001:2#1:11:200|1:22:2|1:24:2 | R16: 10 | S16: 0
A17: 24 | B17: 北方边境 | C17: 201 | D17: 2 | E17: MapBingXue1 | F17: MapBingXue | G17: =VLOOKUP(C17,Sheet3!I:J,2,FALSE) -> 201301 | H17: =H7+1 -> 3 | I17: =A18 -> 25 | J17: 14 | K17: =_xlfn.IFS(D17=1,Sheet3!$C$1,D17=2,Sheet3!$C$2,D17=3,Sheet3!$C$3,D17=4,Sheet3!$C$4,D17=5,Sheet3!$C$5) -> 1:1|2:2|3:3|4:2|5:1 | L17: 500 | M17: 0 | N17: 14 | O17: =H17+J17 -> 17 | P17: =P16 -> 15 | Q17: 1:12:1000|1:20001:2#1:11:200|1:24:1|1:1010102:1|1:1010103:1|1:20001:2#1:11:200|1:22:2|1:24:2 | R17: 10 | S17: 0
A18: 25 | B18: 北方边境 | C18: 301 | D18: 3 | E18: MapBingXue1 | F18: MapBingXue | G18: =VLOOKUP(C18,Sheet3!I:J,2,FALSE) -> 301301 | H18: =H8+1 -> 3 | I18: =A19 -> 26 | J18: 15 | K18: =_xlfn.IFS(D18=1,Sheet3!$C$1,D18=2,Sheet3!$C$2,D18=3,Sheet3!$C$3,D18=4,Sheet3!$C$4,D18=5,Sheet3!$C$5) -> 1:1|2:2|3:7|4:5|5:1 | L18: 550 | M18: 0 | N18: 15 | O18: =H18+J18 -> 18 | P18: =P17 -> 15 | Q18: 1:12:1000|1:20001:2#1:11:200|1:24:1|1:1010102:1|1:1010103:1|1:20001:2#1:11:200|1:22:2|1:24:2 | R18: 10 | S18: 0
A19: 26 | B19: 北方边境 | C19: 201 | D19: 2 | E19: MapBingXue1 | F19: MapBingXue | G19: =VLOOKUP(C19,Sheet3!I:J,2,FALSE) -> 201301 | H19: =H9+1 -> 2 | I19: =A20 -> 27 | J19: 16 | K19: =_xlfn.IFS(D19=1,Sheet3!$C$1,D19=2,Sheet3!$C$2,D19=3,Sheet3!$C$3,D19=4,Sheet3!$C$4,D19=5,Sheet3!$C$5) -> 1:1|2:2|3:3|4:2|5:1 | L19: 500 | M19: 0 | N19: 16 | O19: =H19+J19 -> 18 | P19: =P18 -> 15 | Q19: 1:12:1000|1:20001:2#1:11:200|1:24:1|1:1010102:1|1:1010103:1|1:20001:2#1:11:200|1:22:2|1:24:2 | R19: 10 | S19: 0
A20: 27 | B20: 北方边境 | C20: 201 | D20: 2 | E20: MapBingXue1 | F20: MapBingXue | G20: =VLOOKUP(C20,Sheet3!I:J,2,FALSE) -> 201301 | H20: =H10+1 -> 3 | I20: =A21 -> 28 | J20: 17 | K20: =_xlfn.IFS(D20=1,Sheet3!$C$1,D20=2,Sheet3!$C$2,D20=3,Sheet3!$C$3,D20=4,Sheet3!$C$4,D20=5,Sheet3!$C$5) -> 1:1|2:2|3:3|4:2|5:1 | L20: 500 | M20: 0 | N20: 17 | O20: =H20+J20 -> 20 | P20: =P19 -> 15 | Q20: 1:12:1000|1:20001:2#1:11:200|1:24:1|1:1010102:1|1:1010103:1|1:20001:2#1:11:200|1:22:2|1:24:2 | R20: 10 | S20: 0
A21: 28 | B21: 北方边境 | C21: 201 | D21: 2 | E21: MapBingXue1 | F21: MapBingXue | G21: =VLOOKUP(C21,Sheet3!I:J,2,FALSE) -> 201301 | H21: =H11+1 -> 4 | I21: =A22 -> 29 | J21: 18 | K21: =_xlfn.IFS(D21=1,Sheet3!$C$1,D21=2,Sheet3!$C$2,D21=3,Sheet3!$C$3,D21=4,Sheet3!$C$4,D21=5,Sheet3!$C$5) -> 1:1|2:2|3:3|4:2|5:1 | L21: 500 | M21: 0 | N21: 18 | O21: =H21+J21 -> 22 | P21: =P20 -> 15 | Q21: 1:12:1000|1:20001:2#1:11:200|1:24:1|1:1010102:1|1:1010103:1|1:20001:2#1:11:200|1:22:2|1:24:2 | R21: 10 | S21: 0
A22: 29 | B22: 北方边境 | C22: 201 | D22: 2 | E22: MapBingXue1 | F22: MapBingXue | G22: =VLOOKUP(C22,Sheet3!I:J,2,FALSE) -> 201301 | H22: =H12+1 -> 2 | I22: =A23 -> 30 | J22: 19 | K22: =_xlfn.IFS(D22=1,Sheet3!$C$1,D22=2,Sheet3!$C$2,D22=3,Sheet3!$C$3,D22=4,Sheet3!$C$4,D22=5,Sheet3!$C$5) -> 1:1|2:2|3:3|4:2|5:1 | L22: 500 | M22: 0 | N22: 19 | O22: =H22+J22 -> 21 | P22: =P21 -> 15 | Q22: 1:12:1000|1:20001:2#1:11:200|1:24:1|1:1010102:1|1:1010103:1|1:20001:2#1:11:200|1:22:2|1:24:2 | R22: 10 | S22: 0
A23: 30 | B23: 北方边境 | C23: 301 | D23: 3 | E23: MapBingXue1 | F23: MapBingXue | G23: =VLOOKUP(C23,Sheet3!I:J,2,FALSE) -> 301301 | H23: =H13+1 -> 5 | I23: =A24 -> 31 | J23: 20 | K23: =_xlfn.IFS(D23=1,Sheet3!$C$1,D23=2,Sheet3!$C$2,D23=3,Sheet3!$C$3,D23=4,Sheet3!$C$4,D23=5,Sheet3!$C$5) -> 1:1|2:2|3:7|4:5|5:1 | L23: 550 | M23: 0 | N23: 20 | O23: =H23+J23 -> 25 | P23: =P22 -> 15 | Q23: 1:12:1000|1:20001:2#1:11:200|1:24:1|1:1010102:1|1:1010103:1|1:20001:2#1:11:200|1:22:2|1:24:2 | R23: 10 | S23: 0
A24: 31 | B24: 北方边境 | C24: 201 | D24: 2 | E24: MapBingXue1 | F24: MapBingXue | G24: =VLOOKUP(C24,Sheet3!I:J,2,FALSE) -> 201301 | H24: =H14+1 -> 4 | I24: =A25 -> 32 | J24: 21 | K24: =_xlfn.IFS(D24=1,Sheet3!$C$1,D24=2,Sheet3!$C$2,D24=3,Sheet3!$C$3,D24=4,Sheet3!$C$4,D24=5,Sheet3!$C$5) -> 1:1|2:2|3:3|4:2|5:1 | L24: 500 | M24: 0 | N24: 21 | O24: =H24+J24 -> 25 | P24: =P23 -> 15 | Q24: 1:12:1000|1:20001:2#1:11:200|1:24:1|1:1010102:1|1:1010103:1|1:20001:2#1:11:200|1:22:2|1:24:2 | R24: 10 | S24: 0
A25: 32 | B25: 北方边境 | C25: 201 | D25: 2 | E25: MapBingXue1 | F25: MapBingXue | G25: =VLOOKUP(C25,Sheet3!I:J,2,FALSE) -> 201301 | H25: =H15+1 -> 3 | I25: =A26 -> 33 | J25: 22 | K25: =_xlfn.IFS(D25=1,Sheet3!$C$1,D25=2,Sheet3!$C$2,D25=3,Sheet3!$C$3,D25=4,Sheet3!$C$4,D25=5,Sheet3!$C$5) -> 1:1|2:2|3:3|4:2|5:1 | L25: 500 | M25: 0 | N25: 22 | O25: =H25+J25 -> 25 | P25: =P24 -> 15 | Q25: 1:12:1000|1:20001:2#1:11:200|1:24:1|1:1010102:1|1:1010103:1|1:20001:2#1:11:200|1:22:2|1:24:2 | R25: 10 | S25: 0
... A30: 37 | B30: 北方边境 | C30: 301 | D30: 3 | E30: MapBingXue1 | F30: MapBingXue | G30: =VLOOKUP(C30,Sheet3!I:J,2,FALSE) -> 301301 | H30: =H20+1 -> 4 | I30: =A31 -> 38 | J30: 27 | K30: =_xlfn.IFS(D30=1,Sheet3!$C$1,D30=2,Sheet3!$C$2,D30=3,Sheet3!$C$3,D30=4,Sheet3!$C$4,D30=5,Sheet3!$C$5) -> 1:1|2:2|3:7|4:5|5:1 | L30: 550 | M30: 0 | N30: 27 | O30: =H30+J30 -> 31 | P30: =P29 -> 15 | Q30: 1:12:1000|1:20001:2#1:11:200|1:24:1|1:1010102:1|1:1010103:1|1:20001:2#1:11:200|1:22:2|1:24:2 | R30: 10 | S30: 0
A31: 38 | B31: 北方边境 | C31: 301 | D31: 3 | E31: MapBingXue1 | F31: MapBingXue | G31: =VLOOKUP(C31,Sheet3!I:J,2,FALSE) -> 301301 | H31: =H21+1 -> 5 | I31: =A32 -> 39 | J31: 28 | K31: =_xlfn.IFS(D31=1,Sheet3!$C$1,D31=2,Sheet3!$C$2,D31=3,Sheet3!$C$3,D31=4,Sheet3!$C$4,D31=5,Sheet3!$C$5) -> 1:1|2:2|3:7|4:5|5:1 | L31: 550 | M31: 0 | N31: 28 | O31: 55 | P31: =P30 -> 15 | Q31: 1:12:1000|1:20001:2#1:11:200|1:24:1|1:1010102:1|1:1010103:1|1:20001:2#1:11:200|1:22:2|1:24:2 | R31: 10 | S31: 0
A32: 39 | B32: 北方边境 | C32: 301 | D32: 3 | E32: MapBingXue1 | F32: MapBingXue | G32: =VLOOKUP(C32,Sheet3!I:J,2,FALSE) -> 301301 | H32: =H22+1 -> 3 | I32: =A33 -> 40 | J32: 29 | K32: =_xlfn.IFS(D32=1,Sheet3!$C$1,D32=2,Sheet3!$C$2,D32=3,Sheet3!$C$3,D32=4,Sheet3!$C$4,D32=5,Sheet3!$C$5) -> 1:1|2:2|3:7|4:5|5:1 | L32: 550 | M32: 0 | N32: 29 | O32: 60 | P32: =P31 -> 15 | Q32: 1:12:1000|1:20001:2#1:11:200|1:24:1|1:1010102:1|1:1010103:1|1:20001:2#1:11:200|1:22:2|1:24:2 | R32: 10 | S32: 0
A33: 40 | B33: 北方边境 | C33: 401 | D33: 4 | E33: MapBingXue1 | F33: MapBingXue | G33: =VLOOKUP(C33,Sheet3!I:J,2,FALSE) -> 401301 | H33: =H23+1 -> 6 | I33: =A34 -> 41 | J33: 30 | K33: =_xlfn.IFS(D33=1,Sheet3!$C$1,D33=2,Sheet3!$C$2,D33=3,Sheet3!$C$3,D33=4,Sheet3!$C$4,D33=5,Sheet3!$C$5) -> 1:1|2:5|3:8|4:10|5:1 | L33: 600 | M33: 0 | N33: 30 | O33: 70 | P33: =P32 -> 15 | Q33: 1:12:1000|1:20001:2#1:11:200|1:24:1|1:1010102:1|1:1010103:1|1:20001:2#1:11:200|1:22:2|1:24:2 | R33: 10 | S33: 0
A34: 41 | B34: 北方边境 | C34: 201 | D34: 2 | E34: MapBingXue1 | F34: MapBingXue | G34: =VLOOKUP(C34,Sheet3!I:J,2,FALSE) -> 201301 | H34: =H24+1 -> 5 | I34: =A35 -> 42 | J34: 31 | K34: =_xlfn.IFS(D34=1,Sheet3!$C$1,D34=2,Sheet3!$C$2,D34=3,Sheet3!$C$3,D34=4,Sheet3!$C$4,D34=5,Sheet3!$C$5) -> 1:1|2:2|3:3|4:2|5:1 | L34: 500 | M34: 0 | N34: 31 | O34: =H34+J34 -> 36 | P34: =P33 -> 15 | Q34: 1:12:1000|1:20001:2#1:11:200|1:24:1|1:1010102:1|1:1010103:1|1:20001:2#1:11:200|1:22:2|1:24:2 | R34: 10 | S34: 0
A35: 42 | B35: 北方边境 | C35: 201 | D35: 2 | E35: MapBingXue1 | F35: MapBingXue | G35: =VLOOKUP(C35,Sheet3!I:J,2,FALSE) -> 201301 | H35: =H25+1 -> 4 | I35: =A36 -> 43 | J35: 32 | K35: =_xlfn.IFS(D35=1,Sheet3!$C$1,D35=2,Sheet3!$C$2,D35=3,Sheet3!$C$3,D35=4,Sheet3!$C$4,D35=5,Sheet3!$C$5) -> 1:1|2:2|3:3|4:2|5:1 | L35: 500 | M35: 0 | N35: 32 | O35: =H35+J35 -> 36 | P35: =P34 -> 15 | Q35: 1:12:1000|1:20001:2#1:11:200|1:24:1|1:1010102:1|1:1010103:1|1:20001:2#1:11:200|1:22:2|1:24:2 | R35: 10 | S35: 0
A36: 43 | B36: 北方边境 | C36: 301 | D36: 3 | E36: MapBingXue1 | F36: MapBingXue | G36: =VLOOKUP(C36,Sheet3!I:J,2,FALSE) -> 301301 | H36: =H26+1 -> 4 | I36: =A37 -> 44 | J36: 33 | K36: =_xlfn.IFS(D36=1,Sheet3!$C$1,D36=2,Sheet3!$C$2,D36=3,Sheet3!$C$3,D36=4,Sheet3!$C$4,D36=5,Sheet3!$C$5) -> 1:1|2:2|3:7|4:5|5:1 | L36: 550 | M36: 0 | N36: 33 | O36: =H36+J36 -> 37 | P36: =P35 -> 15 | Q36: 1:12:1000|1:20001:2#1:11:200|1:24:1|1:1010102:1|1:1010103:1|1:20001:2#1:11:200|1:22:2|1:24:2 | R36: 10 | S36: 0
A37: 44 | B37: 北方边境 | C37: 301 | D37: 3 | E37: MapBingXue1 | F37: MapBingXue | G37: =VLOOKUP(C37,Sheet3!I:J,2,FALSE) -> 301301 | H37: =H27+1 -> 5 | I37: =A38 -> 45 | J37: 34 | K37: =_xlfn.IFS(D37=1,Sheet3!$C$1,D37=2,Sheet3!$C$2,D37=3,Sheet3!$C$3,D37=4,Sheet3!$C$4,D37=5,Sheet3!$C$5) -> 1:1|2:2|3:7|4:5|5:1 | L37: 550 | M37: 0 | N37: 34 | O37: =H37+J37 -> 39 | P37: =P36 -> 15 | Q37: 1:12:1000|1:20001:2#1:11:200|1:24:1|1:1010102:1|1:1010103:1|1:20001:2#1:11:200|1:22:2|1:24:2 | R37: 10 | S37: 0
A38: 45 | B38: 北方边境 | C38: 401 | D38: 4 | E38: MapBingXue1 | F38: MapBingXue | G38: =VLOOKUP(C38,Sheet3!I:J,2,FALSE) -> 401301 | H38: =H28+1 -> 5 | I38: =A39 -> 46 | J38: 35 | K38: =_xlfn.IFS(D38=1,Sheet3!$C$1,D38=2,Sheet3!$C$2,D38=3,Sheet3!$C$3,D38=4,Sheet3!$C$4,D38=5,Sheet3!$C$5) -> 1:1|2:5|3:8|4:10|5:1 | L38: 600 | M38: 0 | N38: 35 | O38: =H38+J38 -> 40 | P38: =P37 -> 15 | Q38: 1:12:1000|1:20001:2#1:11:200|1:24:1|1:1010102:1|1:1010103:1|1:20001:2#1:11:200|1:22:2|1:24:2 | R38: 10 | S38: 0
A39: 46 | B39: 北方边境 | C39: 401 | D39: 4 | E39: MapBingXue1 | F39: MapBingXue | G39: =VLOOKUP(C39,Sheet3!I:J,2,FALSE) -> 401301 | H39: =H29+1 -> 4 | I39: =A40 -> 47 | J39: 36 | K39: =_xlfn.IFS(D39=1,Sheet3!$C$1,D39=2,Sheet3!$C$2,D39=3,Sheet3!$C$3,D39=4,Sheet3!$C$4,D39=5,Sheet3!$C$5) -> 1:1|2:5|3:8|4:10|5:1 | L39: 600 | M39: 0 | N39: 36 | O39: =H39+J39 -> 40 | P39: =P38 -> 15 | Q39: 1:12:1000|1:20001:2#1:11:200|1:24:1|1:1010102:1|1:1010103:1|1:20001:2#1:11:200|1:22:2|1:24:2 | R39: 10 | S39: 0
A40: 47 | B40: 北方边境 | C40: 301 | D40: 3 | E40: MapBingXue1 | F40: MapBingXue | G40: =VLOOKUP(C40,Sheet3!I:J,2,FALSE) -> 301301 | H40: =H30+1 -> 5 | I40: =A41 -> 48 | J40: 37 | K40: =_xlfn.IFS(D40=1,Sheet3!$C$1,D40=2,Sheet3!$C$2,D40=3,Sheet3!$C$3,D40=4,Sheet3!$C$4,D40=5,Sheet3!$C$5) -> 1:1|2:2|3:7|4:5|5:1 | L40: 550 | M40: 0 | N40: 37 | O40: =H40+J40 -> 42 | P40: =P39 -> 15 | Q40: 1:12:1000|1:20001:2#1:11:200|1:24:1|1:1010102:1|1:1010103:1|1:20001:2#1:11:200|1:22:2|1:24:2 | R40: 10 | S40: 0
A41: 48 | B41: 北方边境 | C41: 401 | D41: 4 | E41: MapBingXue1 | F41: MapBingXue | G41: =VLOOKUP(C41,Sheet3!I:J,2,FALSE) -> 401301 | H41: =H31+1 -> 6 | I41: =A42 -> 49 | J41: 38 | K41: =_xlfn.IFS(D41=1,Sheet3!$C$1,D41=2,Sheet3!$C$2,D41=3,Sheet3!$C$3,D41=4,Sheet3!$C$4,D41=5,Sheet3!$C$5) -> 1:1|2:5|3:8|4:10|5:1 | L41: 600 | M41: 0 | N41: 38 | O41: =H41+J41 -> 44 | P41: =P40 -> 15 | Q41: 1:12:1000|1:20001:2#1:11:200|1:24:1|1:1010102:1|1:1010103:1|1:20001:2#1:11:200|1:22:2|1:24:2 | R41: 10 | S41: 0
A42: 49 | B42: 北方边境 | C42: 401 | D42: 4 | E42: MapBingXue1 | F42: MapBingXue | G42: =VLOOKUP(C42,Sheet3!I:J,2,FALSE) -> 401301 | H42: =H32+1 -> 4 | I42: =A43 -> 50 | J42: 39 | K42: =_xlfn.IFS(D42=1,Sheet3!$C$1,D42=2,Sheet3!$C$2,D42=3,Sheet3!$C$3,D42=4,Sheet3!$C$4,D42=5,Sheet3!$C$5) -> 1:1|2:5|3:8|4:10|5:1 | L42: 600 | M42: 0 | N42: 39 | O42: =H42+J42 -> 43 | P42: =P41 -> 15 | Q42: 1:12:1000|1:20001:2#1:11:200|1:24:1|1:1010102:1|1:1010103:1|1:20001:2#1:11:200|1:22:2|1:24:2 | R42: 10 | S42: 0
A43: 50 | B43: 北方边境 | C43: 501 | D43: 5 | E43: MapBingXue1 | F43: MapBingXue | G43: =VLOOKUP(C43,Sheet3!I:J,2,FALSE) -> 501301 | H43: =H33+1 -> 7 | I43: =A44 -> 51 | J43: 40 | K43: =_xlfn.IFS(D43=1,Sheet3!$C$1,D43=2,Sheet3!$C$2,D43=3,Sheet3!$C$3,D43=4,Sheet3!$C$4,D43=5,Sheet3!$C$5) -> 1:1|2:6|3:12|4:16|5:1 | L43: 650 | M43: 0 | N43: 40 | O43: =H43+J43 -> 47 | P43: =P42 -> 15 | Q43: 1:12:1000|1:20001:2#1:11:200|1:24:1|1:1010102:1|1:1010103:1|1:20001:2#1:11:200|1:22:2|1:24:2 | R43: 10 | S43: 0
A44: 51 | B44: 北方边境 | C44: 201 | D44: 2 | E44: MapBingXue1 | F44: MapBingXue | G44: =VLOOKUP(C44,Sheet3!I:J,2,FALSE) -> 201301 | H44: =H34+1 -> 6 | I44: =A45 -> 52 | J44: 41 | K44: =_xlfn.IFS(D44=1,Sheet3!$C$1,D44=2,Sheet3!$C$2,D44=3,Sheet3!$C$3,D44=4,Sheet3!$C$4,D44=5,Sheet3!$C$5) -> 1:1|2:2|3:3|4:2|5:1 | L44: 500 | M44: 0 | N44: 41 | O44: =H44+J44 -> 47 | P44: =P43 -> 15 | Q44: 1:12:1000|1:20001:2#1:11:200|1:24:1|1:1010102:1|1:1010103:1|1:20001:2#1:11:200|1:22:2|1:24:2 | R44: 10 | S44: 0
...

Sheet Sheet2

Sheet Sheet3
A1: 4 | B1: 1 | C1: 1:1|3:1|4:2 | I1: 98 | J1: 98301
A2: 9 | B2: 2 | C2: 1:1|2:2|3:3|4:2|5:1 | I2: 99 | J2: 99301
A3: 16 | B3: 3 | C3: 1:1|2:2|3:7|4:5|5:1 | I3: 100 | J3: 100301
A4: 25 | B4: 4 | C4: 1:1|2:5|3:8|4:10|5:1 | I4: 101 | J4: 101301
A5: 36 | B5: 5 | C5: 1:1|2:6|3:12|4:16|5:1 | I5: 201 | J5: 201301
I6: 301 | J6: 301301
I7: 401 | J7: 401301
I8: 501 | J8: 501301
