Workbook

Sheet SoldierAdd
A1: ID | B1: ID1 | C1: Type | D1: Type1 | E1: Type2 | F1: AddID | G1: Name | H1: Icon | I1: Show | J1: Lv | K1: Nextid | L1: Cost | M1: Unlock | N1: Effcet | O1: zuobiao | P1: Text
A2: int | B2: int | C2: int | D2: int | E2: int | F2: int | G2: string | H2: string | I2: string | J2: int | K2: int | L2: string | M2: string | N2: string | O2: int | P2: string
A3: 主键ID | B3: 科技ID | C3: 类型 | D3: 科技类型 | E3: 兵种和科技 | F3: 科技阶段 | G3: 科技名称 | H3: 科技图标 | I3: 士兵缩放 | J3: 科技等级 | K3: 下级等级 | L3: 升级消耗 | M3: 科技解锁 | N3: 效果 | O3: 位置坐标 | P3: 描述
A4: 10000 | B4: 10000 | C4: 1 | D4: 10001 | E4: 1 | F4: 1 | G4: 初级生命 | H4: icon_01 | I4: 0 | J4: 0 | K4: 10001 | L4: 12:5000|10101:1|10119:1|10122:1 | M4: 0 | N4: 101:0 | O4: 1 | P4: 所有步兵生命增加0
A5: 10001 | B5: 10000 | C5: 1 | D5: 10001 | E5: 1 | F5: 1 | G5: 初级生命 | H5: icon_01 | I5: 0 | J5: 1 | K5: 10002 | L5: 12:6000|10101:2|10119:2|10122:2 | M5: 0 | N5: 101:30 | O5: 1 | P5: 所有步兵生命增加30
A6: 10002 | B6: 10000 | C6: 1 | D6: 10001 | E6: 1 | F6: 1 | G6: 初级生命 | H6: icon_01 | I6: 0 | J6: 2 | K6: 10003 | L6: 12:8000|10101:3|10119:3|10122:3 | M6: 0 | N6: 101:30 | O6: 1 | P6: 所有步兵生命增加60
A7: 10003 | B7: 10000 | C7: 1 | D7: 10001 | E7: 1 | F7: 1 | G7: 初级生命 | H7: icon_01 | I7: 0 | J7: 3 | K7: 10004 | L7: 12:10000|10101:4|10119:4|10122:4 | M7: 0 | N7: 101:30 | O7: 1 | P7: 所有步兵生命增加90
A8: 10004 | B8: 10000 | C8: 1 | D8: 10001 | E8: 1 | F8: 1 | G8: 初级生命 | H8: icon_01 | I8: 0 | J8: 4 | K8: 10005 | L8: 12:13000|10101:5|10119:5|10122:5 | M8: 0 | N8: 101:30 | O8: 1 | P8: 所有步兵生命增加120
A9: 10005 | B9: 10000 | C9: 1 | D9: 10001 | E9: 1 | F9: 1 | G9: 初级生命 | H9: icon_01 | I9: 0 | J9: 5 | K9: 0 | L9: 0 | M9: 0 | N9: 101:30 | O9: 1 | P9: 所有步兵生命增加150
A10: 10100 | B10: 10100 | C10: 1 | D10: 10001 | E10: 1 | F10: 1 | G10: 初级防御 | H10: icon_02 | I10: 0 | J10: 0 | K10: 10101 | L10: 12:5000|10101:1|10119:1|10122:1 | M10: 1:10000:1 | N10: 103:0 | O10: 2 | P10: 所有步兵防御增加0
A11: 10101 | B11: 10100 | C11: 1 | D11: 10001 | E11: 1 | F11: 1 | G11: 初级防御 | H11: icon_02 | I11: 0 | J11: 1 | K11: 10102 | L11: 12:6000|10101:2|10119:2|10122:2 | M11: 1:10000:1 | N11: 103:6 | O11: 2 | P11: 所有步兵防御增加6
A12: 10102 | B12: 10100 | C12: 1 | D12: 10001 | E12: 1 | F12: 1 | G12: 初级防御 | H12: icon_02 | I12: 0 | J12: 2 | K12: 10103 | L12: 12:8000|10101:3|10119:3|10122:3 | M12: 1:10000:1 | N12: 103:6 | O12: 2 | P12: 所有步兵防御增加12
... A2433: 62920 | B2433: 62900 | C2433: 6 | D2433: 60003 | E2433: 2 | F2433: 3 | G2433: 死灵法师训练 | H2433: moshou03_Lv3 | I2433: 1.5 | J2433: 20 | K2433: 0 | L2433: 0 | M2433: 0 | N2433: 1022:1 | O2433: 10 | P2433: 死灵法师全属性提升20%

Sheet 链接表
A1: ID | B1: ID1 | C1: Type | D1: Type1 | E1: Type2 | F1: AddID | G1: Name | H1: Icon | I1: Show | J1: Lv | K1: Nextid | L1: Cost | M1: Unlock | N1: Effcet | O1: zuobiao | P1: Text | Q1: 增加 | R1: 所有步兵 | S1: 所有飞兵
A2: int | B2: int | C2: int | D2: int | E2: int | F2: int | G2: string | H2: string | I2: string | J2: int | K2: int | L2: string | M2: string | N2: string | O2: int | P2: string | R2: 所有骑兵 | S2: 所有牧师和法师 | W2: :
A3: 主键ID | B3: 科技ID | C3: 类型 | D3: 科技 | E3: 兵种和科技 | F3: 科技阶段 | G3: 科技名称 | H3: 科技图标 | I3: 士兵缩放 | J3: 科技等级 | K3: 下级等级 | L3: 升级消耗 | M3: 科技解锁 | N3: 效果 | O3: 位置坐标 | P3: 描述 | R3: 所有弓兵 | S3: 所有魔物和野兽 | V3: 属性名称 | W3: 属性id
A4: 10000 | B4: =ROUND(A4,-2) -> 10000 | C4: =LEFT(A4,1) -> 1 | D4: =$A$4+F4 -> 10001 | E4: 1 | F4: =MID(B4,2,1)+1 -> 1 | G4: 初级生命 | H4: icon_01 | I4: 0 | J4: 0 | K4: =A5 -> 10001 | L4: 12:5000|10101:1|10119:1|10122:1 | M4: 0 | N4: =W4&$W$2&X4 -> 101:1 | O4: =MID(A4,3,1)+1 -> 1 | P4: =$R$1&R4&$Q$1&T4 -> 所有步兵生命增加0 | R4: 生命 | T4: =加成属性!L5 -> 0 | U4: =MID(P4,3,2) -> 步兵 | V4: 步兵生命 | W4: =属性类型!G4 -> 101 | X4: 1
A5: =A4+1 -> 10001 | B5: =ROUND(A5,-2) -> 10000 | C5: =LEFT(A5,1) -> 1 | D5: =$A$4+F5 -> 10001 | E5: 1 | F5: =MID(B5,2,1)+1 -> 1 | G5: =G4 -> 初级生命 | H5: =H4 -> icon_01 | I5: 0 | J5: 1 | K5: =A6 -> 10002 | L5: 12:6000|10101:2|10119:2|10122:2 | M5: =M4 -> 0 | N5: =W5&$W$2&X5 -> 101:1 | O5: =MID(A5,3,1)+1 -> 1 | P5: =$R$1&R5&$Q$1&T5 -> 所有步兵生命增加0 | R5: =R4 -> 生命 | T5: =加成属性!L6 -> 0 | U5: =MID(P5,3,2) -> 步兵 | V5: 步兵生命 | W5: =属性类型!G5 -> 101 | X5: 1
A6: =A5+1 -> 10002 | B6: =ROUND(A6,-2) -> 10000 | C6: =LEFT(A6,1) -> 1 | D6: =$A$4+F6 -> 10001 | E6: 1 | F6: =MID(B6,2,1)+1 -> 1 | G6: =G5 -> 初级生命 | H6: =H5 -> icon_01 | I6: 0 | J6: 2 | K6: =A7 -> 10003 | L6: 12:8000|10101:3|10119:3|10122:3 | M6: =M5 -> 0 | N6: =W6&$W$2&X6 -> 101:1 | O6: =MID(A6,3,1)+1 -> 1 | P6: =$R$1&R6&$Q$1&T6 -> 所有步兵生命增加0 | R6: =R5 -> 生命 | T6: =加成属性!L7 -> 0 | U6: =MID(P6,3,2) -> 步兵 | V6: 步兵生命 | W6: =属性类型!G6 -> 101 | X6: 1
A7: =A6+1 -> 10003 | B7: =ROUND(A7,-2) -> 10000 | C7: =LEFT(A7,1) -> 1 | D7: =$A$4+F7 -> 10001 | E7: 1 | F7: =MID(B7,2,1)+1 -> 1 | G7: =G6 -> 初级生命 | H7: =H6 -> icon_01 | I7: 0 | J7: 3 | K7: =A8 -> 10004 | L7: 12:10000|10101:4|10119:4|10122:4 | M7: =M6 -> 0 | N7: =W7&$W$2&X7 -> 101:1 | O7: =MID(A7,3,1)+1 -> 1 | P7: =$R$1&R7&$Q$1&T7 -> 所有步兵生命增加0 | R7: =R6 -> 生命 | T7: =加成属性!L8 -> 0 | U7: =MID(P7,3,2) -> 步兵 | V7: 步兵生命 | W7: =属性类型!G7 -> 101 | X7: 1
A8: =A7+1 -> 10004 | B8: =ROUND(A8,-2) -> 10000 | C8: =LEFT(A8,1) -> 1 | D8: =$A$4+F8 -> 10001 | E8: 1 | F8: =MID(B8,2,1)+1 -> 1 | G8: =G7 -> 初级生命 | H8: =H7 -> icon_01 | I8: 0 | J8: 4 | K8: =A9 -> 10005 | L8: 12:13000|10101:5|10119:5|10122:5 | M8: =M7 -> 0 | N8: =W8&$W$2&X8 -> 101:1 | O8: =MID(A8,3,1)+1 -> 1 | P8: =$R$1&R8&$Q$1&T8 -> 所有步兵生命增加0 | R8: =R7 -> 生命 | T8: =加成属性!L9 -> 0 | U8: =MID(P8,3,2) -> 步兵 | V8: 步兵生命 | W8: =属性类型!G8 -> 101 | X8: 1
A9: =A8+1 -> 10005 | B9: =ROUND(A9,-2) -> 10000 | C9: =LEFT(A9,1) -> 1 | D9: =$A$4+F9 -> 10001 | E9: 1 | F9: =MID(B9,2,1)+1 -> 1 | G9: =G8 -> 初级生命 | H9: =H8 -> icon_01 | I9: 0 | J9: 5 | K9: 0 | L9: 0 | M9: =M8 -> 0 | N9: =W9&$W$2&X9 -> 101:1 | O9: =MID(A9,3,1)+1 -> 1 | P9: =$R$1&R9&$Q$1&T9 -> 所有步兵生命增加 | R9: =R8 -> 生命 | U9: =MID(P9,3,2) -> 步兵 | V9: 步兵生命 | W9: =属性类型!G9 -> 101 | X9: 1
A10: =A4+100 -> 10100 | B10: =ROUND(A10,-2) -> 10100 | C10: =LEFT(A10,1) -> 1 | D10: =$A$4+F10 -> 10001 | E10: 1 | F10: =MID(B10,2,1)+1 -> 1 | G10: 初级防御 | H10: icon_02 | I10: 0 | J10: 0 | K10: =A11 -> 10101 | L10: 12:5000|10101:1|10119:1|10122:1 | M10: 1:10000:1 | N10: =W10&$W$2&X10 -> 103:1 | O10: =MID(A10,3,1)+1 -> 2 | P10: =$R$1&R10&$Q$1&T10 -> 所有步兵防御增加:1 | R10: 防御 | T10: =RIGHT(N10,2) -> :1 | U10: =MID(P10,3,2) -> 步兵 | V10: 步兵防御 | W10: =属性类型!G10 -> 103 | X10: 1
A11: =A10+1 -> 10101 | B11: =ROUND(A11,-2) -> 10100 | C11: =LEFT(A11,1) -> 1 | D11: =$A$4+F11 -> 10001 | E11: 1 | F11: =MID(B11,2,1)+1 -> 1 | G11: =G10 -> 初级防御 | H11: =H10 -> icon_02 | I11: 0 | J11: 1 | K11: =A12 -> 10102 | L11: 12:6000|10101:2|10119:2|10122:2 | M11: =M10 -> 1:10000:1 | N11: =W11&$W$2&X11 -> 103:1 | O11: =MID(A11,3,1)+1 -> 2 | P11: =$R$1&R11&$Q$1&T11 -> 所有步兵防御增加:1 | R11: =R10 -> 防御 | T11: =RIGHT(N11,2) -> :1 | U11: =MID(P11,3,2) -> 步兵 | V11: 步兵防御 | W11: =属性类型!G11 -> 103 | X11: 1
A12: =A11+1 -> 10102 | B12: =ROUND(A12,-2) -> 10100 | C12: =LEFT(A12,1) -> 1 | D12: =$A$4+F12 -> 10001 | E12: 1 | F12: =MID(B12,2,1)+1 -> 1 | G12: =G11 -> 初级防御 | H12: =H11 -> icon_02 | I12: 0 | J12: 2 | K12: =A13 -> 10103 | L12: 12:8000|10101:3|10119:3|10122:3 | M12: =M11 -> 1:10000:1 | N12: =W12&$W$2&X12 -> 103:1 | O12: =MID(A12,3,1)+1 -> 2 | P12: =$R$1&R12&$Q$1&T12 -> 所有步兵防御增加:1 | R12: =R11 -> 防御 | T12: =RIGHT(N12,2) -> :1 | U12: =MID(P12,3,2) -> 步兵 | V12: 步兵防御 | W12: =属性类型!G12 -> 103 | X12: 1
A13: =A12+1 -> 10103 | B13: =ROUND(A13,-2) -> 10100 | C13: =LEFT(A13,1) -> 1 | D13: =$A$4+F13 -> 10001 | E13: 1 | F13: =MID(B13,2,1)+1 -> 1 | G13: =G12 -> 初级防御 | H13: =H12 -> icon_02 | I13: 0 | J13: 3 | K13: =A14 -> 10104 | L13: 12:10000|10101:4|10119:4|10122:4 | M13: =M12 -> 1:10000:1 | N13: =W13&$W$2&X13 -> 103:1 | O13: =MID(A13,3,1)+1 -> 2 | P13: =$R$1&R13&$Q$1&T13 -> 所有步兵防御增加:1 | R13: =R12 -> 防御 | T13: =RIGHT(N13,2) -> :1 | U13: =MID(P13,3,2) -> 步兵 | V13: 步兵防御 | W13: =属性类型!G13 -> 103 | X13: 1
A14: =A13+1 -> 10104 | B14: =ROUND(A14,-2) -> 10100 | C14: =LEFT(A14,1) -> 1 | D14: =$A$4+F14 -> 10001 | E14: 1 | F14: =MID(B14,2,1)+1 -> 1 | G14: =G13 -> 初级防御 | H14: =H13 -> icon_02 | I14: 0 | J14: 4 | K14: =A15 -> 10105 | L14: 12:13000|10101:5|10119:5|10122:5 | M14: =M13 -> 1:10000:1 | N14: =W14&$W$2&X14 -> 103:1 | O14: =MID(A14,3,1)+1 -> 2 | P14: =$R$1&R14&$Q$1&T14 -> 所有步兵防御增加:1 | R14: =R13 -> 防御 | T14: =RIGHT(N14,2) -> :1 | U14: =MID(P14,3,2) -> 步兵 | V14: 步兵防御 | W14: =属性类型!G14 -> 103 | X14: 1
A15: =A14+1 -> 10105 | B15: =ROUND(A15,-2) -> 10100 | C15: =LEFT(A15,1) -> 1 | D15: =$A$4+F15 -> 10001 | E15: 1 | F15: =MID(B15,2,1)+1 -> 1 | G15: =G14 -> 初级防御 | H15: =H14 -> icon_02 | I15: 0 | J15: 5 | K15: 0 | L15: 0 | M15: =M14 -> 1:10000:1 | N15: =W15&$W$2&X15 -> 103:1 | O15: =MID(A15,3,1)+1 -> 2 | P15: =$R$1&R15&$Q$1&T15 -> 所有步兵防御增加:1 | R15: =R14 -> 防御 | T15: =RIGHT(N15,2) -> :1 | U15: =MID(P15,3,2) -> 步兵 | V15: 步兵防御 | W15: =属性类型!G15 -> 103 | X15: 1
A16: =A10+100 -> 10200 | B16: =ROUND(A16,-2) -> 10200 | C16: =LEFT(A16,1) -> 1 | D16: =$A$4+F16 -> 10001 | E16: 1 | F16: =MID(B16,2,1)+1 -> 1 | G16: 初级攻击 | H16: icon_03 | I16: 0 | J16: 0 | K16: =A17 -> 10201 | L16: 12:5000|10101:1|10119:1|10122:1 | M16: 1:10000:1 | N16: =W16&$W$2&X16 -> 102:1 | O16: =MID(A16,3,1)+1 -> 3 | P16: =$R$1&R16&$Q$1&T16 -> 所有步兵攻击增加:1 | R16: 攻击 | T16: =RIGHT(N16,2) -> :1 | U16: =MID(P16,3,2) -> 步兵 | V16: 步兵攻击 | W16: =属性类型!G16 -> 102 | X16: 1
A17: =A16+1 -> 10201 | B17: =ROUND(A17,-2) -> 10200 | C17: =LEFT(A17,1) -> 1 | D17: =$A$4+F17 -> 10001 | E17: 1 | F17: =MID(B17,2,1)+1 -> 1 | G17: =G16 -> 初级攻击 | H17: =H16 -> icon_03 | I17: 0 | J17: 1 | K17: =A18 -> 10202 | L17: 12:6000|10101:2|10119:2|10122:2 | M17: =M16 -> 1:10000:1 | N17: =W17&$W$2&X17 -> 102:1 | O17: =MID(A17,3,1)+1 -> 3 | P17: =$R$1&R17&$Q$1&T17 -> 所有步兵攻击增加:1 | R17: =R16 -> 攻击 | T17: =RIGHT(N17,2) -> :1 | U17: =MID(P17,3,2) -> 步兵 | V17: 步兵攻击 | W17: =属性类型!G17 -> 102 | X17: 1
A18: =A17+1 -> 10202 | B18: =ROUND(A18,-2) -> 10200 | C18: =LEFT(A18,1) -> 1 | D18: =$A$4+F18 -> 10001 | E18: 1 | F18: =MID(B18,2,1)+1 -> 1 | G18: =G17 -> 初级攻击 | H18: =H17 -> icon_03 | I18: 0 | J18: 2 | K18: =A19 -> 10203 | L18: 12:8000|10101:3|10119:3|10122:3 | M18: =M17 -> 1:10000:1 | N18: =W18&$W$2&X18 -> 102:1 | O18: =MID(A18,3,1)+1 -> 3 | P18: =$R$1&R18&$Q$1&T18 -> 所有步兵攻击增加:1 | R18: =R17 -> 攻击 | T18: =RIGHT(N18,2) -> :1 | U18: =MID(P18,3,2) -> 步兵 | V18: 步兵攻击 | W18: =属性类型!G18 -> 102 | X18: 1
A19: =A18+1 -> 10203 | B19: =ROUND(A19,-2) -> 10200 | C19: =LEFT(A19,1) -> 1 | D19: =$A$4+F19 -> 10001 | E19: 1 | F19: =MID(B19,2,1)+1 -> 1 | G19: =G18 -> 初级攻击 | H19: =H18 -> icon_03 | I19: 0 | J19: 3 | K19: =A20 -> 10204 | L19: 12:10000|10101:4|10119:4|10122:4 | M19: =M18 -> 1:10000:1 | N19: =W19&$W$2&X19 -> 102:1 | O19: =MID(A19,3,1)+1 -> 3 | P19: =$R$1&R19&$Q$1&T19 -> 所有步兵攻击增加:1 | R19: =R18 -> 攻击 | T19: =RIGHT(N19,2) -> :1 | U19: =MID(P19,3,2) -> 步兵 | V19: 步兵攻击 | W19: =属性类型!G19 -> 102 | X19: 1
A20: =A19+1 -> 10204 | B20: =ROUND(A20,-2) -> 10200 | C20: =LEFT(A20,1) -> 1 | D20: =$A$4+F20 -> 10001 | E20: 1 | F20: =MID(B20,2,1)+1 -> 1 | G20: =G19 -> 初级攻击 | H20: =H19 -> icon_03 | I20: 0 | J20: 4 | K20: =A21 -> 10205 | L20: 12:13000|10101:5|10119:5|10122:5 | M20: =M19 -> 1:10000:1 | N20: =W20&$W$2&X20 -> 102:1 | O20: =MID(A20,3,1)+1 -> 3 | P20: =$R$1&R20&$Q$1&T20 -> 所有步兵攻击增加:1 | R20: =R19 -> 攻击 | T20: =RIGHT(N20,2) -> :1 | U20: =MID(P20,3,2) -> 步兵 | V20: 步兵攻击 | W20: =属性类型!G20 -> 102 | X20: 1
A21: =A20+1 -> 10205 | B21: =ROUND(A21,-2) -> 10200 | C21: =LEFT(A21,1) -> 1 | D21: =$A$4+F21 -> 10001 | E21: 1 | F21: =MID(B21,2,1)+1 -> 1 | G21: =G20 -> 初级攻击 | H21: =H20 -> icon_03 | I21: 0 | J21: 5 | K21: 0 | L21: 0 | M21: =M20 -> 1:10000:1 | N21: =W21&$W$2&X21 -> 102:1 | O21: =MID(A21,3,1)+1 -> 3 | P21: =$R$1&R21&$Q$1&T21 -> 所有步兵攻击增加:1 | R21: =R20 -> 攻击 | T21: =RIGHT(N21,2) -> :1 | U21: =MID(P21,3,2) -> 步兵 | V21: 步兵攻击 | W21: =属性类型!G21 -> 102 | X21: 1
A22: =A16+100 -> 10300 | B22: =ROUND(A22,-2) -> 10300 | C22: =LEFT(A22,1) -> 1 | D22: =$A$4+F22 -> 10001 | E22: 1 | F22: =MID(B22,2,1)+1 -> 1 | G22: 初级魔防 | H22: icon_04 | I22: 0 | J22: 0 | K22: =A23 -> 10301 | L22: 12:5000|10101:1|10119:1|10122:1 | M22: 1:10000:1 | N22: =W22&$W$2&X22 -> 104:1 | O22: =MID(A22,3,1)+1 -> 4 | P22: =$R$1&R22&$Q$1&T22 -> 所有步兵魔防增加:1 | R22: 魔防 | T22: =RIGHT(N22,2) -> :1 | U22: =MID(P22,3,2) -> 步兵 | V22: 步兵魔防 | W22: =属性类型!G22 -> 104 | X22: 1
A23: =A22+1 -> 10301 | B23: =ROUND(A23,-2) -> 10300 | C23: =LEFT(A23,1) -> 1 | D23: =$A$4+F23 -> 10001 | E23: 1 | F23: =MID(B23,2,1)+1 -> 1 | G23: =G22 -> 初级魔防 | H23: =H22 -> icon_04 | I23: 0 | J23: 1 | K23: =A24 -> 10302 | L23: 12:6000|10101:2|10119:2|10122:2 | M23: =M22 -> 1:10000:1 | N23: =W23&$W$2&X23 -> 104:1 | O23: =MID(A23,3,1)+1 -> 4 | P23: =$R$1&R23&$Q$1&T23 -> 所有步兵魔防增加:1 | R23: =R22 -> 魔防 | T23: =RIGHT(N23,2) -> :1 | U23: =MID(P23,3,2) -> 步兵 | V23: 步兵魔防 | W23: =属性类型!G23 -> 104 | X23: 1
A24: =A23+1 -> 10302 | B24: =ROUND(A24,-2) -> 10300 | C24: =LEFT(A24,1) -> 1 | D24: =$A$4+F24 -> 10001 | E24: 1 | F24: =MID(B24,2,1)+1 -> 1 | G24: =G23 -> 初级魔防 | H24: =H23 -> icon_04 | I24: 0 | J24: 2 | K24: =A25 -> 10303 | L24: 12:8000|10101:3|10119:3|10122:3 | M24: =M23 -> 1:10000:1 | N24: =W24&$W$2&X24 -> 104:1 | O24: =MID(A24,3,1)+1 -> 4 | P24: =$R$1&R24&$Q$1&T24 -> 所有步兵魔防增加:1 | R24: =R23 -> 魔防 | T24: =RIGHT(N24,2) -> :1 | U24: =MID(P24,3,2) -> 步兵 | V24: 步兵魔防 | W24: =属性类型!G24 -> 104 | X24: 1
A25: =A24+1 -> 10303 | B25: =ROUND(A25,-2) -> 10300 | C25: =LEFT(A25,1) -> 1 | D25: =$A$4+F25 -> 10001 | E25: 1 | F25: =MID(B25,2,1)+1 -> 1 | G25: =G24 -> 初级魔防 | H25: =H24 -> icon_04 | I25: 0 | J25: 3 | K25: =A26 -> 10304 | L25: 12:10000|10101:4|10119:4|10122:4 | M25: =M24 -> 1:10000:1 | N25: =W25&$W$2&X25 -> 104:1 | O25: =MID(A25,3,1)+1 -> 4 | P25: =$R$1&R25&$Q$1&T25 -> 所有步兵魔防增加:1 | R25: =R24 -> 魔防 | T25: =RIGHT(N25,2) -> :1 | U25: =MID(P25,3,2) -> 步兵 | V25: 步兵魔防 | W25: =属性类型!G25 -> 104 | X25: 1
A26: =A25+1 -> 10304 | B26: =ROUND(A26,-2) -> 10300 | C26: =LEFT(A26,1) -> 1 | D26: =$A$4+F26 -> 10001 | E26: 1 | F26: =MID(B26,2,1)+1 -> 1 | G26: =G25 -> 初级魔防 | H26: =H25 -> icon_04 | I26: 0 | J26: 4 | K26: =A27 -> 10305 | L26: 12:13000|10101:5|10119:5|10122:5 | M26: =M25 -> 1:10000:1 | N26: =W26&$W$2&X26 -> 104:1 | O26: =MID(A26,3,1)+1 -> 4 | P26: =$R$1&R26&$Q$1&T26 -> 所有步兵魔防增加:1 | R26: =R25 -> 魔防 | T26: =RIGHT(N26,2) -> :1 | U26: =MID(P26,3,2) -> 步兵 | V26: 步兵魔防 | W26: =属性类型!G26 -> 104 | X26: 1
A27: =A26+1 -> 10305 | B27: =ROUND(A27,-2) -> 10300 | C27: =LEFT(A27,1) -> 1 | D27: =$A$4+F27 -> 10001 | E27: 1 | F27: =MID(B27,2,1)+1 -> 1 | G27: =G26 -> 初级魔防 | H27: =H26 -> icon_04 | I27: 0 | J27: 5 | K27: 0 | L27: 0 | M27: =M26 -> 1:10000:1 | N27: =W27&$W$2&X27 -> 104:1 | O27: =MID(A27,3,1)+1 -> 4 | P27: =$R$1&R27&$Q$1&T27 -> 所有步兵魔防增加:1 | R27: =R26 -> 魔防 | T27: =RIGHT(N27,2) -> :1 | U27: =MID(P27,3,2) -> 步兵 | V27: 步兵魔防 | W27: =属性类型!G27 -> 104 | X27: 1
A28: =A22+100 -> 10400 | B28: =ROUND(A28,-2) -> 10400 | C28: =LEFT(A28,1) -> 1 | D28: =$A$4+F28 -> 10001 | E28: 1 | F28: =MID(B28,2,1)+1 -> 1 | G28: 初级防御百分比 | H28: icon_05 | I28: 0 | J28: 0 | K28: =A29 -> 10401 | L28: 12:5000|10101:1|10119:1|10122:1 | M28: 1:10100:5 | N28: =W28&$W$2&X28 -> 108:1 | O28: =MID(A28,3,1)+1 -> 5 | P28: =$R$1&R28&$Q$1&T28 -> 所有步兵防御百分比增加1 | R28: 防御百分比 | T28: =RIGHT(N28,1) -> 1 | U28: =MID(P28,3,2) -> 步兵 | V28: 步兵防御百分比 | W28: =属性类型!G28 -> 108 | X28: 1
A29: =A28+1 -> 10401 | B29: =ROUND(A29,-2) -> 10400 | C29: =LEFT(A29,1) -> 1 | D29: =$A$4+F29 -> 10001 | E29: 1 | F29: =MID(B29,2,1)+1 -> 1 | G29: =G28 -> 初级防御百分比 | H29: =H28 -> icon_05 | I29: 0 | J29: 1 | K29: =A30 -> 10402 | L29: 12:6000|10101:2|10119:2|10122:2 | M29: =M28 -> 1:10100:5 | N29: =W29&$W$2&X29 -> 108:1 | O29: =MID(A29,3,1)+1 -> 5 | P29: =$R$1&R29&$Q$1&T29 -> 所有步兵防御百分比增加:1 | R29: =R28 -> 防御百分比 | T29: =RIGHT(N29,2) -> :1 | U29: =MID(P29,3,2) -> 步兵 | V29: 步兵防御百分比 | W29: =属性类型!G29 -> 108 | X29: 1
A30: =A29+1 -> 10402 | B30: =ROUND(A30,-2) -> 10400 | C30: =LEFT(A30,1) -> 1 | D30: =$A$4+F30 -> 10001 | E30: 1 | F30: =MID(B30,2,1)+1 -> 1 | G30: =G29 -> 初级防御百分比 | H30: =H29 -> icon_05 | I30: 0 | J30: 2 | K30: =A31 -> 10403 | L30: 12:8000|10101:3|10119:3|10122:3 | M30: =M29 -> 1:10100:5 | N30: =W30&$W$2&X30 -> 108:1 | O30: =MID(A30,3,1)+1 -> 5 | P30: =$R$1&R30&$Q$1&T30 -> 所有步兵防御百分比增加:1 | R30: =R29 -> 防御百分比 | T30: =RIGHT(N30,2) -> :1 | U30: =MID(P30,3,2) -> 步兵 | V30: 步兵防御百分比 | W30: =属性类型!G30 -> 108 | X30: 1
A31: =A30+1 -> 10403 | B31: =ROUND(A31,-2) -> 10400 | C31: =LEFT(A31,1) -> 1 | D31: =$A$4+F31 -> 10001 | E31: 1 | F31: =MID(B31,2,1)+1 -> 1 | G31: =G30 -> 初级防御百分比 | H31: =H30 -> icon_05 | I31: 0 | J31: 3 | K31: =A32 -> 10404 | L31: 12:10000|10101:4|10119:4|10122:4 | M31: =M30 -> 1:10100:5 | N31: =W31&$W$2&X31 -> 108:1 | O31: =MID(A31,3,1)+1 -> 5 | P31: =$R$1&R31&$Q$1&T31 -> 所有步兵防御百分比增加:1 | R31: =R30 -> 防御百分比 | T31: =RIGHT(N31,2) -> :1 | U31: =MID(P31,3,2) -> 步兵 | V31: 步兵防御百分比 | W31: =属性类型!G31 -> 108 | X31: 1
A32: =A31+1 -> 10404 | B32: =ROUND(A32,-2) -> 10400 | C32: =LEFT(A32,1) -> 1 | D32: =$A$4+F32 -> 10001 | E32: 1 | F32: =MID(B32,2,1)+1 -> 1 | G32: =G31 -> 初级防御百分比 | H32: =H31 -> icon_05 | I32: 0 | J32: 4 | K32: =A33 -> 10405 | L32: 12:13000|10101:5|10119:5|10122:5 | M32: =M31 -> 1:10100:5 | N32: =W32&$W$2&X32 -> 108:1 | O32: =MID(A32,3,1)+1 -> 5 | P32: =$R$1&R32&$Q$1&T32 -> 所有步兵防御百分比增加:1 | R32: =R31 -> 防御百分比 | T32: =RIGHT(N32,2) -> :1 | U32: =MID(P32,3,2) -> 步兵 | V32: 步兵防御百分比 | W32: =属性类型!G32 -> 108 | X32: 1
A33: =A32+1 -> 10405 | B33: =ROUND(A33,-2) -> 10400 | C33: =LEFT(A33,1) -> 1 | D33: =$A$4+F33 -> 10001 | E33: 1 | F33: =MID(B33,2,1)+1 -> 1 | G33: =G32 -> 初级防御百分比 | H33: =H32 -> icon_05 | I33: 0 | J33: 5 | K33: =A34 -> 10406 | L33: 12:16000|10101:7|10119:7|10122:7 | M33: =M32 -> 1:10100:5 | N33: =W33&$W$2&X33 -> 108:1 | O33: =MID(A33,3,1)+1 -> 5 | P33: =$R$1&R33&$Q$1&T33 -> 所有步兵防御百分比增加:1 | R33: =R32 -> 防御百分比 | T33: =RIGHT(N33,2) -> :1 | U33: =MID(P33,3,2) -> 步兵 | V33: 步兵防御百分比 | W33: =属性类型!G33 -> 108 | X33: 1
A34: =A33+1 -> 10406 | B34: =ROUND(A34,-2) -> 10400 | C34: =LEFT(A34,1) -> 1 | D34: =$A$4+F34 -> 10001 | E34: 1 | F34: =MID(B34,2,1)+1 -> 1 | G34: =G33 -> 初级防御百分比 | H34: =H33 -> icon_05 | I34: 0 | J34: 6 | K34: =A35 -> 10407 | L34: 12:20000|10101:9|10119:9|10122:9 | M34: =M33 -> 1:10100:5 | N34: =W34&$W$2&X34 -> 108:1 | O34: =MID(A34,3,1)+1 -> 5 | P34: =$R$1&R34&$Q$1&T34 -> 所有步兵防御百分比增加:1 | R34: =R33 -> 防御百分比 | T34: =RIGHT(N34,2) -> :1 | U34: =MID(P34,3,2) -> 步兵 | V34: 步兵防御百分比 | W34: =属性类型!G34 -> 108 | X34: 1
A35: =A34+1 -> 10407 | B35: =ROUND(A35,-2) -> 10400 | C35: =LEFT(A35,1) -> 1 | D35: =$A$4+F35 -> 10001 | E35: 1 | F35: =MID(B35,2,1)+1 -> 1 | G35: =G34 -> 初级防御百分比 | H35: =H34 -> icon_05 | I35: 0 | J35: 7 | K35: =A36 -> 10408 | L35: 12:25000|10101:11|10119:11|10122:11 | M35: =M34 -> 1:10100:5 | N35: =W35&$W$2&X35 -> 108:1 | O35: =MID(A35,3,1)+1 -> 5 | P35: =$R$1&R35&$Q$1&T35 -> 所有步兵防御百分比增加:1 | R35: =R34 -> 防御百分比 | T35: =RIGHT(N35,2) -> :1 | U35: =MID(P35,3,2) -> 步兵 | V35: 步兵防御百分比 | W35: =属性类型!G35 -> 108 | X35: 1
A36: =A35+1 -> 10408 | B36: =ROUND(A36,-2) -> 10400 | C36: =LEFT(A36,1) -> 1 | D36: =$A$4+F36 -> 10001 | E36: 1 | F36: =MID(B36,2,1)+1 -> 1 | G36: =G35 -> 初级防御百分比 | H36: =H35 -> icon_05 | I36: 0 | J36: 8 | K36: =A37 -> 10409 | L36: 12:31000|10101:13|10119:13|10122:13 | M36: =M35 -> 1:10100:5 | N36: =W36&$W$2&X36 -> 108:1 | O36: =MID(A36,3,1)+1 -> 5 | P36: =$R$1&R36&$Q$1&T36 -> 所有步兵防御百分比增加:1 | R36: =R35 -> 防御百分比 | T36: =RIGHT(N36,2) -> :1 | U36: =MID(P36,3,2) -> 步兵 | V36: 步兵防御百分比 | W36: =属性类型!G36 -> 108 | X36: 1
A37: =A36+1 -> 10409 | B37: =ROUND(A37,-2) -> 10400 | C37: =LEFT(A37,1) -> 1 | D37: =$A$4+F37 -> 10001 | E37: 1 | F37: =MID(B37,2,1)+1 -> 1 | G37: =G36 -> 初级防御百分比 | H37: =H36 -> icon_05 | I37: 0 | J37: 9 | K37: =A38 -> 10410 | L37: 12:39000|10101:15|10119:15|10122:15 | M37: =M36 -> 1:10100:5 | N37: =W37&$W$2&X37 -> 108:1 | O37: =MID(A37,3,1)+1 -> 5 | P37: =$R$1&R37&$Q$1&T37 -> 所有步兵防御百分比增加:1 | R37: =R36 -> 防御百分比 | T37: =RIGHT(N37,2) -> :1 | U37: =MID(P37,3,2) -> 步兵 | V37: 步兵防御百分比 | W37: =属性类型!G37 -> 108 | X37: 1
A38: =A37+1 -> 10410 | B38: =ROUND(A38,-2) -> 10400 | C38: =LEFT(A38,1) -> 1 | D38: =$A$4+F38 -> 10001 | E38: 1 | F38: =MID(B38,2,1)+1 -> 1 | G38: =G37 -> 初级防御百分比 | H38: =H37 -> icon_05 | I38: 0 | J38: 10 | K38: 0 | L38: 0 | M38: =M37 -> 1:10100:5 | N38: =W38&$W$2&X38 -> 108:1 | O38: =MID(A38,3,1)+1 -> 5 | P38: =$R$1&R38&$Q$1&T38 -> 所有步兵防御百分比增加:1 | R38: =R37 -> 防御百分比 | T38: =RIGHT(N38,2) -> :1 | U38: =MID(P38,3,2) -> 步兵 | V38: 步兵防御百分比 | W38: =属性类型!G38 -> 108 | X38: 1
A39: =A28+100 -> 10500 | B39: =ROUND(A39,-2) -> 10500 | C39: =LEFT(A39,1) -> 1 | D39: =$A$4+F39 -> 10001 | E39: 1 | F39: =MID(B39,2,1)+1 -> 1 | G39: 初级攻击百分比 | H39: icon_06 | I39: 0 | J39: 0 | K39: =A40 -> 10501 | L39: 12:5000|10101:1|10119:1|10122:1 | M39: 1:10200:5 | N39: =W39&$W$2&X39 -> 107:1 | O39: =MID(A39,3,1)+1 -> 6 | P39: =$R$1&R39&$Q$1&T39 -> 所有步兵攻击百分比增加1 | R39: 攻击百分比 | T39: =RIGHT(N39,1) -> 1 | U39: =MID(P39,3,2) -> 步兵 | V39: 步兵攻击百分比 | W39: =属性类型!G39 -> 107 | X39: 1
A40: =A39+1 -> 10501 | B40: =ROUND(A40,-2) -> 10500 | C40: =LEFT(A40,1) -> 1 | D40: =$A$4+F40 -> 10001 | E40: 1 | F40: =MID(B40,2,1)+1 -> 1 | G40: =G39 -> 初级攻击百分比 | H40: =H39 -> icon_06 | I40: 0 | J40: 1 | K40: =A41 -> 10502 | L40: 12:6000|10101:2|10119:2|10122:2 | M40: =M39 -> 1:10200:5 | N40: =W40&$W$2&X40 -> 107:1 | O40: =MID(A40,3,1)+1 -> 6 | P40: =$R$1&R40&$Q$1&T40 -> 所有步兵攻击百分比增加:1 | R40: =R39 -> 攻击百分比 | T40: =RIGHT(N40,2) -> :1 | U40: =MID(P40,3,2) -> 步兵 | V40: 步兵攻击百分比 | W40: =属性类型!G40 -> 107 | X40: 1
...

Sheet 加成属性
J1: 1级生命 | K1: 150 | L1: 1级攻击 | M1: 50 | N1: 1级防御 | O1: 30 | Q1: 各项百分比 | R1: 50
J2: 2级生命 | K2: 200 | L2: 2级攻击 | M2: 80 | N2: 2级防御 | O2: 50
A3: 科技等级 | B3: 科技阶段 | C3: 科技名称 | D3: 加成值 | J3: 3级生命 | K3: 300 | L3: 3级攻击 | M3: 120 | N3: 3级防御 | O3: 70
A4: 0 | B4: 1 | C4: 初级生命 | D4: 0
A5: 1 | B5: 1 | C5: 初级生命 | D5: 30
A6: 2 | B6: 1 | C6: 初级生命 | D6: 30
A7: 3 | B7: 1 | C7: 初级生命 | D7: 30
A8: 4 | B8: 1 | C8: 初级生命 | D8: 30
A9: 5 | B9: 1 | C9: 初级生命 | D9: 30
A10: 0 | B10: 1 | C10: 初级防御
A11: 1 | B11: 1 | C11: 初级防御
A12: 2 | B12: 1 | C12: 初级防御
A13: 3 | B13: 1 | C13: 初级防御
A14: 4 | B14: 1 | C14: 初级防御
A15: 5 | B15: 1 | C15: 初级防御
A16: 0 | B16: 1 | C16: 初级攻击
A17: 1 | B17: 1 | C17: 初级攻击
A18: 2 | B18: 1 | C18: 初级攻击
A19: 3 | B19: 1 | C19: 初级攻击
A20: 4 | B20: 1 | C20: 初级攻击
A21: 5 | B21: 1 | C21: 初级攻击
... A279: 20 | B279: 3 | C279: 高级生命百分比

Sheet 升级消耗
A1: 金币道具ID | B1: 12 | C1: : | D1: | | F1: 初级 | H1: 中级 | J1: 高级 | M1: 步兵 | N1: 骑兵 | O1: 弓兵 | P1: 飞兵 | Q1: 元素 | R1: 生物
A2: 金币基础基础 | B2: 1500 | C2: 品质系数 | D2: 3.4 | F2: 10119 | G2: 10122 | H2: 10120 | I2: 10121 | J2: 10123 | K2: 10124 | L2: =R2 -> 10106 | M2: 10101 | N2: 10102 | O2: 10103 | P2: 10104 | Q2: 10105 | R2: 10106
L3: =R3 -> 10112 | M3: 10107 | N3: 10108 | O3: 10109 | P3: 10110 | Q3: 10111 | R3: 10112
L4: =R4 -> 10118 | M4: 10113 | N4: 10114 | O4: 10115 | P4: 10116 | Q4: 10117 | R4: 10118
A5: 等级系数 | B5: 品质 | C5: 等级 | D5: 金币消耗 | E5: 士兵 | F5: 通用1 | G5: 通用2
A6: 1.25 | B6: 1 | C6: 1 | D6: =ROUND(B2*D2*B6,-3) -> 5000 | E6: 1 | F6: =E6 -> 1 | G6: =F6 -> 1 | H6: =$B$1&$C$1&D6 -> 12:5000 | I6: =$L$2&$C$1&E6 -> 10106:1 | J6: =$F$2&$C$1&F6 -> 10119:1 | K6: =$G$2&$C$1&G6 -> 10122:1 | L6: =H6&$D$1&I6&$D$1&J6&$D$1&K6 -> 12:5000|10106:1|10119:1|10122:1
B7: 1 | C7: 2 | D7: =ROUND(D6*$A$6,-3) -> 6000 | E7: 2 | F7: =E7 -> 2 | G7: =F7 -> 2 | H7: =$B$1&$C$1&D7 -> 12:6000 | I7: =$L$2&$C$1&E7 -> 10106:2 | J7: =$F$2&$C$1&F7 -> 10119:2 | K7: =$G$2&$C$1&G7 -> 10122:2 | L7: =H7&$D$1&I7&$D$1&J7&$D$1&K7 -> 12:6000|10106:2|10119:2|10122:2
B8: 1 | C8: 3 | D8: =ROUND(D7*$A$6,-3) -> 8000 | E8: 3 | F8: =E8 -> 3 | G8: =F8 -> 3 | H8: =$B$1&$C$1&D8 -> 12:8000 | I8: =$L$2&$C$1&E8 -> 10106:3 | J8: =$F$2&$C$1&F8 -> 10119:3 | K8: =$G$2&$C$1&G8 -> 10122:3 | L8: =H8&$D$1&I8&$D$1&J8&$D$1&K8 -> 12:8000|10106:3|10119:3|10122:3
B9: 1 | C9: 4 | D9: =ROUND(D8*$A$6,-3) -> 10000 | E9: 4 | F9: =E9 -> 4 | G9: =F9 -> 4 | H9: =$B$1&$C$1&D9 -> 12:10000 | I9: =$L$2&$C$1&E9 -> 10106:4 | J9: =$F$2&$C$1&F9 -> 10119:4 | K9: =$G$2&$C$1&G9 -> 10122:4 | L9: =H9&$D$1&I9&$D$1&J9&$D$1&K9 -> 12:10000|10106:4|10119:4|10122:4
B10: 1 | C10: 5 | D10: =ROUND(D9*$A$6,-3) -> 13000 | E10: 5 | F10: =E10 -> 5 | G10: =F10 -> 5 | H10: =$B$1&$C$1&D10 -> 12:13000 | I10: =$L$2&$C$1&E10 -> 10106:5 | J10: =$F$2&$C$1&F10 -> 10119:5 | K10: =$G$2&$C$1&G10 -> 10122:5 | L10: =H10&$D$1&I10&$D$1&J10&$D$1&K10 -> 12:13000|10106:5|10119:5|10122:5
B11: 1 | C11: 6 | D11: =ROUND(D10*$A$6,-3) -> 16000 | E11: 7 | F11: =E11 -> 7 | G11: =F11 -> 7 | H11: =$B$1&$C$1&D11 -> 12:16000 | I11: =$L$2&$C$1&E11 -> 10106:7 | J11: =$F$2&$C$1&F11 -> 10119:7 | K11: =$G$2&$C$1&G11 -> 10122:7 | L11: =H11&$D$1&I11&$D$1&J11&$D$1&K11 -> 12:16000|10106:7|10119:7|10122:7
B12: 1 | C12: 7 | D12: =ROUND(D11*$A$6,-3) -> 20000 | E12: 9 | F12: =E12 -> 9 | G12: =F12 -> 9 | H12: =$B$1&$C$1&D12 -> 12:20000 | I12: =$L$2&$C$1&E12 -> 10106:9 | J12: =$F$2&$C$1&F12 -> 10119:9 | K12: =$G$2&$C$1&G12 -> 10122:9 | L12: =H12&$D$1&I12&$D$1&J12&$D$1&K12 -> 12:20000|10106:9|10119:9|10122:9
B13: 1 | C13: 8 | D13: =ROUND(D12*$A$6,-3) -> 25000 | E13: 11 | F13: =E13 -> 11 | G13: =F13 -> 11 | H13: =$B$1&$C$1&D13 -> 12:25000 | I13: =$L$2&$C$1&E13 -> 10106:11 | J13: =$F$2&$C$1&F13 -> 10119:11 | K13: =$G$2&$C$1&G13 -> 10122:11 | L13: =H13&$D$1&I13&$D$1&J13&$D$1&K13 -> 12:25000|10106:11|10119:11|10122:11
B14: 1 | C14: 9 | D14: =ROUND(D13*$A$6,-3) -> 31000 | E14: 13 | F14: =E14 -> 13 | G14: =F14 -> 13 | H14: =$B$1&$C$1&D14 -> 12:31000 | I14: =$L$2&$C$1&E14 -> 10106:13 | J14: =$F$2&$C$1&F14 -> 10119:13 | K14: =$G$2&$C$1&G14 -> 10122:13 | L14: =H14&$D$1&I14&$D$1&J14&$D$1&K14 -> 12:31000|10106:13|10119:13|10122:13
B15: 1 | C15: 10 | D15: =ROUND(D14*$A$6,-3) -> 39000 | E15: 15 | F15: =E15 -> 15 | G15: =F15 -> 15 | H15: =$B$1&$C$1&D15 -> 12:39000 | I15: =$L$2&$C$1&E15 -> 10106:15 | J15: =$F$2&$C$1&F15 -> 10119:15 | K15: =$G$2&$C$1&G15 -> 10122:15 | L15: =H15&$D$1&I15&$D$1&J15&$D$1&K15 -> 12:39000|10106:15|10119:15|10122:15
B16: 1 | C16: 11 | D16: =ROUND(D15*$A$6,-3) -> 49000 | E16: 17 | F16: =E16 -> 17 | G16: =F16 -> 17 | H16: =$B$1&$C$1&D16 -> 12:49000 | I16: =$L$2&$C$1&E16 -> 10106:17 | J16: =$F$2&$C$1&F16 -> 10119:17 | K16: =$G$2&$C$1&G16 -> 10122:17 | L16: =H16&$D$1&I16&$D$1&J16&$D$1&K16 -> 12:49000|10106:17|10119:17|10122:17
B17: 1 | C17: 12 | D17: =ROUND(D16*$A$6,-3) -> 61000 | E17: 19 | F17: =E17 -> 19 | G17: =F17 -> 19 | H17: =$B$1&$C$1&D17 -> 12:61000 | I17: =$L$2&$C$1&E17 -> 10106:19 | J17: =$F$2&$C$1&F17 -> 10119:19 | K17: =$G$2&$C$1&G17 -> 10122:19 | L17: =H17&$D$1&I17&$D$1&J17&$D$1&K17 -> 12:61000|10106:19|10119:19|10122:19
B18: 1 | C18: 13 | D18: =ROUND(D17*$A$6,-3) -> 76000 | E18: 21 | F18: =E18 -> 21 | G18: =F18 -> 21 | H18: =$B$1&$C$1&D18 -> 12:76000 | I18: =$L$2&$C$1&E18 -> 10106:21 | J18: =$F$2&$C$1&F18 -> 10119:21 | K18: =$G$2&$C$1&G18 -> 10122:21 | L18: =H18&$D$1&I18&$D$1&J18&$D$1&K18 -> 12:76000|10106:21|10119:21|10122:21
... B25: 1 | C25: 20 | D25: =ROUND(D24*$A$6,-3) -> 364000 | E25: 35 | F25: =E25 -> 35 | G25: =F25 -> 35 | H25: =$B$1&$C$1&D25 -> 12:364000 | I25: =$L$2&$C$1&E25 -> 10106:35 | J25: =$F$2&$C$1&F25 -> 10119:35 | K25: =$G$2&$C$1&G25 -> 10122:35 | L25: =H25&$D$1&I25&$D$1&J25&$D$1&K25 -> 12:364000|10106:35|10119:35|10122:35
A26: 等级系数 | B26: 2 | C26: 1 | D26: =ROUND(B2*D2*B26,-3) -> 10000 | E26: 1 | F26: =E26 -> 1 | G26: =F26 -> 1 | H26: =$B$1&$C$1&D26 -> 12:10000 | I26: =$L$3&$C$1&E26 -> 10112:1 | J26: =$H$2&$C$1&F26 -> 10120:1 | K26: =$I$2&$C$1&G26 -> 10121:1 | L26: =H26&$D$1&I26&$D$1&J26&$D$1&K26 -> 12:10000|10112:1|10120:1|10121:1
A27: 1.26 | B27: 2 | C27: 2 | D27: =ROUND(D26*$A$27,-3) -> 13000 | E27: 3 | F27: =E27 -> 3 | G27: =F27 -> 3 | H27: =$B$1&$C$1&D27 -> 12:13000 | I27: =$L$3&$C$1&E27 -> 10112:3 | J27: =$H$2&$C$1&F27 -> 10120:3 | K27: =$I$2&$C$1&G27 -> 10121:3 | L27: =H27&$D$1&I27&$D$1&J27&$D$1&K27 -> 12:13000|10112:3|10120:3|10121:3
B28: 2 | C28: 3 | D28: =ROUND(D27*$A$27,-3) -> 16000 | E28: 5 | F28: =E28 -> 5 | G28: =F28 -> 5 | H28: =$B$1&$C$1&D28 -> 12:16000 | I28: =$L$3&$C$1&E28 -> 10112:5 | J28: =$H$2&$C$1&F28 -> 10120:5 | K28: =$I$2&$C$1&G28 -> 10121:5 | L28: =H28&$D$1&I28&$D$1&J28&$D$1&K28 -> 12:16000|10112:5|10120:5|10121:5
B29: 2 | C29: 4 | D29: =ROUND(D28*$A$27,-3) -> 20000 | E29: 7 | F29: =E29 -> 7 | G29: =F29 -> 7 | H29: =$B$1&$C$1&D29 -> 12:20000 | I29: =$L$3&$C$1&E29 -> 10112:7 | J29: =$H$2&$C$1&F29 -> 10120:7 | K29: =$I$2&$C$1&G29 -> 10121:7 | L29: =H29&$D$1&I29&$D$1&J29&$D$1&K29 -> 12:20000|10112:7|10120:7|10121:7
B30: 2 | C30: 5 | D30: =ROUND(D29*$A$27,-3) -> 25000 | E30: 9 | F30: =E30 -> 9 | G30: =F30 -> 9 | H30: =$B$1&$C$1&D30 -> 12:25000 | I30: =$L$3&$C$1&E30 -> 10112:9 | J30: =$H$2&$C$1&F30 -> 10120:9 | K30: =$I$2&$C$1&G30 -> 10121:9 | L30: =H30&$D$1&I30&$D$1&J30&$D$1&K30 -> 12:25000|10112:9|10120:9|10121:9
B31: 2 | C31: 6 | D31: =ROUND(D30*$A$27,-3) -> 32000 | E31: 11 | F31: =E31 -> 11 | G31: =F31 -> 11 | H31: =$B$1&$C$1&D31 -> 12:32000 | I31: =$L$3&$C$1&E31 -> 10112:11 | J31: =$H$2&$C$1&F31 -> 10120:11 | K31: =$I$2&$C$1&G31 -> 10121:11 | L31: =H31&$D$1&I31&$D$1&J31&$D$1&K31 -> 12:32000|10112:11|10120:11|10121:11
B32: 2 | C32: 7 | D32: =ROUND(D31*$A$27,-3) -> 40000 | E32: 13 | F32: =E32 -> 13 | G32: =F32 -> 13 | H32: =$B$1&$C$1&D32 -> 12:40000 | I32: =$L$3&$C$1&E32 -> 10112:13 | J32: =$H$2&$C$1&F32 -> 10120:13 | K32: =$I$2&$C$1&G32 -> 10121:13 | L32: =H32&$D$1&I32&$D$1&J32&$D$1&K32 -> 12:40000|10112:13|10120:13|10121:13
B33: 2 | C33: 8 | D33: =ROUND(D32*$A$27,-3) -> 50000 | E33: 15 | F33: =E33 -> 15 | G33: =F33 -> 15 | H33: =$B$1&$C$1&D33 -> 12:50000 | I33: =$L$3&$C$1&E33 -> 10112:15 | J33: =$H$2&$C$1&F33 -> 10120:15 | K33: =$I$2&$C$1&G33 -> 10121:15 | L33: =H33&$D$1&I33&$D$1&J33&$D$1&K33 -> 12:50000|10112:15|10120:15|10121:15
B34: 2 | C34: 9 | D34: =ROUND(D33*$A$27,-3) -> 63000 | E34: 18 | F34: =E34 -> 18 | G34: =F34 -> 18 | H34: =$B$1&$C$1&D34 -> 12:63000 | I34: =$L$3&$C$1&E34 -> 10112:18 | J34: =$H$2&$C$1&F34 -> 10120:18 | K34: =$I$2&$C$1&G34 -> 10121:18 | L34: =H34&$D$1&I34&$D$1&J34&$D$1&K34 -> 12:63000|10112:18|10120:18|10121:18
B35: 2 | C35: 10 | D35: =ROUND(D34*$A$27,-3) -> 79000 | E35: 21 | F35: =E35 -> 21 | G35: =F35 -> 21 | H35: =$B$1&$C$1&D35 -> 12:79000 | I35: =$L$3&$C$1&E35 -> 10112:21 | J35: =$H$2&$C$1&F35 -> 10120:21 | K35: =$I$2&$C$1&G35 -> 10121:21 | L35: =H35&$D$1&I35&$D$1&J35&$D$1&K35 -> 12:79000|10112:21|10120:21|10121:21
B36: 2 | C36: 11 | D36: =ROUND(D35*$A$27,-3) -> 100000 | E36: 24 | F36: =E36 -> 24 | G36: =F36 -> 24 | H36: =$B$1&$C$1&D36 -> 12:100000 | I36: =$L$3&$C$1&E36 -> 10112:24 | J36: =$H$2&$C$1&F36 -> 10120:24 | K36: =$I$2&$C$1&G36 -> 10121:24 | L36: =H36&$D$1&I36&$D$1&J36&$D$1&K36 -> 12:100000|10112:24|10120:24|10121:24
B37: 2 | C37: 12 | D37: =ROUND(D36*$A$27,-3) -> 126000 | E37: 27 | F37: =E37 -> 27 | G37: =F37 -> 27 | H37: =$B$1&$C$1&D37 -> 12:126000 | I37: =$L$3&$C$1&E37 -> 10112:27 | J37: =$H$2&$C$1&F37 -> 10120:27 | K37: =$I$2&$C$1&G37 -> 10121:27 | L37: =H37&$D$1&I37&$D$1&J37&$D$1&K37 -> 12:126000|10112:27|10120:27|10121:27
B38: 2 | C38: 13 | D38: =ROUND(D37*$A$27,-3) -> 159000 | E38: 30 | F38: =E38 -> 30 | G38: =F38 -> 30 | H38: =$B$1&$C$1&D38 -> 12:159000 | I38: =$L$3&$C$1&E38 -> 10112:30 | J38: =$H$2&$C$1&F38 -> 10120:30 | K38: =$I$2&$C$1&G38 -> 10121:30 | L38: =H38&$D$1&I38&$D$1&J38&$D$1&K38 -> 12:159000|10112:30|10120:30|10121:30
B39: 2 | C39: 14 | D39: =ROUND(D38*$A$27,-3) -> 200000 | E39: 33 | F39: =E39 -> 33 | G39: =F39 -> 33 | H39: =$B$1&$C$1&D39 -> 12:200000 | I39: =$L$3&$C$1&E39 -> 10112:33 | J39: =$H$2&$C$1&F39 -> 10120:33 | K39: =$I$2&$C$1&G39 -> 10121:33 | L39: =H39&$D$1&I39&$D$1&J39&$D$1&K39 -> 12:200000|10112:33|10120:33|10121:33
... B45: 2 | C45: 20 | D45: =ROUND(D44*$A$27,-3) -> 801000 | E45: 50 | F45: =E45 -> 50 | G45: =F45 -> 50 | H45: =$B$1&$C$1&D45 -> 12:801000 | I45: =$L$3&$C$1&E45 -> 10112:50 | J45: =$H$2&$C$1&F45 -> 10120:50 | K45: =$I$2&$C$1&G45 -> 10121:50 | L45: =H45&$D$1&I45&$D$1&J45&$D$1&K45 -> 12:801000|10112:50|10120:50|10121:50
A46: 等级系数 | B46: 3 | C46: 1 | D46: =ROUND(B2*D2*B46,-3) -> 15000 | E46: 5 | F46: =E46 -> 5 | G46: =F46 -> 5 | H46: =$B$1&$C$1&D46 -> 12:15000 | I46: =$L$4&$C$1&E46 -> 10118:5 | J46: =$J$2&$C$1&F46 -> 10123:5 | K46: =$K$2&$C$1&G46 -> 10124:5 | L46: =H46&$D$1&I46&$D$1&J46&$D$1&K46 -> 12:15000|10118:5|10123:5|10124:5
A47: 1.3 | B47: 3 | C47: 2 | D47: =ROUND(D46*$A$47,-3) -> 20000 | E47: 10 | F47: =E47 -> 10 | G47: =F47 -> 10 | H47: =$B$1&$C$1&D47 -> 12:20000 | I47: =$L$4&$C$1&E47 -> 10118:10 | J47: =$J$2&$C$1&F47 -> 10123:10 | K47: =$K$2&$C$1&G47 -> 10124:10 | L47: =H47&$D$1&I47&$D$1&J47&$D$1&K47 -> 12:20000|10118:10|10123:10|10124:10
B48: 3 | C48: 3 | D48: =ROUND(D47*$A$47,-3) -> 26000 | E48: 15 | F48: =E48 -> 15 | G48: =F48 -> 15 | H48: =$B$1&$C$1&D48 -> 12:26000 | I48: =$L$4&$C$1&E48 -> 10118:15 | J48: =$J$2&$C$1&F48 -> 10123:15 | K48: =$K$2&$C$1&G48 -> 10124:15 | L48: =H48&$D$1&I48&$D$1&J48&$D$1&K48 -> 12:26000|10118:15|10123:15|10124:15
B49: 3 | C49: 4 | D49: =ROUND(D48*$A$47,-3) -> 34000 | E49: 20 | F49: =E49 -> 20 | G49: =F49 -> 20 | H49: =$B$1&$C$1&D49 -> 12:34000 | I49: =$L$4&$C$1&E49 -> 10118:20 | J49: =$J$2&$C$1&F49 -> 10123:20 | K49: =$K$2&$C$1&G49 -> 10124:20 | L49: =H49&$D$1&I49&$D$1&J49&$D$1&K49 -> 12:34000|10118:20|10123:20|10124:20
B50: 3 | C50: 5 | D50: =ROUND(D49*$A$47,-3) -> 44000 | E50: 25 | F50: =E50 -> 25 | G50: =F50 -> 25 | H50: =$B$1&$C$1&D50 -> 12:44000 | I50: =$L$4&$C$1&E50 -> 10118:25 | J50: =$J$2&$C$1&F50 -> 10123:25 | K50: =$K$2&$C$1&G50 -> 10124:25 | L50: =H50&$D$1&I50&$D$1&J50&$D$1&K50 -> 12:44000|10118:25|10123:25|10124:25
B51: 3 | C51: 6 | D51: =ROUND(D50*$A$47,-3) -> 57000 | E51: 30 | F51: =E51 -> 30 | G51: =F51 -> 30 | H51: =$B$1&$C$1&D51 -> 12:57000 | I51: =$L$4&$C$1&E51 -> 10118:30 | J51: =$J$2&$C$1&F51 -> 10123:30 | K51: =$K$2&$C$1&G51 -> 10124:30 | L51: =H51&$D$1&I51&$D$1&J51&$D$1&K51 -> 12:57000|10118:30|10123:30|10124:30
...

Sheet 属性类型
A1: Attributeid | B1: type | C1: Desc | D1: TypeHero
A2: int | B2: int | C2: string | D2: int
A3: 属性id | B3: 属性类型 | C3: 属性名称 | D3: 职业 | F3: 属性名称 | G3: 属性id
A4: 1 | B4: 1 | C4: 生命 | D4: 0 | F4: 步兵生命 | G4: =_xlfn.XLOOKUP(F4,$C$4:$C$220,$A$4:$A$220) -> 101
A5: 2 | B5: 1 | C5: 攻击 | D5: 0 | F5: 步兵生命 | G5: =_xlfn.XLOOKUP(F5,$C$4:$C$220,$A$4:$A$220) -> 101
A6: 3 | B6: 1 | C6: 物防 | D6: 0 | F6: 步兵生命 | G6: =_xlfn.XLOOKUP(F6,$C$4:$C$220,$A$4:$A$220) -> 101
A7: 4 | B7: 1 | C7: 魔力 | D7: 0 | F7: 步兵生命 | G7: =_xlfn.XLOOKUP(F7,$C$4:$C$220,$A$4:$A$220) -> 101
A8: 5 | B8: 1 | C8: 移速 | D8: 0 | F8: 步兵生命 | G8: =_xlfn.XLOOKUP(F8,$C$4:$C$220,$A$4:$A$220) -> 101
A9: 6 | B9: 1 | C9: 射程 | D9: 0 | F9: 步兵生命 | G9: =_xlfn.XLOOKUP(F9,$C$4:$C$220,$A$4:$A$220) -> 101
A10: 7 | B10: 1 | C10: 攻速 | D10: 0 | F10: 步兵防御 | G10: =_xlfn.XLOOKUP(F10,$C$4:$C$220,$A$4:$A$220) -> 103
A11: 8 | B11: 2 | C11: 物免 | D11: 0 | F11: 步兵防御 | G11: =_xlfn.XLOOKUP(F11,$C$4:$C$220,$A$4:$A$220) -> 103
A12: 9 | B12: 2 | C12: 普攻增伤 | D12: 0 | F12: 步兵防御 | G12: =_xlfn.XLOOKUP(F12,$C$4:$C$220,$A$4:$A$220) -> 103
A13: 10 | B13: 2 | C13: 魔免 | D13: 0 | F13: 步兵防御 | G13: =_xlfn.XLOOKUP(F13,$C$4:$C$220,$A$4:$A$220) -> 103
A14: 11 | B14: 2 | C14: 法术增伤 | D14: 0 | F14: 步兵防御 | G14: =_xlfn.XLOOKUP(F14,$C$4:$C$220,$A$4:$A$220) -> 103
A15: 12 | B15: 2 | C15: 暴击 | D15: 0 | F15: 步兵防御 | G15: =_xlfn.XLOOKUP(F15,$C$4:$C$220,$A$4:$A$220) -> 103
... A37: 34 | B37: 2 | C37: 魔攻 | D37: 0 | F37: 步兵防御百分比 | G37: =_xlfn.XLOOKUP(F37,$C$4:$C$220,$A$4:$A$220) -> 108
A38: 35 | B38: =IF(J38="值",1,2) -> 2 | C38: 魔防 | D38: 0 | F38: 步兵防御百分比 | G38: =_xlfn.XLOOKUP(F38,$C$4:$C$220,$A$4:$A$220) -> 108
A39: 36 | B39: =IF(J39="值",1,2) -> 2 | C39: 士兵生命百分比 | D39: 0 | F39: 步兵攻击百分比 | G39: =_xlfn.XLOOKUP(F39,$C$4:$C$220,$A$4:$A$220) -> 107
A40: 37 | B40: =IF(J40="值",1,2) -> 2 | C40: 士兵攻击百分比 | D40: 0 | F40: 步兵攻击百分比 | G40: =_xlfn.XLOOKUP(F40,$C$4:$C$220,$A$4:$A$220) -> 107
A41: 38 | B41: =IF(J41="值",1,2) -> 2 | C41: 士兵防御百分比 | D41: 0 | F41: 步兵攻击百分比 | G41: =_xlfn.XLOOKUP(F41,$C$4:$C$220,$A$4:$A$220) -> 107
A42: 39 | B42: =IF(J42="值",1,2) -> 2 | C42: 士兵魔防百分比 | D42: 0 | F42: 步兵攻击百分比 | G42: =_xlfn.XLOOKUP(F42,$C$4:$C$220,$A$4:$A$220) -> 107
A43: 40 | B43: =IF(J43="值",1,2) -> 2 | C43: 士兵魔力百分比 | D43: 0 | F43: 步兵攻击百分比 | G43: =_xlfn.XLOOKUP(F43,$C$4:$C$220,$A$4:$A$220) -> 107
A44: 101 | B44: =IF(J44="值",1,2) -> 2 | C44: 步兵生命 | D44: 1 | F44: 步兵攻击百分比 | G44: =_xlfn.XLOOKUP(F44,$C$4:$C$220,$A$4:$A$220) -> 107
A45: 102 | B45: =IF(J45="值",1,2) -> 2 | C45: 步兵攻击 | D45: 1 | F45: 步兵攻击百分比 | G45: =_xlfn.XLOOKUP(F45,$C$4:$C$220,$A$4:$A$220) -> 107
A46: 103 | B46: =IF(J46="值",1,2) -> 2 | C46: 步兵防御 | D46: 1 | F46: 步兵攻击百分比 | G46: =_xlfn.XLOOKUP(F46,$C$4:$C$220,$A$4:$A$220) -> 107
A47: 104 | B47: =IF(J47="值",1,2) -> 2 | C47: 步兵魔防 | D47: 1 | F47: 步兵攻击百分比 | G47: =_xlfn.XLOOKUP(F47,$C$4:$C$220,$A$4:$A$220) -> 107
A48: 105 | B48: 1 | C48: 步兵魔力 | D48: 1 | F48: 步兵攻击百分比 | G48: =_xlfn.XLOOKUP(F48,$C$4:$C$220,$A$4:$A$220) -> 107
A49: 106 | B49: =IF(J49="值",1,2) -> 2 | C49: 步兵生命百分比 | D49: 1 | F49: 步兵攻击百分比 | G49: =_xlfn.XLOOKUP(F49,$C$4:$C$220,$A$4:$A$220) -> 107
A50: 107 | B50: =IF(J50="值",1,2) -> 2 | C50: 步兵攻击百分比 | D50: 1 | F50: 步兵魔防百分比 | G50: =_xlfn.XLOOKUP(F50,$C$4:$C$220,$A$4:$A$220) -> 109
A51: 108 | B51: =IF(J51="值",1,2) -> 2 | C51: 步兵防御百分比 | D51: 1 | F51: 步兵魔防百分比 | G51: =_xlfn.XLOOKUP(F51,$C$4:$C$220,$A$4:$A$220) -> 109
A52: 109 | B52: =IF(J52="值",1,2) -> 2 | C52: 步兵魔防百分比 | D52: 1 | F52: 步兵魔防百分比 | G52: =_xlfn.XLOOKUP(F52,$C$4:$C$220,$A$4:$A$220) -> 109
A53: 110 | B53: 1 | C53: 步兵魔力百分比 | D53: 1 | F53: 步兵魔防百分比 | G53: =_xlfn.XLOOKUP(F53,$C$4:$C$220,$A$4:$A$220) -> 109
A54: 111 | B54: =IF(J54="值",1,2) -> 2 | C54: 骑兵生命 | D54: =D44+1 -> 2 | F54: 步兵魔防百分比 | G54: =_xlfn.XLOOKUP(F54,$C$4:$C$220,$A$4:$A$220) -> 109
A55: 112 | B55: =IF(J55="值",1,2) -> 2 | C55: 骑兵攻击 | D55: =D45+1 -> 2 | F55: 步兵魔防百分比 | G55: =_xlfn.XLOOKUP(F55,$C$4:$C$220,$A$4:$A$220) -> 109
A56: 113 | B56: =IF(J56="值",1,2) -> 2 | C56: 骑兵防御 | D56: =D46+1 -> 2 | F56: 步兵魔防百分比 | G56: =_xlfn.XLOOKUP(F56,$C$4:$C$220,$A$4:$A$220) -> 109
A57: 114 | B57: =IF(J57="值",1,2) -> 2 | C57: 骑兵魔防 | D57: =D47+1 -> 2 | F57: 步兵魔防百分比 | G57: =_xlfn.XLOOKUP(F57,$C$4:$C$220,$A$4:$A$220) -> 109
A58: 115 | B58: =IF(J58="值",1,2) -> 2 | C58: 骑兵魔力 | D58: =D48+1 -> 2 | F58: 步兵魔防百分比 | G58: =_xlfn.XLOOKUP(F58,$C$4:$C$220,$A$4:$A$220) -> 109
A59: 116 | B59: =IF(J59="值",1,2) -> 2 | C59: 骑兵生命百分比 | D59: =D49+1 -> 2 | F59: 步兵魔防百分比 | G59: =_xlfn.XLOOKUP(F59,$C$4:$C$220,$A$4:$A$220) -> 109
A60: 117 | B60: =IF(J60="值",1,2) -> 2 | C60: 骑兵攻击百分比 | D60: =D50+1 -> 2 | F60: 步兵魔防百分比 | G60: =_xlfn.XLOOKUP(F60,$C$4:$C$220,$A$4:$A$220) -> 109
A61: 118 | B61: =IF(J61="值",1,2) -> 2 | C61: 骑兵防御百分比 | D61: =D51+1 -> 2 | F61: 皇室禁卫防御百分比 | G61: =_xlfn.XLOOKUP(F61,$C$4:$C$220,$A$4:$A$220) -> 10001
...
